Workbook
Name Adequacao_Imovel: 'Listas (não utilizar)'!$G$2:$G$7
Name ADEQUAR: 'Listas (não utilizar)'!$G$2:$G$7
Name Apartamento: 'Listas (não utilizar)'!$D$2:$D$21
Name APROVCEF: #REF!
Name Área: 'Listas (não utilizar)'!$A$2:$A$28
Name AREAS: #REF!
Name AVILDATA: #REF!
Name AVILDATA1: #REF!
Name BARCDATA: #REF!
Name BILBDATA: #REF!
Name Bloco: 'Listas (não utilizar)'!$C$2:$C$16
Name CEF: #REF!
Name CEUTDATA: #REF!
Name Condomínio: 'Listas (não utilizar)'!$B$2:$B$15
Name INDDEMAND: #REF!
Name INDEMAND: #REF!
Name it: #REF!
Name Pendência: 'Listas (não utilizar)'!$I$2:$I$7
Name PLANCCO: #REF!
Name Renúncia: 'Listas (não utilizar)'!$H$2:$H$6
Name RetornoSMADS: '[1]Listas (não utilizar)'!$E$2:$E$3
Name selogo: #REF!
Name selomv: #REF!
Name selos_go: #REF!
Name selosgo: #REF!
Name selosgo1: #REF!
Name SITAH_CAIXA: 'Listas (não utilizar)'!$E$2:$E$9
Name StatusCAIXA: 'Listas (não utilizar)'!$F$2:$F$5
Name TEPROC: #REF!
Name TEPROC1: #REF!

Sheet Listas (não utilizar)
A1: Área | B1: Condomínio | C1: Bloco | D1: Apartamento | E1: SITAH / CAIXA | F1: Status CAIXA | G1: Adequacao Imovel | H1: Renúncia | I1: Pendência | J1: Pendências / Reprovados caixa
A2: ALTO DA ALEGRIA | B2: AVILA | C2: 1 | D2: 101 | E2: AGENDADO | F2: APROVADO | G2: NÃO | H2: NÃO | I2: CRAS | J2: RENDA SUPERIOR
A3: ALTO DA ALEGRIA (OBRAS) | B3: BARCELONA | C3: 2 | D3: 102 | E3: AGUARDANDO OFICIO | F3: REPROVADO | G3: FÍSICA | H3: RENDA | I3: CRAS + DOCUMENTOS | J3: CADMUT
A4: ALTO DA ALEGRIA (RESERVA) | B4: BILBAO | C4: 3 | D4: 103 | E4: ATENDIMENTO CANCELADO | F4: PENDENCIA | G4: VISUAL | H4: CADIN | I4: DOCUMENTOS | J4: CADIN
A5: ANTERO GOMES | B5: CEUTA | C5: 4 | D5: 104 | E5: CADMUT | F5: SEM DOSSIE | G5: INTELECTUAL | H5: ESTADO CIVIL | I5: CADIN
A6: CANTINHO DO CEU / GAIVOTAS | B6: IBIZA | C6: 5 | D6: 201 | E6: CHACARA DO CONDE | G6: AUDITIVA | H6: SEPARACAO | I6: CRAS + CADIN
A7: CANTINHO DO CEU / OBRAS | B7: LEAO | C7: 6 | D7: 202 | E7: CONFLITO | G7: NANISMO | I7: R.LI.AV.
A8: CASTRO ALVES | B8: MADRID | C8: 7 | D8: 203 | E8: ENVIADO CAIXA | I8: IEME
A9: COCAIA | B9: MELILLA | C9: 8 | D9: 204 | E9: FALECEU
A10: ERUNDINA | B10: PAMPLONA | C10: 9 | D10: 301 | E10: FALTANTE DOSSIÊ
A11: FUMACA | B11: SALAMANCA | C11: 10 | D11: 302 | E11: HABISP ACERTO DE ÁREA
A12: GUAICURI (OBRAS) | B12: TERUEL | C12: 11 | D12: 303 | E12: HABISP AGUARDANDO CRÍTICA
A13: GUAICURI / CIDADE JULIA | B13: VALENCIA | C13: 12 | D13: 304 | E13: HABISP PEND DE ATUALIZ CADASTRAL
A14: JARDIM MIRNA | B14: VALVERDE | C14: 13 | D14: 401 | E14: INDENIZACAO
A15: JARDIM SELMA II | B15: VITORIA | C15: 14 | D15: 402 | E15: PENDENCIA
A16: JARDIM TUBO | C16: 15 | D16: 403 | E16: PERMUTA
A17: LEBLON | D17: 404 | E17: PESQUISA SMADS
A18: MARGINAL DOIS / FUNDAO | D18: 501 | E18: REANALISE
A19: MATA VIRGEM / JD ELDORADO | D19: 502 | E19: RECLUSO
A20: NEBLINA | D20: 503 | E20: RELATÓRIO SOCIAL
A21: NORONHA | D21: 504 | E21: RENDA SUPERIOR
A22: NOVA GRAJAU | E22: RESISTENTE
A23: NOVA MARILDA | E23: TROCA DE TITULARIDADE
A24: NOVA VARGINHA
A25: PABREU / PRAINHA
A26: PENDENCIA GABINETE
A27: PILAO / APURA
A28: PILAO / DOIS
A29: PILAO / PAULISTAS
A30: SANTA AMELIA
A31: VALE VERDE / MONTE VERDE
A32: VILA BREJINHO
A33: VILA NASCENTE
A34: ZR / COSTA BRANCA
A35: VILA RUBI

Sheet QUANT COND
A1: CONDOMINIOS | B1: QUANT
A2: AVILA | B2: =COUNTIF(#REF!,'QUANT COND'!A2) -> #REF!
A3: BARCELONA | B3: =COUNTIF(#REF!,'QUANT COND'!A3) -> #REF!
A4: BILBAO | B4: =COUNTIF(#REF!,'QUANT COND'!A4) -> #REF!
A5: CEUTA | B5: =COUNTIF(#REF!,'QUANT COND'!A5) -> #REF!
A6: IBIZA | B6: =COUNTIF(#REF!,'QUANT COND'!A6) -> #REF!
A7: LEAO | B7: =COUNTIF(#REF!,'QUANT COND'!A7) -> #REF!
A8: MADRID | B8: =COUNTIF(#REF!,'QUANT COND'!A8) -> #REF!
A9: MELILLA | B9: =COUNTIF(#REF!,'QUANT COND'!A9) -> #REF!
A10: PAMPLONA | B10: =COUNTIF(#REF!,'QUANT COND'!A10) -> #REF!
A11: SALAMANCA | B11: =COUNTIF(#REF!,'QUANT COND'!A11) -> #REF!
A12: TERUEL | B12: =COUNTIF(#REF!,'QUANT COND'!A12) -> #REF!
A13: VALENCIA | B13: =COUNTIF(#REF!,'QUANT COND'!A13) -> #REF!
... A15: VITORIA | B15: =COUNTIF(#REF!,'QUANT COND'!A15) -> #REF!

Sheet OFÍCIOS
A1: PLANILHA DE CONFRONTO OFÍCIOS DE INDICAÇÃO COM ENVIADOS CAIXA ECONÔMICA FEDERAL - CEF
A2: TITULAR | B2: CPF | C2: Cônjuge | D2: CPF | E2: OFÍCIO | F2: DATA | G2: STATUS CEF | H2: DATA ENVIO CAIXA | I2: DUPLICIDADE OFÍCIO | J2: DATA | K2: DATA ENVIO CAIXA | L2: OFÍCIO DE INDICAÇÃO | M2: DATA OFÍCIO INDICAÇÃO | O2: NR OFICIO | P2: QUANT | Q2: APROV | R2: REPROV | S2: PEND | T2: SEM STATUS (ANÁLISE) | Y2: CEF BD | Z2: CEF OFICIOS | AA2: CEF PLANILHA
A3: ABEL MEDEIROS FILHO | B3: 27140979871 | E3: 1128 | F3: 42972 | G3: APROVADO | H3: 42979 | O3: 810 | P3: =COUNTIF(OFÍCIOS!E:E,O3) -> 156 | Q3: =COUNTIFS(OFÍCIOS!$E:$E,$O3,OFÍCIOS!$G:$G,"APROVADO") -> 149 | R3: =COUNTIFS(OFÍCIOS!$E:$E,$O3,OFÍCIOS!$G:$G,"REPROVADO") -> 3 | S3: =COUNTIFS(OFÍCIOS!$E:$E,$O3,OFÍCIOS!$G:$G,"PENDENCIA") -> 2 | T3: =COUNTIFS(OFÍCIOS!$E:$E,$O3,OFÍCIOS!$G:$G,"") -> 2 | U3: =SUM(Q3:T3) -> 156 | X3: FEITOS | Y3: 1850 | Z3: 1827 | AA3: =SUM(AA4:AA7) -> 1615
A4: ABELINA FERREIRA DOS SANTOS | B4: 39200633846 | O4: 1417 | P4: =COUNTIF(OFÍCIOS!E:E,O4) -> 42 | Q4: =COUNTIFS(OFÍCIOS!$E:$E,$O4,OFÍCIOS!$G:$G,"APROVADO") -> 36 | R4: =COUNTIFS(OFÍCIOS!$E:$E,$O4,OFÍCIOS!$G:$G,"REPROVADO") -> 3 | S4: =COUNTIFS(OFÍCIOS!$E:$E,$O4,OFÍCIOS!$G:$G,"PENDENCIA") -> 3 | T4: =COUNTIFS(OFÍCIOS!$E:$E,$O4,OFÍCIOS!$G:$G,"") -> 0 | U4: =SUM(Q4:T4) -> 42 | X4: APROVADOS | Y4: 1517 | Z4: 1427 | AA4: 1559
A5: ABIGAIL DE OLIVEIRA PAULINO | B5: 75489104872 | E5: 1752 | F5: 43051 | G5: APROVADO | H5: 43089 | L5: 1759 | O5: 1359 | P5: =COUNTIF(OFÍCIOS!E:E,O5) -> 14 | Q5: =COUNTIFS(OFÍCIOS!$E:$E,$O5,OFÍCIOS!$G:$G,"APROVADO") -> 13 | R5: =COUNTIFS(OFÍCIOS!$E:$E,$O5,OFÍCIOS!$G:$G,"REPROVADO") -> 1 | S5: =COUNTIFS(OFÍCIOS!$E:$E,$O5,OFÍCIOS!$G:$G,"PENDENCIA") -> 0 | T5: =COUNTIFS(OFÍCIOS!$E:$E,$O5,OFÍCIOS!$G:$G,"") -> 0 | U5: =SUM(Q5:T5) -> 14 | X5: REPROVADOS | Y5: 73 | Z5: 79 | AA5: 28
A6: ABILIO OLIVEIRA SANTOS | B6: 43286003620 | O6: 1350 | P6: =COUNTIF(OFÍCIOS!E:E,O6) -> 79 | Q6: =COUNTIFS(OFÍCIOS!$E:$E,$O6,OFÍCIOS!$G:$G,"APROVADO") -> 75 | R6: =COUNTIFS(OFÍCIOS!$E:$E,$O6,OFÍCIOS!$G:$G,"REPROVADO") -> 3 | S6: =COUNTIFS(OFÍCIOS!$E:$E,$O6,OFÍCIOS!$G:$G,"PENDENCIA") -> 0 | T6: =COUNTIFS(OFÍCIOS!$E:$E,$O6,OFÍCIOS!$G:$G,"") -> 1 | U6: =SUM(Q6:T6) -> 79 | X6: PENDENCIAS | Y6: 36 | Z6: 32 | AA6: 11
A7: ABRAHAO SANTOS SILVA | O7: 1343 | P7: =COUNTIF(OFÍCIOS!E:E,O7) -> 6 | Q7: =COUNTIFS(OFÍCIOS!$E:$E,$O7,OFÍCIOS!$G:$G,"APROVADO") -> 5 | R7: =COUNTIFS(OFÍCIOS!$E:$E,$O7,OFÍCIOS!$G:$G,"REPROVADO") -> 0 | S7: =COUNTIFS(OFÍCIOS!$E:$E,$O7,OFÍCIOS!$G:$G,"PENDENCIA") -> 0 | T7: =COUNTIFS(OFÍCIOS!$E:$E,$O7,OFÍCIOS!$G:$G,"") -> 1 | U7: =SUM(Q7:T7) -> 6 | X7: SS / ANALISE | Y7: 224 | Z7: 275 | AA7: 17
A8: ADAIR DA SILVA BARROS | B8: 97443271620 | E8: 1106 | F8: 42965 | G8: APROVADO | H8: 42978 | O8: 1267 | P8: =COUNTIF(OFÍCIOS!E:E,O8) -> 34 | Q8: =COUNTIFS(OFÍCIOS!$E:$E,$O8,OFÍCIOS!$G:$G,"APROVADO") -> 28 | R8: =COUNTIFS(OFÍCIOS!$E:$E,$O8,OFÍCIOS!$G:$G,"REPROVADO") -> 5 | S8: =COUNTIFS(OFÍCIOS!$E:$E,$O8,OFÍCIOS!$G:$G,"PENDENCIA") -> 1 | T8: =COUNTIFS(OFÍCIOS!$E:$E,$O8,OFÍCIOS!$G:$G,"") -> 0 | U8: =SUM(Q8:T8) -> 34
A9: ADALBERTO CARVALHO DE OLIVEIRA | B9: 98058690597 | E9: 423 | F9: 43182 | G9: APROVADO | O9: 1262 | P9: =COUNTIF(OFÍCIOS!E:E,O9) -> 8 | Q9: =COUNTIFS(OFÍCIOS!$E:$E,$O9,OFÍCIOS!$G:$G,"APROVADO") -> 7 | R9: =COUNTIFS(OFÍCIOS!$E:$E,$O9,OFÍCIOS!$G:$G,"REPROVADO") -> 1 | S9: =COUNTIFS(OFÍCIOS!$E:$E,$O9,OFÍCIOS!$G:$G,"PENDENCIA") -> 0 | T9: =COUNTIFS(OFÍCIOS!$E:$E,$O9,OFÍCIOS!$G:$G,"") -> 0 | U9: =SUM(Q9:T9) -> 8
A10: ADALBERTO CAVALCANTE DOS SANTOS | B10: 38088438888 | O10: 1106 | P10: =COUNTIF(OFÍCIOS!E:E,O10) -> 78 | Q10: =COUNTIFS(OFÍCIOS!$E:$E,$O10,OFÍCIOS!$G:$G,"APROVADO") -> 73 | R10: =COUNTIFS(OFÍCIOS!$E:$E,$O10,OFÍCIOS!$G:$G,"REPROVADO") -> 5 | S10: =COUNTIFS(OFÍCIOS!$E:$E,$O10,OFÍCIOS!$G:$G,"PENDENCIA") -> 0 | T10: =COUNTIFS(OFÍCIOS!$E:$E,$O10,OFÍCIOS!$G:$G,"") -> 0 | U10: =SUM(Q10:T10) -> 78
A11: ADALMA MOREIRA DA ROCHA | B11: 26939799869 | E11: 573 | F11: 43224 | O11: 1128 | P11: =COUNTIF(OFÍCIOS!E:E,O11) -> 92 | Q11: =COUNTIFS(OFÍCIOS!$E:$E,$O11,OFÍCIOS!$G:$G,"APROVADO") -> 91 | R11: =COUNTIFS(OFÍCIOS!$E:$E,$O11,OFÍCIOS!$G:$G,"REPROVADO") -> 1 | S11: =COUNTIFS(OFÍCIOS!$E:$E,$O11,OFÍCIOS!$G:$G,"PENDENCIA") -> 0 | T11: =COUNTIFS(OFÍCIOS!$E:$E,$O11,OFÍCIOS!$G:$G,"") -> 0 | U11: =SUM(Q11:T11) -> 92
A12: ADAMILTON PEREIRA DA SILVA ( ALANA ) | B12: 34470559873 | E12: 292 | F12: 43168 | G12: APROVADO | H12: 43182 | L12: 318 | O12: 1214 | P12: =COUNTIF(OFÍCIOS!E:E,O12) -> 76 | Q12: =COUNTIFS(OFÍCIOS!$E:$E,$O12,OFÍCIOS!$G:$G,"APROVADO") -> 71 | R12: =COUNTIFS(OFÍCIOS!$E:$E,$O12,OFÍCIOS!$G:$G,"REPROVADO") -> 3 | S12: =COUNTIFS(OFÍCIOS!$E:$E,$O12,OFÍCIOS!$G:$G,"PENDENCIA") -> 0 | T12: =COUNTIFS(OFÍCIOS!$E:$E,$O12,OFÍCIOS!$G:$G,"") -> 2 | U12: =SUM(Q12:T12) -> 76
A13: ADAO MENDES AGOSTINHO | B13: 14369564808 | O13: 1241 | P13: =COUNTIF(OFÍCIOS!E:E,O13) -> 33 | Q13: =COUNTIFS(OFÍCIOS!$E:$E,$O13,OFÍCIOS!$G:$G,"APROVADO") -> 32 | R13: =COUNTIFS(OFÍCIOS!$E:$E,$O13,OFÍCIOS!$G:$G,"REPROVADO") -> 0 | S13: =COUNTIFS(OFÍCIOS!$E:$E,$O13,OFÍCIOS!$G:$G,"PENDENCIA") -> 1 | T13: =COUNTIFS(OFÍCIOS!$E:$E,$O13,OFÍCIOS!$G:$G,"") -> 0 | U13: =SUM(Q13:T13) -> 33
A14: ADEGMARIO DOS SANTOS | B14: 39544185844 | E14: 810 | F14: 42915 | G14: APROVADO | H14: 42921 | L14: 568-17 | O14: 1422 | P14: =COUNTIF(OFÍCIOS!E:E,O14) -> 7 | Q14: =COUNTIFS(OFÍCIOS!$E:$E,$O14,OFÍCIOS!$G:$G,"APROVADO") -> 7 | R14: =COUNTIFS(OFÍCIOS!$E:$E,$O14,OFÍCIOS!$G:$G,"REPROVADO") -> 0 | S14: =COUNTIFS(OFÍCIOS!$E:$E,$O14,OFÍCIOS!$G:$G,"PENDENCIA") -> 0 | T14: =COUNTIFS(OFÍCIOS!$E:$E,$O14,OFÍCIOS!$G:$G,"") -> 0 | U14: =SUM(Q14:T14) -> 7
A15: ADEILDA GABRIELA CAITANO SILVA | B15: 38772276860 | C15: LUCIANO MANOEL DA SILVA | D15: 3808243457 | O15: 1439 | P15: =COUNTIF(OFÍCIOS!E:E,O15) -> 16 | Q15: =COUNTIFS(OFÍCIOS!$E:$E,$O15,OFÍCIOS!$G:$G,"APROVADO") -> 14 | R15: =COUNTIFS(OFÍCIOS!$E:$E,$O15,OFÍCIOS!$G:$G,"REPROVADO") -> 1 | S15: =COUNTIFS(OFÍCIOS!$E:$E,$O15,OFÍCIOS!$G:$G,"PENDENCIA") -> 1 | T15: =COUNTIFS(OFÍCIOS!$E:$E,$O15,OFÍCIOS!$G:$G,"") -> 0 | U15: =SUM(Q15:T15) -> 16
A16: ADEILDA RODRIGUES DE OLIVEIRA | B16: 21538837846 | C16: PEDRO LUIZ SANTOS OLIVEIRA | D16: 94203180520 | E16: 810 | F16: 42915 | G16: APROVADO | H16: 42921 | L16: 568-17 | O16: 1451 | P16: =COUNTIF(OFÍCIOS!E:E,O16) -> 4 | Q16: =COUNTIFS(OFÍCIOS!$E:$E,$O16,OFÍCIOS!$G:$G,"APROVADO") -> 3 | R16: =COUNTIFS(OFÍCIOS!$E:$E,$O16,OFÍCIOS!$G:$G,"REPROVADO") -> 1 | S16: =COUNTIFS(OFÍCIOS!$E:$E,$O16,OFÍCIOS!$G:$G,"PENDENCIA") -> 0 | T16: =COUNTIFS(OFÍCIOS!$E:$E,$O16,OFÍCIOS!$G:$G,"") -> 0 | U16: =SUM(Q16:T16) -> 4
A17: ADEILDO ADELINO DE CARVALHO | B17: 57455392591 | O17: 1470 | P17: =COUNTIF(OFÍCIOS!E:E,O17) -> 4 | Q17: =COUNTIFS(OFÍCIOS!$E:$E,$O17,OFÍCIOS!$G:$G,"APROVADO") -> 4 | R17: =COUNTIFS(OFÍCIOS!$E:$E,$O17,OFÍCIOS!$G:$G,"REPROVADO") -> 0 | S17: =COUNTIFS(OFÍCIOS!$E:$E,$O17,OFÍCIOS!$G:$G,"PENDENCIA") -> 0 | T17: =COUNTIFS(OFÍCIOS!$E:$E,$O17,OFÍCIOS!$G:$G,"") -> 0 | U17: =SUM(Q17:T17) -> 4
A18: ADELCIDES DA CONCEICAO ALMEIDA | B18: 5304941594 | E18: 1106 | F18: 42965 | G18: APROVADO | H18: 42978 | O18: 1489 | P18: =COUNTIF(OFÍCIOS!E:E,O18) -> 35 | Q18: =COUNTIFS(OFÍCIOS!$E:$E,$O18,OFÍCIOS!$G:$G,"APROVADO") -> 34 | R18: =COUNTIFS(OFÍCIOS!$E:$E,$O18,OFÍCIOS!$G:$G,"REPROVADO") -> 0 | S18: =COUNTIFS(OFÍCIOS!$E:$E,$O18,OFÍCIOS!$G:$G,"PENDENCIA") -> 1 | T18: =COUNTIFS(OFÍCIOS!$E:$E,$O18,OFÍCIOS!$G:$G,"") -> 0 | U18: =SUM(Q18:T18) -> 35
A19: ADELIA MARIA DE OLIVEIRA | B19: 21600057896 | E19: 262 | F19: 43160 | G19: REPROVADO | H19: 43164 | L19: 255 | O19: 1555 | P19: =COUNTIF(OFÍCIOS!E:E,O19) -> 25 | Q19: =COUNTIFS(OFÍCIOS!$E:$E,$O19,OFÍCIOS!$G:$G,"APROVADO") -> 22 | R19: =COUNTIFS(OFÍCIOS!$E:$E,$O19,OFÍCIOS!$G:$G,"REPROVADO") -> 1 | S19: =COUNTIFS(OFÍCIOS!$E:$E,$O19,OFÍCIOS!$G:$G,"PENDENCIA") -> 2 | T19: =COUNTIFS(OFÍCIOS!$E:$E,$O19,OFÍCIOS!$G:$G,"") -> 0 | U19: =SUM(Q19:T19) -> 25
A20: ADEMARIO FERREIRA DOS SANTOS | B20: 18419589802 | O20: 1570 | P20: =COUNTIF(OFÍCIOS!E:E,O20) -> 24 | Q20: =COUNTIFS(OFÍCIOS!$E:$E,$O20,OFÍCIOS!$G:$G,"APROVADO") -> 23 | R20: =COUNTIFS(OFÍCIOS!$E:$E,$O20,OFÍCIOS!$G:$G,"REPROVADO") -> 1 | S20: =COUNTIFS(OFÍCIOS!$E:$E,$O20,OFÍCIOS!$G:$G,"PENDENCIA") -> 0 | T20: =COUNTIFS(OFÍCIOS!$E:$E,$O20,OFÍCIOS!$G:$G,"") -> 0 | U20: =SUM(Q20:T20) -> 24
A21: ADEMIR DA SILVA LIMA | B21: 15538537846 | E21: 573 | F21: 43224 | O21: 1752 | P21: =COUNTIF(OFÍCIOS!E:E,O21) -> 89 | Q21: =COUNTIFS(OFÍCIOS!$E:$E,$O21,OFÍCIOS!$G:$G,"APROVADO") -> 80 | R21: =COUNTIFS(OFÍCIOS!$E:$E,$O21,OFÍCIOS!$G:$G,"REPROVADO") -> 2 | S21: =COUNTIFS(OFÍCIOS!$E:$E,$O21,OFÍCIOS!$G:$G,"PENDENCIA") -> 5 | T21: =COUNTIFS(OFÍCIOS!$E:$E,$O21,OFÍCIOS!$G:$G,"") -> 2 | U21: =SUM(Q21:T21) -> 89
A22: ADENILDE SANTOS DA SILVA | B22: 899837506 | E22: 1824 | F22: 43091 | G22: APROVADO | H22: 43097 | L22: 1828 | O22: 1824 | P22: =COUNTIF(OFÍCIOS!E:E,O22) -> 81 | Q22: =COUNTIFS(OFÍCIOS!$E:$E,$O22,OFÍCIOS!$G:$G,"APROVADO") -> 67 | R22: =COUNTIFS(OFÍCIOS!$E:$E,$O22,OFÍCIOS!$G:$G,"REPROVADO") -> 7 | S22: =COUNTIFS(OFÍCIOS!$E:$E,$O22,OFÍCIOS!$G:$G,"PENDENCIA") -> 6 | T22: =COUNTIFS(OFÍCIOS!$E:$E,$O22,OFÍCIOS!$G:$G,"") -> 1 | U22: =SUM(Q22:T22) -> 81
A23: ADENILSON DA CONCEICAO | B23: 36197160803 | E23: 229 | F23: 43151 | G23: APROVADO | L23: 232 | O23: 1628 | P23: =COUNTIF(OFÍCIOS!E:E,O23) -> 6 | Q23: =COUNTIFS(OFÍCIOS!$E:$E,$O23,OFÍCIOS!$G:$G,"APROVADO") -> 5 | R23: =COUNTIFS(OFÍCIOS!$E:$E,$O23,OFÍCIOS!$G:$G,"REPROVADO") -> 1 | S23: =COUNTIFS(OFÍCIOS!$E:$E,$O23,OFÍCIOS!$G:$G,"PENDENCIA") -> 0 | T23: =COUNTIFS(OFÍCIOS!$E:$E,$O23,OFÍCIOS!$G:$G,"") -> 0 | U23: =SUM(Q23:T23) -> 6
A24: ADENIR MODESTO RIBEIRO | B24: 39248826814 | E24: 292 | F24: 43168 | G24: APROVADO | H24: 43182 | L24: 318 | O24: 608 | P24: =COUNTIF(OFÍCIOS!E:E,O24) -> 35 | Q24: =COUNTIFS(OFÍCIOS!$E:$E,$O24,OFÍCIOS!$G:$G,"APROVADO") -> 31 | R24: =COUNTIFS(OFÍCIOS!$E:$E,$O24,OFÍCIOS!$G:$G,"REPROVADO") -> 3 | S24: =COUNTIFS(OFÍCIOS!$E:$E,$O24,OFÍCIOS!$G:$G,"PENDENCIA") -> 1 | T24: =COUNTIFS(OFÍCIOS!$E:$E,$O24,OFÍCIOS!$G:$G,"") -> 0 | U24: =SUM(Q24:T24) -> 35
A25: ADILINA FARIAS DO NASCIMENTO | B25: 48925276534 | E25: 229 | F25: 43151 | L25: 232 | O25: 527 | P25: =COUNTIF(OFÍCIOS!E:E,O25) -> 29 | Q25: =COUNTIFS(OFÍCIOS!$E:$E,$O25,OFÍCIOS!$G:$G,"APROVADO") -> 0 | R25: =COUNTIFS(OFÍCIOS!$E:$E,$O25,OFÍCIOS!$G:$G,"REPROVADO") -> 0 | S25: =COUNTIFS(OFÍCIOS!$E:$E,$O25,OFÍCIOS!$G:$G,"PENDENCIA") -> 0 | T25: =COUNTIFS(OFÍCIOS!$E:$E,$O25,OFÍCIOS!$G:$G,"") -> 29 | U25: =SUM(Q25:T25) -> 29
A26: ADILSON SOARES DA COSTA | O26: 509 | P26: =COUNTIF(OFÍCIOS!E:E,O26) -> 14 | Q26: =COUNTIFS(OFÍCIOS!$E:$E,$O26,OFÍCIOS!$G:$G,"APROVADO") -> 0 | R26: =COUNTIFS(OFÍCIOS!$E:$E,$O26,OFÍCIOS!$G:$G,"REPROVADO") -> 0 | S26: =COUNTIFS(OFÍCIOS!$E:$E,$O26,OFÍCIOS!$G:$G,"PENDENCIA") -> 0 | T26: =COUNTIFS(OFÍCIOS!$E:$E,$O26,OFÍCIOS!$G:$G,"") -> 14 | U26: =SUM(Q26:T26) -> 14
A27: ADMEIA BARBOSA DE SOUZA | B27: 25894152810 | C27: REINALDO SANTOS REIS | D27: 8263008808 | E27: 292 | F27: 43168 | G27: APROVADO | H27: 43182 | L27: 318 | O27: 292 | P27: =COUNTIF(OFÍCIOS!E:E,O27) -> 233 | Q27: =COUNTIFS(OFÍCIOS!$E:$E,$O27,OFÍCIOS!$G:$G,"APROVADO") -> 212 | R27: =COUNTIFS(OFÍCIOS!$E:$E,$O27,OFÍCIOS!$G:$G,"REPROVADO") -> 9 | S27: =COUNTIFS(OFÍCIOS!$E:$E,$O27,OFÍCIOS!$G:$G,"PENDENCIA") -> 0 | T27: =COUNTIFS(OFÍCIOS!$E:$E,$O27,OFÍCIOS!$G:$G,"") -> 12 | U27: =SUM(Q27:T27) -> 233
A28: ADONES FERREIRA JORGE | B28: 43026389587 | C28: EUNICE FELICIANA BRITO JORGE | D28: 29124464813 | E28: 485 | F28: 43196 | H28: 43206 | L28: 483 | O28: 573 | P28: =COUNTIF(OFÍCIOS!E:E,O28) -> 43 | Q28: =COUNTIFS(OFÍCIOS!$E:$E,$O28,OFÍCIOS!$G:$G,"APROVADO") -> 0 | R28: =COUNTIFS(OFÍCIOS!$E:$E,$O28,OFÍCIOS!$G:$G,"REPROVADO") -> 0 | S28: =COUNTIFS(OFÍCIOS!$E:$E,$O28,OFÍCIOS!$G:$G,"PENDENCIA") -> 0 | T28: =COUNTIFS(OFÍCIOS!$E:$E,$O28,OFÍCIOS!$G:$G,"") -> 43 | U28: =SUM(Q28:T28) -> 43
A29: ADRIANA ALVES DA SILVA | B29: 26245112885 | E29: 262 | F29: 43160 | G29: REPROVADO | H29: 43164 | L29: 255 | O29: 563 | P29: =COUNTIF(OFÍCIOS!E:E,O29) -> 64 | Q29: =COUNTIFS(OFÍCIOS!$E:$E,$O29,OFÍCIOS!$G:$G,"APROVADO") -> 0 | R29: =COUNTIFS(OFÍCIOS!$E:$E,$O29,OFÍCIOS!$G:$G,"REPROVADO") -> 0 | S29: =COUNTIFS(OFÍCIOS!$E:$E,$O29,OFÍCIOS!$G:$G,"PENDENCIA") -> 0 | T29: =COUNTIFS(OFÍCIOS!$E:$E,$O29,OFÍCIOS!$G:$G,"") -> 64 | U29: =SUM(Q29:T29) -> 64
A30: ADRIANA ALVES FERREIRA | B30: 36531080809 | C30: MARCIO ROSA DE MIRA | D30: 22485483892 | E30: 1489 | F30: 43038 | G30: APROVADO | L30: 1647-17 | O30: 443 | P30: =COUNTIF(OFÍCIOS!E:E,O30) -> 66 | Q30: =COUNTIFS(OFÍCIOS!$E:$E,$O30,OFÍCIOS!$G:$G,"APROVADO") -> 0 | R30: =COUNTIFS(OFÍCIOS!$E:$E,$O30,OFÍCIOS!$G:$G,"REPROVADO") -> 0 | S30: =COUNTIFS(OFÍCIOS!$E:$E,$O30,OFÍCIOS!$G:$G,"PENDENCIA") -> 0 | T30: =COUNTIFS(OFÍCIOS!$E:$E,$O30,OFÍCIOS!$G:$G,"") -> 66 | U30: =SUM(Q30:T30) -> 66
A31: ADRIANA APARECIDA ROBERTO | B31: 28147186819 | C31: CARLOS ANTONIO BATISTA DOS SANTOS | D31: 24499714400 | O31: 423 | P31: =COUNTIF(OFÍCIOS!E:E,O31) -> 9 | Q31: =COUNTIFS(OFÍCIOS!$E:$E,$O31,OFÍCIOS!$G:$G,"APROVADO") -> 7 | R31: =COUNTIFS(OFÍCIOS!$E:$E,$O31,OFÍCIOS!$G:$G,"REPROVADO") -> 1 | S31: =COUNTIFS(OFÍCIOS!$E:$E,$O31,OFÍCIOS!$G:$G,"PENDENCIA") -> 0 | T31: =COUNTIFS(OFÍCIOS!$E:$E,$O31,OFÍCIOS!$G:$G,"") -> 1 | U31: =SUM(Q31:T31) -> 9
A32: ADRIANA ARAUJO DE LIMA | B32: 37559228860 | C32: ALEXANDRO ARAUJO DE LIMA | D32: 28072024892 | E32: 1555 | F32: 43049 | G32: APROVADO | O32: 229 | P32: =COUNTIF(OFÍCIOS!E:E,O32) -> 89 | Q32: =COUNTIFS(OFÍCIOS!$E:$E,$O32,OFÍCIOS!$G:$G,"APROVADO") -> 81 | R32: =COUNTIFS(OFÍCIOS!$E:$E,$O32,OFÍCIOS!$G:$G,"REPROVADO") -> 2 | S32: =COUNTIFS(OFÍCIOS!$E:$E,$O32,OFÍCIOS!$G:$G,"PENDENCIA") -> 5 | T32: =COUNTIFS(OFÍCIOS!$E:$E,$O32,OFÍCIOS!$G:$G,"") -> 1 | U32: =SUM(Q32:T32) -> 89
A33: ADRIANA CORDEIRO MACHADO | B33: 23635229822 | C33: ANDERSON DE MORAIS SANTOS | D33: 21668057875 | E33: 262 | F33: 43160 | G33: APROVADO | H33: 43164 | L33: 255 | O33: 262 | P33: =COUNTIF(OFÍCIOS!E:E,O33) -> 224 | Q33: =COUNTIFS(OFÍCIOS!$E:$E,$O33,OFÍCIOS!$G:$G,"APROVADO") -> 181 | R33: =COUNTIFS(OFÍCIOS!$E:$E,$O33,OFÍCIOS!$G:$G,"REPROVADO") -> 15 | S33: =COUNTIFS(OFÍCIOS!$E:$E,$O33,OFÍCIOS!$G:$G,"PENDENCIA") -> 0 | T33: =COUNTIFS(OFÍCIOS!$E:$E,$O33,OFÍCIOS!$G:$G,"") -> 28 | U33: =SUM(Q33:T33) -> 224
A34: ADRIANA DA SILVA | O34: 117 | P34: =COUNTIF(OFÍCIOS!E:E,O34) -> 91 | Q34: =COUNTIFS(OFÍCIOS!$E:$E,$O34,OFÍCIOS!$G:$G,"APROVADO") -> 77 | R34: =COUNTIFS(OFÍCIOS!$E:$E,$O34,OFÍCIOS!$G:$G,"REPROVADO") -> 7 | S34: =COUNTIFS(OFÍCIOS!$E:$E,$O34,OFÍCIOS!$G:$G,"PENDENCIA") -> 5 | T34: =COUNTIFS(OFÍCIOS!$E:$E,$O34,OFÍCIOS!$G:$G,"") -> 2 | U34: =SUM(Q34:T34) -> 91
A35: ADRIANA DA SILVA SANTOS | B35: 40902634844 | C35: GUILHERME DE OLIVEIRA SOUZA | D35: 23795007895 | E35: 117 | F35: 43117 | G35: APROVADO | H35: 43151 | L35: 118-18 | O35: 485 | P35: =COUNTIF(OFÍCIOS!E:E,O35) -> 23 | Q35: =COUNTIFS(OFÍCIOS!$E:$E,$O35,OFÍCIOS!$G:$G,"APROVADO") -> 0 | R35: =COUNTIFS(OFÍCIOS!$E:$E,$O35,OFÍCIOS!$G:$G,"REPROVADO") -> 3 | S35: =COUNTIFS(OFÍCIOS!$E:$E,$O35,OFÍCIOS!$G:$G,"PENDENCIA") -> 0 | T35: =COUNTIFS(OFÍCIOS!$E:$E,$O35,OFÍCIOS!$G:$G,"") -> 20 | U35: =SUM(Q35:T35) -> 23
A36: ADRIANA DE SA ROCHA | B36: 39615629898 | C36: MARCELO FERNANDES LIMA | D36: 43328275894 | E36: 423 | F36: 43182 | G36: APROVADO | O36: 85 | P36: =COUNTIF(OFÍCIOS!E:E,O36) -> 93 | Q36: =COUNTIFS(OFÍCIOS!$E:$E,$O36,OFÍCIOS!$G:$G,"APROVADO") -> 86 | R36: =COUNTIFS(OFÍCIOS!$E:$E,$O36,OFÍCIOS!$G:$G,"REPROVADO") -> 4 | S36: =COUNTIFS(OFÍCIOS!$E:$E,$O36,OFÍCIOS!$G:$G,"PENDENCIA") -> 3 | T36: =COUNTIFS(OFÍCIOS!$E:$E,$O36,OFÍCIOS!$G:$G,"") -> 0 | U36: =SUM(Q36:T36) -> 93
A37: ADRIANA DOS SANTOS | P37: =COUNTIF(OFÍCIOS!E:E,O37) -> 0 | Q37: =COUNTIFS(OFÍCIOS!$E:$E,$O37,OFÍCIOS!$G:$G,"APROVADO") -> 0 | R37: =COUNTIFS(OFÍCIOS!$E:$E,$O37,OFÍCIOS!$G:$G,"REPROVADO") -> 0 | S37: =COUNTIFS(OFÍCIOS!$E:$E,$O37,OFÍCIOS!$G:$G,"PENDENCIA") -> 0 | T37: =COUNTIFS(OFÍCIOS!$E:$E,$O37,OFÍCIOS!$G:$G,"") -> 0 | U37: =SUM(Q37:T37) -> 0
A38: ADRIANA FERREIRA DA SILVA | C38: LOURIVAL CANDIDO SILVA | P38: =COUNTIF(OFÍCIOS!E:E,O38) -> 0 | Q38: =COUNTIFS(OFÍCIOS!$E:$E,$O38,OFÍCIOS!$G:$G,"APROVADO") -> 0 | R38: =COUNTIFS(OFÍCIOS!$E:$E,$O38,OFÍCIOS!$G:$G,"REPROVADO") -> 0 | S38: =COUNTIFS(OFÍCIOS!$E:$E,$O38,OFÍCIOS!$G:$G,"PENDENCIA") -> 0 | T38: =COUNTIFS(OFÍCIOS!$E:$E,$O38,OFÍCIOS!$G:$G,"") -> 0 | U38: =SUM(Q38:T38) -> 0
A39: ADRIANA HELENA DE MORAIS | B39: 14268808809 | E39: 262 | F39: 43160 | G39: APROVADO | H39: 43164 | L39: 255 | P39: =COUNTIF(OFÍCIOS!E:E,O39) -> 0 | Q39: =COUNTIFS(OFÍCIOS!$E:$E,$O39,OFÍCIOS!$G:$G,"APROVADO") -> 0 | R39: =COUNTIFS(OFÍCIOS!$E:$E,$O39,OFÍCIOS!$G:$G,"REPROVADO") -> 0 | S39: =COUNTIFS(OFÍCIOS!$E:$E,$O39,OFÍCIOS!$G:$G,"PENDENCIA") -> 0 | T39: =COUNTIFS(OFÍCIOS!$E:$E,$O39,OFÍCIOS!$G:$G,"") -> 0 | U39: =SUM(Q39:T39) -> 0
A40: ADRIANA JESUS DA CUNHA | B40: 29628693867 | E40: 292 | F40: 43168 | G40: APROVADO | H40: 43182 | L40: 318 | P40: =COUNTIF(OFÍCIOS!E:E,O40) -> 0 | Q40: =COUNTIFS(OFÍCIOS!$E:$E,$O40,OFÍCIOS!$G:$G,"APROVADO") -> 0 | R40: =COUNTIFS(OFÍCIOS!$E:$E,$O40,OFÍCIOS!$G:$G,"REPROVADO") -> 0 | S40: =COUNTIFS(OFÍCIOS!$E:$E,$O40,OFÍCIOS!$G:$G,"PENDENCIA") -> 0 | T40: =COUNTIFS(OFÍCIOS!$E:$E,$O40,OFÍCIOS!$G:$G,"") -> 0 | U40: =SUM(Q40:T40) -> 0
...

Sheet PRIORIDADES
A3: INFORMAÇÕES INICIAIS | O3: INFORMAÇÕES AUXÍLIO ALUGUEL | AA3: INFORMAÇÕES INDENIZAÇÃO | BG3: PROCESSO ATENDIMENTO HABITACIONAL
A4: ORDEM | B4: ÁREA | C4: TRECHO | D4: FASE | E4: PRIORIDADE | F4: SELO | G4: SITUAÇÃO INICIAL IMÓVEL | H4: USO IMÓVEL | I4: SITUAÇÃO DO RESIDENTE | J4: TITULAR | K4: RG | L4: CPF | M4: CADASTRO HABITA SAMPA | N4: OPÇÃO DE ATENDIMENTO HABITACIONAL | O4: SOLICITAÇÃO AUXÍLIO ALUGUEL ÁREA | P4: No PROCESSO SEI (AUXÍLIO ALUGUEL) | Q4: ANÁLISE DTS CADASTRO + CHECAGEM DUPLO | R4: INSTRUÇÃO PROCESSO SEI DTS | S4: ANÁLISE CTS ASSINATURA GABINETE | T4: DATA PUBLICAÇÃO DIÁRIO OFICIAL | U4: CONFECÇÃO TERMO | V4: ENVIO TERMO CARTÃO | W4: PREVISÃO PAGAMENTO | X4: DATA SAQUE | Y4: DATA MUDANÇA | Z4: OBSERVAÇÕES AA | AA4: PROPRIETÁRIO | AB4: RG | AC4: CPF | AD4: SITUAÇÃO DO PROPRIETÁRIO | AE4: CADASTRO HABITASAMPA | AF4: VALOR AVALIAÇÃO | AG4: VALOR INDENIZAÇÃO | AH4: ACEITA VALOR INDENIZAÇÃO | AI4: Nº SEI LAUDOS AVALIAÇÃO | AJ4: Nº DOCUMENTO LAUDO | AK4: RECEBIMENTO TERMO CTS | AL4: CONFERÊNCIA TERMO CTS | AM4: ENVIO ASSINATURA CTS | AN4: ENVIO ASSINATURA GAB | AO4: RETORNO TERMO GAB | AP4: ENVIO TERMO DTS | AQ4: EM CORREÇÃO | AR4: STATUS TERMO INDENIZAÇÃO | AS4: PENDÊNCIA | AT4: OBSERVAÇÕES INDENIZAÇÃO | AU4: No PROCESSO SEI (INDENIZAÇÃO) | AV4: INSTRUÇÃO PROCESSO SEI DTS | AW4: ASSINATURA DIRETOR DTS | AX4: ELABORAÇÃO DESPACHO CTS | AY4: ASSINATURA DESPACHO GABINETE | AZ4: PUBLICAÇÃO DIÁRIO OFICIAL | BA4: ENCAMINHAMENTO DAF/DIF CTS | BB4: LIBERAÇÃO PAGAMENTO DAF/DIF | BC4: PREVISÃO PAGAMENTO | BD4: DATA PAGAMENTO | BE4: DATA ENTREGA IMÓVEL | BF4: SITUAÇÃO ATUAL IMÓVEL | BG4: STATUS | BH4: DIAS TOTAIS | BI4: OPÇÃO ATENDIMENTO | BJ4: NECESSITA BLOQUEIO AA | BK4: SOLICITAÇÃO BLOQUEIO AA DTS | BL4: SOLICITAÇÃO BLOQUEIO AA | BM4: DATA BLOQUEIO AA | BN4: DESPACHO EXCLUSÃO GABINETE | BO4: ASSINATURA DESPACHO GABINETE | BP4: PUBLICAÇÃO DOC | BQ4: ENCAMINHAMENTO SOLICITAÇÃO EXCLUSÃO DEPLAN | BR4: ENCERRAMENTO PROCESSO DTS
A5: 1 | B5: JD. PANTANAL | C5: NOVO HORIZONTE | D5: 1 | E5: -- | F5: 001/0001/A | G5: OCUPADO | H5: RESIDENCIAL | I5: PROPRIETÁRIO RESIDENTE | J5: ARIANA APARECIDA DE PAULA | K5: -- | L5: 403.154.248-85 | M5: CADASTRADO | N5: AUXÍLIO ALUGUEL UH | O5: 45986 | P5: 6014.2025/0007513-3 | Q5: 45985 | R5: 45986 | S5: 45987 | T5: 45992 | U5: OK | V5: OK | W5: 45999 | X5: 46000 | Y5: 46017 | AA5: ARIANA APARECIDA DE PAULA | AB5: -- | AC5: 403.154.248-85 | AD5: PROPRIETÁRIO RESIDENTE | AE5: CADASTRADO | AF5: N.A | AG5: N.A | AH5: UH | AI5: 6014.2025/0007373-4 | AK5: 45979 | AL5: 45979 | AM5: 45979 | AN5: 45979 | AO5: 45979 | AP5: 45979 | AR5: =IF(AQ5="SIM","AGUARDANDO CORREÇÃO",IF(AP5<>"","FINALIZADO",IF(AO5<>"","AGUARDANDO ENVIO DTS",IF(AN5<>"","AGUARDANDO ASSINATURA GAB",IF(AM5<>"","AGUARDANDO ASSINATURA CTS",IF(AL5<>"","AGUARDANDO ENVIO ASSINATURA CTS",IF(AK5<>"","AGUARDANDO CONFERÊNCIA",""))))))) -> FINALIZADO | BE5: 46017 | BF5: DEMOLIDO | BH5: =IFERROR(IF(BD5-KI5=0,"",BD5-AK5),"") | BI5: =IF(AND(AH5<>"SIM",AH5="UH"),"AA","INDENIZAÇÃO") -> AA | BJ5: =IF(AND(BD5<>"AGUARDANDO",BD5<>"",N5="AUXÍLIO ALUGUEL ATÉ INDENIZAÇÃO"),"SIM","NÃO") -> NÃO
A6: 2 | B6: JD. PANTANAL | C6: VILA DA PAZ | D6: 1 | E6: -- | F6: 001/0001/A | G6: OCUPADO | H6: RESIDENCIAL | I6: INQUILINO | J6: KISSY KATAIANA SANTOS SILVA | K6: -- | L6: 421.459.738-93 | M6: CADASTRADO | N6: AUXÍLIO ALUGUEL UH | O6: PENDENTE | P6: 6014.2025/0007513-3 | AA6: GABRIEL ROCHA RODRIGUES | AB6: 39.394.079-2 | AC6: 367.570.418-12 | AD6: PROPRIETÁRIO NÃO RESIDENTE | AE6: CADASTRADO | AF6: 62160.58 | AG6: 62160.58 | AH6: SIM | AI6: 6014.2025/0007373-4 | AJ6: 160375813 | AK6: 46080 | AL6: 46080 | AM6: 46080 | AN6: 46080 | AO6: 46080 | AP6: 46080 | AR6: =IF(AQ6="SIM","AGUARDANDO CORREÇÃO",IF(AP6<>"","FINALIZADO",IF(AO6<>"","AGUARDANDO ENVIO DTS",IF(AN6<>"","AGUARDANDO ASSINATURA GAB",IF(AM6<>"","AGUARDANDO ASSINATURA CTS",IF(AL6<>"","AGUARDANDO ENVIO ASSINATURA CTS",IF(AK6<>"","AGUARDANDO CONFERÊNCIA",""))))))) -> FINALIZADO | AS6: SEM PENDÊNCIA | AU6: 6014.2026/0005831-1 | AV6: FINALIZADO | AW6: FINALIZADO | AX6: EM BLOCO | BF6: OCUPADO | BH6: =IFERROR(IF(BD6-KI6=0,"",BD6-AK6),"") | BI6: =IF(AND(AH6<>"SIM",AH6="UH"),"AA","INDENIZAÇÃO") -> INDENIZAÇÃO | BJ6: =IF(AND(BD6<>"AGUARDANDO",BD6<>"",N6="AUXÍLIO ALUGUEL ATÉ INDENIZAÇÃO"),"SIM","NÃO") -> NÃO
A7: 3 | B7: JD. PANTANAL | C7: SÃO MARTINHO VÁRZEA | D7: 1 | E7: -- | F7: 001/0001/A | G7: OCUPADO | H7: COMERCIAL | I7: PROPRIETÁRIO NÃO RESIDENTE | J7: ADENILSON BATISTA FERREIRA | K7: 24.743.676-8 | L7: 468.366.675-87 | M7: CADASTRADO | N7: INDENIZAÇÃO | O7: N.A | P7: N.A | Q7: N.A | R7: N.A | S7: N.A | T7: N.A | U7: N.A | V7: N.A | W7: N.A | X7: N.A | AA7: ADENILSON BATISTA FERREIRA | AB7: 24.743.676-8 | AC7: 468.366.675-87 | AD7: PROPRIETÁRIO NÃO RESIDENTE | AE7: CADASTRADO | AF7: 54401.18 | AG7: 60000 | AH7: SIM | AI7: 6014.2025/0007373-4 | AJ7: 147744665 | AK7: 45988 | AL7: 45988 | AM7: 45988 | AN7: 45988 | AO7: 45988 | AP7: 45988 | AR7: =IF(AQ7="SIM","AGUARDANDO CORREÇÃO",IF(AP7<>"","FINALIZADO",IF(AO7<>"","AGUARDANDO ENVIO DTS",IF(AN7<>"","AGUARDANDO ASSINATURA GAB",IF(AM7<>"","AGUARDANDO ASSINATURA CTS",IF(AL7<>"","AGUARDANDO ENVIO ASSINATURA CTS",IF(AK7<>"","AGUARDANDO CONFERÊNCIA",""))))))) -> FINALIZADO | AS7: SEM PENDÊNCIA | AU7: 6014.2025/0008612-7 | AV7: FINALIZADO | AW7: FINALIZADO | AX7: FINALIZADO | AY7: FINALIZADO | AZ7: 46024 | BA7: FINALIZADO | BB7: FINALIZADO | BC7: 46038 | BD7: 46038 | BE7: AGUARDANDO | BF7: LIBERADO DEMOLIÇÃO | BG7: FINALIZADO | BH7: =IFERROR(IF(BD7-KI7=0,"",BD7-AK7),"") -> 50 | BI7: =IF(AND(AH7<>"SIM",AH7="UH"),"AA","INDENIZAÇÃO") -> INDENIZAÇÃO | BJ7: =IF(AND(BD7<>"AGUARDANDO",BD7<>"",N7="AUXÍLIO ALUGUEL ATÉ INDENIZAÇÃO"),"SIM","NÃO") -> NÃO | BK7: N/A | BL7: N/A | BM7: N/A | BN7: FINALIZADO | BO7: FINALIZADO | BP7: 46128 | BQ7: FINALIZADO | BR7: AGUARDANDO
A8: 4 | B8: JD. PANTANAL | C8: VILA DA PAZ | D8: 1 | E8: -- | F8: 001/0001/B | G8: OCUPADO | H8: RESIDENCIAL | I8: PROPRIETÁRIO RESIDENTE | J8: KLEINY SIRLANE DA ROCHA | K8: _ | L8: 260.215.948-43 | M8: CADASTRADO | N8: INDENIZAÇÃO | P8: N.A | Q8: N.A | R8: N.A | S8: N.A | T8: N.A | U8: N.A | V8: N.A | W8: N.A | X8: N.A | AA8: KLEINY SIRLANE DA ROCHA | AB8: _ | AC8: 260.215.948-43 | AD8: PROPRIETÁRIO RESIDENTE | AE8: CADASTRADO | AF8: 91776.57 | AG8: 91776.57 | AH8: SIM | AI8: 6014.2025/0007373-4 | AJ8: 153000357 | AK8: 46112 | AL8: 46112 | AM8: 46112 | AN8: 46112 | AO8: 46112 | AP8: 46112 | AR8: =IF(AQ8="SIM","AGUARDANDO CORREÇÃO",IF(AP8<>"","FINALIZADO",IF(AO8<>"","AGUARDANDO ENVIO DTS",IF(AN8<>"","AGUARDANDO ASSINATURA GAB",IF(AM8<>"","AGUARDANDO ASSINATURA CTS",IF(AL8<>"","AGUARDANDO ENVIO ASSINATURA CTS",IF(AK8<>"","AGUARDANDO CONFERÊNCIA",""))))))) -> FINALIZADO | AS8: SEM PENDÊNCIA | AU8: 6014.2026/0001975-8 | AV8: FINALIZADO | AW8: FINALIZADO | AX8: FINALIZADO | AY8: FINALIZADO | AZ8: 46189 | BA8: FINALIZADO | BB8: FINALIZADO | BC8: 46196 | BD8: 46196 | BE8: AGUARDANDO | BF8: LIBERADO DEMOLIÇÃO | BG8: FINALIZADO | BH8: =IFERROR(IF(BD8-KI8=0,"",BD8-AK8),"") -> 84 | BI8: =IF(AND(AH8<>"SIM",AH8="UH"),"AA","INDENIZAÇÃO") -> INDENIZAÇÃO | BJ8: =IF(AND(BD8<>"AGUARDANDO",BD8<>"",N8="AUXÍLIO ALUGUEL ATÉ INDENIZAÇÃO"),"SIM","NÃO") -> NÃO | BK8: N/A | BL8: N/A | BM8: N/A | BN8: FINALIZADO | BO8: FINALIZADO | BP8: 46224 | BQ8: FINALIZADO | BR8: AGUARDANDO
A9: 5 | B9: JD. PANTANAL | C9: VILA DA PAZ | D9: 1 | E9: -- | F9: 001/0001/C | G9: OCUPADO | H9: RESIDENCIAL | I9: PROPRIETÁRIO NÃO RESIDENTE | J9: JULIA DA ROCHA RODRIGUES | K9: _ | L9: 367.978.788-02 | O9: N.A | P9: N.A | Q9: N.A | R9: N.A | S9: N.A | T9: N.A | U9: N.A | V9: N.A | W9: N.A | X9: N.A | AA9: JULIA DA ROCHA RODRIGUES | AB9: _ | AC9: 367.978.788-02 | AD9: PROPRIETÁRIO NÃO RESIDENTE | AE9: CADASTRADO | AF9: 93714.3 | AG9: 93714.3 | AH9: SIM | AI9: 6014.2025/0007373-4 | AJ9: 161384436 | AK9: 46258 | AL9: 46258 | AM9: 46258 | AN9: 46258 | AR9: =IF(AQ9="SIM","AGUARDANDO CORREÇÃO",IF(AP9<>"","FINALIZADO",IF(AO9<>"","AGUARDANDO ENVIO DTS",IF(AN9<>"","AGUARDANDO ASSINATURA GAB",IF(AM9<>"","AGUARDANDO ASSINATURA CTS",IF(AL9<>"","AGUARDANDO ENVIO ASSINATURA CTS",IF(AK9<>"","AGUARDANDO CONFERÊNCIA",""))))))) -> AGUARDANDO ASSINATURA GAB | AS9: TERMO ASSINADO SECRETÁRIO | BH9: =IFERROR(IF(BD9-KI9=0,"",BD9-AK9),"") | BI9: =IF(AND(AH9<>"SIM",AH9="UH"),"AA","INDENIZAÇÃO") -> INDENIZAÇÃO | BJ9: =IF(AND(BD9<>"AGUARDANDO",BD9<>"",N9="AUXÍLIO ALUGUEL ATÉ INDENIZAÇÃO"),"SIM","NÃO") -> NÃO
A10: 6 | B10: JD. PANTANAL | C10: NOVO HORIZONTE | D10: 1 | E10: -- | F10: 001/0002/A | G10: OCUPADO | H10: GARAGEM | I10: PROPRIETÁRIO NÃO RESIDENTE | J10: CARLINDO ELOI DA SILVA | K10: 38.470.928 | L10: 659.657.734-87 | M10: CADASTRADO | N10: INDENIZAÇÃO | O10: N.A | P10: N.A | Q10: N.A | R10: N.A | S10: N.A | T10: N.A | U10: N.A | V10: N.A | W10: N.A | X10: N.A | AA10: CARLINDO ELOI DA SILVA | AB10: 38.470.928 | AC10: 659.657.734-87 | AD10: PROPRIETÁRIO NÃO RESIDENTE | AE10: CADASTRADO | AI10: 6014.2025/0007373-4 | AK10: 46037 | AL10: 46037 | AM10: 46037 | AN10: 46037 | AO10: 46037 | AP10: 46037 | AR10: =IF(AQ10="SIM","AGUARDANDO CORREÇÃO",IF(AP10<>"","FINALIZADO",IF(AO10<>"","AGUARDANDO ENVIO DTS",IF(AN10<>"","AGUARDANDO ASSINATURA GAB",IF(AM10<>"","AGUARDANDO ASSINATURA CTS",IF(AL10<>"","AGUARDANDO ENVIO ASSINATURA CTS",IF(AK10<>"","AGUARDANDO CONFERÊNCIA",""))))))) -> FINALIZADO | BH10: =IFERROR(IF(BD10-KI10=0,"",BD10-AK10),"") | BI10: =IF(AND(AH10<>"SIM",AH10="UH"),"AA","INDENIZAÇÃO") -> INDENIZAÇÃO | BJ10: =IF(AND(BD10<>"AGUARDANDO",BD10<>"",N10="AUXÍLIO ALUGUEL ATÉ INDENIZAÇÃO"),"SIM","NÃO") -> NÃO
A11: 7 | B11: JD. PANTANAL | C11: TERRA PROMETIDA | D11: 1 | E11: -- | F11: 001/0002/A | G11: OCUPADO | H11: RESIDENCIAL | I11: PROPRIETÁRIO RESIDENTE | J11: MARIA GILDENIA BENTO ALVES | K11: 64.948.618- | L11: 094.955.464-27 | M11: CADASTRADO | N11: AUXÍLIO ALUGUEL UH | O11: 45986 | P11: 6014.2025/0007513-3 | Q11: 45985 | R11: 45986 | S11: 45987 | T11: 45992 | U11: OK | V11: OK | W11: 45999 | X11: 46000 | Y11: 46017 | AA11: MARIA GILDENIA BENTO ALVES | AB11: 64.948.618- | AC11: 094.955.464-27 | AD11: PROPRIETÁRIO RESIDENTE | AE11: CADASTRADO | AF11: N.A | AG11: N.A | AH11: UH | AI11: 6014.2025/0007373-4 | AK11: 45979 | AL11: 45979 | AM11: 45979 | AN11: 45979 | AO11: 45979 | AP11: 45979 | AR11: =IF(AQ11="SIM","AGUARDANDO CORREÇÃO",IF(AP11<>"","FINALIZADO",IF(AO11<>"","AGUARDANDO ENVIO DTS",IF(AN11<>"","AGUARDANDO ASSINATURA GAB",IF(AM11<>"","AGUARDANDO ASSINATURA CTS",IF(AL11<>"","AGUARDANDO ENVIO ASSINATURA CTS",IF(AK11<>"","AGUARDANDO CONFERÊNCIA",""))))))) -> FINALIZADO | BE11: 46017 | BF11: DEMOLIDO | BH11: =IFERROR(IF(BD11-KI11=0,"",BD11-AK11),"") | BI11: =IF(AND(AH11<>"SIM",AH11="UH"),"AA","INDENIZAÇÃO") -> AA | BJ11: =IF(AND(BD11<>"AGUARDANDO",BD11<>"",N11="AUXÍLIO ALUGUEL ATÉ INDENIZAÇÃO"),"SIM","NÃO") -> NÃO
A12: 8 | B12: JD. PANTANAL | C12: SÃO MARTINHO VÁRZEA | D12: 1 | E12: -- | F12: 001/0002/A | G12: OCUPADO | H12: RESIDENCIAL | I12: PROPRIETÁRIO RESIDENTE | J12: LUZIANE JESUS DA SILVA | K12: -- | L12: 237.785.408-74 | M12: CADASTRADO | N12: INDENIZAÇÃO | O12: N.A | P12: N.A | Q12: N.A | R12: N.A | S12: N.A | T12: N.A | U12: N.A | V12: N.A | W12: N.A | X12: N.A | AA12: LUZIANE JESUS DA SILVA | AB12: -- | AC12: 237.785.408-74 | AD12: PROPRIETÁRIO RESIDENTE | AE12: CADASTRADO | AF12: 20634.24 | AG12: =AF12+30000 -> 50634.24 | AH12: SIM | AI12: 6014.2025/0007373-4 | AJ12: 147744826 | AK12: 46001 | AL12: 46001 | AM12: 46001 | AN12: 46001 | AO12: 46001 | AP12: 46001 | AR12: =IF(AQ12="SIM","AGUARDANDO CORREÇÃO",IF(AP12<>"","FINALIZADO",IF(AO12<>"","AGUARDANDO ENVIO DTS",IF(AN12<>"","AGUARDANDO ASSINATURA GAB",IF(AM12<>"","AGUARDANDO ASSINATURA CTS",IF(AL12<>"","AGUARDANDO ENVIO ASSINATURA CTS",IF(AK12<>"","AGUARDANDO CONFERÊNCIA",""))))))) -> FINALIZADO | AS12: SEM PENDÊNCIA | AU12: 6014.2025/0008616-0 | AV12: FINALIZADO | AW12: FINALIZADO | AX12: FINALIZADO | AY12: FINALIZADO | AZ12: 46024 | BA12: FINALIZADO | BB12: FINALIZADO | BC12: 46037 | BD12: 46037 | BE12: AGUARDANDO | BF12: LIBERADO DEMOLIÇÃO | BG12: FINALIZADO | BH12: =IFERROR(IF(BD12-KI12=0,"",BD12-AK12),"") -> 36 | BI12: =IF(AND(AH12<>"SIM",AH12="UH"),"AA","INDENIZAÇÃO") -> INDENIZAÇÃO | BJ12: =IF(AND(BD12<>"AGUARDANDO",BD12<>"",N12="AUXÍLIO ALUGUEL ATÉ INDENIZAÇÃO"),"SIM","NÃO") -> NÃO | BK12: N/A | BL12: N/A | BM12: N/A | BN12: FINALIZADO | BO12: FINALIZADO | BP12: 46128 | BQ12: FINALIZADO | BR12: AGUARDANDO
A13: 9 | B13: JD. PANTANAL | C13: TERRA PROMETIDA | D13: 1 | E13: -- | F13: 001/0002/B | G13: OCUPADO | H13: RESIDENCIAL | I13: PROPRIETÁRIO RESIDENTE | J13: FRANCISCA SOARES DOS SANTOS | K13: 23.458.574-2 | L13: 155.316.448-25 | M13: CADASTRADO | N13: AUXÍLIO ALUGUEL UH | O13: 46044 | P13: 6014.2025/0007513-3 | Q13: 46043 | R13: 46044 | S13: 46045 | T13: 46155 | U13: OK | V13: OK | W13: 46055 | X13: 46063 | Y13: 46017 | AA13: FRANCISCA SOARES DOS SANTOS | AB13: 23.458.574-2 | AC13: 155.316.448-25 | AD13: PROPRIETÁRIO RESIDENTE | AE13: CADASTRADO | AF13: N.A | AG13: N.A | AH13: UH | AI13: 6014.2025/0007373-4 | AK13: 46041 | AL13: 46041 | AM13: 46041 | AN13: 46041 | AO13: 46041 | AP13: 46041 | AR13: =IF(AQ13="SIM","AGUARDANDO CORREÇÃO",IF(AP13<>"","FINALIZADO",IF(AO13<>"","AGUARDANDO ENVIO DTS",IF(AN13<>"","AGUARDANDO ASSINATURA GAB",IF(AM13<>"","AGUARDANDO ASSINATURA CTS",IF(AL13<>"","AGUARDANDO ENVIO ASSINATURA CTS",IF(AK13<>"","AGUARDANDO CONFERÊNCIA",""))))))) -> FINALIZADO | BE13: 46017 | BF13: DEMOLIDO | BH13: =IFERROR(IF(BD13-KI13=0,"",BD13-AK13),"") | BI13: =IF(AND(AH13<>"SIM",AH13="UH"),"AA","INDENIZAÇÃO") -> AA | BJ13: =IF(AND(BD13<>"AGUARDANDO",BD13<>"",N13="AUXÍLIO ALUGUEL ATÉ INDENIZAÇÃO"),"SIM","NÃO") -> NÃO
A14: 10 | B14: JD. PANTANAL | C14: SÃO MARTINHO VÁRZEA | D14: 1 | E14: -- | F14: 001/0002/B | G14: OCUPADO | H14: RESIDENCIAL | I14: PROPRIETÁRIO RESIDENTE | J14: JESANIA CRISTINA OSÓRIO DA SILVA | K14: -- | L14: 360.808.578.55 | M14: CADASTRADO | N14: AUXÍLIO ALUGUEL UH | O14: 46084 | P14: 6014.2025/0007513-3 | Q14: 46083 | R14: 46084 | S14: 46087 | T14: 46090 | U14: OK | V14: OK | W14: 46101 | X14: 46101 | AA14: JESANIA CRISTINA OSÓRIO DA SILVA | AB14: -- | AC14: 360.808.578.55 | AD14: PROPRIETÁRIO RESIDENTE | AE14: CADASTRADO | AF14: N.A | AG14: N.A | AH14: UH | AI14: 6014.2025/0007373-4 | AK14: 46084 | AL14: 46084 | AM14: 46084 | AN14: 46084 | AO14: 46084 | AP14: 46084 | AR14: =IF(AQ14="SIM","AGUARDANDO CORREÇÃO",IF(AP14<>"","FINALIZADO",IF(AO14<>"","AGUARDANDO ENVIO DTS",IF(AN14<>"","AGUARDANDO ASSINATURA GAB",IF(AM14<>"","AGUARDANDO ASSINATURA CTS",IF(AL14<>"","AGUARDANDO ENVIO ASSINATURA CTS",IF(AK14<>"","AGUARDANDO CONFERÊNCIA",""))))))) -> FINALIZADO | BH14: =IFERROR(IF(BD14-KI14=0,"",BD14-AK14),"") | BI14: =IF(AND(AH14<>"SIM",AH14="UH"),"AA","INDENIZAÇÃO") -> AA | BJ14: =IF(AND(BD14<>"AGUARDANDO",BD14<>"",N14="AUXÍLIO ALUGUEL ATÉ INDENIZAÇÃO"),"SIM","NÃO") -> NÃO
A15: 11 | B15: JD. PANTANAL | C15: SÃO MARTINHO VÁRZEA | D15: 1 | E15: -- | F15: 001/0002/C | G15: OCUPADO | H15: RESIDENCIAL | I15: PROPRIETÁRIO RESIDENTE | J15: GABRIEL MIRANDA DOS SANTOS | K15: 58.626.407-3 | L15: 587.339.488-10 | M15: CADASTRADO | N15: INDENIZAÇÃO | O15: N.A | P15: N.A | Q15: N.A | R15: N.A | S15: N.A | T15: N.A | U15: N.A | V15: N.A | W15: N.A | X15: N.A | AA15: GABRIEL MIRANDA DOS SANTOS | AB15: 58.626.407-3 | AC15: 587.339.488-10 | AD15: PROPRIETÁRIO RESIDENTE | AE15: CADASTRADO | AF15: 20185.43 | AG15: =AF15+30000 -> 50185.43 | AH15: SIM | AI15: 6014.2025/0007373-4 | AJ15: 149592865 | AK15: 46059 | AL15: 46059 | AM15: 46059 | AN15: 46059 | AR15: =IF(AQ15="SIM","AGUARDANDO CORREÇÃO",IF(AP15<>"","FINALIZADO",IF(AO15<>"","AGUARDANDO ENVIO DTS",IF(AN15<>"","AGUARDANDO ASSINATURA GAB",IF(AM15<>"","AGUARDANDO ASSINATURA CTS",IF(AL15<>"","AGUARDANDO ENVIO ASSINATURA CTS",IF(AK15<>"","AGUARDANDO CONFERÊNCIA",""))))))) -> AGUARDANDO ASSINATURA GAB | BH15: =IFERROR(IF(BD15-KI15=0,"",BD15-AK15),"") | BI15: =IF(AND(AH15<>"SIM",AH15="UH"),"AA","INDENIZAÇÃO") -> INDENIZAÇÃO | BJ15: =IF(AND(BD15<>"AGUARDANDO",BD15<>"",N15="AUXÍLIO ALUGUEL ATÉ INDENIZAÇÃO"),"SIM","NÃO") -> NÃO
A16: 12 | B16: JD. PANTANAL | C16: SÃO MARTINHO VÁRZEA | D16: 1 | E16: -- | F16: 001/0002/D | G16: OCUPADO | H16: RESIDENCIAL | I16: PROPRIETÁRIO RESIDENTE | J16: ROSILDA RIBEIRO DOS SANTOS | K16: 13.497.334-82 | L16: 034.194.515-39 | M16: CADASTRADO | N16: AUXÍLIO ALUGUEL UH | O16: 45986 | P16: 6014.2025/0007513-3 | Q16: 45985 | R16: 45986 | S16: 45987 | T16: 45992 | U16: OK | V16: OK | W16: 45999 | X16: 46009 | AA16: ROSILDA RIBEIRO DOS SANTOS | AB16: 13.497.334-82 | AC16: 034.194.515-39 | AD16: PROPRIETÁRIO RESIDENTE | AE16: CADASTRADO | AF16: N.A | AG16: N.A | AH16: UH | AI16: 6014.2025/0007373-4 | AK16: 45980 | AL16: 45980 | AM16: 45980 | AN16: 45980 | AO16: 45980 | AP16: 45980 | AR16: =IF(AQ16="SIM","AGUARDANDO CORREÇÃO",IF(AP16<>"","FINALIZADO",IF(AO16<>"","AGUARDANDO ENVIO DTS",IF(AN16<>"","AGUARDANDO ASSINATURA GAB",IF(AM16<>"","AGUARDANDO ASSINATURA CTS",IF(AL16<>"","AGUARDANDO ENVIO ASSINATURA CTS",IF(AK16<>"","AGUARDANDO CONFERÊNCIA",""))))))) -> FINALIZADO | BH16: =IFERROR(IF(BD16-KI16=0,"",BD16-AK16),"") | BI16: =IF(AND(AH16<>"SIM",AH16="UH"),"AA","INDENIZAÇÃO") -> AA | BJ16: =IF(AND(BD16<>"AGUARDANDO",BD16<>"",N16="AUXÍLIO ALUGUEL ATÉ INDENIZAÇÃO"),"SIM","NÃO") -> NÃO
A17: 13 | B17: JD. PANTANAL | C17: SÃO MARTINHO VÁRZEA | D17: 1 | E17: -- | F17: 001/0002/E | G17: OCUPADO | H17: RESIDENCIAL | I17: PROPRIETÁRIO RESIDENTE | J17: GIVALDO TAVARES DE SOUZA | K17: 62.620.783-6 | L17: 093.716.044-09 | M17: CADASTRADO | N17: INDENIZAÇÃO | O17: N.A | P17: N.A | Q17: N.A | R17: N.A | S17: N.A | T17: N.A | U17: N.A | V17: N.A | W17: N.A | X17: N.A | AA17: GIVALDO TAVARES DE SOUZA | AB17: 62.620.783-6 | AC17: 093.716.044-09 | AD17: PROPRIETÁRIO RESIDENTE | AE17: CADASTRADO | AF17: 30184.77 | AG17: 60000 | AH17: SIM | AI17: 6014.2025/0007373-4 | AJ17: 154259974 | AK17: 46086 | AL17: 46086 | AM17: 46086 | AN17: 46086 | AO17: 46086 | AP17: 46086 | AR17: =IF(AQ17="SIM","AGUARDANDO CORREÇÃO",IF(AP17<>"","FINALIZADO",IF(AO17<>"","AGUARDANDO ENVIO DTS",IF(AN17<>"","AGUARDANDO ASSINATURA GAB",IF(AM17<>"","AGUARDANDO ASSINATURA CTS",IF(AL17<>"","AGUARDANDO ENVIO ASSINATURA CTS",IF(AK17<>"","AGUARDANDO CONFERÊNCIA",""))))))) -> FINALIZADO | AS17: SEM PENDÊNCIA | AU17: 6014.2026/0001162-5 | AV17: FINALIZADO | AW17: FINALIZADO | AX17: FINALIZADO | AY17: FINALIZADO | AZ17: 46174 | BA17: FINALIZADO | BB17: FINALIZADO | BC17: 46182 | BD17: 46182 | BE17: AGUARDANDO | BF17: LIBERADO DEMOLIÇÃO | BG17: FINALIZADO | BH17: =IFERROR(IF(BD17-KI17=0,"",BD17-AK17),"") -> 96 | BI17: =IF(AND(AH17<>"SIM",AH17="UH"),"AA","INDENIZAÇÃO") -> INDENIZAÇÃO | BJ17: =IF(AND(BD17<>"AGUARDANDO",BD17<>"",N17="AUXÍLIO ALUGUEL ATÉ INDENIZAÇÃO"),"SIM","NÃO") -> NÃO | BK17: N/A | BL17: N/A | BM17: N/A | BN17: FINALIZADO | BO17: FINALIZADO | BP17: 46224 | BQ17: FINALIZADO | BR17: AGUARDANDO
A18: 14 | B18: JD. PANTANAL | C18: SÃO MARTINHO VÁRZEA | D18: 1 | E18: -- | F18: 001/0002/F | G18: OCUPADO | H18: RESIDENCIAL | I18: PROPRIETÁRIO RESIDENTE | J18: KARINA TENORIO AZEVEDO | K18: 38.439.503-X | L18: 447.989.178-18 | M18: CADASTRADO | N18: AUXÍLIO ALUGUEL UH | O18: 46002 | P18: 6014.2025/0007513-3 | Q18: 45999 | R18: 46006 | S18: 46006 | T18: 46009 | U18: OK | V18: OK | W18: 46014 | X18: 46017 | AA18: KARINA TENORIO AZEVEDO | AB18: 38.439.503-X | AC18: 447.989.178-18 | AD18: PROPRIETÁRIO RESIDENTE | AE18: CADASTRADO | AF18: N.A | AG18: N.A | AH18: UH | AI18: 6014.2025/0007373-4 | AK18: 45988 | AL18: 45988 | AM18: 45988 | AN18: 45988 | AO18: 45988 | AP18: 45988 | AR18: =IF(AQ18="SIM","AGUARDANDO CORREÇÃO",IF(AP18<>"","FINALIZADO",IF(AO18<>"","AGUARDANDO ENVIO DTS",IF(AN18<>"","AGUARDANDO ASSINATURA GAB",IF(AM18<>"","AGUARDANDO ASSINATURA CTS",IF(AL18<>"","AGUARDANDO ENVIO ASSINATURA CTS",IF(AK18<>"","AGUARDANDO CONFERÊNCIA",""))))))) -> FINALIZADO | BH18: =IFERROR(IF(BD18-KI18=0,"",BD18-AK18),"") | BI18: =IF(AND(AH18<>"SIM",AH18="UH"),"AA","INDENIZAÇÃO") -> AA | BJ18: =IF(AND(BD18<>"AGUARDANDO",BD18<>"",N18="AUXÍLIO ALUGUEL ATÉ INDENIZAÇÃO"),"SIM","NÃO") -> NÃO
A19: 15 | B19: JD. PANTANAL | C19: SÃO MARTINHO VÁRZEA | D19: 1 | E19: -- | F19: 001/0002/G | G19: OCUPADO | H19: RESIDENCIAL | I19: PROPRIETÁRIO RESIDENTE | J19: GILFRAN CARNEIRO VIANA | K19: -- | L19: 62.458.105-58 | M19: CADASTRADO | N19: INDENIZAÇÃO | O19: N.A | P19: N.A | Q19: N.A | R19: N.A | S19: N.A | T19: N.A | U19: N.A | V19: N.A | W19: N.A | X19: N.A | AA19: ANA MARIA DOS SANTOS | AB19: 57.162.248.3 | AC19: 595.893.418.02 | AD19: PROPRIETÁRIO NÃO RESIDENTE | AE19: CADASTRADO | AF19: 20634.24 | AG19: =AF19+30000 -> 50634.24 | AH19: SIM | AI19: 6014.2025/0007373-4 | AJ19: 147744898 | AK19: 46045 | AL19: 46045 | AM19: 46045 | AN19: 46045 | AO19: 46045 | AP19: 46045 | AR19: =IF(AQ19="SIM","AGUARDANDO CORREÇÃO",IF(AP19<>"","FINALIZADO",IF(AO19<>"","AGUARDANDO ENVIO DTS",IF(AN19<>"","AGUARDANDO ASSINATURA GAB",IF(AM19<>"","AGUARDANDO ASSINATURA CTS",IF(AL19<>"","AGUARDANDO ENVIO ASSINATURA CTS",IF(AK19<>"","AGUARDANDO CONFERÊNCIA",""))))))) -> FINALIZADO | AS19: SEM PENDÊNCIA | AU19: 6014.2026/0000450-5 | AV19: FINALIZADO | AW19: FINALIZADO | AX19: FINALIZADO | AY19: FINALIZADO | AZ19: 46071 | BA19: FINALIZADO | BB19: FINALIZADO | BC19: 46093 | BD19: 46093 | BE19: AGUARDANDO | BF19: LIBERADO DEMOLIÇÃO | BG19: FINALIZADO | BH19: =IFERROR(IF(BD19-KI19=0,"",BD19-AK19),"") -> 48 | BI19: =IF(AND(AH19<>"SIM",AH19="UH"),"AA","INDENIZAÇÃO") -> INDENIZAÇÃO | BJ19: =IF(AND(BD19<>"AGUARDANDO",BD19<>"",N19="AUXÍLIO ALUGUEL ATÉ INDENIZAÇÃO"),"SIM","NÃO") -> NÃO | BK19: N/A | BL19: N/A | BM19: N/A | BN19: FINALIZADO | BO19: FINALIZADO | BP19: 46128 | BQ19: FINALIZADO | BR19: AGUARDANDO
A20: 16 | B20: JD. PANTANAL | C20: SÃO MARTINHO VÁRZEA | D20: 1 | E20: -- | F20: 001/0002/H | G20: OCUPADO | H20: RESIDENCIAL | I20: PROPRIETÁRIO RESIDENTE | J20: MÉRCIA LOPES SILVA | K20: 41.317.212-0 | L20: 051.115.775-48 | M20: CADASTRADO | N20: INDENIZAÇÃO | O20: N.A | P20: N.A | Q20: N.A | R20: N.A | S20: N.A | T20: N.A | U20: N.A | V20: N.A | W20: N.A | X20: N.A | AA20: MÉRCIA LOPES SILVA | AB20: 41.317.212-0 | AC20: 051.115.775-48 | AD20: PROPRIETÁRIO RESIDENTE | AE20: CADASTRO | AF20: 17173.63 | AG20: 47173.63 | AH20: SIM | AI20: 6014.2025/0007373-4 | AJ20: 149594350 | AK20: 46099 | AL20: 46099 | AM20: 46099 | AN20: 46099 | AO20: 46099 | AP20: 46099 | AR20: =IF(AQ20="SIM","AGUARDANDO CORREÇÃO",IF(AP20<>"","FINALIZADO",IF(AO20<>"","AGUARDANDO ENVIO DTS",IF(AN20<>"","AGUARDANDO ASSINATURA GAB",IF(AM20<>"","AGUARDANDO ASSINATURA CTS",IF(AL20<>"","AGUARDANDO ENVIO ASSINATURA CTS",IF(AK20<>"","AGUARDANDO CONFERÊNCIA",""))))))) -> FINALIZADO | AS20: SEM PENDÊNCIA | AU20: 6014.2026/0000683-4 | AV20: FINALIZADO | AW20: FINALIZADO | AX20: FINALIZADO | AY20: FINALIZADO | AZ20: 46153 | BA20: FINALIZADO | BB20: FINALIZADO | BC20: 46157 | BD20: 46157 | BE20: AGUARDANDO | BF20: LIBERADO DEMOLIÇÃO | BG20: FINALIZADO | BH20: =IFERROR(IF(BD20-KI20=0,"",BD20-AK20),"") -> 58 | BI20: =IF(AND(AH20<>"SIM",AH20="UH"),"AA","INDENIZAÇÃO") -> INDENIZAÇÃO | BJ20: =IF(AND(BD20<>"AGUARDANDO",BD20<>"",N20="AUXÍLIO ALUGUEL ATÉ INDENIZAÇÃO"),"SIM","NÃO") -> NÃO | BK20: N/A | BL20: N/A | BM20: N/A | BN20: FINALIZADO | BO20: FINALIZADO | BP20: 46195 | BQ20: FINALIZADO | BR20: AGUARDANDO
A21: 17 | B21: JD. PANTANAL | C21: SÃO MARTINHO VÁRZEA | D21: 1 | E21: -- | F21: 001/0002/I | G21: OCUPADO | H21: RESIDENCIAL | I21: PROPRIETÁRIO NÃO RESIDENTE | J21: FRANCISCO CIRILO DA COSTA NETO | K21: 56.300.779-5 | L21: 042.698.233-99 | M21: CADASTRADO | N21: INDENIZAÇÃO | O21: N.A | P21: N.A | Q21: N.A | R21: N.A | S21: N.A | T21: N.A | U21: N.A | V21: N.A | W21: N.A | X21: N.A | AA21: FRANCISCO CIRILO DA COSTA NETO | AB21: 56.300.779-5 | AC21: 042.698.233-99 | AD21: PROPRIETÁRIO RESIDENTE | AE21: CADASTRADO | AF21: 34404.25 | AG21: 60000 | AH21: SIM | AI21: 6014.2025/0007373-4 | AJ21: 147744978 | AK21: 46001 | AL21: 46001 | AM21: 46001 | AN21: 46001 | AO21: 46001 | AP21: 46001 | AR21: =IF(AQ21="SIM","AGUARDANDO CORREÇÃO",IF(AP21<>"","FINALIZADO",IF(AO21<>"","AGUARDANDO ENVIO DTS",IF(AN21<>"","AGUARDANDO ASSINATURA GAB",IF(AM21<>"","AGUARDANDO ASSINATURA CTS",IF(AL21<>"","AGUARDANDO ENVIO ASSINATURA CTS",IF(AK21<>"","AGUARDANDO CONFERÊNCIA",""))))))) -> FINALIZADO | AS21: SEM PENDÊNCIA | AU21: 6014.2025/0008621-6 | AV21: FINALIZADO | AW21: FINALIZADO | AX21: FINALIZADO | AY21: FINALIZADO | AZ21: 46024 | BA21: FINALIZADO | BB21: FINALIZADO | BC21: 46037 | BD21: 46037 | BE21: AGUARDANDO | BF21: LIBERADO DEMOLIÇÃO | BG21: FINALIZADO | BH21: =IFERROR(IF(BD21-KI21=0,"",BD21-AK21),"") -> 36 | BI21: =IF(AND(AH21<>"SIM",AH21="UH"),"AA","INDENIZAÇÃO") -> INDENIZAÇÃO | BJ21: =IF(AND(BD21<>"AGUARDANDO",BD21<>"",N21="AUXÍLIO ALUGUEL ATÉ INDENIZAÇÃO"),"SIM","NÃO") -> NÃO | BK21: N/A | BL21: N/A | BM21: N/A | BN21: FINALIZADO | BO21: FINALIZADO | BP21: 46128 | BQ21: FINALIZADO | BR21: AGUARDANDO
A22: 18 | B22: JD. PANTANAL | C22: NOVO HORIZONTE | D22: 1 | E22: -- | F22: 001/0003/A | G22: OCUPADO | H22: GARAGEM | I22: PROPRIETÁRIO NÃO RESIDENTE | J22: ALEX RODRIGUES DE SOUZA | K22: 42.483.537 | L22: 071.643.266-81 | M22: CADASTRADO | N22: INDENIZAÇÃO | O22: N.A | P22: N.A | Q22: N.A | R22: N.A | S22: N.A | T22: N.A | U22: N.A | V22: N.A | W22: N.A | X22: N.A | AI22: 6014.2025/0007373-4 | AK22: 46037 | AL22: 46037 | AM22: 46037 | AN22: 46037 | AO22: 46037 | AP22: 46037 | AR22: =IF(AQ22="SIM","AGUARDANDO CORREÇÃO",IF(AP22<>"","FINALIZADO",IF(AO22<>"","AGUARDANDO ENVIO DTS",IF(AN22<>"","AGUARDANDO ASSINATURA GAB",IF(AM22<>"","AGUARDANDO ASSINATURA CTS",IF(AL22<>"","AGUARDANDO ENVIO ASSINATURA CTS",IF(AK22<>"","AGUARDANDO CONFERÊNCIA",""))))))) -> FINALIZADO | BH22: =IFERROR(IF(BD22-KI22=0,"",BD22-AK22),"") | BI22: =IF(AND(AH22<>"SIM",AH22="UH"),"AA","INDENIZAÇÃO") -> INDENIZAÇÃO | BJ22: =IF(AND(BD22<>"AGUARDANDO",BD22<>"",N22="AUXÍLIO ALUGUEL ATÉ INDENIZAÇÃO"),"SIM","NÃO") -> NÃO
A23: 19 | B23: JD. PANTANAL | C23: SÃO MARTINHO VÁRZEA | D23: 1 | E23: -- | F23: 001/0003/A | G23: OCUPADO | H23: RESIDENCIAL | I23: PROPRIETÁRIO RESIDENTE | J23: JUCELIA DE JESUS | K23: 12593055-03 | L23: 779.056.015-87 | M23: CADASTRADO | N23: AUXÍLIO ALUGUEL UH | O23: 46106 | P23: 6014.2025/0007513-3 | Q23: 46106 | R23: 46107 | S23: 46111 | T23: 46087 | U23: OK | V23: OK | W23: 46132 | X23: 46129 | AA23: JUCELIA DE JESUS | AB23: 12593055-03 | AC23: 779.056.015-87 | AD23: PROPRIETÁRIO RESIDENTE | AE23: CADASTRADO | AF23: N.A | AG23: N.A | AH23: UH | AI23: 6014.2025/0007373-4 | AK23: 46001 | AL23: 46001 | AM23: 46001 | AN23: 46001 | AO23: 46001 | AP23: 46001 | AR23: =IF(AQ23="SIM","AGUARDANDO CORREÇÃO",IF(AP23<>"","FINALIZADO",IF(AO23<>"","AGUARDANDO ENVIO DTS",IF(AN23<>"","AGUARDANDO ASSINATURA GAB",IF(AM23<>"","AGUARDANDO ASSINATURA CTS",IF(AL23<>"","AGUARDANDO ENVIO ASSINATURA CTS",IF(AK23<>"","AGUARDANDO CONFERÊNCIA",""))))))) -> FINALIZADO | BH23: =IFERROR(IF(BD23-KI23=0,"",BD23-AK23),"") | BI23: =IF(AND(AH23<>"SIM",AH23="UH"),"AA","INDENIZAÇÃO") -> AA | BJ23: =IF(AND(BD23<>"AGUARDANDO",BD23<>"",N23="AUXÍLIO ALUGUEL ATÉ INDENIZAÇÃO"),"SIM","NÃO") -> NÃO
A24: 20 | B24: JD. PANTANAL | C24: TERRA PROMETIDA | D24: 1 | E24: -- | F24: 001/0003/A | G24: OCUPADO | H24: RESIDENCIAL | I24: PROPRIETÁRIO RESIDENTE | J24: MOISÉS GUERRA SANTOS | K24: 41.157.942-3 | L24: 297.627.628-51 | M24: CADASTRADO | N24: AUXÍLIO ALUGUEL UH | O24: 46002 | P24: 6014.2025/0007513-3 | Q24: 45999 | R24: 46006 | S24: 46006 | T24: 46009 | U24: OK | V24: OK | W24: 46014 | X24: 46017 | Y24: 46017 | AA24: MOISÉS GUERRA SANTOS | AB24: 41.157.942-3 | AC24: 297.627.628-51 | AD24: PROPRIETÁRIO RESIDENTE | AE24: CADASTRADO | AF24: N.A | AG24: N.A | AH24: UH | AI24: 6014.2025/0007373-4 | AK24: 45996 | AL24: 45996 | AM24: 45996 | AN24: 45996 | AO24: 45996 | AP24: 45996 | AR24: =IF(AQ24="SIM","AGUARDANDO CORREÇÃO",IF(AP24<>"","FINALIZADO",IF(AO24<>"","AGUARDANDO ENVIO DTS",IF(AN24<>"","AGUARDANDO ASSINATURA GAB",IF(AM24<>"","AGUARDANDO ASSINATURA CTS",IF(AL24<>"","AGUARDANDO ENVIO ASSINATURA CTS",IF(AK24<>"","AGUARDANDO CONFERÊNCIA",""))))))) -> FINALIZADO | BE24: 46017 | BF24: DEMOLIDO | BH24: =IFERROR(IF(BD24-KI24=0,"",BD24-AK24),"") | BI24: =IF(AND(AH24<>"SIM",AH24="UH"),"AA","INDENIZAÇÃO") -> AA | BJ24: =IF(AND(BD24<>"AGUARDANDO",BD24<>"",N24="AUXÍLIO ALUGUEL ATÉ INDENIZAÇÃO"),"SIM","NÃO") -> NÃO
A25: 21 | B25: JD. PANTANAL | C25: TERRA PROMETIDA | D25: 1 | E25: -- | F25: 001/0004/A | G25: OCUPADO | H25: RESIDENCIAL | I25: PROPRIETÁRIO RESIDENTE | J25: JOSÉ ALMIR ROCHA DA SILVA | K25: 67.486.680-0 | L25: 107.758.984-06 | M25: CADASTRADO | N25: AUXÍLIO ALUGUEL UH | O25: 45986 | P25: 6014.2025/0007513-3 | Q25: 45985 | R25: 45986 | S25: 45987 | T25: 45992 | U25: OK | V25: OK | W25: 45999 | X25: 46000 | Y25: 46017 | AA25: JOSÉ ALMIR ROCHA DA SILVA | AB25: 67.486.680-0 | AC25: 107.758.984-06 | AD25: PROPRIETÁRIO RESIDENTE | AE25: CADASTRADO | AF25: N.A | AG25: N.A | AH25: UH | AI25: 6014.2025/0007373-4 | AK25: 45979 | AL25: 45979 | AM25: 45979 | AN25: 45979 | AO25: 45979 | AP25: 45979 | AR25: =IF(AQ25="SIM","AGUARDANDO CORREÇÃO",IF(AP25<>"","FINALIZADO",IF(AO25<>"","AGUARDANDO ENVIO DTS",IF(AN25<>"","AGUARDANDO ASSINATURA GAB",IF(AM25<>"","AGUARDANDO ASSINATURA CTS",IF(AL25<>"","AGUARDANDO ENVIO ASSINATURA CTS",IF(AK25<>"","AGUARDANDO CONFERÊNCIA",""))))))) -> FINALIZADO | BE25: 46017 | BF25: DEMOLIDO | BH25: =IFERROR(IF(BD25-KI25=0,"",BD25-AK25),"") | BI25: =IF(AND(AH25<>"SIM",AH25="UH"),"AA","INDENIZAÇÃO") -> AA | BJ25: =IF(AND(BD25<>"AGUARDANDO",BD25<>"",N25="AUXÍLIO ALUGUEL ATÉ INDENIZAÇÃO"),"SIM","NÃO") -> NÃO
A26: 22 | B26: JD. PANTANAL | C26: SÃO MARTINHO VÁRZEA | D26: 1 | E26: -- | F26: 001/0004/A | G26: OCUPADO | H26: RESIDENCIAL | I26: PROPRIETÁRIO RESIDENTE | J26: KARINY SOARES ALVES | K26: 48.263.444-3 | L26: 400.738.458-41 | M26: CADASTRADO | N26: INDENIZAÇÃO | O26: N.A | P26: N.A | Q26: N.A | R26: N.A | S26: N.A | T26: N.A | U26: N.A | V26: N.A | W26: N.A | X26: N.A | AA26: KARINY SOARES ALVES | AB26: 48.263.444-3 | AC26: 400.738.458-41 | AD26: PROPRIETÁRIO RESIDENTE | AE26: CADASTRADO | AF26: 30397.82 | AG26: 60000 | AH26: SIM | AI26: 6014.2025/0007373-4 | AJ26: 146670420 | AK26: 45995 | AL26: 45995 | AM26: 45995 | AN26: 45995 | AO26: 45995 | AP26: 45995 | AR26: =IF(AQ26="SIM","AGUARDANDO CORREÇÃO",IF(AP26<>"","FINALIZADO",IF(AO26<>"","AGUARDANDO ENVIO DTS",IF(AN26<>"","AGUARDANDO ASSINATURA GAB",IF(AM26<>"","AGUARDANDO ASSINATURA CTS",IF(AL26<>"","AGUARDANDO ENVIO ASSINATURA CTS",IF(AK26<>"","AGUARDANDO CONFERÊNCIA",""))))))) -> FINALIZADO | AS26: SEM PENDÊNCIA | AU26: 6014.2025/0008617-8 | AV26: FINALIZADO | AW26: FINALIZADO | AX26: FINALIZADO | AY26: FINALIZADO | AZ26: 46024 | BA26: FINALIZADO | BB26: FINALIZADO | BC26: 46038 | BD26: 46038 | BE26: AGUARDANDO | BF26: LIBERADO DEMOLIÇÃO | BG26: FINALIZADO | BH26: =IFERROR(IF(BD26-KI26=0,"",BD26-AK26),"") -> 43 | BI26: =IF(AND(AH26<>"SIM",AH26="UH"),"AA","INDENIZAÇÃO") -> INDENIZAÇÃO | BJ26: =IF(AND(BD26<>"AGUARDANDO",BD26<>"",N26="AUXÍLIO ALUGUEL ATÉ INDENIZAÇÃO"),"SIM","NÃO") -> NÃO | BK26: N/A | BL26: N/A | BM26: N/A | BN26: FINALIZADO | BO26: FINALIZADO | BP26: 46128 | BQ26: FINALIZADO | BR26: AGUARDANDO
A27: 23 | B27: JD. PANTANAL | C27: NOVO HORIZONTE | D27: 1 | E27: -- | F27: 001/0004/AF2 | G27: OCUPADO | H27: RESIDENCIAL | I27: PROPRIETÁRIO RESIDENTE | J27: VALDELICE SILVA DE SOUZA | K27: 36.113.625-0 | L27: 306.868.168-54 | M27: CADASTRADO | N27: AUXÍLIO ALUGUEL UH | O27: 46058 | P27: 6014.2025/0007513-3 | Q27: 46058 | R27: 46058 | S27: 46059 | T27: 46063 | U27: OK | V27: OK | W27: 46073 | X27: 46104 | AA27: VALDELICE SILVA DE SOUZA | AB27: 36.113.625-0 | AC27: 306.868.168-54 | AD27: PROPRIETÁRIO RESIDENTE | AE27: CADASTRADO | AF27: N.A | AG27: N.A | AH27: UH | AI27: 6014.2025/0007373-4 | AK27: 46050 | AL27: 46050 | AM27: 46050 | AN27: 46050 | AO27: 46050 | AP27: 46050 | AR27: =IF(AQ27="SIM","AGUARDANDO CORREÇÃO",IF(AP27<>"","FINALIZADO",IF(AO27<>"","AGUARDANDO ENVIO DTS",IF(AN27<>"","AGUARDANDO ASSINATURA GAB",IF(AM27<>"","AGUARDANDO ASSINATURA CTS",IF(AL27<>"","AGUARDANDO ENVIO ASSINATURA CTS",IF(AK27<>"","AGUARDANDO CONFERÊNCIA",""))))))) -> FINALIZADO | BH27: =IFERROR(IF(BD27-KI27=0,"",BD27-AK27),"") | BI27: =IF(AND(AH27<>"SIM",AH27="UH"),"AA","INDENIZAÇÃO") -> AA | BJ27: =IF(AND(BD27<>"AGUARDANDO",BD27<>"",N27="AUXÍLIO ALUGUEL ATÉ INDENIZAÇÃO"),"SIM","NÃO") -> NÃO
A28: 24 | B28: JD. PANTANAL | C28: NOVO HORIZONTE | D28: 1 | E28: -- | F28: 001/0005/A | G28: OCUPADO | H28: RESIDENCIAL | I28: PROPRIETÁRIO RESIDENTE | J28: LUCAS GERALDO DOS SANTOS | K28: 42.641.652-1 | L28: 424.164.178-43 | M28: CADASTRADO | N28: AUXÍLIO ALUGUEL UH | O28: 46044 | P28: 6014.2025/0007513-3 | Q28: 46043 | R28: 46044 | S28: 46045 | T28: 46155 | U28: OK | V28: OK | W28: 46055 | X28: 46056 | AA28: LUCAS GERALDO DOS SANTOS | AB28: 42.641.652-1 | AC28: 424.164.178-43 | AD28: PROPRIETÁRIO RESIDENTE | AE28: CADASTRADO | AF28: N.A | AG28: N.A | AH28: UH | AI28: 6014.2025/0007373-4 | AK28: 46037 | AL28: 46037 | AM28: 46037 | AN28: 46037 | AO28: 46037 | AP28: 46037 | AR28: =IF(AQ28="SIM","AGUARDANDO CORREÇÃO",IF(AP28<>"","FINALIZADO",IF(AO28<>"","AGUARDANDO ENVIO DTS",IF(AN28<>"","AGUARDANDO ASSINATURA GAB",IF(AM28<>"","AGUARDANDO ASSINATURA CTS",IF(AL28<>"","AGUARDANDO ENVIO ASSINATURA CTS",IF(AK28<>"","AGUARDANDO CONFERÊNCIA",""))))))) -> FINALIZADO | BH28: =IFERROR(IF(BD28-KI28=0,"",BD28-AK28),"") | BI28: =IF(AND(AH28<>"SIM",AH28="UH"),"AA","INDENIZAÇÃO") -> AA | BJ28: =IF(AND(BD28<>"AGUARDANDO",BD28<>"",N28="AUXÍLIO ALUGUEL ATÉ INDENIZAÇÃO"),"SIM","NÃO") -> NÃO
A29: 25 | B29: JD. PANTANAL | C29: TERRA PROMETIDA | D29: 1 | E29: -- | F29: 001/0005/A | G29: OCUPADO | H29: RESIDENCIAL | I29: PROPRIETÁRIO RESIDENTE | J29: CECILIO BORGES DE SANTANA | K29: 01.353.707-52 | L29: 144.230.305-00 | M29: CADASTRADO | N29: AUXÍLIO ALUGUEL UH | O29: 46002 | P29: 6014.2025/0007513-3 | Q29: 45999 | R29: 46006 | S29: 46006 | T29: 46009 | U29: OK | V29: OK | W29: 46014 | X29: 46017 | Y29: 46017 | AA29: CECILIO BORGES DE SANTANA | AB29: 01.353.707-52 | AC29: 144.230.305-00 | AD29: PROPRIETÁRIO RESIDENTE | AE29: CADASTRADO | AF29: N.A | AG29: N.A | AH29: UH | AI29: 6014.2025/0007373-4 | AK29: 45996 | AL29: 45996 | AM29: 45996 | AN29: 45996 | AO29: 45996 | AP29: 45996 | AR29: =IF(AQ29="SIM","AGUARDANDO CORREÇÃO",IF(AP29<>"","FINALIZADO",IF(AO29<>"","AGUARDANDO ENVIO DTS",IF(AN29<>"","AGUARDANDO ASSINATURA GAB",IF(AM29<>"","AGUARDANDO ASSINATURA CTS",IF(AL29<>"","AGUARDANDO ENVIO ASSINATURA CTS",IF(AK29<>"","AGUARDANDO CONFERÊNCIA",""))))))) -> FINALIZADO | BE29: 46017 | BF29: DEMOLIDO | BH29: =IFERROR(IF(BD29-KI29=0,"",BD29-AK29),"") | BI29: =IF(AND(AH29<>"SIM",AH29="UH"),"AA","INDENIZAÇÃO") -> AA | BJ29: =IF(AND(BD29<>"AGUARDANDO",BD29<>"",N29="AUXÍLIO ALUGUEL ATÉ INDENIZAÇÃO"),"SIM","NÃO") -> NÃO
A30: 26 | B30: JD. PANTANAL | C30: SÃO MARTINHO VÁRZEA | D30: 1 | E30: -- | F30: 001/0005/A | G30: OCUPADO | H30: RESIDENCIAL | I30: PROPRIETÁRIO RESIDENTE | J30: JOSE ANDRE COELHO | K30: 38.520.790-6 | L30: 689.398.683-15 | M30: CADASTRADO | N30: INDENIZAÇÃO | O30: N.A | P30: N.A | Q30: N.A | R30: N.A | S30: N.A | T30: N.A | U30: N.A | V30: N.A | W30: N.A | X30: N.A | AA30: JOSE ANDRE COELHO | AB30: 38.520.790-6 | AC30: 689.398.683-15 | AD30: PROPRIETÁRIO RESIDENTE | AE30: CADASTRADO | AF30: 96282.33 | AG30: 96282.33 | AH30: SIM | AI30: 6014.2025/0007373-4 | AJ30: 146654114 | AK30: 46038 | AL30: 46038 | AM30: 46038 | AN30: 46038 | AO30: 46038 | AP30: 46038 | AR30: =IF(AQ30="SIM","AGUARDANDO CORREÇÃO",IF(AP30<>"","FINALIZADO",IF(AO30<>"","AGUARDANDO ENVIO DTS",IF(AN30<>"","AGUARDANDO ASSINATURA GAB",IF(AM30<>"","AGUARDANDO ASSINATURA CTS",IF(AL30<>"","AGUARDANDO ENVIO ASSINATURA CTS",IF(AK30<>"","AGUARDANDO CONFERÊNCIA",""))))))) -> FINALIZADO | AS30: SEM PENDÊNCIA | AU30: 6014.2026/0001005-0 | AV30: FINALIZADO | AW30: FINALIZADO | AX30: FINALIZADO | AY30: FINALIZADO | AZ30: 46085 | BA30: FINALIZADO | BB30: FINALIZADO | BC30: 46092 | BD30: 46092 | BE30: AGUARDANDO | BF30: LIBERADO DEMOLIÇÃO | BG30: FINALIZADO | BH30: =IFERROR(IF(BD30-KI30=0,"",BD30-AK30),"") -> 54 | BI30: =IF(AND(AH30<>"SIM",AH30="UH"),"AA","INDENIZAÇÃO") -> INDENIZAÇÃO | BJ30: =IF(AND(BD30<>"AGUARDANDO",BD30<>"",N30="AUXÍLIO ALUGUEL ATÉ INDENIZAÇÃO"),"SIM","NÃO") -> NÃO | BK30: N/A | BL30: N/A | BM30: N/A | BN30: FINALIZADO | BO30: FINALIZADO | BP30: 46128 | BQ30: FINALIZADO | BR30: AGUARDANDO
A31: 27 | B31: JD. PANTANAL | C31: NOVO HORIZONTE | D31: 1 | E31: -- | F31: 001/0005/AF2 | G31: OCUPADO | H31: COABITAÇÃO | I31: COABITAÇÃO | J31: LUIS AMADEU DA SILVA | K31: 37.843.968-6 | L31: 022.361.004-69 | M31: CADASTRADO | N31: AUXÍLIO ALUGUEL UH | O31: 46044 | P31: 6014.2025/0007513-3 | Q31: 46043 | R31: 46044 | S31: 46045 | T31: 46155 | U31: OK | V31: OK | W31: 46055 | X31: 46063 | AA31: LUIS AMADEU DA SILVA | AB31: 37.843.968-6 | AC31: 022.361.004-69 | AD31: PROPRIETÁRIO RESIDENTE | AE31: CADASTRADO | AF31: N.A | AG31: N.A | AH31: UH | AI31: 6014.2025/0007373-4 | AK31: 46038 | AL31: 46038 | AM31: 46038 | AN31: 46038 | AO31: 46038 | AP31: 46038 | AR31: =IF(AQ31="SIM","AGUARDANDO CORREÇÃO",IF(AP31<>"","FINALIZADO",IF(AO31<>"","AGUARDANDO ENVIO DTS",IF(AN31<>"","AGUARDANDO ASSINATURA GAB",IF(AM31<>"","AGUARDANDO ASSINATURA CTS",IF(AL31<>"","AGUARDANDO ENVIO ASSINATURA CTS",IF(AK31<>"","AGUARDANDO CONFERÊNCIA",""))))))) -> FINALIZADO | BH31: =IFERROR(IF(BD31-KI31=0,"",BD31-AK31),"") | BI31: =IF(AND(AH31<>"SIM",AH31="UH"),"AA","INDENIZAÇÃO") -> AA | BJ31: =IF(AND(BD31<>"AGUARDANDO",BD31<>"",N31="AUXÍLIO ALUGUEL ATÉ INDENIZAÇÃO"),"SIM","NÃO") -> NÃO
A32: 28 | B32: JD. PANTANAL | C32: NOVO HORIZONTE | D32: 1 | E32: -- | F32: 001/0005/B | G32: OCUPADO | H32: RESIDENCIAL | I32: PROPRIETÁRIO RESIDENTE | J32: GABRIEL DOS SANTOS OLIVEIRA | K32: 52.393.186 | L32: 451.473.188-95 | M32: CADASTRADO | N32: AUXÍLIO ALUGUEL UH | O32: 46044 | P32: 6014.2025/0007513-3 | Q32: 46043 | R32: 46044 | S32: 46045 | T32: 46155 | U32: OK | V32: OK | W32: 46055 | X32: 46056 | AA32: GABRIEL DOS SANTOS OLIVEIRA | AB32: 52.393.186 | AC32: 451.473.188-95 | AD32: PROPRIETÁRIO RESIDENTE | AE32: CADASTRADO | AF32: N.A | AG32: N.A | AH32: UH | AI32: 6014.2025/0007373-4 | AK32: 46037 | AL32: 46037 | AM32: 46037 | AN32: 46037 | AO32: 46037 | AP32: 46037 | AR32: =IF(AQ32="SIM","AGUARDANDO CORREÇÃO",IF(AP32<>"","FINALIZADO",IF(AO32<>"","AGUARDANDO ENVIO DTS",IF(AN32<>"","AGUARDANDO ASSINATURA GAB",IF(AM32<>"","AGUARDANDO ASSINATURA CTS",IF(AL32<>"","AGUARDANDO ENVIO ASSINATURA CTS",IF(AK32<>"","AGUARDANDO CONFERÊNCIA",""))))))) -> FINALIZADO | BH32: =IFERROR(IF(BD32-KI32=0,"",BD32-AK32),"") | BI32: =IF(AND(AH32<>"SIM",AH32="UH"),"AA","INDENIZAÇÃO") -> AA | BJ32: =IF(AND(BD32<>"AGUARDANDO",BD32<>"",N32="AUXÍLIO ALUGUEL ATÉ INDENIZAÇÃO"),"SIM","NÃO") -> NÃO
