Workbook
Name Adequacao_Imovel: 'Listas (não utilizar)'!$G$2:$G$7
Name ADEQUAR: 'Listas (não utilizar)'!$G$2:$G$7
Name Apartamento: 'Listas (não utilizar)'!$D$2:$D$21
Name APROVCEF: #REF!
Name Área: 'Listas (não utilizar)'!$A$2:$A$28
Name AREAS: #REF!
Name AVILDATA: #REF!
Name AVILDATA1: #REF!
Name BARCDATA: #REF!
Name BILBDATA: #REF!
Name Bloco: 'Listas (não utilizar)'!$C$2:$C$16
Name CEF: #REF!
Name CEUTDATA: #REF!
Name Condomínio: 'Listas (não utilizar)'!$B$2:$B$15
Name INDDEMAND: #REF!
Name INDEMAND: #REF!
Name it: #REF!
Name Pendência: 'Listas (não utilizar)'!$I$2:$I$7
Name PLANCCO: #REF!
Name Renúncia: 'Listas (não utilizar)'!$H$2:$H$6
Name RetornoSMADS: '[1]Listas (não utilizar)'!$E$2:$E$3
Name selogo: #REF!
Name selomv: #REF!
Name selos_go: #REF!
Name selosgo: #REF!
Name selosgo1: #REF!
Name SITAH_CAIXA: 'Listas (não utilizar)'!$E$2:$E$9
Name StatusCAIXA: 'Listas (não utilizar)'!$F$2:$F$5
Name TEPROC: #REF!
Name TEPROC1: #REF!

Sheet PRIORIDADES
C3: 2 | D3: PRIORITÁRIO | G3: OCUPADO | H3: RESIDENCIAL | I3: PROPRIETÁRIO NÃO RESIDENTE | M3: CADASTRADO | N3: INDENIZAÇÃO | P3: SIM | R3: SIM | X3: SAQUE PENDENTE | AE3: PROPRIETÁRIO NÃO RESIDENTE | AF3: CADASTRADO | AI3: SIM | AK3: SIM | AM3: COMPLETA | AN3: SEM PENDÊNCIAS
C4: 4 | G4: VAZIO | H4: COMERCIAL | I4: PROPRIETÁRIO RESIDENTE | M4: NÃO CADASTRADO | N4: AUXÍLIO ALUGUEL UH | P4: NÃO | R4: NÃO | AE4: PROPRIETÁRIO RESIDENTE | AF4: NÃO CADASTRADO | AI4: NÃO | AK4: NÃO | AM4: PENDENTE | AN4: FALTA TERMO
G5: OCUPADO/RISCO | H5: MISTO | I5: INQULINO | N5: RECUSA AUXÍLIO ALUGUEL UH | AI5: UH | AK5: N/A | AN5: FALTA DOCS
G6: CONSTRUÇÃO | N6: NÃO TEM DIREITO ATENDIMENTO | AI6: ESTUDO DE CASO | AK6: PENDENTE | AN6: FALTA TERMO E DOCS
G7: DEMOLIDO
G8: DESCARACTERIZADO
G9: DESABADO
AP10: AGUARDANDO
A12: INFORMAÇÕES INICIAIS | P12: INFORMAÇÕES AUXÍLIO ALUGUEL | AB12: INFORMAÇÕES INDENIZAÇÃO | BB12: PROCESSO ATENDIMENTO HABITACIONAL
A13: ORDEM | B13: ÁREA | C13: FASE | D13: TRECHO | E13: PRIORIDADE | F13: SELO | G13: SITUAÇÃO INICIAL IMÓVEL | H13: USO IMÓVEL | I13: SITUAÇÃO DO RESIDENTE | J13: TITULAR | K13: RG | L13: CPF | M13: CADASTRO HABITA SAMPA | N13: OPÇÃO DE ATENDIMENTO HABITACIONAL | O13: ENVIO DADOS | P13: SOLICITAÇÃO AUXÍLIO ALUGUEL ÁREA | Q13: No PROCESSO SEI (AUXÍLIO ALUGUEL) | R13: ANÁLISE DTS CADASTRO + CHECAGEM DUPLO | S13: INSTRUÇÃO PROCESSO SEI DTS | T13: ANÁLISE CTS ASSINATURA GABINETE | U13: DATA PUBLICAÇÃO DIÁRIO OFICIAL | V13: CONFECÇÃO TERMO | W13: ENVIO TERMO CARTÃO | X13: PREVISÃO PAGAMENTO | Y13: DATA SAQUE | Z13: DATA MUDANÇA | AA13: OBSERVAÇÕES AA | AB13: PROPRIETÁRIO | AC13: RG | AD13: CPF | AE13: SITUAÇÃO DO PROPRIETÁRIO | AF13: CADASTRO HABITASAMPA | AG13: VALOR AVALIAÇÃO | AH13: VALOR FINAL INDENIZAÇÃO C/ BONIFICAÇÃO | AI13: ACEITA VALOR INDENIZAÇÃO | AJ13: Nº SEI LAUDOS AVALIAÇÃO | AK13: Nº DOCUMENTO LAUDO | AL13: TERMO INDENIZAÇÃO | AM13: DOSSIÊ | AN13: PENDÊNCIA | AO13: OBSERVAÇÕES INDENIZAÇÃO | AP13: No PROCESSO SEI (INDENIZAÇÃO) | AQ13: INSTRUÇÃO PROCESSO SEI DTS | AR13: ASSINATURA DIRETOR DTS | AS13: ELABORAÇÃO DESPACHO CTS | AT13: ASSINATURA DESPACHO GABINETE | AU13: PUBLICAÇÃO DIÁRIO OFICIAL | AV13: ENCAMINHAMENTO DAF/DIF CTS | AW13: LIBERAÇÃO PAGAMENTO DAF/DIF | AX13: PREVISÃO PAGAMENTO | AY13: DATA PAGAMENTO | AZ13: DATA ENTREGA IMÓVEL | BA13: SITUAÇÃO ATUAL IMÓVEL | BB13: STATUS | BC13: DIAS TOTAIS | BD13: OPÇÃO ATENDIMENTO | BE13: NECESSITA BLOQUEIO AA | BF13: SOLICITAÇÃO BLOQUEIO AA DTS | BG13: DATA SOLICITAÇÃO BLOQUEIO AA | BH13: DATA BLOQUEIO AA | BI13: DESPACHO EXCLUSÃO GABINETE | BJ13: ASSINATURA DESPACHO GABINETE | BK13: PUBLICAÇÃO DOC | BL13: ENCAMINHAMENTO SOLICITAÇÃO EXCLUSÃO DEPLAN | BM13: ENCERRAMENTO PROCESSO DTS
A14: 1 | B14: PARAISÓPOLIS/ANTONICO | C14: 1 | D14: 022 | E14: -- | F14: 022/0004/A | G14: OCUPADO | H14: RESIDENCIAL | I14: PROPRIETÁRIO RESIDENTE | J14: PRISCILA SILVA LIMA | K14: 45.750.631-3 | L14: 230.081.618-04 | M14: CADASTRADO | N14: AUXÍLIO ALUGUEL UH | O14: 45513 | P14: 45513 | Q14: 6014.2021/0000734-3 | R14: 45513 | S14: 45520 | T14: 45520 | U14: 45540 | V14: 45540 | W14: 45540 | X14: 45555 | Y14: 20-set-24 | AB14: PRISCILA SILVA LIMA | AC14: 45.750.631-3 | AD14: 230.081.618-04 | AE14: PROPRIETÁRIO RESIDENTE | AF14: CADASTRADO | AG14: 0 | AH14: 0 | AI14: UH | AJ14: 6014.2024/0003834-1 | AK14: FINALIZADO | AL14: N/A | AM14: N/A | AN14: N/A | AP14: N/A | AQ14: N/A | AR14: N/A | AS14: N/A | AT14: N/A | AU14: N/A | AV14: N/A | AW14: N/A | AZ14: 45596 | BA14: DESCARACTERIZADO | BC14: =IF(AY14-KD14=0,"",AY14-O14) | BD14: =IF(AND(AI14<>"SIM",AI14="UH"),"AA","INDENIZAÇÃO") -> AA | BE14: =IF(AND(AY14<>"AGUARDANDO",AY14<>"",N14="AUXÍLIO ALUGUEL ATÉ INDENIZAÇÃO"),"SIM","NÃO") -> NÃO
A15: 2 | B15: PARAISÓPOLIS/ANTONICO | C15: 1 | D15: 022 | E15: -- | F15: 022/0004/B | G15: OCUPADO | H15: RESIDENCIAL | I15: INQUILINO | J15: LAIANE BELARMINA DOS SANTOS | K15: 50.026.091-6 | L15: 427.190.128-82 | M15: CADASTRADO | N15: AUXÍLIO ALUGUEL UH | O15: 45513 | P15: 45513 | Q15: 6014.2021/0000734-3 | R15: 45513 | S15: 45520 | T15: 45520 | U15: 45540 | V15: 45540 | W15: 45540 | X15: 45555 | Y15: 24-set-24 | AB15: MARLENE BELARMINA DOS SANTOS MACEDO | AC15: 15.439.464-6 | AD15: 470.080755-53 | AE15: PROPRIETÁRIO NÃO RESIDENTE | AF15: CADASTRADO | AG15: 30697.43 | AH15: =AG15 -> 30697.43 | AI15: SIM | AJ15: 6014.2024/0003834-1 | AK15: FINALIZADO | AL15: FINALIZADO | AM15: FINALIZADO | AN15: SEM PENDÊNCIA | AP15: 6014.2024/0004757-0 | AQ15: FINALIZADO | AR15: FINALIZADO | AS15: FINALIZADO | AT15: FINALIZADO | AU15: 45597 | AV15: FINALIZADO | AW15: FINALIZADO | AX15: 45615 | AY15: 45615 | AZ15: 45993 | BA15: LIBERADO DEMOLIÇÃO | BB15: FINALIZADO | BC15: =IF(AY15-KD15=0,"",AY15-O15) -> 102 | BD15: =IF(AND(AI15<>"SIM",AI15="UH"),"AA","INDENIZAÇÃO") -> INDENIZAÇÃO | BE15: =IF(AND(AY15<>"AGUARDANDO",AY15<>"",N15="AUXÍLIO ALUGUEL ATÉ INDENIZAÇÃO"),"SIM","NÃO") -> NÃO | BF15: N/A | BG15: N/A | BH15: N/A | BI15: FINALIZADO | BJ15: FINALIZADO | BK15: 45635 | BL15: FINALIZADO | BM15: FINALIZADO
A16: 3 | B16: PARAISÓPOLIS/ANTONICO | C16: 2 | D16: 024 | E16: URG | F16: 024/0001/A | G16: OCUPADO | H16: RESIDENCIAL | I16: INQUILINO | J16: JORGE OLIVEIRA SANTOS | K16: 20.372.964-10 | L16: 079.557.355-36 | M16: CADASTRADO | N16: AUXÍLIO ALUGUEL UH | O16: 45118 | P16: 45121 | Q16: 6014.2021/0000734-3 | R16: 45125 | S16: 45126 | T16: 45138 | U16: 45142 | V16: 45142 | W16: 45142 | X16: 45159 | Y16: 45160 | Z16: 45202 | AB16: ALEXANDRE RODRIGUES FERREIRA | AC16: 60.410.535-6 | AD16: 075.483.425-51 | AE16: PROPRIETÁRIO NÃO RESIDENTE | AF16: CADASTRADO | AG16: 32907.08 | AH16: 60000 | AI16: SIM | AJ16: 6014.2022/0000163-0 | AK16: FINALIZADO | AL16: FINALIZADO | AM16: FINALIZADO | AN16: SEM PENDÊNCIA | AP16: 6014.2023/0002356-3 | AQ16: FINALIZADO | AR16: FINALIZADO | AS16: FINALIZADO | AT16: FINALIZADO | AU16: 45180 | AV16: FINALIZADO | AW16: FINALIZADO | AX16: 45202 | AY16: 45202 | AZ16: 45202 | BA16: DEMOLIDO | BB16: FINALIZADO | BC16: =IF(AY16-KD16=0,"",AY16-O16) -> 84 | BD16: =IF(AND(AI16<>"SIM",AI16="UH"),"AA","INDENIZAÇÃO") -> INDENIZAÇÃO | BE16: =IF(AND(AY16<>"AGUARDANDO",AY16<>"",N16="AUXÍLIO ALUGUEL ATÉ INDENIZAÇÃO"),"SIM","NÃO") -> NÃO | BF16: N/A | BG16: N/A | BH16: N/A | BI16: FINALIZADO | BJ16: FINALIZADO | BK16: 45303 | BL16: FINALIZADO | BM16: FINALIZADO
A17: 4 | B17: PARAISÓPOLIS/ANTONICO | C17: 2 | D17: 024 | E17: URG | F17: 024/0001/B | G17: OCUPADO | H17: RESIDENCIAL | I17: PROPRIETÁRIO RESIDENTE | J17: GINEILDA MARIA DE LOIOLA | K17: 50.543.365-5 | L17: 918.687.853-00 | M17: CADASTRADO | N17: INDENIZAÇÃO | O17: 44866 | P17: N/A | Q17: N/A | R17: N/A | S17: N/A | T17: N/A | U17: N/A | V17: N/A | W17: N/A | X17: N/A | Y17: N/A | Z17: N/A | AB17: GINEILDA MARIA DE LOIOLA | AC17: 50.543.365-5 | AD17: 918.687.853-00 | AE17: PROPRIETÁRIO RESIDENTE | AF17: CADASTRADO | AG17: =AH17-30000 -> 28361.19 | AH17: 58361.19 | AI17: SIM | AJ17: 6014.2022/0000163-0 | AK17: FINALIZADO | AL17: FINALIZADO | AM17: FINALIZADO | AN17: SEM PENDÊNCIA | AP17: 6014.2022/0003753-8 | AQ17: FINALIZADO | AR17: FINALIZADO | AS17: FINALIZADO | AT17: FINALIZADO | AU17: 44992 | AV17: FINALIZADO | AW17: FINALIZADO | AX17: 45014 | AY17: 45029 | AZ17: 45048 | BA17: DESCARACTERIZADO | BB17: FINALIZADO | BC17: =IF(AY17-KD17=0,"",AY17-O17) -> 163 | BD17: =IF(AND(AI17<>"SIM",AI17="UH"),"AA","INDENIZAÇÃO") -> INDENIZAÇÃO | BE17: =IF(AND(AY17<>"AGUARDANDO",AY17<>"",N17="AUXÍLIO ALUGUEL ATÉ INDENIZAÇÃO"),"SIM","NÃO") -> NÃO | BF17: N/A | BG17: N/A | BH17: N/A | BI17: FINALIZADO | BJ17: FINALIZADO | BK17: 45175 | BL17: FINALIZADO | BM17: FINALIZADO
A18: 5 | B18: PARAISÓPOLIS/ANTONICO | C18: 2 | D18: 024 | E18: URG | F18: 024/0002/A | G18: OCUPADO | H18: RESIDENCIAL | I18: PROPRIETÁRIO RESIDENTE | J18: CARLOS ALBERTO MIRANDA DOS ANJOS | K18: 30.866.690-2 | L18: 073.573.568-92 | M18: CADASTRADO | N18: INDENIZAÇÃO | O18: 44866 | P18: N/A | Q18: N/A | R18: N/A | S18: N/A | T18: N/A | U18: N/A | V18: N/A | W18: N/A | X18: N/A | Y18: N/A | Z18: N/A | AB18: CARLOS ALBERTO MIRANDA DOS ANJOS | AC18: 30.866.690-2 | AD18: 073.573.568-92 | AE18: PROPRIETÁRIO RESIDENTE | AF18: CADASTRADO | AG18: 44132 | AH18: 60000 | AI18: SIM | AJ18: 6014.2022/0000163-0 | AK18: FINALIZADO | AL18: FINALIZADO | AM18: FINALIZADO | AN18: SEM PENDÊNCIA | AP18: 6014.2022/0004094-6 | AQ18: FINALIZADO | AR18: FINALIZADO | AS18: FINALIZADO | AT18: FINALIZADO | AU18: 44992 | AV18: FINALIZADO | AW18: FINALIZADO | AX18: 45014 | AY18: 45014 | AZ18: 45055 | BA18: DESCARACTERIZADO | BB18: FINALIZADO | BC18: =IF(AY18-KD18=0,"",AY18-O18) -> 148 | BD18: =IF(AND(AI18<>"SIM",AI18="UH"),"AA","INDENIZAÇÃO") -> INDENIZAÇÃO | BE18: =IF(AND(AY18<>"AGUARDANDO",AY18<>"",N18="AUXÍLIO ALUGUEL ATÉ INDENIZAÇÃO"),"SIM","NÃO") -> NÃO | BF18: N/A | BG18: N/A | BH18: N/A | BI18: FINALIZADO | BJ18: FINALIZADO | BK18: 45175 | BL18: FINALIZADO | BM18: FINALIZADO
A19: 6 | B19: PARAISÓPOLIS/ANTONICO | C19: 2 | D19: 024 | E19: URG | F19: 024/0002/B | G19: OCUPADO | H19: RESIDENCIAL | I19: PROPRIETÁRIO RESIDENTE | J19: SUZANA DE OLIVEIRA LIMA | K19: 41.043.062-6 | L19: 314.835.758-29 | M19: CADASTRADO | N19: INDENIZAÇÃO | O19: 44866 | P19: N/A | Q19: N/A | R19: N/A | S19: N/A | T19: N/A | U19: N/A | V19: N/A | W19: N/A | X19: N/A | Y19: N/A | Z19: N/A | AB19: SUZANA DE OLIVEIRA LIMA | AC19: 41.043.062-6 | AD19: 314.835.758-29 | AE19: PROPRIETÁRIO RESIDENTE | AF19: CADASTRADO | AG19: 43831.3 | AH19: 60000 | AI19: SIM | AJ19: 6014.2022/0000163-0 | AK19: FINALIZADO | AL19: FINALIZADO | AM19: FINALIZADO | AN19: SEM PENDÊNCIA | AP19: 6014.2022/0004095-4 | AQ19: FINALIZADO | AR19: FINALIZADO | AS19: FINALIZADO | AT19: FINALIZADO | AU19: 44992 | AV19: FINALIZADO | AW19: FINALIZADO | AX19: 45016 | AY19: 45016 | AZ19: 45027 | BA19: DESCARACTERIZADO | BB19: FINALIZADO | BC19: =IF(AY19-KD19=0,"",AY19-O19) -> 150 | BD19: =IF(AND(AI19<>"SIM",AI19="UH"),"AA","INDENIZAÇÃO") -> INDENIZAÇÃO | BE19: =IF(AND(AY19<>"AGUARDANDO",AY19<>"",N19="AUXÍLIO ALUGUEL ATÉ INDENIZAÇÃO"),"SIM","NÃO") -> NÃO | BF19: N/A | BG19: N/A | BH19: N/A | BI19: FINALIZADO | BJ19: FINALIZADO | BK19: 45175 | BL19: FINALIZADO | BM19: FINALIZADO
A20: 7 | B20: PARAISÓPOLIS/ANTONICO | C20: 2 | D20: 024 | E20: URG | F20: 024/0003/A | G20: OCUPADO | H20: RESIDENCIAL | I20: INQUILINO | J20: JOSE MARCIO LOPES DA SILVA | K20: 33.771.900-7 | L20: 622.409.195-15 | M20: CADASTRADO | N20: AUXÍLIO ALUGUEL UH | O20: 45066 | P20: 45457 | Q20: 6014.2021/0000734-3 | R20: 45470 | S20: 45476 | T20: 45509 | U20: 45510 | V20: 45540 | W20: 45540 | X20: 45555 | Y20: 23-set-24 | Z20: 45594 | AA20: AA BLOQUEADO - RECUSA ENTREGAR IMÓVEL | AB20: GRACILIANO SANTOS BISPO | AC20: 54.028.579-1 | AD20: 052.278.458-21 | AE20: PROPRIETÁRIO NÃO RESIDENTE | AF20: CADASTRADO | AG20: =AH20 -> 84686.08 | AH20: 84686.08 | AI20: SIM | AJ20: 6014.2022/0000163-0 | AK20: FINALIZADO | AL20: FINALIZADO | AM20: FINALIZADO | AN20: SEM PENDÊNCIA | AO20: RESISTENTE | AP20: 6014.2024/0002783-8 | AQ20: FINALIZADO | AR20: FINALIZADO | AS20: FINALIZADO | AT20: FINALIZADO | AU20: 45524 | AV20: FINALIZADO | AW20: FINALIZADO | AX20: 45530 | AY20: 45530 | AZ20: 45594 | BA20: DESCARACTERIZADO | BB20: FINALIZADO | BC20: =IF(AY20-KD20=0,"",AY20-O20) -> 464 | BD20: =IF(AND(AI20<>"SIM",AI20="UH"),"AA","INDENIZAÇÃO") -> INDENIZAÇÃO | BE20: =IF(AND(AY20<>"AGUARDANDO",AY20<>"",N20="AUXÍLIO ALUGUEL ATÉ INDENIZAÇÃO"),"SIM","NÃO") -> NÃO | BF20: N/A | BG20: N/A | BH20: N/A | BI20: FINALIZADO | BJ20: FINALIZADO | BK20: 45621 | BL20: FINALIZADO | BM20: AGUARDANDO
A21: 8 | B21: PARAISÓPOLIS/ANTONICO | C21: 2 | D21: 024 | E21: URG | F21: 024/0004/AF1 | G21: OCUPADO | H21: RESIDENCIAL | I21: INQUILINO | J21: ANNE SARAH ALVES LIMA | K21: 68.039.443-6 | L21: 117.438.746-77 | M21: CADASTRADO | N21: AUXÍLIO ALUGUEL UH | O21: 44987 | P21: 44988 | Q21: 6014.2021/0000734-3 | R21: FINALIZADO | S21: 45015 | T21: 45012 | U21: 45014 | V21: 45016 | W21: 45022 | X21: 45036 | Y21: 45049 | Z21: 45173 | AB21: RONILDO SOARES FERREIRA | AC21: 66.250.703-4 | AD21: 911.251.115-34 | AE21: PROPRIETÁRIO NÃO RESIDENTE | AF21: CADASTRADO | AG21: 106215.4 | AH21: 106215.4 | AI21: SIM | AJ21: 6014.2022/0000163-0 | AK21: FINALIZADO | AL21: FINALIZADO | AM21: FINALIZADO | AN21: SEM PENDÊNCIA | AO21: MOBILIZAÇÃO AGENDADA PARA DIA 21/11/2022 | AP21: 6014.2023/0000856-4 | AQ21: FINALIZADO | AR21: FINALIZADO | AS21: FINALIZADO | AT21: FINALIZADO | AU21: 45148 | AV21: FINALIZADO | AW21: FINALIZADO | AX21: 45160 | AY21: 45160 | AZ21: 45173 | BA21: DESCARACTERIZADO | BB21: FINALIZADO | BC21: =IF(AY21-KD21=0,"",AY21-O21) -> 173 | BD21: =IF(AND(AI21<>"SIM",AI21="UH"),"AA","INDENIZAÇÃO") -> INDENIZAÇÃO | BE21: =IF(AND(AY21<>"AGUARDANDO",AY21<>"",N21="AUXÍLIO ALUGUEL ATÉ INDENIZAÇÃO"),"SIM","NÃO") -> NÃO | BF21: N/A | BG21: N/A | BH21: N/A | BI21: FINALIZADO | BJ21: FINALIZADO | BK21: 45303 | BL21: FINALIZADO | BM21: FINALIZADO
A22: 9 | B22: PARAISÓPOLIS/ANTONICO | C22: 2 | D22: 024 | E22: URG | F22: 024/0004/B | G22: OCUPADO | H22: RESIDENCIAL | I22: PROPRIETÁRIO RESIDENTE | J22: EURICO DUTRA DA SILVA | K22: 9.091.805-8 | L22: 679.590.088-68 | M22: CADASTRADO | N22: INDENIZAÇÃO | O22: 44866 | P22: N/A | Q22: N/A | R22: N/A | S22: N/A | T22: N/A | U22: N/A | V22: N/A | W22: N/A | X22: N/A | Y22: N/A | Z22: N/A | AB22: EURICO DUTRA DA SILVA | AC22: 9.091.805-8 | AD22: 679.590.088-68 | AE22: PROPRIETÁRIO RESIDENTE | AF22: CADASTRADO | AG22: 50767.94 | AH22: 60000 | AI22: SIM | AJ22: 6014.2022/0000163-0 | AK22: FINALIZADO | AL22: FINALIZADO | AM22: FINALIZADO | AN22: SEM PENDÊNCIA | AP22: 6014.2023/0000410-0 | AQ22: FINALIZADO | AR22: FINALIZADO | AS22: FINALIZADO | AT22: FINALIZADO | AU22: 45013 | AV22: FINALIZADO | AW22: FINALIZADO | AX22: 45063 | AY22: 45063 | AZ22: 45082 | BA22: DESCARACTERIZADO | BB22: FINALIZADO | BC22: =IF(AY22-KD22=0,"",AY22-O22) -> 197 | BD22: =IF(AND(AI22<>"SIM",AI22="UH"),"AA","INDENIZAÇÃO") -> INDENIZAÇÃO | BE22: =IF(AND(AY22<>"AGUARDANDO",AY22<>"",N22="AUXÍLIO ALUGUEL ATÉ INDENIZAÇÃO"),"SIM","NÃO") -> NÃO | BF22: N/A | BG22: N/A | BH22: N/A | BI22: FINALIZADO | BJ22: FINALIZADO | BK22: 45175 | BL22: FINALIZADO | BM22: FINALIZADO
A23: 10 | B23: PARAISÓPOLIS/ANTONICO | C23: 2 | D23: 024 | E23: 0 | F23: 024/0005/A | G23: OCUPADO | H23: RESIDENCIAL | I23: PROPRIETÁRIO RESIDENTE | J23: JOÃO FELIX DA SILVA FILHO | K23: 34.755.587-1 | L23: 195.477.574-15 | M23: CADASTRADO | N23: AUXÍLIO ALUGUEL UH | O23: 44671 | P23: 44671 | Q23: 6014.2021/0000734-3 | R23: FINALIZADO | S23: FINALIZADO | T23: FINALIZADO | U23: 44693 | V23: 44693 | W23: 44693 | X23: 44713 | Y23: 44718 | Z23: 44725 | AB23: JOÃO FELIX DA SILVA FILHO | AC23: 34.755.587-1 | AD23: 195.477.574-15 | AE23: PROPRIETÁRIO RESIDENTE | AF23: N/A | AG23: 8228.41 | AH23: 38228.41 | AI23: UH | AJ23: 6014.2022/0000163-0 | AK23: N/A | AL23: N/A | AM23: N/A | AN23: N/A | AP23: N/A | AQ23: N/A | AR23: N/A | AS23: N/A | AT23: N/A | AU23: N/A | AV23: N/A | AW23: N/A | AX23: =X23 -> 44713 | AY23: 44713 | AZ23: 44725 | BA23: DEMOLIDO | BB23: FINALIZADO | BC23: =IF(AY23-KD23=0,"",AY23-O23) -> 42 | BD23: =IF(AND(AI23<>"SIM",AI23="UH"),"AA","INDENIZAÇÃO") -> AA | BE23: =IF(AND(AY23<>"AGUARDANDO",AY23<>"",N23="AUXÍLIO ALUGUEL ATÉ INDENIZAÇÃO"),"SIM","NÃO") -> NÃO | BF23: N/A | BG23: N/A | BH23: N/A | BI23: N/A | BJ23: N/A | BK23: N/A | BL23: N/A | BM23: FINALIZADO
A24: 11 | B24: PARAISÓPOLIS/ANTONICO | C24: 2 | D24: 024 | E24: URG | F24: 024/0005/B | G24: OCUPADO | H24: RESIDENCIAL | I24: PROPRIETÁRIO RESIDENTE | J24: MARIA JOSE HONORIO SILVA | K24: 34.808.793-7 | L24: 397.255.294-72 | M24: CADASTRADO | N24: INDENIZAÇÃO | O24: 45610 | P24: N/A | Q24: N/A | R24: N/A | S24: N/A | T24: N/A | U24: N/A | V24: N/A | W24: N/A | X24: N/A | Y24: N/A | Z24: N/A | AA24: RESISTENTE | AB24: MARIA JOSE HONORIO SILVA | AC24: 34.808.793-7 | AD24: 397.255.294-72 | AE24: PROPRIETÁRIO RESIDENTE | AF24: CADASTRADO | AG24: 66528.26 | AH24: 66528.26 | AI24: SIM | AJ24: 6014.2022/0000163-0 | AK24: FINALIZADO | AL24: FINALIZADO | AM24: FINALIZADO | AN24: SEM PENDÊNCIA | AO24: RESISTENTE | AP24: 6014.2024/0005858-0 | AQ24: FINALIZADO | AR24: FINALIZADO | AS24: FINALIZADO | AT24: FINALIZADO | AU24: 45755 | AV24: FINALIZADO | AW24: FINALIZADO | AX24: 45763 | AY24: 45763 | AZ24: 45538 | BA24: DEMOLIDO | BB24: FINALIZADO | BC24: =IF(AY24-KD24=0,"",AY24-O24) -> 153 | BD24: =IF(AND(AI24<>"SIM",AI24="UH"),"AA","INDENIZAÇÃO") -> INDENIZAÇÃO | BE24: =IF(AND(AY24<>"AGUARDANDO",AY24<>"",N24="AUXÍLIO ALUGUEL ATÉ INDENIZAÇÃO"),"SIM","NÃO") -> NÃO | BF24: N/A | BG24: N/A | BH24: N/A | BI24: FINALIZADO | BJ24: FINALIZADO | BK24: 45790 | BL24: FINALIZADO | BM24: AGUARDANDO
A25: 12 | B25: PARAISÓPOLIS/ANTONICO | C25: 2 | D25: 024 | E25: URG | F25: 024/0005/C | G25: OCUPADO | H25: RESIDENCIAL | I25: PROPRIETÁRIO RESIDENTE | J25: DOUGLAS FELIX DA SILVA | K25: 32.702.611-X | L25: 350.792.428-50 | M25: CADASTRADO | N25: AUXÍLIO ALUGUEL UH | O25: 45770 | P25: PENDENTE | Q25: 6014.2021/0000734-3 | R25: FINALIZADO | S25: FINALIZADO | T25: FINALIZADO | U25: FINALIZADO | V25: FINALIZADO | W25: FINALIZADO | X25: 45848 | Y25: 45854 | Z25: 45538 | AB25: DOUGLAS FELIX DA SILVA | AC25: 32.702.611-X | AD25: 350.792.428-50 | AE25: PROPRIETÁRIO RESIDENTE | AF25: CADASTRADO | AG25: 45817.58 | AH25: 60000 | AI25: UH | AJ25: N/A | AK25: N/A | AL25: N/A | AM25: N/A | AN25: N/A | AO25: RESISTENTE | AP25: 6014.2024/0003624-1 | AQ25: N/A | AR25: N/A | AS25: N/A | AT25: N/A | AU25: N/A | AV25: N/A | AW25: N/A | AZ25: 45538 | BA25: DEMOLIDO | BB25: RESISTENTE | BC25: =IF(AY25-KD25=0,"",AY25-O25) | BD25: =IF(AND(AI25<>"SIM",AI25="UH"),"AA","INDENIZAÇÃO") -> AA | BE25: =IF(AND(AY25<>"AGUARDANDO",AY25<>"",N25="AUXÍLIO ALUGUEL ATÉ INDENIZAÇÃO"),"SIM","NÃO") -> NÃO
A26: 13 | B26: PARAISÓPOLIS/ANTONICO | C26: 2 | D26: 024 | E26: URG | F26: 024/0005/D | G26: OCUPADO | H26: COMERCIAL | I26: PROPRIETÁRIO RESIDENTE | J26: MELISSA SANTOS CORREIA | K26: 59.383.150-0 | L26: 550.872.238.69 | M26: CADASTRADO | N26: INDENIZAÇÃO | O26: 45700 | P26: N/A | Q26: N/A | R26: N/A | S26: N/A | T26: N/A | U26: N/A | V26: N/A | W26: N/A | X26: N/A | Y26: N/A | Z26: N/A | AB26: MELISSA SANTOS CORREIA | AC26: 59.383.150-0 | AD26: 550.872.238.69 | AE26: PROPRIETÁRIO RESIDENTE | AF26: CADASTRADO | AG26: 39672.55 | AH26: 60000 | AI26: SIM | AJ26: 6014.2022/0000163-0 | AK26: 149276600 | AL26: FINALIZADO | AM26: FINALIZADO | AN26: SEM PENDÊNCIA | AP26: 6014.2025/0001188-7 | AQ26: FINALIZADO | AR26: FINALIZADO | AS26: FINALIZADO | AT26: FINALIZADO | AU26: 46142 | AV26: FINALIZADO | AW26: FINALIZADO | AX26: 46149 | AY26: 46149 | AZ26: 45538 | BA26: DEMOLIDO | BB26: FINALIZADO | BC26: =IF(AY26-KD26=0,"",AY26-O26) -> 449 | BD26: =IF(AND(AI26<>"SIM",AI26="UH"),"AA","INDENIZAÇÃO") -> INDENIZAÇÃO | BE26: =IF(AND(AY26<>"AGUARDANDO",AY26<>"",N26="AUXÍLIO ALUGUEL ATÉ INDENIZAÇÃO"),"SIM","NÃO") -> NÃO | BF26: N/A | BG26: N/A | BH26: N/A | BI26: FINALIZADO | BJ26: FINALIZADO | BK26: 46224 | BL26: FINALIZADO | BM26: AGUARDANDO
A27: 14 | B27: PARAISÓPOLIS/ANTONICO | C27: 2 | D27: 024 | E27: URG | F27: 024/0005/E | G27: VAZIO | H27: VAZIO | I27: SELO CANCELADO | J27: N/A | K27: N/A | L27: N/A | M27: N/A | N27: SELO CANCELADO | O27: 44866 | P27: N/A | Q27: N/A | R27: N/A | S27: N/A | T27: N/A | U27: N/A | V27: N/A | W27: N/A | X27: N/A | Y27: N/A | Z27: N/A | AB27: N/A | AC27: N/A | AD27: N/A | AE27: SELO CANCELADO | AF27: N/A | AG27: 22351.07 | AH27: 52351.07 | AI27: SELO CANCELADO | AJ27: 6014.2022/0000163-0 | AK27: N/A | AL27: N/A | AM27: N/A | AN27: N/A | AP27: N/A | AQ27: N/A | AR27: N/A | AS27: N/A | AT27: N/A | AU27: N/A | AV27: N/A | AW27: N/A | AX27: N/A | AY27: N/A | AZ27: 44725 | BA27: DEMOLIDO | BB27: FINALIZADO | BC27: N/A | BD27: =IF(AND(AI27<>"SIM",AI27="UH"),"AA","INDENIZAÇÃO") -> INDENIZAÇÃO | BE27: =IF(AND(AY27<>"AGUARDANDO",AY27<>"",N27="AUXÍLIO ALUGUEL ATÉ INDENIZAÇÃO"),"SIM","NÃO") -> NÃO | BF27: N/A | BG27: N/A | BH27: N/A | BI27: N/A | BJ27: N/A | BK27: N/A | BL27: N/A | BM27: FINALIZADO
A28: 15 | B28: PARAISÓPOLIS/ANTONICO | C28: 2 | D28: 024 | E28: URG | F28: 024/0029/A | G28: OCUPADO | H28: RESIDENCIAL | I28: PROPRIETÁRIO RESIDENTE | J28: JANAINA MOTA DA SILVA | K28: 39.155.046-9 | L28: 400.120.708-74 | M28: CADASTRADO | N28: INDENIZAÇÃO | O28: 45083 | P28: N/A | Q28: N/A | R28: N/A | S28: N/A | T28: N/A | U28: N/A | V28: N/A | W28: N/A | X28: N/A | Y28: N/A | Z28: N/A | AB28: JANAINA MOTA DA SILVA | AC28: 39.155.046-9 | AD28: 400.120.708-74 | AE28: PROPRIETÁRIO RESIDENTE | AF28: CADASTRADO | AG28: =AH28-30000 -> 23382.82 | AH28: 53382.82 | AI28: SIM | AJ28: 6014.2022/0000163-0 | AK28: FINALIZADO | AL28: FINALIZADO | AM28: FINALIZADO | AN28: SEM PENDÊNCIA | AP28: 6014.2023/0001968-0 | AQ28: FINALIZADO | AR28: FINALIZADO | AS28: FINALIZADO | AT28: FINALIZADO | AU28: 45278 | AV28: FINALIZADO | AW28: FINALIZADO | AX28: 45295 | AY28: 45300 | AZ28: 45301 | BA28: DESCARACTERIZADO | BB28: FINALIZADO | BC28: =IF(AY28-KD28=0,"",AY28-O28) -> 217 | BD28: =IF(AND(AI28<>"SIM",AI28="UH"),"AA","INDENIZAÇÃO") -> INDENIZAÇÃO | BE28: =IF(AND(AY28<>"AGUARDANDO",AY28<>"",N28="AUXÍLIO ALUGUEL ATÉ INDENIZAÇÃO"),"SIM","NÃO") -> NÃO | BF28: N/A | BG28: N/A | BH28: N/A | BI28: FINALIZADO | BJ28: FINALIZADO | BK28: 45378 | BL28: FINALIZADO | BM28: FINALIZADO
A29: 16 | B29: PARAISÓPOLIS/ANTONICO | C29: 2 | D29: 024 | E29: URG | F29: 024/0029/B | G29: OCUPADO | H29: RESIDENCIAL | I29: PROPRIETÁRIO RESIDENTE | J29: MARIA CHAVES DE CARVALHO | K29: 55.420.866-0 | L29: 018.257.863-13 | M29: CADASTRADO | N29: INDENIZAÇÃO | O29: 45083 | P29: N/A | Q29: N/A | R29: N/A | S29: N/A | T29: N/A | U29: N/A | V29: N/A | W29: N/A | X29: N/A | Y29: N/A | Z29: N/A | AB29: MARIA CHAVES DE CARVALHO | AC29: 55.420.866-0 | AD29: 018.257.863-13 | AE29: PROPRIETÁRIO RESIDENTE | AF29: CADASTRADO | AG29: =AH29-30000 -> 25091.16 | AH29: 55091.16 | AI29: SIM | AJ29: 6014.2022/0000163-0 | AK29: FINALIZADO | AL29: FINALIZADO | AM29: FINALIZADO | AN29: SEM PENDÊNCIA | AP29: 6014.2023/0001973-6 | AQ29: FINALIZADO | AR29: FINALIZADO | AS29: FINALIZADO | AT29: FINALIZADO | AU29: 45224 | AV29: FINALIZADO | AW29: FINALIZADO | AX29: 45243 | AY29: 45243 | AZ29: 45251 | BA29: DESCARACTERIZADO | BB29: FINALIZADO | BC29: =IF(AY29-KD29=0,"",AY29-O29) -> 160 | BD29: =IF(AND(AI29<>"SIM",AI29="UH"),"AA","INDENIZAÇÃO") -> INDENIZAÇÃO | BE29: =IF(AND(AY29<>"AGUARDANDO",AY29<>"",N29="AUXÍLIO ALUGUEL ATÉ INDENIZAÇÃO"),"SIM","NÃO") -> NÃO | BF29: N/A | BG29: N/A | BH29: N/A | BI29: FINALIZADO | BJ29: FINALIZADO | BK29: 45378 | BL29: FINALIZADO | BM29: FINALIZADO
A30: 17 | B30: PARAISÓPOLIS/ANTONICO | C30: 2 | D30: 024 | E30: URG | F30: 024/0030/A | G30: OCUPADO | H30: RESIDENCIAL | I30: PROPRIETÁRIO RESIDENTE | J30: ELAINE DOS SANTOS BOMFIM | K30: 53.408.597-0 | L30: 504.010.478-22 | M30: CADASTRADO | N30: INDENIZAÇÃO | O30: 44844 | P30: N/A | Q30: N/A | R30: N/A | S30: N/A | T30: N/A | U30: N/A | V30: N/A | W30: N/A | X30: N/A | Y30: N/A | Z30: N/A | AB30: ELAINE DOS SANTOS BOMFIM | AC30: 53.408.597-0 | AD30: 504.010.478-22 | AE30: PROPRIETÁRIO RESIDENTE | AF30: CADASTRADO | AG30: 33285.94 | AH30: 60000 | AI30: SIM | AJ30: 6014.2022/0000163-0 | AK30: FINALIZADO | AL30: FINALIZADO | AM30: FINALIZADO | AN30: SEM PENDÊNCIA | AO30: RECUSA ENTREGAR IMÓVEL | AP30: 6014.2022/0003314-1 | AQ30: FINALIZADO | AR30: FINALIZADO | AS30: FINALIZADO | AT30: FINALIZADO | AU30: 44869 | AV30: FINALIZADO | AW30: FINALIZADO | AX30: 44887 | AY30: 44887 | AZ30: 45031 | BA30: DESCARACTERIZADO | BB30: FINALIZADO | BC30: =IF(AY30-KD30=0,"",AY30-O30) -> 43 | BD30: =IF(AND(AI30<>"SIM",AI30="UH"),"AA","INDENIZAÇÃO") -> INDENIZAÇÃO | BE30: =IF(AND(AY30<>"AGUARDANDO",AY30<>"",N30="AUXÍLIO ALUGUEL ATÉ INDENIZAÇÃO"),"SIM","NÃO") -> NÃO | BF30: N/A | BG30: N/A | BH30: N/A | BI30: FINALIZADO | BJ30: FINALIZADO | BK30: 45057 | BL30: FINALIZADO | BM30: FINALIZADO
A31: 18 | B31: PARAISÓPOLIS/ANTONICO | C31: 2 | D31: 024 | E31: 0 | F31: 024/0030/B | G31: OCUPADO | H31: RESIDENCIAL | I31: PROPRIETÁRIO RESIDENTE | J31: OSMAR DOS SANTOS SOUSA | K31: 22.697.907-6 | L31: 134.831.788-48 | M31: CADASTRADO | N31: AUXÍLIO ALUGUEL ATÉ INDENIZAÇÃO | O31: 44844 | P31: 44671 | Q31: 6013.2022/0004909-3 | R31: FINALIZADO | S31: FINALIZADO | T31: FINALIZADO | U31: 44693 | V31: 44698 | W31: 44698 | X31: 44713 | Y31: 44719 | Z31: 44748 | AA31: BLOQUEADO - POR PAGAMENTO DE INDENIZAÇÃO | AB31: OSMAR DOS SANTOS SOUSA | AC31: 22.697.907-6 | AD31: 134.831.788-48 | AE31: PROPRIETÁRIO RESIDENTE | AF31: CADASTRADO | AG31: 20968.45 | AH31: 50968.45 | AI31: SIM | AJ31: 6014.2022/0000163-0 | AK31: FINALIZADO | AL31: FINALIZADO | AM31: FINALIZADO | AN31: SEM PENDÊNCIA | AP31: 6014.2022/0003318-4 | AQ31: FINALIZADO | AR31: FINALIZADO | AS31: FINALIZADO | AT31: FINALIZADO | AU31: 44869 | AV31: FINALIZADO | AW31: FINALIZADO | AX31: 44888 | AY31: 44888 | AZ31: 44748 | BA31: DESCARACTERIZADO | BB31: FINALIZADO | BC31: =IF(AY31-KD31=0,"",AY31-O31) -> 44 | BD31: =IF(AND(AI31<>"SIM",AI31="UH"),"AA","INDENIZAÇÃO") -> INDENIZAÇÃO | BE31: =IF(AND(AY31<>"AGUARDANDO",AY31<>"",N31="AUXÍLIO ALUGUEL ATÉ INDENIZAÇÃO"),"SIM","NÃO") -> SIM | BF31: FINALIZADO | BG31: 44916 | BH31: 44916 | BI31: FINALIZADO | BJ31: FINALIZADO | BK31: 45057 | BL31: FINALIZADO | BM31: FINALIZADO
A32: 19 | B32: PARAISÓPOLIS/ANTONICO | C32: 2 | D32: 024 | E32: URG | F32: 024/0031/A | G32: OCUPADO | H32: RESIDENCIAL | I32: PROPRIETÁRIO RESIDENTE | J32: GEREMIAS DA SILVA CHAVES | K32: 50.671.906-6 | L32: 451.881.958-60 | M32: CADASTRADO | N32: INDENIZAÇÃO | O32: 44844 | P32: N/A | Q32: N/A | R32: N/A | S32: N/A | T32: N/A | U32: N/A | V32: N/A | W32: N/A | X32: N/A | Y32: N/A | Z32: N/A | AB32: GEREMIAS DA SILVA CHAVES | AC32: 50.671.906-6 | AD32: 451.881.958-60 | AE32: PROPRIETÁRIO RESIDENTE | AF32: CADASTRADO | AG32: 18391.36 | AH32: 48391.36 | AI32: SIM | AJ32: 6014.2022/0000163-0 | AK32: FINALIZADO | AL32: FINALIZADO | AM32: FINALIZADO | AN32: SEM PENDÊNCIA | AP32: 6014.2022/0003319-2 | AQ32: FINALIZADO | AR32: FINALIZADO | AS32: FINALIZADO | AT32: FINALIZADO | AU32: 44869 | AV32: FINALIZADO | AW32: FINALIZADO | AX32: 45020 | AY32: 45020 | AZ32: 45026 | BA32: DESCARACTERIZADO | BB32: FINALIZADO | BC32: =IF(AY32-KD32=0,"",AY32-O32) -> 176 | BD32: =IF(AND(AI32<>"SIM",AI32="UH"),"AA","INDENIZAÇÃO") -> INDENIZAÇÃO | BE32: =IF(AND(AY32<>"AGUARDANDO",AY32<>"",N32="AUXÍLIO ALUGUEL ATÉ INDENIZAÇÃO"),"SIM","NÃO") -> NÃO | BF32: N/A | BG32: N/A | BH32: N/A | BI32: FINALIZADO | BJ32: FINALIZADO | BK32: 45175 | BL32: FINALIZADO | BM32: FINALIZADO
A33: 20 | B33: PARAISÓPOLIS/ANTONICO | C33: 2 | D33: 024 | E33: URG | F33: 024/0031/B | G33: OCUPADO | H33: RESIDENCIAL | I33: INQUILINO | J33: ANDRELY CARVALHO DE CASTRO | K33: 52.022.971-X | L33: 069.650.965-27 | M33: CADASTRADO | N33: AUXÍLIO ALUGUEL UH | O33: 44844 | P33: 44844 | Q33: 6014.2021/0000734-3 | R33: FINALIZADO | S33: FINALIZADO | T33: FINALIZADO | U33: 44859 | V33: 44859 | W33: 44859 | X33: 44875 | Y33: 44875 | Z33: 44875 | AB33: FRANCISCA MARIA ALCANTARA CHAVES | AC33: 50.671.326-X | AD33: 841.759.073-00 | AE33: PROPRIETÁRIO NÃO RESIDENTE | AF33: CADASTRADO | AG33: 21948.03 | AH33: 51948.03 | AI33: SIM | AJ33: 6014.2022/0000163-0 | AK33: FINALIZADO | AL33: FINALIZADO | AM33: FINALIZADO | AN33: SEM PENDÊNCIA | AP33: 6014.2022/0003489-0 | AQ33: FINALIZADO | AR33: FINALIZADO | AS33: FINALIZADO | AT33: FINALIZADO | AU33: 44889 | AV33: FINALIZADO | AW33: FINALIZADO | AX33: 44604 | AY33: 44604 | AZ33: 44922 | BA33: DESCARACTERIZADO | BB33: FINALIZADO | BC33: =IF(AY33-KD33=0,"",AY33-O33) -> -240 | BD33: =IF(AND(AI33<>"SIM",AI33="UH"),"AA","INDENIZAÇÃO") -> INDENIZAÇÃO | BE33: =IF(AND(AY33<>"AGUARDANDO",AY33<>"",N33="AUXÍLIO ALUGUEL ATÉ INDENIZAÇÃO"),"SIM","NÃO") -> NÃO | BF33: N/A | BG33: N/A | BH33: N/A | BI33: FINALIZADO | BJ33: FINALIZADO | BK33: 45057 | BL33: FINALIZADO | BM33: FINALIZADO
A34: 21 | B34: PARAISÓPOLIS/ANTONICO | C34: 2 | D34: 024 | E34: URG | F34: 024/0031/C | G34: OCUPADO | H34: RESIDENCIAL | I34: PROPRIETÁRIO RESIDENTE | J34: ANTONIO FRANCISCO CHAVES | K34: 54.896.484-1 | L34: 482.205.903-00 | M34: CADASTRADO | N34: INDENIZAÇÃO | O34: 44788 | P34: N/A | Q34: N/A | R34: N/A | S34: N/A | T34: N/A | U34: N/A | V34: N/A | W34: N/A | X34: N/A | Y34: N/A | Z34: N/A | AB34: ANTONIO FRANCISCO CHAVES | AC34: 54.896.484-1 | AD34: 482.205.903-00 | AE34: PROPRIETÁRIO RESIDENTE | AF34: CADASTRADO | AG34: 36299.56 | AH34: 60000 | AI34: SIM | AJ34: 6014.2022/0000163-0 | AK34: FINALIZADO | AL34: FINALIZADO | AM34: FINALIZADO | AN34: SEM PENDÊNCIA | AP34: 6014.2022/0003413-0 | AQ34: FINALIZADO | AR34: FINALIZADO | AS34: FINALIZADO | AT34: FINALIZADO | AU34: 44877 | AV34: FINALIZADO | AW34: FINALIZADO | AX34: 44894 | AY34: 44894 | AZ34: 44933 | BA34: DESCARACTERIZADO | BB34: FINALIZADO | BC34: =IF(AY34-KD34=0,"",AY34-O34) -> 106 | BD34: =IF(AND(AI34<>"SIM",AI34="UH"),"AA","INDENIZAÇÃO") -> INDENIZAÇÃO | BE34: =IF(AND(AY34<>"AGUARDANDO",AY34<>"",N34="AUXÍLIO ALUGUEL ATÉ INDENIZAÇÃO"),"SIM","NÃO") -> NÃO | BF34: N/A | BG34: N/A | BH34: N/A | BI34: FINALIZADO | BJ34: FINALIZADO | BK34: 45057 | BL34: FINALIZADO | BM34: FINALIZADO
A35: 22 | B35: PARAISÓPOLIS/ANTONICO | C35: 2 | D35: 024 | E35: URG | F35: 024/0031/D | G35: OCUPADO | H35: RESIDENCIAL | I35: PROPRIETÁRIO RESIDENTE | J35: JOSINEIA RIBEIRO SANTANA | K35: 33.299.250-0 | L35: 284.739.748-59 | M35: CADASTRADO | N35: INDENIZAÇÃO | O35: 44844 | P35: N/A | Q35: N/A | R35: N/A | S35: N/A | T35: N/A | U35: N/A | V35: N/A | W35: N/A | X35: N/A | Y35: N/A | Z35: N/A | AB35: JOSINEIA RIBEIRO SANTANA | AC35: 33.299.250-0 | AD35: 284.739.748-59 | AE35: PROPRIETÁRIO RESIDENTE | AF35: CADASTRADO | AG35: 17885.25 | AH35: 47885.25 | AI35: SIM | AJ35: 6014.2022/0000163-0 | AK35: FINALIZADO | AL35: FINALIZADO | AM35: FINALIZADO | AN35: SEM PENDÊNCIA | AP35: 6014.2022/0003286-2 | AQ35: FINALIZADO | AR35: FINALIZADO | AS35: FINALIZADO | AT35: FINALIZADO | AU35: 44869 | AV35: FINALIZADO | AW35: FINALIZADO | AX35: 44886 | AY35: 44887 | AZ35: 44890 | BA35: DESCARACTERIZADO | BB35: FINALIZADO | BC35: =IF(AY35-KD35=0,"",AY35-O35) -> 43 | BD35: =IF(AND(AI35<>"SIM",AI35="UH"),"AA","INDENIZAÇÃO") -> INDENIZAÇÃO | BE35: =IF(AND(AY35<>"AGUARDANDO",AY35<>"",N35="AUXÍLIO ALUGUEL ATÉ INDENIZAÇÃO"),"SIM","NÃO") -> NÃO | BF35: N/A | BG35: N/A | BH35: N/A | BI35: FINALIZADO | BJ35: FINALIZADO | BK35: 45057 | BL35: FINALIZADO | BM35: FINALIZADO
A36: 23 | B36: PARAISÓPOLIS/ANTONICO | C36: 2 | D36: 024 | E36: URG | F36: 024/0031/E | G36: OCUPADO | H36: RESIDENCIAL | I36: PROPRIETÁRIO RESIDENTE | J36: MARIA DO SOCORRO SILVA MENDES | K36: 36.581.031-9 | L36: 503.853.993-91 | M36: CADASTRADO | N36: AUXÍLIO ALUGUEL UH | O36: 44866 | P36: 44844 | Q36: 6014.2021/0000734-3 | R36: FINALIZADO | S36: FINALIZADO | T36: FINALIZADO | U36: 44859 | V36: FINALIZADO | W36: 44859 | X36: 44875 | Y36: 44881 | Z36: 44881 | AB36: MARIA DO SOCORRO SILVA MENDES | AC36: 36.581.031-9 | AD36: 503.853.993-91 | AE36: PROPRIETÁRIO RESIDENTE | AF36: N/A | AG36: 17331.66 | AH36: 47331.66 | AI36: UH | AJ36: 6014.2022/0000163-0 | AK36: N/A | AL36: N/A | AM36: N/A | AN36: N/A | AP36: N/A | AQ36: N/A | AR36: N/A | AS36: N/A | AT36: N/A | AU36: N/A | AV36: N/A | AW36: N/A | AX36: 44875 | AY36: 44881 | AZ36: 44881 | BA36: DESCARACTERIZADO | BB36: FINALIZADO | BC36: =IF(AY36-KD36=0,"",AY36-O36) -> 15 | BD36: =IF(AND(AI36<>"SIM",AI36="UH"),"AA","INDENIZAÇÃO") -> AA | BE36: =IF(AND(AY36<>"AGUARDANDO",AY36<>"",N36="AUXÍLIO ALUGUEL ATÉ INDENIZAÇÃO"),"SIM","NÃO") -> NÃO | BF36: N/A | BG36: N/A | BH36: N/A | BI36: N/A | BJ36: N/A | BK36: N/A | BL36: N/A | BM36: FINALIZADO
A37: 24 | B37: PARAISÓPOLIS/ANTONICO | C37: 2 | D37: 024 | E37: URG | F37: 024/0032/A | G37: OCUPADO | H37: RESIDENCIAL | I37: PROPRIETÁRIO RESIDENTE | J37: VANDERLEI SILVA PEREIRA | K37: 49.464.277-4 | L37: 388.374.528-61 | M37: CADASTRADO | N37: INDENIZAÇÃO | O37: 44844 | P37: N/A | Q37: N/A | R37: N/A | S37: N/A | T37: N/A | U37: N/A | V37: N/A | W37: N/A | X37: N/A | Y37: N/A | Z37: N/A | AB37: VANDERLEI SILVA PEREIRA | AC37: 49.464.277-4 | AD37: 388.374.528-61 | AE37: PROPRIETÁRIO RESIDENTE | AF37: CADASTRADO | AG37: 9670.04 | AH37: 39670.04 | AI37: SIM | AJ37: 6014.2022/0000163-0 | AK37: FINALIZADO | AL37: FINALIZADO | AM37: FINALIZADO | AN37: SEM PENDÊNCIA | AP37: 6014.2022/0003320-6 | AQ37: FINALIZADO | AR37: FINALIZADO | AS37: FINALIZADO | AT37: FINALIZADO | AU37: 44869 | AV37: FINALIZADO | AW37: FINALIZADO | AX37: 44886 | AY37: 44887 | AZ37: 44894 | BA37: DESCARACTERIZADO | BB37: FINALIZADO | BC37: =IF(AY37-KD37=0,"",AY37-O37) -> 43 | BD37: =IF(AND(AI37<>"SIM",AI37="UH"),"AA","INDENIZAÇÃO") -> INDENIZAÇÃO | BE37: =IF(AND(AY37<>"AGUARDANDO",AY37<>"",N37="AUXÍLIO ALUGUEL ATÉ INDENIZAÇÃO"),"SIM","NÃO") -> NÃO | BF37: N/A | BG37: N/A | BH37: N/A | BI37: FINALIZADO | BJ37: FINALIZADO | BK37: 45057 | BL37: FINALIZADO | BM37: FINALIZADO
A38: 25 | B38: PARAISÓPOLIS/ANTONICO | C38: 2 | D38: 024 | E38: URG | F38: 024/0035/A | G38: OCUPADO | H38: RESIDENCIAL | I38: PROPRIETÁRIO RESIDENTE | J38: MARIA DAS GRAÇAS DIAS DE MORAES | K38: 27.670.236-0 | L38: 186.997.498-05 | M38: CADASTRADO | N38: AUXÍLIO ALUGUEL ATÉ INDENIZAÇÃO | O38: 44788 | P38: 45042 | Q38: 6014.2021/0000734-3 | R38: 45068 | S38: 45068 | T38: 45070 | U38: 45076 | V38: 45125 | W38: 45125 | X38: 45159 | Y38: 45160 | Z38: 45040 | AA38: MUNÍCIPE RECEBERÁ 4 MESES DE AA PELA CONSTRUTORA PARA DESOCUPAR IMÓVEL | AB38: MARIA DAS GRAÇAS DIAS DE MORAES | AC38: 27.670.236-0 | AD38: 186.997.498-05 | AE38: PROPRIETÁRIO RESIDENTE | AF38: CADASTRADO | AG38: =AH38-30000 -> 22249.02 | AH38: 52249.02 | AI38: SIM | AJ38: 6014.2022/0000163-0 | AK38: FINALIZADO | AL38: FINALIZADO | AM38: FINALIZADO | AN38: SEM PENDÊNCIA | AP38: 6014.2023/0004425-0 | AQ38: FINALIZADO | AR38: FINALIZADO | AS38: FINALIZADO | AT38: FINALIZADO | AU38: 45387 | AV38: FINALIZADO | AW38: FINALIZADO | AX38: 45394 | AY38: 45394 | AZ38: 45040 | BA38: DEMOLIDO | BB38: FINALIZADO | BC38: =IF(AY38-KD38=0,"",AY38-O38) -> 606 | BD38: =IF(AND(AI38<>"SIM",AI38="UH"),"AA","INDENIZAÇÃO") -> INDENIZAÇÃO | BE38: =IF(AND(AY38<>"AGUARDANDO",AY38<>"",N38="AUXÍLIO ALUGUEL ATÉ INDENIZAÇÃO"),"SIM","NÃO") -> SIM | BF38: FINALIZADO | BG38: 45421 | BH38: 45421 | BI38: FINALIZADO | BJ38: FINALIZADO | BK38: 45483 | BL38: FINALIZADO | BM38: AGUARDANDO
A39: 26 | B39: PARAISÓPOLIS/ANTONICO | C39: 2 | D39: 024 | E39: 0 | F39: 024/0035/B | G39: OCUPADO | H39: RESIDENCIAL | I39: INQUILINO | J39: BRUNO BEZERRA CUPERTINO | K39: 38.115.309-5 | L39: 487.843.668-93 | M39: CADASTRADO | N39: AUXÍLIO ALUGUEL UH | O39: 44788 | P39: 44746 | Q39: 6014.2021/0000734-3 | R39: FINALIZADO | S39: FINALIZADO | T39: FINALIZADO | U39: 44776 | V39: 44782 | W39: 44782 | X39: 44795 | Y39: 44799 | Z39: 44837 | AB39: CEZAR LOREDO NETTO | AC39: 43.889.739-0 | AD39: 402.384.138-29 | AE39: PROPRIETÁRIO NÃO RESIDENTE | AF39: CADASTRADO | AG39: 30308.12 | AH39: 60000 | AI39: SIM | AJ39: 6014.2022/0000163-0 | AK39: FINALIZADO | AL39: FINALIZADO | AM39: FINALIZADO | AN39: SEM PENDÊNCIA | AP39: 6014.2022/0002870-9 | AQ39: FINALIZADO | AR39: FINALIZADO | AS39: FINALIZADO | AT39: FINALIZADO | AU39: 44840 | AV39: FINALIZADO | AW39: FINALIZADO | AX39: 44852 | AY39: 44852 | AZ39: 44837 | BA39: DESCARACTERIZADO | BB39: FINALIZADO | BC39: =IF(AY39-KD39=0,"",AY39-O39) -> 64 | BD39: =IF(AND(AI39<>"SIM",AI39="UH"),"AA","INDENIZAÇÃO") -> INDENIZAÇÃO | BE39: =IF(AND(AY39<>"AGUARDANDO",AY39<>"",N39="AUXÍLIO ALUGUEL ATÉ INDENIZAÇÃO"),"SIM","NÃO") -> NÃO | BF39: N/A | BG39: N/A | BH39: N/A | BI39: FINALIZADO | BJ39: FINALIZADO | BK39: 45057 | BL39: FINALIZADO | BM39: FINALIZADO
A40: 27 | B40: PARAISÓPOLIS/ANTONICO | C40: 2 | D40: 024 | E40: 0 | F40: 024/0036/A | G40: OCUPADO | H40: RESIDENCIAL | I40: INQUILINO | J40: NAYANE ALVES DE SOUSA | K40: 2846210 | L40: 044.606.643-56 | M40: CADASTRADO | N40: AUXÍLIO ALUGUEL UH | O40: 44844 | P40: 44671 | Q40: 6014.2021/0000734-3 | R40: FINALIZADO | S40: FINALIZADO | T40: FINALIZADO | U40: 44693 | V40: 44693 | W40: 44693 | X40: 44713 | Y40: 44720 | Z40: 44725 | AB40: MARIA DO CARMO APRIGIO | AC40: 37.187.670-9 | AD40: 322.862.768-38 | AE40: PROPRIETÁRIO NÃO RESIDENTE | AF40: CADASTRADO | AG40: 15340.39 | AH40: 45340.39 | AI40: SIM | AJ40: 6014.2022/0000163-0 | AK40: FINALIZADO | AL40: FINALIZADO | AM40: FINALIZADO | AN40: SEM PENDÊNCIA | AP40: 6014.2022/0003634-5 | AQ40: FINALIZADO | AR40: FINALIZADO | AS40: FINALIZADO | AT40: FINALIZADO | AU40: 44816 | AV40: FINALIZADO | AW40: FINALIZADO | AX40: 44914 | AY40: 44914 | AZ40: 44725 | BA40: DEMOLIDO | BB40: FINALIZADO | BC40: =IF(AY40-KD40=0,"",AY40-O40) -> 70 | BD40: =IF(AND(AI40<>"SIM",AI40="UH"),"AA","INDENIZAÇÃO") -> INDENIZAÇÃO | BE40: =IF(AND(AY40<>"AGUARDANDO",AY40<>"",N40="AUXÍLIO ALUGUEL ATÉ INDENIZAÇÃO"),"SIM","NÃO") -> NÃO | BF40: N/A | BG40: N/A | BH40: N/A | BI40: FINALIZADO | BJ40: FINALIZADO | BK40: 45057 | BL40: FINALIZADO | BM40: FINALIZADO
A41: 28 | B41: PARAISÓPOLIS/ANTONICO | C41: 2 | D41: 024 | E41: 0 | F41: 024/0036/B | G41: OCUPADO | H41: RESIDENCIAL | I41: PROPRIETÁRIO RESIDENTE | J41: AILDA NUNES DE OLIVEIRA ARAÚJO | K41: 56.715.594-8 | L41: 458.793.008-38 | M41: CADASTRADO | N41: INDENIZAÇÃO | O41: 44844 | P41: N/A | Q41: N/A | R41: N/A | S41: N/A | T41: N/A | U41: N/A | V41: N/A | W41: N/A | X41: N/A | Y41: N/A | Z41: N/A | AB41: AILDA NUNES DE OLIVEIRA ARAÚJO | AC41: 56.715.594-8 | AD41: 458.793.008-38 | AE41: PROPRIETÁRIO RESIDENTE | AF41: CADASTRADO | AG41: 13501.61 | AH41: 43501.61 | AI41: SIM | AJ41: 6014.2022/0000163-0 | AK41: FINALIZADO | AL41: FINALIZADO | AM41: FINALIZADO | AN41: SEM PENDÊNCIA | AP41: 6014.2022/0003262-5 | AQ41: FINALIZADO | AR41: FINALIZADO | AS41: FINALIZADO | AT41: FINALIZADO | AU41: 44877 | AV41: FINALIZADO | AW41: FINALIZADO | AX41: 44894 | AY41: 44894 | AZ41: 44894 | BA41: DEMOLIDO | BB41: FINALIZADO | BC41: =IF(AY41-KD41=0,"",AY41-O41) -> 50 | BD41: =IF(AND(AI41<>"SIM",AI41="UH"),"AA","INDENIZAÇÃO") -> INDENIZAÇÃO | BE41: =IF(AND(AY41<>"AGUARDANDO",AY41<>"",N41="AUXÍLIO ALUGUEL ATÉ INDENIZAÇÃO"),"SIM","NÃO") -> NÃO | BF41: N/A | BG41: N/A | BH41: N/A | BI41: FINALIZADO | BJ41: FINALIZADO | BK41: 45057 | BL41: FINALIZADO | BM41: FINALIZADO
A42: 29 | B42: PARAISÓPOLIS/ANTONICO | C42: 2 | D42: 024 | E42: URG | F42: 024/0036/C | G42: OCUPADO | H42: RESIDENCIAL | I42: INQUILINO | J42: MARLENE MARIA DE JESUS | K42: 24.816.448-X | L42: 146.680.448-30 | M42: CADASTRADO | N42: AUXÍLIO ALUGUEL UH | O42: 44844 | P42: 44774 | Q42: 6014.2021/0000734-3 | R42: FINALIZADO | S42: FINALIZADO | T42: FINALIZADO | U42: 44813 | V42: 44818 | W42: 44818 | X42: 44837 | Y42: 44841 | Z42: 44873 | AB42: INÊS DE OLIVEIRA | AC42: 55.224.980-4 | AD42: 001.126.885-94 | AE42: PROPRIETÁRIO NÃO RESIDENTE | AF42: CADASTRADO | AG42: 10219.17 | AH42: 40219.17 | AI42: SIM | AJ42: 6014.2022/0000163-0 | AK42: FINALIZADO | AL42: FINALIZADO | AM42: FINALIZADO | AN42: SEM PENDÊNCIA | AP42: 6014.2022/0003332-0 | AQ42: FINALIZADO | AR42: FINALIZADO | AS42: FINALIZADO | AT42: FINALIZADO | AU42: 44877 | AV42: FINALIZADO | AW42: FINALIZADO | AX42: 44894 | AY42: 44894 | AZ42: 44873 | BA42: DEMOLIDO | BB42: FINALIZADO | BC42: =IF(AY42-KD42=0,"",AY42-O42) -> 50 | BD42: =IF(AND(AI42<>"SIM",AI42="UH"),"AA","INDENIZAÇÃO") -> INDENIZAÇÃO | BE42: =IF(AND(AY42<>"AGUARDANDO",AY42<>"",N42="AUXÍLIO ALUGUEL ATÉ INDENIZAÇÃO"),"SIM","NÃO") -> NÃO | BF42: N/A | BG42: N/A | BH42: N/A | BI42: FINALIZADO | BJ42: FINALIZADO | BK42: 45057 | BL42: FINALIZADO | BM42: FINALIZADO
A43: 30 | B43: PARAISÓPOLIS/ANTONICO | C43: 2 | D43: 024 | E43: URG | F43: 024/0036/D | G43: OCUPADO | H43: RESIDENCIAL | I43: PROPRIETÁRIO RESIDENTE | J43: ADAILTON PANTALEÃO DA SILVA | K43: 35.904.704-X | L43: 077.047.244-36 | M43: CADASTRADO | N43: INDENIZAÇÃO | O43: 44844 | P43: N/A | Q43: N/A | R43: N/A | S43: N/A | T43: N/A | U43: N/A | V43: N/A | W43: N/A | X43: N/A | Y43: N/A | Z43: N/A | AB43: ADAILTON PANTALEÃO DA SILVA | AC43: 35.904.704-X | AD43: 077.047.244-36 | AE43: PROPRIETÁRIO RESIDENTE | AF43: CADASTRADO | AG43: 16131.9 | AH43: 46131.9 | AI43: SIM | AJ43: 6014.2022/0000163-0 | AK43: FINALIZADO | AL43: FINALIZADO | AM43: FINALIZADO | AN43: SEM PENDÊNCIA | AP43: 6014.2022/0003263-3 | AQ43: FINALIZADO | AR43: FINALIZADO | AS43: FINALIZADO | AT43: FINALIZADO | AU43: 44867 | AV43: FINALIZADO | AW43: FINALIZADO | AX43: 44886 | AY43: 44887 | AZ43: 44877 | BA43: DEMOLIDO | BB43: FINALIZADO | BC43: =IF(AY43-KD43=0,"",AY43-O43) -> 43 | BD43: =IF(AND(AI43<>"SIM",AI43="UH"),"AA","INDENIZAÇÃO") -> INDENIZAÇÃO | BE43: =IF(AND(AY43<>"AGUARDANDO",AY43<>"",N43="AUXÍLIO ALUGUEL ATÉ INDENIZAÇÃO"),"SIM","NÃO") -> NÃO | BF43: N/A | BG43: N/A | BH43: N/A | BI43: FINALIZADO | BJ43: FINALIZADO | BK43: 45057 | BL43: FINALIZADO | BM43: FINALIZADO
...

Sheet EMAIL
F2: PUBLICAÇÃO DOC
F3: PREVISÃO PAGAMENTO | M3: 024/0030/B | O3: 029/0024/C
A4: ÁREA | B4: FASE | C4: SELO | D4: TITULAR | E4: PREVISÃO PAGAMENTO | F4: CONFIRMAÇÃO PAGAMENTO | G4: ÁREA | H4: SELO | I4: PROPRIETÁRIO | J4: CPF | K4: No PROCESSO SEI (INDENIZAÇÃO) | M4: 024/0041/A | O4: 029/0023/E
A5: PARAISÓPOLIS/ANTONICO | B5: 3 | C5: 025/0025/S | D5: BEATRIZ LIMA DOS SANTOS | E5: 46259 | G5: PARAISÓPOLIS/ANTONICO | H5: 027/0009/B | I5: MATHEUS DA SILVA COSTA | J5: 484.521.348-60 | K5: 6014.2024/0005253-0 | M5: 024/0052/A | O5: 031/0033/Q
G6: PARAISÓPOLIS/ANTONICO | H6: 031/0020/G | I6: EDILSON GUIMARÃES DE CARVALHO | J6: 418.009.058-90 | K6: 6014.2024/0003508-3 | M6: 024/0055/B | O6: 029/0066/A
M7: 024/0070/E | O7: 031/0022/E
M8: 024/0077/B | O8: 031/0031/B
M9: 024/0079/C | O9: 031/0020/C
M10: 024/0099/A | O10: 031/0033/K
M11: 024/0102/D | O11: 029/0016/B
M12: 024/0105/A | O12: 029/0066/E
M13: 024/0105/B | O13: 024/0099/A
M14: 029/0007/A | O14: 029/0022/B
M15: 029/0016/B | O15: 029/0081/A
M16: 029/0022/B | O16: 024/0052/A
M17: 029/0023/E | O17: 029/0035/B
M18: 029/0024/C | O18: 029/0027/A
... M22: 029/0045/A | O22: 029/0007/A
A23: PARAISÓPOLIS/ANTONICO | B23: 4 | C23: 031/0078/A | D23: MARIA JOSÉ DOS SANTOS | E23: 45300 | M23: 029/0061/A | O23: 029/0070/C
A24: PARAISÓPOLIS/ANTONICO | B24: 4 | C24: 031/0078/B | D24: BRUNO DA SILVA MARQUES | E24: 45300 | M24: 029/0064/A | O24: 029/0007/B
A25: PARAISÓPOLIS/ANTONICO | B25: 4 | C25: 031/0078/E | D25: JURACEMA RIBEIRO DE JESUS DIAS | E25: 45300 | M25: 029/0064/F | O25: 029/0070/B
A26: PARAISÓPOLIS/ANTONICO | D26: MARIA JOSÉ DOS SANTOS | M26: 029/0066/A | O26: 029/0045/A
A27: PARAISÓPOLIS/ANTONICO | D27: BRUNO DA SILVA MARQUES | M27: 029/0066/B | O27: 024/0102/D
A28: PARAISÓPOLIS/ANTONICO | D28: JURACEMA RIBEIRO DE JESUS DIAS | M28: 029/0066/E | O28: 024/0041/A
A29: PARAISÓPOLIS/ANTONICO | D29: MARIA JOSÉ DOS SANTOS | M29: 029/0067/A | O29: 031/0035/A
D30: BRUNO DA SILVA MARQUES | M30: 029/0067/F | O30: 031/0067/B
D31: JURACEMA RIBEIRO DE JESUS DIAS | M31: 029/0069/B | O31: 024/0077/B
D32: MARIA JOSÉ DOS SANTOS | M32: 029/0069/C | O32: 033/0016/C
D33: BRUNO DA SILVA MARQUES | M33: 029/0069/D | O33: 029/0069/C
D34: JURACEMA RIBEIRO DE JESUS DIAS | M34: 029/0070/B | O34: 029/0061/A
D35: MARIA JOSÉ DOS SANTOS | M35: 029/0070/C | O35: 029/0066/B
A36: PARAISÓPOLIS/ANTONICO | B36: 4 | C36: 031/0033/Q | D36: BRUNO DA SILVA MARQUES | E36: 45247 | M36: 029/0071/B | O36: 029/0071/D
A37: PARAISÓPOLIS/ANTONICO | B37: 4 | C37: 031/0034/I | D37: JURACEMA RIBEIRO DE JESUS DIAS | E37: 45247 | M37: 029/0071/D | O37: 031/0058/A
A38: PARAISÓPOLIS/ANTONICO | B38: 4 | C38: 031/0034/J | D38: MARIA JOSÉ DOS SANTOS | E38: 45244 | M38: 029/0071/E | O38: 029/0036/F
A39: PARAISÓPOLIS/ANTONICO | B39: 4 | C39: 031/0040/C | D39: BRUNO DA SILVA MARQUES | E39: 45243 | M39: 029/0080/E | O39: 031/0067/A
A40: PARAISÓPOLIS/ANTONICO | B40: 4 | C40: 031/0076/B | D40: JURACEMA RIBEIRO DE JESUS DIAS | E40: 45243 | M40: 029/0081/A | O40: 031/0028/L
A41: PARAISÓPOLIS/ANTONICO | B41: 4 | C41: 031/0076/C | D41: MARIA JOSÉ DOS SANTOS | E41: 45243 | M41: 029/0083/A | O41: 024/0105/A
A42: PARAISÓPOLIS/ANTONICO | B42: 4 | C42: 031/0076/D | D42: BRUNO DA SILVA MARQUES | E42: 45243 | M42: 029/0085/G | O42: 029/0064/F
D43: JURACEMA RIBEIRO DE JESUS DIAS | M43: 029/0086/B | O43: 031/0025/A
D44: MARIA JOSÉ DOS SANTOS | M44: 031/0004/C | O44: 024/0051/A
...

Sheet Quantitativo Fora da Demanda
A1: REPROVADOS QUE NÃO DEVERÃO SER REASSENTADOS NO ESPANHA | E1: APROVADOS SEM CONDOMÍNIO QUE DEVERÃO SER REASSENTADOS NO CHÁCARA DO CONDE
A2: ÁREA | B2: QTD | E2: ÁREA | F2: QTD
A3: AUXÍLIO ALUGUEL | B3: 39 | E3: AUXÍLIO ALUGUEL | F3: 54
A4: CANTINHO DO CÉU (OBRAS) | B4: 15 | E4: CANTINHO DO CÉU (OBRAS) SETORES: 138 E 140 | F4: 13
A5: FUMAÇA | B5: 7 | E5: FUMAÇA | F5: 15
A6: NEBLINA | B6: 2 | E6: NEBLINA | F6: 9
A7: LEBLON | B7: 0 | E7: LEBLON | F7: 9
A8: PABREU / PRAINHA | B8: 15 | E8: PABREU / PRAINHA | F8: 21
A9: TOTAL | B9: =SUM(B3:B8) -> 78 | E9: TOTAL | F9: =SUM(F3:F8) -> 121

Sheet Listas (não utilizar)
A1: Área | B1: Condomínio | C1: Bloco | D1: Apartamento | E1: SITAH / CAIXA | F1: Status CAIXA | G1: Adequacao Imovel | H1: Renúncia | I1: Pendência | J1: Pendências / Reprovados caixa
A2: ALTO DA ALEGRIA | B2: AVILA | C2: 1 | D2: 101 | E2: AGENDADO | F2: APROVADO | G2: NÃO | H2: NÃO | I2: CRAS | J2: RENDA SUPERIOR
A3: ALTO DA ALEGRIA (OBRAS) | B3: BARCELONA | C3: 2 | D3: 102 | E3: AGUARDANDO OFICIO | F3: REPROVADO | G3: FÍSICA | H3: RENDA | I3: CRAS + DOCUMENTOS | J3: CADMUT
A4: ALTO DA ALEGRIA (RESERVA) | B4: BILBAO | C4: 3 | D4: 103 | E4: ATENDIMENTO CANCELADO | F4: PENDENCIA | G4: VISUAL | H4: CADIN | I4: DOCUMENTOS | J4: CADIN
A5: ANTERO GOMES | B5: CEUTA | C5: 4 | D5: 104 | E5: CADMUT | F5: SEM DOSSIE | G5: INTELECTUAL | H5: ESTADO CIVIL | I5: CADIN
A6: CANTINHO DO CEU / GAIVOTAS | B6: IBIZA | C6: 5 | D6: 201 | E6: CHACARA DO CONDE | G6: AUDITIVA | H6: SEPARACAO | I6: CRAS + CADIN
A7: CANTINHO DO CEU / OBRAS | B7: LEAO | C7: 6 | D7: 202 | E7: CONFLITO | G7: NANISMO | I7: R.LI.AV.
A8: CASTRO ALVES | B8: MADRID | C8: 7 | D8: 203 | E8: ENVIADO CAIXA | I8: IEME
A9: COCAIA | B9: MELILLA | C9: 8 | D9: 204 | E9: FALECEU
A10: ERUNDINA | B10: PAMPLONA | C10: 9 | D10: 301 | E10: FALTANTE DOSSIÊ
A11: FUMACA | B11: SALAMANCA | C11: 10 | D11: 302 | E11: HABISP ACERTO DE ÁREA
A12: GUAICURI (OBRAS) | B12: TERUEL | C12: 11 | D12: 303 | E12: HABISP AGUARDANDO CRÍTICA
A13: GUAICURI / CIDADE JULIA | B13: VALENCIA | C13: 12 | D13: 304 | E13: HABISP PEND DE ATUALIZ CADASTRAL
A14: JARDIM MIRNA | B14: VALVERDE | C14: 13 | D14: 401 | E14: INDENIZACAO
A15: JARDIM SELMA II | B15: VITORIA | C15: 14 | D15: 402 | E15: PENDENCIA
A16: JARDIM TUBO | C16: 15 | D16: 403 | E16: PERMUTA
A17: LEBLON | D17: 404 | E17: PESQUISA SMADS
A18: MARGINAL DOIS / FUNDAO | D18: 501 | E18: REANALISE
A19: MATA VIRGEM / JD ELDORADO | D19: 502 | E19: RECLUSO
A20: NEBLINA | D20: 503 | E20: RELATÓRIO SOCIAL
A21: NORONHA | D21: 504 | E21: RENDA SUPERIOR
A22: NOVA GRAJAU | E22: RESISTENTE
A23: NOVA MARILDA | E23: TROCA DE TITULARIDADE
A24: NOVA VARGINHA
A25: PABREU / PRAINHA
A26: PENDENCIA GABINETE
A27: PILAO / APURA
A28: PILAO / DOIS
A29: PILAO / PAULISTAS
A30: SANTA AMELIA
A31: VALE VERDE / MONTE VERDE
A32: VILA BREJINHO
A33: VILA NASCENTE
A34: ZR / COSTA BRANCA
A35: VILA RUBI

Sheet QUANT COND
A1: CONDOMINIOS | B1: QUANT
A2: AVILA | B2: =COUNTIF(#REF!,'QUANT COND'!A2) -> #REF!
A3: BARCELONA | B3: =COUNTIF(#REF!,'QUANT COND'!A3) -> #REF!
A4: BILBAO | B4: =COUNTIF(#REF!,'QUANT COND'!A4) -> #REF!
A5: CEUTA | B5: =COUNTIF(#REF!,'QUANT COND'!A5) -> #REF!
A6: IBIZA | B6: =COUNTIF(#REF!,'QUANT COND'!A6) -> #REF!
A7: LEAO | B7: =COUNTIF(#REF!,'QUANT COND'!A7) -> #REF!
A8: MADRID | B8: =COUNTIF(#REF!,'QUANT COND'!A8) -> #REF!
A9: MELILLA | B9: =COUNTIF(#REF!,'QUANT COND'!A9) -> #REF!
A10: PAMPLONA | B10: =COUNTIF(#REF!,'QUANT COND'!A10) -> #REF!
A11: SALAMANCA | B11: =COUNTIF(#REF!,'QUANT COND'!A11) -> #REF!
A12: TERUEL | B12: =COUNTIF(#REF!,'QUANT COND'!A12) -> #REF!
A13: VALENCIA | B13: =COUNTIF(#REF!,'QUANT COND'!A13) -> #REF!
... A15: VITORIA | B15: =COUNTIF(#REF!,'QUANT COND'!A15) -> #REF!

Sheet OFÍCIOS
A1: PLANILHA DE CONFRONTO OFÍCIOS DE INDICAÇÃO COM ENVIADOS CAIXA ECONÔMICA FEDERAL - CEF
A2: TITULAR | B2: CPF | C2: Cônjuge | D2: CPF | E2: OFÍCIO | F2: DATA | G2: STATUS CEF | H2: DATA ENVIO CAIXA | I2: DUPLICIDADE OFÍCIO | J2: DATA | K2: DATA ENVIO CAIXA | L2: OFÍCIO DE INDICAÇÃO | M2: DATA OFÍCIO INDICAÇÃO | O2: NR OFICIO | P2: QUANT | Q2: APROV | R2: REPROV | S2: PEND | T2: SEM STATUS (ANÁLISE) | Y2: CEF BD | Z2: CEF OFICIOS | AA2: CEF PLANILHA
A3: ABEL MEDEIROS FILHO | B3: 27140979871 | E3: 1128 | F3: 42972 | G3: APROVADO | H3: 42979 | O3: 810 | P3: =COUNTIF(OFÍCIOS!E:E,O3) -> 156 | Q3: =COUNTIFS(OFÍCIOS!$E:$E,$O3,OFÍCIOS!$G:$G,"APROVADO") -> 149 | R3: =COUNTIFS(OFÍCIOS!$E:$E,$O3,OFÍCIOS!$G:$G,"REPROVADO") -> 3 | S3: =COUNTIFS(OFÍCIOS!$E:$E,$O3,OFÍCIOS!$G:$G,"PENDENCIA") -> 2 | T3: =COUNTIFS(OFÍCIOS!$E:$E,$O3,OFÍCIOS!$G:$G,"") -> 2 | U3: =SUM(Q3:T3) -> 156 | X3: FEITOS | Y3: 1850 | Z3: 1827 | AA3: =SUM(AA4:AA7) -> 1615
A4: ABELINA FERREIRA DOS SANTOS | B4: 39200633846 | O4: 1417 | P4: =COUNTIF(OFÍCIOS!E:E,O4) -> 42 | Q4: =COUNTIFS(OFÍCIOS!$E:$E,$O4,OFÍCIOS!$G:$G,"APROVADO") -> 36 | R4: =COUNTIFS(OFÍCIOS!$E:$E,$O4,OFÍCIOS!$G:$G,"REPROVADO") -> 3 | S4: =COUNTIFS(OFÍCIOS!$E:$E,$O4,OFÍCIOS!$G:$G,"PENDENCIA") -> 3 | T4: =COUNTIFS(OFÍCIOS!$E:$E,$O4,OFÍCIOS!$G:$G,"") -> 0 | U4: =SUM(Q4:T4) -> 42 | X4: APROVADOS | Y4: 1517 | Z4: 1427 | AA4: 1559
A5: ABIGAIL DE OLIVEIRA PAULINO | B5: 75489104872 | E5: 1752 | F5: 43051 | G5: APROVADO | H5: 43089 | L5: 1759 | O5: 1359 | P5: =COUNTIF(OFÍCIOS!E:E,O5) -> 14 | Q5: =COUNTIFS(OFÍCIOS!$E:$E,$O5,OFÍCIOS!$G:$G,"APROVADO") -> 13 | R5: =COUNTIFS(OFÍCIOS!$E:$E,$O5,OFÍCIOS!$G:$G,"REPROVADO") -> 1 | S5: =COUNTIFS(OFÍCIOS!$E:$E,$O5,OFÍCIOS!$G:$G,"PENDENCIA") -> 0 | T5: =COUNTIFS(OFÍCIOS!$E:$E,$O5,OFÍCIOS!$G:$G,"") -> 0 | U5: =SUM(Q5:T5) -> 14 | X5: REPROVADOS | Y5: 73 | Z5: 79 | AA5: 28
A6: ABILIO OLIVEIRA SANTOS | B6: 43286003620 | O6: 1350 | P6: =COUNTIF(OFÍCIOS!E:E,O6) -> 79 | Q6: =COUNTIFS(OFÍCIOS!$E:$E,$O6,OFÍCIOS!$G:$G,"APROVADO") -> 75 | R6: =COUNTIFS(OFÍCIOS!$E:$E,$O6,OFÍCIOS!$G:$G,"REPROVADO") -> 3 | S6: =COUNTIFS(OFÍCIOS!$E:$E,$O6,OFÍCIOS!$G:$G,"PENDENCIA") -> 0 | T6: =COUNTIFS(OFÍCIOS!$E:$E,$O6,OFÍCIOS!$G:$G,"") -> 1 | U6: =SUM(Q6:T6) -> 79 | X6: PENDENCIAS | Y6: 36 | Z6: 32 | AA6: 11
A7: ABRAHAO SANTOS SILVA | O7: 1343 | P7: =COUNTIF(OFÍCIOS!E:E,O7) -> 6 | Q7: =COUNTIFS(OFÍCIOS!$E:$E,$O7,OFÍCIOS!$G:$G,"APROVADO") -> 5 | R7: =COUNTIFS(OFÍCIOS!$E:$E,$O7,OFÍCIOS!$G:$G,"REPROVADO") -> 0 | S7: =COUNTIFS(OFÍCIOS!$E:$E,$O7,OFÍCIOS!$G:$G,"PENDENCIA") -> 0 | T7: =COUNTIFS(OFÍCIOS!$E:$E,$O7,OFÍCIOS!$G:$G,"") -> 1 | U7: =SUM(Q7:T7) -> 6 | X7: SS / ANALISE | Y7: 224 | Z7: 275 | AA7: 17
A8: ADAIR DA SILVA BARROS | B8: 97443271620 | E8: 1106 | F8: 42965 | G8: APROVADO | H8: 42978 | O8: 1267 | P8: =COUNTIF(OFÍCIOS!E:E,O8) -> 34 | Q8: =COUNTIFS(OFÍCIOS!$E:$E,$O8,OFÍCIOS!$G:$G,"APROVADO") -> 28 | R8: =COUNTIFS(OFÍCIOS!$E:$E,$O8,OFÍCIOS!$G:$G,"REPROVADO") -> 5 | S8: =COUNTIFS(OFÍCIOS!$E:$E,$O8,OFÍCIOS!$G:$G,"PENDENCIA") -> 1 | T8: =COUNTIFS(OFÍCIOS!$E:$E,$O8,OFÍCIOS!$G:$G,"") -> 0 | U8: =SUM(Q8:T8) -> 34
A9: ADALBERTO CARVALHO DE OLIVEIRA | B9: 98058690597 | E9: 423 | F9: 43182 | G9: APROVADO | O9: 1262 | P9: =COUNTIF(OFÍCIOS!E:E,O9) -> 8 | Q9: =COUNTIFS(OFÍCIOS!$E:$E,$O9,OFÍCIOS!$G:$G,"APROVADO") -> 7 | R9: =COUNTIFS(OFÍCIOS!$E:$E,$O9,OFÍCIOS!$G:$G,"REPROVADO") -> 1 | S9: =COUNTIFS(OFÍCIOS!$E:$E,$O9,OFÍCIOS!$G:$G,"PENDENCIA") -> 0 | T9: =COUNTIFS(OFÍCIOS!$E:$E,$O9,OFÍCIOS!$G:$G,"") -> 0 | U9: =SUM(Q9:T9) -> 8
A10: ADALBERTO CAVALCANTE DOS SANTOS | B10: 38088438888 | O10: 1106 | P10: =COUNTIF(OFÍCIOS!E:E,O10) -> 78 | Q10: =COUNTIFS(OFÍCIOS!$E:$E,$O10,OFÍCIOS!$G:$G,"APROVADO") -> 73 | R10: =COUNTIFS(OFÍCIOS!$E:$E,$O10,OFÍCIOS!$G:$G,"REPROVADO") -> 5 | S10: =COUNTIFS(OFÍCIOS!$E:$E,$O10,OFÍCIOS!$G:$G,"PENDENCIA") -> 0 | T10: =COUNTIFS(OFÍCIOS!$E:$E,$O10,OFÍCIOS!$G:$G,"") -> 0 | U10: =SUM(Q10:T10) -> 78
A11: ADALMA MOREIRA DA ROCHA | B11: 26939799869 | E11: 573 | F11: 43224 | O11: 1128 | P11: =COUNTIF(OFÍCIOS!E:E,O11) -> 92 | Q11: =COUNTIFS(OFÍCIOS!$E:$E,$O11,OFÍCIOS!$G:$G,"APROVADO") -> 91 | R11: =COUNTIFS(OFÍCIOS!$E:$E,$O11,OFÍCIOS!$G:$G,"REPROVADO") -> 1 | S11: =COUNTIFS(OFÍCIOS!$E:$E,$O11,OFÍCIOS!$G:$G,"PENDENCIA") -> 0 | T11: =COUNTIFS(OFÍCIOS!$E:$E,$O11,OFÍCIOS!$G:$G,"") -> 0 | U11: =SUM(Q11:T11) -> 92
A12: ADAMILTON PEREIRA DA SILVA ( ALANA ) | B12: 34470559873 | E12: 292 | F12: 43168 | G12: APROVADO | H12: 43182 | L12: 318 | O12: 1214 | P12: =COUNTIF(OFÍCIOS!E:E,O12) -> 76 | Q12: =COUNTIFS(OFÍCIOS!$E:$E,$O12,OFÍCIOS!$G:$G,"APROVADO") -> 71 | R12: =COUNTIFS(OFÍCIOS!$E:$E,$O12,OFÍCIOS!$G:$G,"REPROVADO") -> 3 | S12: =COUNTIFS(OFÍCIOS!$E:$E,$O12,OFÍCIOS!$G:$G,"PENDENCIA") -> 0 | T12: =COUNTIFS(OFÍCIOS!$E:$E,$O12,OFÍCIOS!$G:$G,"") -> 2 | U12: =SUM(Q12:T12) -> 76
A13: ADAO MENDES AGOSTINHO | B13: 14369564808 | O13: 1241 | P13: =COUNTIF(OFÍCIOS!E:E,O13) -> 33 | Q13: =COUNTIFS(OFÍCIOS!$E:$E,$O13,OFÍCIOS!$G:$G,"APROVADO") -> 32 | R13: =COUNTIFS(OFÍCIOS!$E:$E,$O13,OFÍCIOS!$G:$G,"REPROVADO") -> 0 | S13: =COUNTIFS(OFÍCIOS!$E:$E,$O13,OFÍCIOS!$G:$G,"PENDENCIA") -> 1 | T13: =COUNTIFS(OFÍCIOS!$E:$E,$O13,OFÍCIOS!$G:$G,"") -> 0 | U13: =SUM(Q13:T13) -> 33
A14: ADEGMARIO DOS SANTOS | B14: 39544185844 | E14: 810 | F14: 42915 | G14: APROVADO | H14: 42921 | L14: 568-17 | O14: 1422 | P14: =COUNTIF(OFÍCIOS!E:E,O14) -> 7 | Q14: =COUNTIFS(OFÍCIOS!$E:$E,$O14,OFÍCIOS!$G:$G,"APROVADO") -> 7 | R14: =COUNTIFS(OFÍCIOS!$E:$E,$O14,OFÍCIOS!$G:$G,"REPROVADO") -> 0 | S14: =COUNTIFS(OFÍCIOS!$E:$E,$O14,OFÍCIOS!$G:$G,"PENDENCIA") -> 0 | T14: =COUNTIFS(OFÍCIOS!$E:$E,$O14,OFÍCIOS!$G:$G,"") -> 0 | U14: =SUM(Q14:T14) -> 7
A15: ADEILDA GABRIELA CAITANO SILVA | B15: 38772276860 | C15: LUCIANO MANOEL DA SILVA | D15: 3808243457 | O15: 1439 | P15: =COUNTIF(OFÍCIOS!E:E,O15) -> 16 | Q15: =COUNTIFS(OFÍCIOS!$E:$E,$O15,OFÍCIOS!$G:$G,"APROVADO") -> 14 | R15: =COUNTIFS(OFÍCIOS!$E:$E,$O15,OFÍCIOS!$G:$G,"REPROVADO") -> 1 | S15: =COUNTIFS(OFÍCIOS!$E:$E,$O15,OFÍCIOS!$G:$G,"PENDENCIA") -> 1 | T15: =COUNTIFS(OFÍCIOS!$E:$E,$O15,OFÍCIOS!$G:$G,"") -> 0 | U15: =SUM(Q15:T15) -> 16
A16: ADEILDA RODRIGUES DE OLIVEIRA | B16: 21538837846 | C16: PEDRO LUIZ SANTOS OLIVEIRA | D16: 94203180520 | E16: 810 | F16: 42915 | G16: APROVADO | H16: 42921 | L16: 568-17 | O16: 1451 | P16: =COUNTIF(OFÍCIOS!E:E,O16) -> 4 | Q16: =COUNTIFS(OFÍCIOS!$E:$E,$O16,OFÍCIOS!$G:$G,"APROVADO") -> 3 | R16: =COUNTIFS(OFÍCIOS!$E:$E,$O16,OFÍCIOS!$G:$G,"REPROVADO") -> 1 | S16: =COUNTIFS(OFÍCIOS!$E:$E,$O16,OFÍCIOS!$G:$G,"PENDENCIA") -> 0 | T16: =COUNTIFS(OFÍCIOS!$E:$E,$O16,OFÍCIOS!$G:$G,"") -> 0 | U16: =SUM(Q16:T16) -> 4
A17: ADEILDO ADELINO DE CARVALHO | B17: 57455392591 | O17: 1470 | P17: =COUNTIF(OFÍCIOS!E:E,O17) -> 4 | Q17: =COUNTIFS(OFÍCIOS!$E:$E,$O17,OFÍCIOS!$G:$G,"APROVADO") -> 4 | R17: =COUNTIFS(OFÍCIOS!$E:$E,$O17,OFÍCIOS!$G:$G,"REPROVADO") -> 0 | S17: =COUNTIFS(OFÍCIOS!$E:$E,$O17,OFÍCIOS!$G:$G,"PENDENCIA") -> 0 | T17: =COUNTIFS(OFÍCIOS!$E:$E,$O17,OFÍCIOS!$G:$G,"") -> 0 | U17: =SUM(Q17:T17) -> 4
A18: ADELCIDES DA CONCEICAO ALMEIDA | B18: 5304941594 | E18: 1106 | F18: 42965 | G18: APROVADO | H18: 42978 | O18: 1489 | P18: =COUNTIF(OFÍCIOS!E:E,O18) -> 35 | Q18: =COUNTIFS(OFÍCIOS!$E:$E,$O18,OFÍCIOS!$G:$G,"APROVADO") -> 34 | R18: =COUNTIFS(OFÍCIOS!$E:$E,$O18,OFÍCIOS!$G:$G,"REPROVADO") -> 0 | S18: =COUNTIFS(OFÍCIOS!$E:$E,$O18,OFÍCIOS!$G:$G,"PENDENCIA") -> 1 | T18: =COUNTIFS(OFÍCIOS!$E:$E,$O18,OFÍCIOS!$G:$G,"") -> 0 | U18: =SUM(Q18:T18) -> 35
A19: ADELIA MARIA DE OLIVEIRA | B19: 21600057896 | E19: 262 | F19: 43160 | G19: REPROVADO | H19: 43164 | L19: 255 | O19: 1555 | P19: =COUNTIF(OFÍCIOS!E:E,O19) -> 25 | Q19: =COUNTIFS(OFÍCIOS!$E:$E,$O19,OFÍCIOS!$G:$G,"APROVADO") -> 22 | R19: =COUNTIFS(OFÍCIOS!$E:$E,$O19,OFÍCIOS!$G:$G,"REPROVADO") -> 1 | S19: =COUNTIFS(OFÍCIOS!$E:$E,$O19,OFÍCIOS!$G:$G,"PENDENCIA") -> 2 | T19: =COUNTIFS(OFÍCIOS!$E:$E,$O19,OFÍCIOS!$G:$G,"") -> 0 | U19: =SUM(Q19:T19) -> 25
A20: ADEMARIO FERREIRA DOS SANTOS | B20: 18419589802 | O20: 1570 | P20: =COUNTIF(OFÍCIOS!E:E,O20) -> 24 | Q20: =COUNTIFS(OFÍCIOS!$E:$E,$O20,OFÍCIOS!$G:$G,"APROVADO") -> 23 | R20: =COUNTIFS(OFÍCIOS!$E:$E,$O20,OFÍCIOS!$G:$G,"REPROVADO") -> 1 | S20: =COUNTIFS(OFÍCIOS!$E:$E,$O20,OFÍCIOS!$G:$G,"PENDENCIA") -> 0 | T20: =COUNTIFS(OFÍCIOS!$E:$E,$O20,OFÍCIOS!$G:$G,"") -> 0 | U20: =SUM(Q20:T20) -> 24
A21: ADEMIR DA SILVA LIMA | B21: 15538537846 | E21: 573 | F21: 43224 | O21: 1752 | P21: =COUNTIF(OFÍCIOS!E:E,O21) -> 89 | Q21: =COUNTIFS(OFÍCIOS!$E:$E,$O21,OFÍCIOS!$G:$G,"APROVADO") -> 80 | R21: =COUNTIFS(OFÍCIOS!$E:$E,$O21,OFÍCIOS!$G:$G,"REPROVADO") -> 2 | S21: =COUNTIFS(OFÍCIOS!$E:$E,$O21,OFÍCIOS!$G:$G,"PENDENCIA") -> 5 | T21: =COUNTIFS(OFÍCIOS!$E:$E,$O21,OFÍCIOS!$G:$G,"") -> 2 | U21: =SUM(Q21:T21) -> 89
A22: ADENILDE SANTOS DA SILVA | B22: 899837506 | E22: 1824 | F22: 43091 | G22: APROVADO | H22: 43097 | L22: 1828 | O22: 1824 | P22: =COUNTIF(OFÍCIOS!E:E,O22) -> 81 | Q22: =COUNTIFS(OFÍCIOS!$E:$E,$O22,OFÍCIOS!$G:$G,"APROVADO") -> 67 | R22: =COUNTIFS(OFÍCIOS!$E:$E,$O22,OFÍCIOS!$G:$G,"REPROVADO") -> 7 | S22: =COUNTIFS(OFÍCIOS!$E:$E,$O22,OFÍCIOS!$G:$G,"PENDENCIA") -> 6 | T22: =COUNTIFS(OFÍCIOS!$E:$E,$O22,OFÍCIOS!$G:$G,"") -> 1 | U22: =SUM(Q22:T22) -> 81
A23: ADENILSON DA CONCEICAO | B23: 36197160803 | E23: 229 | F23: 43151 | G23: APROVADO | L23: 232 | O23: 1628 | P23: =COUNTIF(OFÍCIOS!E:E,O23) -> 6 | Q23: =COUNTIFS(OFÍCIOS!$E:$E,$O23,OFÍCIOS!$G:$G,"APROVADO") -> 5 | R23: =COUNTIFS(OFÍCIOS!$E:$E,$O23,OFÍCIOS!$G:$G,"REPROVADO") -> 1 | S23: =COUNTIFS(OFÍCIOS!$E:$E,$O23,OFÍCIOS!$G:$G,"PENDENCIA") -> 0 | T23: =COUNTIFS(OFÍCIOS!$E:$E,$O23,OFÍCIOS!$G:$G,"") -> 0 | U23: =SUM(Q23:T23) -> 6
A24: ADENIR MODESTO RIBEIRO | B24: 39248826814 | E24: 292 | F24: 43168 | G24: APROVADO | H24: 43182 | L24: 318 | O24: 608 | P24: =COUNTIF(OFÍCIOS!E:E,O24) -> 35 | Q24: =COUNTIFS(OFÍCIOS!$E:$E,$O24,OFÍCIOS!$G:$G,"APROVADO") -> 31 | R24: =COUNTIFS(OFÍCIOS!$E:$E,$O24,OFÍCIOS!$G:$G,"REPROVADO") -> 3 | S24: =COUNTIFS(OFÍCIOS!$E:$E,$O24,OFÍCIOS!$G:$G,"PENDENCIA") -> 1 | T24: =COUNTIFS(OFÍCIOS!$E:$E,$O24,OFÍCIOS!$G:$G,"") -> 0 | U24: =SUM(Q24:T24) -> 35
A25: ADILINA FARIAS DO NASCIMENTO | B25: 48925276534 | E25: 229 | F25: 43151 | L25: 232 | O25: 527 | P25: =COUNTIF(OFÍCIOS!E:E,O25) -> 29 | Q25: =COUNTIFS(OFÍCIOS!$E:$E,$O25,OFÍCIOS!$G:$G,"APROVADO") -> 0 | R25: =COUNTIFS(OFÍCIOS!$E:$E,$O25,OFÍCIOS!$G:$G,"REPROVADO") -> 0 | S25: =COUNTIFS(OFÍCIOS!$E:$E,$O25,OFÍCIOS!$G:$G,"PENDENCIA") -> 0 | T25: =COUNTIFS(OFÍCIOS!$E:$E,$O25,OFÍCIOS!$G:$G,"") -> 29 | U25: =SUM(Q25:T25) -> 29
A26: ADILSON SOARES DA COSTA | O26: 509 | P26: =COUNTIF(OFÍCIOS!E:E,O26) -> 14 | Q26: =COUNTIFS(OFÍCIOS!$E:$E,$O26,OFÍCIOS!$G:$G,"APROVADO") -> 0 | R26: =COUNTIFS(OFÍCIOS!$E:$E,$O26,OFÍCIOS!$G:$G,"REPROVADO") -> 0 | S26: =COUNTIFS(OFÍCIOS!$E:$E,$O26,OFÍCIOS!$G:$G,"PENDENCIA") -> 0 | T26: =COUNTIFS(OFÍCIOS!$E:$E,$O26,OFÍCIOS!$G:$G,"") -> 14 | U26: =SUM(Q26:T26) -> 14
