Workbook
Name Adequacao_Imovel: 'Listas (não utilizar)'!$G$2:$G$7
Name ADEQUAR: 'Listas (não utilizar)'!$G$2:$G$7
Name Apartamento: 'Listas (não utilizar)'!$D$2:$D$21
Name APROVCEF: #REF!
Name Área: 'Listas (não utilizar)'!$A$2:$A$28
Name AREAS: #REF!
Name AVILDATA: #REF!
Name AVILDATA1: #REF!
Name BARCDATA: #REF!
Name BILBDATA: #REF!
Name Bloco: 'Listas (não utilizar)'!$C$2:$C$16
Name CEF: #REF!
Name CEUTDATA: #REF!
Name Condomínio: 'Listas (não utilizar)'!$B$2:$B$15
Name INDDEMAND: #REF!
Name INDEMAND: #REF!
Name it: #REF!
Name Pendência: 'Listas (não utilizar)'!$I$2:$I$7
Name PLANCCO: #REF!
Name Renúncia: 'Listas (não utilizar)'!$H$2:$H$6
Name RetornoSMADS: '[1]Listas (não utilizar)'!$E$2:$E$3
Name selogo: #REF!
Name selomv: #REF!
Name selos_go: #REF!
Name selosgo: #REF!
Name selosgo1: #REF!
Name SITAH_CAIXA: 'Listas (não utilizar)'!$E$2:$E$9
Name StatusCAIXA: 'Listas (não utilizar)'!$F$2:$F$5
Name TEPROC: #REF!
Name TEPROC1: #REF!

Sheet PRIORIDADES
C3: 2 | D3: PRIORITÁRIO | G3: OCUPADO | H3: RESIDENCIAL | I3: PROPRIETÁRIO NÃO RESIDENTE | M3: CADASTRADO | N3: INDENIZAÇÃO | P3: SIM | R3: SIM | X3: SAQUE PENDENTE | AE3: PROPRIETÁRIO NÃO RESIDENTE | AF3: CADASTRADO | AI3: SIM | AK3: SIM | AM3: COMPLETA | AN3: SEM PENDÊNCIAS
C4: 4 | G4: VAZIO | H4: COMERCIAL | I4: PROPRIETÁRIO RESIDENTE | M4: NÃO CADASTRADO | N4: AUXÍLIO ALUGUEL UH | P4: NÃO | R4: NÃO | AE4: PROPRIETÁRIO RESIDENTE | AF4: NÃO CADASTRADO | AI4: NÃO | AK4: NÃO | AM4: PENDENTE | AN4: FALTA TERMO
G5: OCUPADO/RISCO | H5: MISTO | I5: INQULINO | N5: RECUSA AUXÍLIO ALUGUEL UH | AI5: UH | AK5: N/A | AN5: FALTA DOCS
G6: CONSTRUÇÃO | N6: NÃO TEM DIREITO ATENDIMENTO | AI6: ESTUDO DE CASO | AK6: PENDENTE | AN6: FALTA TERMO E DOCS
G7: DEMOLIDO
G8: DESCARACTERIZADO
G9: DESABADO
A12: INFORMAÇÕES INICIAIS | P12: INFORMAÇÕES AUXÍLIO ALUGUEL | AB12: INFORMAÇÕES INDENIZAÇÃO | BB12: PROCESSO ATENDIMENTO HABITACIONAL
A13: ORDEM | B13: ÁREA | C13: FASE | D13: TRECHO | E13: PRIORIDADE | F13: SELO | G13: SITUAÇÃO INICIAL IMÓVEL | H13: USO IMÓVEL | I13: SITUAÇÃO DO RESIDENTE | J13: TITULAR | K13: RG | L13: CPF | M13: CADASTRO HABITA SAMPA | N13: OPÇÃO DE ATENDIMENTO HABITACIONAL | O13: ENVIO DADOS | P13: SOLICITAÇÃO AUXÍLIO ALUGUEL ÁREA | Q13: No PROCESSO SEI (AUXÍLIO ALUGUEL) | R13: ANÁLISE DTS CADASTRO + CHECAGEM DUPLO | S13: INSTRUÇÃO PROCESSO SEI DTS | T13: ANÁLISE CTS ASSINATURA GABINETE | U13: DATA PUBLICAÇÃO DIÁRIO OFICIAL | V13: CONFECÇÃO TERMO | W13: ENVIO TERMO CARTÃO | X13: PREVISÃO PAGAMENTO | Y13: DATA SAQUE | Z13: DATA MUDANÇA | AA13: OBSERVAÇÕES AA | AB13: PROPRIETÁRIO | AC13: RG | AD13: CPF | AE13: SITUAÇÃO DO PROPRIETÁRIO | AF13: CADASTRO HABITASAMPA | AG13: VALOR AVALIAÇÃO | AH13: VALOR INDENIZAÇÃO | AI13: ACEITA VALOR INDENIZAÇÃO | AJ13: Nº SEI LAUDOS AVALIAÇÃO | AK13: Nº DOCUMENTO LAUDO | AL13: TERMO INDENIZAÇÃO | AM13: DOSSIÊ | AN13: PENDÊNCIA | AO13: OBSERVAÇÕES INDENIZAÇÃO | AP13: No PROCESSO SEI (INDENIZAÇÃO) | AQ13: INSTRUÇÃO PROCESSO SEI DTS | AR13: ASSINATURA DIRETOR DTS | AS13: ELABORAÇÃO DESPACHO CTS | AT13: ASSINATURA DESPACHO GABINETE | AU13: PUBLICAÇÃO DIÁRIO OFICIAL | AV13: ENCAMINHAMENTO DAF/DIF CTS | AW13: LIBERAÇÃO PAGAMENTO DAF/DIF | AX13: PREVISÃO PAGAMENTO | AY13: DATA PAGAMENTO | AZ13: DATA ENTREGA IMÓVEL | BA13: SITUAÇÃO ATUAL IMÓVEL | BB13: STATUS | BC13: DIAS TOTAIS | BD13: OPÇÃO ATENDIMENTO | BE13: NECESSITA BLOQUEIO AA | BF13: SOLICITAÇÃO BLOQUEIO AA DTS | BG13: SOLICITAÇÃO BLOQUEIO AA | BH13: DATA BLOQUEIO AA | BI13: DESPACHO EXCLUSÃO GABINETE | BJ13: ASSINATURA DESPACHO GABINETE | BK13: PUBLICAÇÃO DOC | BL13: ENCAMINHAMENTO SOLICITAÇÃO EXCLUSÃO DEPLAN | BM13: ENCERRAMENTO PROCESSO DTS
A14: 1 | B14: ESPERANÇA | C14: - | D14: - | E14: - | F14: 002/0013/A | G14: OCUPADO | H14: RESIDENCIAL | I14: PROPRIETARIO RESIDENTE | J14: WILLIAM DE LIMA DOS SANTOS | K14: 49.297.982-0 | L14: 401.616.058-85 | M14: CADASTRADO | N14: INDENIZAÇÃO | O14: 45604 | P14: N/A | Q14: N/A | R14: N/A | S14: N/A | T14: N/A | U14: N/A | V14: N/A | W14: N/A | X14: N/A | Y14: N/A | Z14: N/A | AB14: WILLIAM DE LIMA DOS SANTOS | AC14: 49.297.982-0 | AD14: 401.616.058-85 | AE14: PROPRIETÁRIO RESIDENTE | AF14: CADASTRADO | AG14: 36237.18 | AH14: 60000 | AI14: SIM | AJ14: 6014.2023/0002305-9 | AK14: FINALIZADO | AL14: FINALIZADO | AM14: FINALIZADO | AN14: SEM PENDÊNCIA | AP14: 6014.2024/0005868-7 | AQ14: FINALIZADO | AR14: FINALIZADO | AS14: FINALIZADO | AT14: FINALIZADO | AU14: 45754 | AV14: FINALIZADO | AW14: FINALIZADO | AX14: 45757 | AY14: 45757 | AZ14: 45776 | BA14: DEMOLIDO | BB14: FINALIZADO | BC14: =IF(AY14-JS16=0,"",AY14-O14) -> 153 | BD14: =IF(AND(AI14<>"SIM",AI14="UH"),"AA","INDENIZAÇÃO") -> INDENIZAÇÃO | BE14: =IF(AND(AY14<>"AGUARDANDO",AY14<>"",N14="AUXÍLIO ALUGUEL ATÉ INDENIZAÇÃO"),"SIM","NÃO") -> NÃO | BF14: N/A | BG14: N/A | BH14: N/A | BI14: FINALIZADO | BJ14: FINALIZADO | BK14: 45783 | BL14: FINALIZADO | BM14: FINALIZADO
B15: ESPERANÇA | C15: - | D15: - | E15: - | F15: 002/0014/A | G15: OCUPADO | H15: RESIDENCIAL | I15: PROPRIETÁRIO RESIDENTE | J15: ALINE DA CONCEIÇÃO RIBEIRO | K15: 36.052.976-8 | L15: 391.609.628-10 | M15: CADASTRADO | N15: AUXÍLIO ALUGUEL UH | O15: 45565 | P15: 30-set-24 | Q15: 6014.2023/0003397-6 | R15: FINALIZADO | S15: FINALIZADO | T15: FINALIZADO | U15: 25-out-24 | V15: FINALIZADO | W15: FINALIZADO | X15: 45604 | Y15: 45607 | Z15: 45618 | AB15: ALINE DA CONCEIÇÃO RIBEIRO | AC15: 36.052.976-8 | AD15: 391.609.628-10 | AE15: PROPRIETÁRIO RESIDENTE | AF15: CADASTRADO | AG15: 0 | AH15: 0 | AI15: UH | AJ15: N/A | AK15: FINALIZADO | AL15: N/A | AM15: N/A | AN15: N/A | AP15: N/A | AQ15: N/A | AR15: N/A | AS15: N/A | AT15: N/A | AU15: N/A | AV15: N/A | AW15: N/A | AX15: N/A | AY15: N/A | AZ15: 45618 | BA15: DEMOLIDO | BB15: FINALIZADO | BC15: =IF(AY15-JS17=0,"",AY15-O15) -> #VALUE! | BD15: =IF(AND(AI15<>"SIM",AI15="UH"),"AA","INDENIZAÇÃO") -> AA | BE15: =IF(AND(AY15<>"AGUARDANDO",AY15<>"",N15="AUXÍLIO ALUGUEL ATÉ INDENIZAÇÃO"),"SIM","NÃO") -> NÃO | BF15: N/A | BG15: N/A | BJ15: N/A | BK15: N/A | BL15: N/A
A16: 2 | B16: ESPERANÇA | C16: - | D16: - | E16: - | F16: 002/0015/A | G16: OCUPADO | H16: RESIDENCIAL | I16: PROPRIETÁRIO RESIDENTE | J16: TATIANE DA CONCEIÇÃO RIBEIRO | K16: 36.052.894-6 | L16: 329.507.468-29 | M16: CADASTRADO | N16: AUXÍLIO ALUGUEL UH | O16: 45476 | P16: 45476 | Q16: 6014.2023/0003397-6 | R16: FINALIZADO | S16: FINALIZADO | T16: FINALIZADO | U16: 45504 | V16: FINALIZADO | W16: FINALIZADO | X16: 45524 | Y16: 45524 | Z16: 45540 | AB16: TATIANE DA CONCEIÇÃO RIBEIRO | AC16: 36.052.894-6 | AD16: 329.507.468-29 | AE16: PROPRIETÁRIO RESIDENTE | AF16: CADASTRADO | AG16: 0 | AH16: 0 | AI16: UH | AJ16: N/A | AK16: FINALIZADO | AL16: N/A | AM16: N/A | AN16: N/A | AP16: N/A | AQ16: N/A | AR16: N/A | AS16: N/A | AT16: N/A | AU16: N/A | AV16: N/A | AW16: N/A | AX16: 45524 | AY16: 45524 | AZ16: 45540 | BA16: DEMOLIDO | BB16: FINALIZADO | BC16: =IF(AY16-JS18=0,"",AY16-O16) -> 48 | BD16: =IF(AND(AI16<>"SIM",AI16="UH"),"AA","INDENIZAÇÃO") -> AA | BE16: =IF(AND(AY16<>"AGUARDANDO",AY16<>"",N16="AUXÍLIO ALUGUEL ATÉ INDENIZAÇÃO"),"SIM","NÃO") -> NÃO | BF16: N/A | BG16: N/A | BH16: N/A | BI16: N/A | BJ16: N/A | BK16: N/A | BL16: N/A | BM16: FINALIZADO
A17: 3 | B17: ESPERANÇA | C17: - | D17: - | E17: - | F17: 002/0015/B | G17: OCUPADO | H17: RESIDENCIAL | I17: PROPRIETÁRIO RESIDENTE | J17: GLECILENE DA CONCEIÇÃO RIBEIRO | K17: 36.052.542-8 | L17: 366.512.758-01 | M17: CADASTRADO | N17: AUXÍLIO ALUGUEL UH | O17: 45476 | P17: 45476 | Q17: 6014.2023/0003397-6 | R17: FINALIZADO | S17: FINALIZADO | T17: FINALIZADO | U17: 45504 | V17: FINALIZADO | W17: FINALIZADO | X17: 45524 | Y17: 45524 | Z17: 45540 | AB17: GLECILENE DA CONCEIÇÃO RIBEIRO | AC17: 36.052.542-8 | AD17: 366.512.758-01 | AE17: PROPRIETÁRIO RESIDENTE | AF17: CADASTRADO | AG17: 0 | AH17: 0 | AI17: UH | AJ17: N/A | AK17: FINALIZADO | AL17: N/A | AM17: N/A | AN17: N/A | AP17: N/A | AQ17: N/A | AR17: N/A | AS17: N/A | AT17: N/A | AU17: N/A | AV17: N/A | AW17: N/A | AX17: 45524 | AY17: 45524 | AZ17: 45540 | BA17: DEMOLIDO | BB17: FINALIZADO | BC17: =IF(AY17-JS19=0,"",AY17-O17) -> 48 | BD17: =IF(AND(AI17<>"SIM",AI17="UH"),"AA","INDENIZAÇÃO") -> AA | BE17: =IF(AND(AY17<>"AGUARDANDO",AY17<>"",N17="AUXÍLIO ALUGUEL ATÉ INDENIZAÇÃO"),"SIM","NÃO") -> NÃO | BF17: N/A | BG17: N/A | BH17: N/A | BI17: N/A | BJ17: N/A | BK17: N/A | BL17: N/A | BM17: FINALIZADO
A18: 4 | B18: ESPERANÇA | C18: - | D18: - | E18: - | F18: 002/0015/C | G18: OCUPADO | H18: RESIDENCIAL | I18: PROPRIETÁRIO RESIDENTE | J18: AMANDA DA CONCEIÇÃO RIBEIRO | K18: 39.634.161-5 | L18: 502.530.038-06 | M18: CADASTRADO | N18: AUXÍLIO ALUGUEL UH | O18: 45476 | P18: 45476 | Q18: 6014.2023/0003397-6 | R18: FINALIZADO | S18: FINALIZADO | T18: FINALIZADO | U18: 45504 | V18: FINALIZADO | W18: FINALIZADO | X18: 45524 | Y18: 45524 | Z18: 45531 | AB18: AMANDA DA CONCEIÇÃO RIBEIRO | AC18: 39.634.161-5 | AD18: 502.530.038-06 | AE18: PROPRIETÁRIO RESIDENTE | AF18: CADASTRADO | AG18: 0 | AH18: 0 | AI18: UH | AJ18: N/A | AK18: FINALIZADO | AL18: N/A | AM18: N/A | AN18: N/A | AP18: N/A | AQ18: N/A | AR18: N/A | AS18: N/A | AT18: N/A | AU18: N/A | AV18: N/A | AW18: N/A | AX18: 45524 | AY18: 45524 | AZ18: 45531 | BA18: DEMOLIDO | BB18: FINALIZADO | BC18: =IF(AY18-JS20=0,"",AY18-O18) -> 48 | BD18: =IF(AND(AI18<>"SIM",AI18="UH"),"AA","INDENIZAÇÃO") -> AA | BE18: =IF(AND(AY18<>"AGUARDANDO",AY18<>"",N18="AUXÍLIO ALUGUEL ATÉ INDENIZAÇÃO"),"SIM","NÃO") -> NÃO | BF18: N/A | BG18: N/A | BH18: N/A | BI18: N/A | BJ18: N/A | BK18: N/A | BL18: N/A | BM18: FINALIZADO
A19: 5 | B19: ESPERANÇA | C19: - | D19: - | E19: - | F19: 002/0015/D | G19: OCUPADO | H19: RESIDENCIAL | I19: PROPRIETÁRIO RESIDENTE | J19: JOANA D'ARC DA CONCEIÇÃO RIBEIRO | K19: 17.397.857-5 | L19: 148.978.928-64 | M19: CADASTRADO | N19: AUXÍLIO ALUGUEL UH | O19: 45476 | P19: 45476 | Q19: 6014.2023/0003397-6 | R19: FINALIZADO | S19: FINALIZADO | T19: FINALIZADO | U19: 45504 | V19: FINALIZADO | W19: FINALIZADO | X19: 45524 | Y19: 45524 | Z19: 45540 | AB19: JOANA D'ARC DA CONCEIÇÃO RIBEIRO | AC19: 17.397.857-5 | AD19: 148.978.928-64 | AE19: PROPRIETÁRIO RESIDENTE | AF19: CADASTRADO | AG19: 0 | AH19: 0 | AI19: UH | AJ19: N/A | AK19: FINALIZADO | AL19: N/A | AM19: N/A | AN19: N/A | AP19: N/A | AQ19: N/A | AR19: N/A | AS19: N/A | AT19: N/A | AU19: N/A | AV19: N/A | AW19: N/A | AX19: 45524 | AY19: 45524 | AZ19: 45540 | BA19: DEMOLIDO | BB19: FINALIZADO | BC19: =IF(AY19-JS21=0,"",AY19-O19) -> 48 | BD19: =IF(AND(AI19<>"SIM",AI19="UH"),"AA","INDENIZAÇÃO") -> AA | BE19: =IF(AND(AY19<>"AGUARDANDO",AY19<>"",N19="AUXÍLIO ALUGUEL ATÉ INDENIZAÇÃO"),"SIM","NÃO") -> NÃO | BF19: N/A | BG19: N/A | BH19: N/A | BI19: N/A | BJ19: N/A | BK19: N/A | BL19: N/A | BM19: FINALIZADO
B20: ESPERANÇA | C20: - | D20: - | E20: - | F20: 002/0015/E | G20: OCUPADO | H20: RESIDENCIAL | I20: PROPRIETÁRIO RESIDENTE | J20: GLESSIO DA CONCEIÇÃO RIBEIRO | K20: 44.824.297-7 | L20: 359.678.398-44 | M20: CADASTRADO | N20: AUXÍLIO ALUGUEL UH | O20: 23-set-24 | P20: 23-set-24 | Q20: 6014.2023/0003397-6 | R20: FINALIZADO | S20: FINALIZADO | T20: FINALIZADO | U20: 25-out-24 | V20: FINALIZADO | W20: FINALIZADO | X20: 45604 | Y20: 45607 | Z20: 45618 | AB20: GLESSIO DA CONCEIÇÃO RIBEIRO | AC20: 44.824.297-7 | AD20: 359.678.398-44 | AE20: PROPRIETÁRIO RESIDENTE | AF20: CADASTRADO | AG20: 0 | AH20: 0 | AI20: UH | AJ20: N/A | AK20: FINALIZADO | AL20: N/A | AM20: N/A | AN20: N/A | AP20: N/A | AQ20: N/A | AR20: N/A | AS20: N/A | AT20: N/A | AU20: N/A | AV20: N/A | AW20: N/A | AX20: N/A | AY20: N/A | AZ20: N/A | BA20: DEMOLIDO | BB20: FINALIZADO | BC20: =IF(AY20-JS22=0,"",AY20-O20) -> #VALUE! | BD20: =IF(AND(AI20<>"SIM",AI20="UH"),"AA","INDENIZAÇÃO") -> AA
A21: 6 | B21: ESPERANÇA | C21: - | D21: - | E21: - | F21: 002/0016/A | G21: OCUPADO | H21: RESIDENCIAL | I21: PROPRIETÁRIO RESIDENTE | J21: MARIA HELENA DA CONCEIÇÃO | K21: 28.149.326-1 | L21: 355.219.818-02 | M21: CADASTRADO | N21: AUXÍLIO ALUGUEL UH | O21: 45476 | P21: 45476 | Q21: 6014.2023/0003397-6 | R21: FINALIZADO | S21: FINALIZADO | T21: FINALIZADO | U21: 45504 | V21: FINALIZADO | W21: FINALIZADO | X21: 45524 | Y21: 45524 | Z21: 45540 | AB21: MARIA HELENA DA CONCEIÇÃO | AC21: 28.149.326-1 | AD21: 355.219.818-02 | AE21: PROPRIETÁRIO RESIDENTE | AF21: CADASTRADO | AG21: 0 | AH21: 0 | AI21: UH | AJ21: N/A | AK21: FINALIZADO | AL21: N/A | AM21: N/A | AN21: N/A | AP21: N/A | AQ21: N/A | AR21: N/A | AS21: N/A | AT21: N/A | AU21: N/A | AV21: N/A | AW21: N/A | AX21: 45524 | AY21: 45524 | AZ21: 45540 | BA21: DEMOLIDO | BB21: FINALIZADO | BC21: =IF(AY21-JS23=0,"",AY21-O21) -> 48 | BD21: =IF(AND(AI21<>"SIM",AI21="UH"),"AA","INDENIZAÇÃO") -> AA | BE21: =IF(AND(AY21<>"AGUARDANDO",AY21<>"",N21="AUXÍLIO ALUGUEL ATÉ INDENIZAÇÃO"),"SIM","NÃO") -> NÃO | BF21: N/A | BG21: N/A | BH21: N/A | BI21: N/A | BJ21: N/A | BK21: N/A | BL21: N/A | BM21: FINALIZADO
A22: 7 | BC22: =IF(AY22-JS23=0,"",AY22-O22) | BD22: =IF(AND(AI22<>"SIM",AI22="UH"),"AA","INDENIZAÇÃO") -> INDENIZAÇÃO | BE22: =IF(AND(AY22<>"AGUARDANDO",AY22<>"",N22="AUXÍLIO ALUGUEL ATÉ INDENIZAÇÃO"),"SIM","NÃO") -> NÃO
A23: 8 | BC23: =IF(AY23-JS24=0,"",AY23-O23) | BD23: =IF(AND(AI23<>"SIM",AI23="UH"),"AA","INDENIZAÇÃO") -> INDENIZAÇÃO | BE23: =IF(AND(AY23<>"AGUARDANDO",AY23<>"",N23="AUXÍLIO ALUGUEL ATÉ INDENIZAÇÃO"),"SIM","NÃO") -> NÃO
A24: 9 | BC24: =IF(AY24-JS25=0,"",AY24-O24) | BD24: =IF(AND(AI24<>"SIM",AI24="UH"),"AA","INDENIZAÇÃO") -> INDENIZAÇÃO | BE24: =IF(AND(AY24<>"AGUARDANDO",AY24<>"",N24="AUXÍLIO ALUGUEL ATÉ INDENIZAÇÃO"),"SIM","NÃO") -> NÃO
A25: 10 | BC25: =IF(AY25-JS26=0,"",AY25-O25) | BD25: =IF(AND(AI25<>"SIM",AI25="UH"),"AA","INDENIZAÇÃO") -> INDENIZAÇÃO | BE25: =IF(AND(AY25<>"AGUARDANDO",AY25<>"",N25="AUXÍLIO ALUGUEL ATÉ INDENIZAÇÃO"),"SIM","NÃO") -> NÃO
A26: 11 | BC26: =IF(AY26-JS27=0,"",AY26-O26) | BD26: =IF(AND(AI26<>"SIM",AI26="UH"),"AA","INDENIZAÇÃO") -> INDENIZAÇÃO | BE26: =IF(AND(AY26<>"AGUARDANDO",AY26<>"",N26="AUXÍLIO ALUGUEL ATÉ INDENIZAÇÃO"),"SIM","NÃO") -> NÃO
A27: 12
A28: 13
A29: 14
A30: 15
A31: 16
A32: 17
A33: 18
A34: 19
A35: 20
A36: 21
A37: 22
A38: 23
... A211: 196

Sheet Planilha1
F3: 024/0030/B | H3: 029/0024/C
A4: ÁREA | B4: SELO | C4: TITULAR | D4: PUBLICAÇÃO DOC | F4: 024/0041/A | H4: 029/0023/E
A5: ESPERANÇA | B5: 002/0013/A | C5: WILLIAM DE LIMA DOS SANTOS | D5: 45754 | F5: 024/0041/B | H5: 029/0071/B
A6: ÁRVORE SÃO TOMÁS | B6: 005/0005/A | C6: VALMIRA MARIA DO NASCIMENTO SILVA | D6: 45412 | F6: 024/0051/A | H6: 024/0057/A
A7: ÁRVORE SÃO TOMÁS | B7: 005/0018/A | C7: JOSÉ AÉCIO CORDEIRO DA SILVA | D7: 45412 | F7: 024/0052/A | H7: 031/0033/Q
F8: 024/0055/B | H8: 029/0066/A
F9: 024/0057/A | H9: 024/0105/B
F10: 024/0070/E | H10: 031/0022/E
A11: ÁRVORE SÃO TOMÁS | B11: 005/0003/A | C11: ADEMAR GONÇALVES DE REZENDE | D11: 45357 | F11: 024/0077/B | H11: 031/0031/B
A12: ÁRVORE SÃO TOMÁS | B12: 005/0010/B | C12: ANDREZA YASMIM CIRIACO MIRANDA DE SOUSA | D12: 45357 | F12: 024/0079/C | H12: 031/0020/C
F13: 024/0088/B | H13: 029/0069/D
F14: 024/0099/A | H14: 031/0033/K
F15: 024/0102/D | H15: 029/0016/B
A16: ÁRVORE SÃO TOMÁS | B16: 003/0056/A | C16: NOÉLIA SILVA COSTA | D16: 45300 | F16: 024/0105/A | H16: 029/0066/E
A17: ÁRVORE SÃO TOMÁS | B17: 003/0057/A | C17: CLÁUDIO VENTURA MACHADO | D17: 45300 | F17: 024/0105/B | H17: 024/0099/A
A18: ÁRVORE SÃO TOMÁS | B18: 003/0059/A | C18: MARIDALVA NERY SANTANA | D18: 45300 | F18: 029/0007/A | H18: 029/0022/B
A19: ÁRVORE SÃO TOMÁS | B19: 003/0087/A | C19: JOSE NILTON FERREIRA MOREIRA | D19: 45300 | F19: 029/0007/B | H19: 031/0039/C
A20: ÁRVORE SÃO TOMÁS | B20: 003/0088/A | C20: MARIA DE FÁTIMA DE JESUS SILVA | D20: 45300 | F20: 029/0016/B | H20: 029/0081/A
A21: ÁRVORE SÃO TOMÁS | B21: 003/0091/A | C21: REGINALDO CORDEIRO DE SOUSA | D21: 45300 | F21: 029/0022/B | H21: 024/0052/A
A22: ÁRVORE SÃO TOMÁS | B22: 003/0092/A | C22: REJANE DA SILVA SANTOS | D22: 45300 | F22: 029/0023/E | H22: 029/0035/B
A23: ÁRVORE SÃO TOMÁS | B23: 003/0092/B | C23: MARIA MENEZES DA SILVA SANTOS | D23: 45300 | F23: 029/0024/C | H23: 029/0027/A
A24: ÁRVORE SÃO TOMÁS | B24: 003/0092/D | C24: ELIZABETE CRISTINA DOS SANTOS SILVA | D24: 45306 | F24: 029/0027/A | H24: 029/0064/A
A25: ÁRVORE SÃO TOMÁS | B25: 003/0094/A | C25: MARTON ALVES DE OLIVEIRA | D25: 45300 | F25: 029/0035/B | H25: 029/0069/B
A26: ÁRVORE SÃO TOMÁS | B26: 003/0095/A | C26: TAMIRES VENANCIO DA SILVA | D26: 45300 | F26: 029/0036/F | H26: 031/0028/D
A27: ÁRVORE SÃO TOMÁS | B27: 003/0101/A | C27: BIANCA ALVES DOS SANTOS LIMA | D27: 45300 | F27: 029/0039/B | H27: 029/0067/A
... A45: ÁRVORE SÃO TOMÁS | B45: 005/0016/A | C45: JOSE LUIS DA SILVEIRA NATEL | D45: 45300 | F45: 029/0080/E | H45: 031/0067/A
F46: 029/0081/A | H46: 031/0028/L
F47: 029/0083/A | H47: 024/0105/A
F48: 029/0085/G | H48: 029/0064/F
F49: 029/0086/B | H49: 031/0025/A
F50: 031/0004/C | H50: 024/0051/A
F51: 031/0014/A | H51: 024/0030/B
D52: 44992 | F52: 031/0015/D | H52: 029/0083/A
D53: 45013 | F53: 031/0020/B | H53: 031/0004/C
D54: 45013 | F54: 031/0020/C | H54: 031/0014/A
D55: N/A | F55: 031/0022/B | H55: 033/0029/B
D56: 45013 | F56: 031/0022/E | H56: 029/0071/E
D57: N/A | F57: 031/0025/A | H57: 031/0033/E
D58: N/A | F58: 031/0028/D | H58: 024/0070/E
D59: 44840 | F59: 031/0028/L | H59: 024/0079/C
...

Sheet Quantitativo Fora da Demanda
A1: REPROVADOS QUE NÃO DEVERÃO SER REASSENTADOS NO ESPANHA | E1: APROVADOS SEM CONDOMÍNIO QUE DEVERÃO SER REASSENTADOS NO CHÁCARA DO CONDE
A2: ÁREA | B2: QTD | E2: ÁREA | F2: QTD
A3: AUXÍLIO ALUGUEL | B3: 39 | E3: AUXÍLIO ALUGUEL | F3: 54
A4: CANTINHO DO CÉU (OBRAS) | B4: 15 | E4: CANTINHO DO CÉU (OBRAS) SETORES: 138 E 140 | F4: 13
A5: FUMAÇA | B5: 7 | E5: FUMAÇA | F5: 15
A6: NEBLINA | B6: 2 | E6: NEBLINA | F6: 9
A7: LEBLON | B7: 0 | E7: LEBLON | F7: 9
A8: PABREU / PRAINHA | B8: 15 | E8: PABREU / PRAINHA | F8: 21
A9: TOTAL | B9: =SUM(B3:B8) -> 78 | E9: TOTAL | F9: =SUM(F3:F8) -> 121

Sheet Listas (não utilizar)
A1: Área | B1: Condomínio | C1: Bloco | D1: Apartamento | E1: SITAH / CAIXA | F1: Status CAIXA | G1: Adequacao Imovel | H1: Renúncia | I1: Pendência | J1: Pendências / Reprovados caixa
A2: ALTO DA ALEGRIA | B2: AVILA | C2: 1 | D2: 101 | E2: AGENDADO | F2: APROVADO | G2: NÃO | H2: NÃO | I2: CRAS | J2: RENDA SUPERIOR
A3: ALTO DA ALEGRIA (OBRAS) | B3: BARCELONA | C3: 2 | D3: 102 | E3: AGUARDANDO OFICIO | F3: REPROVADO | G3: FÍSICA | H3: RENDA | I3: CRAS + DOCUMENTOS | J3: CADMUT
A4: ALTO DA ALEGRIA (RESERVA) | B4: BILBAO | C4: 3 | D4: 103 | E4: ATENDIMENTO CANCELADO | F4: PENDENCIA | G4: VISUAL | H4: CADIN | I4: DOCUMENTOS | J4: CADIN
A5: ANTERO GOMES | B5: CEUTA | C5: 4 | D5: 104 | E5: CADMUT | F5: SEM DOSSIE | G5: INTELECTUAL | H5: ESTADO CIVIL | I5: CADIN
A6: CANTINHO DO CEU / GAIVOTAS | B6: IBIZA | C6: 5 | D6: 201 | E6: CHACARA DO CONDE | G6: AUDITIVA | H6: SEPARACAO | I6: CRAS + CADIN
A7: CANTINHO DO CEU / OBRAS | B7: LEAO | C7: 6 | D7: 202 | E7: CONFLITO | G7: NANISMO | I7: R.LI.AV.
A8: CASTRO ALVES | B8: MADRID | C8: 7 | D8: 203 | E8: ENVIADO CAIXA | I8: IEME
A9: COCAIA | B9: MELILLA | C9: 8 | D9: 204 | E9: FALECEU
A10: ERUNDINA | B10: PAMPLONA | C10: 9 | D10: 301 | E10: FALTANTE DOSSIÊ
A11: FUMACA | B11: SALAMANCA | C11: 10 | D11: 302 | E11: HABISP ACERTO DE ÁREA
A12: GUAICURI (OBRAS) | B12: TERUEL | C12: 11 | D12: 303 | E12: HABISP AGUARDANDO CRÍTICA
A13: GUAICURI / CIDADE JULIA | B13: VALENCIA | C13: 12 | D13: 304 | E13: HABISP PEND DE ATUALIZ CADASTRAL
A14: JARDIM MIRNA | B14: VALVERDE | C14: 13 | D14: 401 | E14: INDENIZACAO
A15: JARDIM SELMA II | B15: VITORIA | C15: 14 | D15: 402 | E15: PENDENCIA
A16: JARDIM TUBO | C16: 15 | D16: 403 | E16: PERMUTA
A17: LEBLON | D17: 404 | E17: PESQUISA SMADS
A18: MARGINAL DOIS / FUNDAO | D18: 501 | E18: REANALISE
A19: MATA VIRGEM / JD ELDORADO | D19: 502 | E19: RECLUSO
A20: NEBLINA | D20: 503 | E20: RELATÓRIO SOCIAL
A21: NORONHA | D21: 504 | E21: RENDA SUPERIOR
A22: NOVA GRAJAU | E22: RESISTENTE
A23: NOVA MARILDA | E23: TROCA DE TITULARIDADE
A24: NOVA VARGINHA
A25: PABREU / PRAINHA
A26: PENDENCIA GABINETE
A27: PILAO / APURA
A28: PILAO / DOIS
A29: PILAO / PAULISTAS
A30: SANTA AMELIA
A31: VALE VERDE / MONTE VERDE
A32: VILA BREJINHO
A33: VILA NASCENTE
A34: ZR / COSTA BRANCA
A35: VILA RUBI

Sheet QUANT COND
A1: CONDOMINIOS | B1: QUANT
A2: AVILA | B2: =COUNTIF(#REF!,'QUANT COND'!A2) -> #REF!
A3: BARCELONA | B3: =COUNTIF(#REF!,'QUANT COND'!A3) -> #REF!
A4: BILBAO | B4: =COUNTIF(#REF!,'QUANT COND'!A4) -> #REF!
A5: CEUTA | B5: =COUNTIF(#REF!,'QUANT COND'!A5) -> #REF!
A6: IBIZA | B6: =COUNTIF(#REF!,'QUANT COND'!A6) -> #REF!
A7: LEAO | B7: =COUNTIF(#REF!,'QUANT COND'!A7) -> #REF!
A8: MADRID | B8: =COUNTIF(#REF!,'QUANT COND'!A8) -> #REF!
A9: MELILLA | B9: =COUNTIF(#REF!,'QUANT COND'!A9) -> #REF!
A10: PAMPLONA | B10: =COUNTIF(#REF!,'QUANT COND'!A10) -> #REF!
A11: SALAMANCA | B11: =COUNTIF(#REF!,'QUANT COND'!A11) -> #REF!
A12: TERUEL | B12: =COUNTIF(#REF!,'QUANT COND'!A12) -> #REF!
A13: VALENCIA | B13: =COUNTIF(#REF!,'QUANT COND'!A13) -> #REF!
... A15: VITORIA | B15: =COUNTIF(#REF!,'QUANT COND'!A15) -> #REF!

Sheet OFÍCIOS
A1: PLANILHA DE CONFRONTO OFÍCIOS DE INDICAÇÃO COM ENVIADOS CAIXA ECONÔMICA FEDERAL - CEF
A2: TITULAR | B2: CPF | C2: Cônjuge | D2: CPF | E2: OFÍCIO | F2: DATA | G2: STATUS CEF | H2: DATA ENVIO CAIXA | I2: DUPLICIDADE OFÍCIO | J2: DATA | K2: DATA ENVIO CAIXA | L2: OFÍCIO DE INDICAÇÃO | M2: DATA OFÍCIO INDICAÇÃO | O2: NR OFICIO | P2: QUANT | Q2: APROV | R2: REPROV | S2: PEND | T2: SEM STATUS (ANÁLISE) | Y2: CEF BD | Z2: CEF OFICIOS | AA2: CEF PLANILHA
A3: ABEL MEDEIROS FILHO | B3: 27140979871 | E3: 1128 | F3: 42972 | G3: APROVADO | H3: 42979 | O3: 810 | P3: =COUNTIF(OFÍCIOS!E:E,O3) -> 156 | Q3: =COUNTIFS(OFÍCIOS!$E:$E,$O3,OFÍCIOS!$G:$G,"APROVADO") -> 149 | R3: =COUNTIFS(OFÍCIOS!$E:$E,$O3,OFÍCIOS!$G:$G,"REPROVADO") -> 3 | S3: =COUNTIFS(OFÍCIOS!$E:$E,$O3,OFÍCIOS!$G:$G,"PENDENCIA") -> 2 | T3: =COUNTIFS(OFÍCIOS!$E:$E,$O3,OFÍCIOS!$G:$G,"") -> 2 | U3: =SUM(Q3:T3) -> 156 | X3: FEITOS | Y3: 1850 | Z3: 1827 | AA3: =SUM(AA4:AA7) -> 1615
A4: ABELINA FERREIRA DOS SANTOS | B4: 39200633846 | O4: 1417 | P4: =COUNTIF(OFÍCIOS!E:E,O4) -> 42 | Q4: =COUNTIFS(OFÍCIOS!$E:$E,$O4,OFÍCIOS!$G:$G,"APROVADO") -> 36 | R4: =COUNTIFS(OFÍCIOS!$E:$E,$O4,OFÍCIOS!$G:$G,"REPROVADO") -> 3 | S4: =COUNTIFS(OFÍCIOS!$E:$E,$O4,OFÍCIOS!$G:$G,"PENDENCIA") -> 3 | T4: =COUNTIFS(OFÍCIOS!$E:$E,$O4,OFÍCIOS!$G:$G,"") -> 0 | U4: =SUM(Q4:T4) -> 42 | X4: APROVADOS | Y4: 1517 | Z4: 1427 | AA4: 1559
A5: ABIGAIL DE OLIVEIRA PAULINO | B5: 75489104872 | E5: 1752 | F5: 43051 | G5: APROVADO | H5: 43089 | L5: 1759 | O5: 1359 | P5: =COUNTIF(OFÍCIOS!E:E,O5) -> 14 | Q5: =COUNTIFS(OFÍCIOS!$E:$E,$O5,OFÍCIOS!$G:$G,"APROVADO") -> 13 | R5: =COUNTIFS(OFÍCIOS!$E:$E,$O5,OFÍCIOS!$G:$G,"REPROVADO") -> 1 | S5: =COUNTIFS(OFÍCIOS!$E:$E,$O5,OFÍCIOS!$G:$G,"PENDENCIA") -> 0 | T5: =COUNTIFS(OFÍCIOS!$E:$E,$O5,OFÍCIOS!$G:$G,"") -> 0 | U5: =SUM(Q5:T5) -> 14 | X5: REPROVADOS | Y5: 73 | Z5: 79 | AA5: 28
A6: ABILIO OLIVEIRA SANTOS | B6: 43286003620 | O6: 1350 | P6: =COUNTIF(OFÍCIOS!E:E,O6) -> 79 | Q6: =COUNTIFS(OFÍCIOS!$E:$E,$O6,OFÍCIOS!$G:$G,"APROVADO") -> 75 | R6: =COUNTIFS(OFÍCIOS!$E:$E,$O6,OFÍCIOS!$G:$G,"REPROVADO") -> 3 | S6: =COUNTIFS(OFÍCIOS!$E:$E,$O6,OFÍCIOS!$G:$G,"PENDENCIA") -> 0 | T6: =COUNTIFS(OFÍCIOS!$E:$E,$O6,OFÍCIOS!$G:$G,"") -> 1 | U6: =SUM(Q6:T6) -> 79 | X6: PENDENCIAS | Y6: 36 | Z6: 32 | AA6: 11
A7: ABRAHAO SANTOS SILVA | O7: 1343 | P7: =COUNTIF(OFÍCIOS!E:E,O7) -> 6 | Q7: =COUNTIFS(OFÍCIOS!$E:$E,$O7,OFÍCIOS!$G:$G,"APROVADO") -> 5 | R7: =COUNTIFS(OFÍCIOS!$E:$E,$O7,OFÍCIOS!$G:$G,"REPROVADO") -> 0 | S7: =COUNTIFS(OFÍCIOS!$E:$E,$O7,OFÍCIOS!$G:$G,"PENDENCIA") -> 0 | T7: =COUNTIFS(OFÍCIOS!$E:$E,$O7,OFÍCIOS!$G:$G,"") -> 1 | U7: =SUM(Q7:T7) -> 6 | X7: SS / ANALISE | Y7: 224 | Z7: 275 | AA7: 17
A8: ADAIR DA SILVA BARROS | B8: 97443271620 | E8: 1106 | F8: 42965 | G8: APROVADO | H8: 42978 | O8: 1267 | P8: =COUNTIF(OFÍCIOS!E:E,O8) -> 34 | Q8: =COUNTIFS(OFÍCIOS!$E:$E,$O8,OFÍCIOS!$G:$G,"APROVADO") -> 28 | R8: =COUNTIFS(OFÍCIOS!$E:$E,$O8,OFÍCIOS!$G:$G,"REPROVADO") -> 5 | S8: =COUNTIFS(OFÍCIOS!$E:$E,$O8,OFÍCIOS!$G:$G,"PENDENCIA") -> 1 | T8: =COUNTIFS(OFÍCIOS!$E:$E,$O8,OFÍCIOS!$G:$G,"") -> 0 | U8: =SUM(Q8:T8) -> 34
A9: ADALBERTO CARVALHO DE OLIVEIRA | B9: 98058690597 | E9: 423 | F9: 43182 | G9: APROVADO | O9: 1262 | P9: =COUNTIF(OFÍCIOS!E:E,O9) -> 8 | Q9: =COUNTIFS(OFÍCIOS!$E:$E,$O9,OFÍCIOS!$G:$G,"APROVADO") -> 7 | R9: =COUNTIFS(OFÍCIOS!$E:$E,$O9,OFÍCIOS!$G:$G,"REPROVADO") -> 1 | S9: =COUNTIFS(OFÍCIOS!$E:$E,$O9,OFÍCIOS!$G:$G,"PENDENCIA") -> 0 | T9: =COUNTIFS(OFÍCIOS!$E:$E,$O9,OFÍCIOS!$G:$G,"") -> 0 | U9: =SUM(Q9:T9) -> 8
A10: ADALBERTO CAVALCANTE DOS SANTOS | B10: 38088438888 | O10: 1106 | P10: =COUNTIF(OFÍCIOS!E:E,O10) -> 78 | Q10: =COUNTIFS(OFÍCIOS!$E:$E,$O10,OFÍCIOS!$G:$G,"APROVADO") -> 73 | R10: =COUNTIFS(OFÍCIOS!$E:$E,$O10,OFÍCIOS!$G:$G,"REPROVADO") -> 5 | S10: =COUNTIFS(OFÍCIOS!$E:$E,$O10,OFÍCIOS!$G:$G,"PENDENCIA") -> 0 | T10: =COUNTIFS(OFÍCIOS!$E:$E,$O10,OFÍCIOS!$G:$G,"") -> 0 | U10: =SUM(Q10:T10) -> 78
A11: ADALMA MOREIRA DA ROCHA | B11: 26939799869 | E11: 573 | F11: 43224 | O11: 1128 | P11: =COUNTIF(OFÍCIOS!E:E,O11) -> 92 | Q11: =COUNTIFS(OFÍCIOS!$E:$E,$O11,OFÍCIOS!$G:$G,"APROVADO") -> 91 | R11: =COUNTIFS(OFÍCIOS!$E:$E,$O11,OFÍCIOS!$G:$G,"REPROVADO") -> 1 | S11: =COUNTIFS(OFÍCIOS!$E:$E,$O11,OFÍCIOS!$G:$G,"PENDENCIA") -> 0 | T11: =COUNTIFS(OFÍCIOS!$E:$E,$O11,OFÍCIOS!$G:$G,"") -> 0 | U11: =SUM(Q11:T11) -> 92
A12: ADAMILTON PEREIRA DA SILVA ( ALANA ) | B12: 34470559873 | E12: 292 | F12: 43168 | G12: APROVADO | H12: 43182 | L12: 318 | O12: 1214 | P12: =COUNTIF(OFÍCIOS!E:E,O12) -> 76 | Q12: =COUNTIFS(OFÍCIOS!$E:$E,$O12,OFÍCIOS!$G:$G,"APROVADO") -> 71 | R12: =COUNTIFS(OFÍCIOS!$E:$E,$O12,OFÍCIOS!$G:$G,"REPROVADO") -> 3 | S12: =COUNTIFS(OFÍCIOS!$E:$E,$O12,OFÍCIOS!$G:$G,"PENDENCIA") -> 0 | T12: =COUNTIFS(OFÍCIOS!$E:$E,$O12,OFÍCIOS!$G:$G,"") -> 2 | U12: =SUM(Q12:T12) -> 76
A13: ADAO MENDES AGOSTINHO | B13: 14369564808 | O13: 1241 | P13: =COUNTIF(OFÍCIOS!E:E,O13) -> 33 | Q13: =COUNTIFS(OFÍCIOS!$E:$E,$O13,OFÍCIOS!$G:$G,"APROVADO") -> 32 | R13: =COUNTIFS(OFÍCIOS!$E:$E,$O13,OFÍCIOS!$G:$G,"REPROVADO") -> 0 | S13: =COUNTIFS(OFÍCIOS!$E:$E,$O13,OFÍCIOS!$G:$G,"PENDENCIA") -> 1 | T13: =COUNTIFS(OFÍCIOS!$E:$E,$O13,OFÍCIOS!$G:$G,"") -> 0 | U13: =SUM(Q13:T13) -> 33
A14: ADEGMARIO DOS SANTOS | B14: 39544185844 | E14: 810 | F14: 42915 | G14: APROVADO | H14: 42921 | L14: 568-17 | O14: 1422 | P14: =COUNTIF(OFÍCIOS!E:E,O14) -> 7 | Q14: =COUNTIFS(OFÍCIOS!$E:$E,$O14,OFÍCIOS!$G:$G,"APROVADO") -> 7 | R14: =COUNTIFS(OFÍCIOS!$E:$E,$O14,OFÍCIOS!$G:$G,"REPROVADO") -> 0 | S14: =COUNTIFS(OFÍCIOS!$E:$E,$O14,OFÍCIOS!$G:$G,"PENDENCIA") -> 0 | T14: =COUNTIFS(OFÍCIOS!$E:$E,$O14,OFÍCIOS!$G:$G,"") -> 0 | U14: =SUM(Q14:T14) -> 7
A15: ADEILDA GABRIELA CAITANO SILVA | B15: 38772276860 | C15: LUCIANO MANOEL DA SILVA | D15: 3808243457 | O15: 1439 | P15: =COUNTIF(OFÍCIOS!E:E,O15) -> 16 | Q15: =COUNTIFS(OFÍCIOS!$E:$E,$O15,OFÍCIOS!$G:$G,"APROVADO") -> 14 | R15: =COUNTIFS(OFÍCIOS!$E:$E,$O15,OFÍCIOS!$G:$G,"REPROVADO") -> 1 | S15: =COUNTIFS(OFÍCIOS!$E:$E,$O15,OFÍCIOS!$G:$G,"PENDENCIA") -> 1 | T15: =COUNTIFS(OFÍCIOS!$E:$E,$O15,OFÍCIOS!$G:$G,"") -> 0 | U15: =SUM(Q15:T15) -> 16
A16: ADEILDA RODRIGUES DE OLIVEIRA | B16: 21538837846 | C16: PEDRO LUIZ SANTOS OLIVEIRA | D16: 94203180520 | E16: 810 | F16: 42915 | G16: APROVADO | H16: 42921 | L16: 568-17 | O16: 1451 | P16: =COUNTIF(OFÍCIOS!E:E,O16) -> 4 | Q16: =COUNTIFS(OFÍCIOS!$E:$E,$O16,OFÍCIOS!$G:$G,"APROVADO") -> 3 | R16: =COUNTIFS(OFÍCIOS!$E:$E,$O16,OFÍCIOS!$G:$G,"REPROVADO") -> 1 | S16: =COUNTIFS(OFÍCIOS!$E:$E,$O16,OFÍCIOS!$G:$G,"PENDENCIA") -> 0 | T16: =COUNTIFS(OFÍCIOS!$E:$E,$O16,OFÍCIOS!$G:$G,"") -> 0 | U16: =SUM(Q16:T16) -> 4
A17: ADEILDO ADELINO DE CARVALHO | B17: 57455392591 | O17: 1470 | P17: =COUNTIF(OFÍCIOS!E:E,O17) -> 4 | Q17: =COUNTIFS(OFÍCIOS!$E:$E,$O17,OFÍCIOS!$G:$G,"APROVADO") -> 4 | R17: =COUNTIFS(OFÍCIOS!$E:$E,$O17,OFÍCIOS!$G:$G,"REPROVADO") -> 0 | S17: =COUNTIFS(OFÍCIOS!$E:$E,$O17,OFÍCIOS!$G:$G,"PENDENCIA") -> 0 | T17: =COUNTIFS(OFÍCIOS!$E:$E,$O17,OFÍCIOS!$G:$G,"") -> 0 | U17: =SUM(Q17:T17) -> 4
A18: ADELCIDES DA CONCEICAO ALMEIDA | B18: 5304941594 | E18: 1106 | F18: 42965 | G18: APROVADO | H18: 42978 | O18: 1489 | P18: =COUNTIF(OFÍCIOS!E:E,O18) -> 35 | Q18: =COUNTIFS(OFÍCIOS!$E:$E,$O18,OFÍCIOS!$G:$G,"APROVADO") -> 34 | R18: =COUNTIFS(OFÍCIOS!$E:$E,$O18,OFÍCIOS!$G:$G,"REPROVADO") -> 0 | S18: =COUNTIFS(OFÍCIOS!$E:$E,$O18,OFÍCIOS!$G:$G,"PENDENCIA") -> 1 | T18: =COUNTIFS(OFÍCIOS!$E:$E,$O18,OFÍCIOS!$G:$G,"") -> 0 | U18: =SUM(Q18:T18) -> 35
A19: ADELIA MARIA DE OLIVEIRA | B19: 21600057896 | E19: 262 | F19: 43160 | G19: REPROVADO | H19: 43164 | L19: 255 | O19: 1555 | P19: =COUNTIF(OFÍCIOS!E:E,O19) -> 25 | Q19: =COUNTIFS(OFÍCIOS!$E:$E,$O19,OFÍCIOS!$G:$G,"APROVADO") -> 22 | R19: =COUNTIFS(OFÍCIOS!$E:$E,$O19,OFÍCIOS!$G:$G,"REPROVADO") -> 1 | S19: =COUNTIFS(OFÍCIOS!$E:$E,$O19,OFÍCIOS!$G:$G,"PENDENCIA") -> 2 | T19: =COUNTIFS(OFÍCIOS!$E:$E,$O19,OFÍCIOS!$G:$G,"") -> 0 | U19: =SUM(Q19:T19) -> 25
A20: ADEMARIO FERREIRA DOS SANTOS | B20: 18419589802 | O20: 1570 | P20: =COUNTIF(OFÍCIOS!E:E,O20) -> 24 | Q20: =COUNTIFS(OFÍCIOS!$E:$E,$O20,OFÍCIOS!$G:$G,"APROVADO") -> 23 | R20: =COUNTIFS(OFÍCIOS!$E:$E,$O20,OFÍCIOS!$G:$G,"REPROVADO") -> 1 | S20: =COUNTIFS(OFÍCIOS!$E:$E,$O20,OFÍCIOS!$G:$G,"PENDENCIA") -> 0 | T20: =COUNTIFS(OFÍCIOS!$E:$E,$O20,OFÍCIOS!$G:$G,"") -> 0 | U20: =SUM(Q20:T20) -> 24
A21: ADEMIR DA SILVA LIMA | B21: 15538537846 | E21: 573 | F21: 43224 | O21: 1752 | P21: =COUNTIF(OFÍCIOS!E:E,O21) -> 89 | Q21: =COUNTIFS(OFÍCIOS!$E:$E,$O21,OFÍCIOS!$G:$G,"APROVADO") -> 80 | R21: =COUNTIFS(OFÍCIOS!$E:$E,$O21,OFÍCIOS!$G:$G,"REPROVADO") -> 2 | S21: =COUNTIFS(OFÍCIOS!$E:$E,$O21,OFÍCIOS!$G:$G,"PENDENCIA") -> 5 | T21: =COUNTIFS(OFÍCIOS!$E:$E,$O21,OFÍCIOS!$G:$G,"") -> 2 | U21: =SUM(Q21:T21) -> 89
A22: ADENILDE SANTOS DA SILVA | B22: 899837506 | E22: 1824 | F22: 43091 | G22: APROVADO | H22: 43097 | L22: 1828 | O22: 1824 | P22: =COUNTIF(OFÍCIOS!E:E,O22) -> 81 | Q22: =COUNTIFS(OFÍCIOS!$E:$E,$O22,OFÍCIOS!$G:$G,"APROVADO") -> 67 | R22: =COUNTIFS(OFÍCIOS!$E:$E,$O22,OFÍCIOS!$G:$G,"REPROVADO") -> 7 | S22: =COUNTIFS(OFÍCIOS!$E:$E,$O22,OFÍCIOS!$G:$G,"PENDENCIA") -> 6 | T22: =COUNTIFS(OFÍCIOS!$E:$E,$O22,OFÍCIOS!$G:$G,"") -> 1 | U22: =SUM(Q22:T22) -> 81
A23: ADENILSON DA CONCEICAO | B23: 36197160803 | E23: 229 | F23: 43151 | G23: APROVADO | L23: 232 | O23: 1628 | P23: =COUNTIF(OFÍCIOS!E:E,O23) -> 6 | Q23: =COUNTIFS(OFÍCIOS!$E:$E,$O23,OFÍCIOS!$G:$G,"APROVADO") -> 5 | R23: =COUNTIFS(OFÍCIOS!$E:$E,$O23,OFÍCIOS!$G:$G,"REPROVADO") -> 1 | S23: =COUNTIFS(OFÍCIOS!$E:$E,$O23,OFÍCIOS!$G:$G,"PENDENCIA") -> 0 | T23: =COUNTIFS(OFÍCIOS!$E:$E,$O23,OFÍCIOS!$G:$G,"") -> 0 | U23: =SUM(Q23:T23) -> 6
A24: ADENIR MODESTO RIBEIRO | B24: 39248826814 | E24: 292 | F24: 43168 | G24: APROVADO | H24: 43182 | L24: 318 | O24: 608 | P24: =COUNTIF(OFÍCIOS!E:E,O24) -> 35 | Q24: =COUNTIFS(OFÍCIOS!$E:$E,$O24,OFÍCIOS!$G:$G,"APROVADO") -> 31 | R24: =COUNTIFS(OFÍCIOS!$E:$E,$O24,OFÍCIOS!$G:$G,"REPROVADO") -> 3 | S24: =COUNTIFS(OFÍCIOS!$E:$E,$O24,OFÍCIOS!$G:$G,"PENDENCIA") -> 1 | T24: =COUNTIFS(OFÍCIOS!$E:$E,$O24,OFÍCIOS!$G:$G,"") -> 0 | U24: =SUM(Q24:T24) -> 35
A25: ADILINA FARIAS DO NASCIMENTO | B25: 48925276534 | E25: 229 | F25: 43151 | L25: 232 | O25: 527 | P25: =COUNTIF(OFÍCIOS!E:E,O25) -> 29 | Q25: =COUNTIFS(OFÍCIOS!$E:$E,$O25,OFÍCIOS!$G:$G,"APROVADO") -> 0 | R25: =COUNTIFS(OFÍCIOS!$E:$E,$O25,OFÍCIOS!$G:$G,"REPROVADO") -> 0 | S25: =COUNTIFS(OFÍCIOS!$E:$E,$O25,OFÍCIOS!$G:$G,"PENDENCIA") -> 0 | T25: =COUNTIFS(OFÍCIOS!$E:$E,$O25,OFÍCIOS!$G:$G,"") -> 29 | U25: =SUM(Q25:T25) -> 29
A26: ADILSON SOARES DA COSTA | O26: 509 | P26: =COUNTIF(OFÍCIOS!E:E,O26) -> 14 | Q26: =COUNTIFS(OFÍCIOS!$E:$E,$O26,OFÍCIOS!$G:$G,"APROVADO") -> 0 | R26: =COUNTIFS(OFÍCIOS!$E:$E,$O26,OFÍCIOS!$G:$G,"REPROVADO") -> 0 | S26: =COUNTIFS(OFÍCIOS!$E:$E,$O26,OFÍCIOS!$G:$G,"PENDENCIA") -> 0 | T26: =COUNTIFS(OFÍCIOS!$E:$E,$O26,OFÍCIOS!$G:$G,"") -> 14 | U26: =SUM(Q26:T26) -> 14
A27: ADMEIA BARBOSA DE SOUZA | B27: 25894152810 | C27: REINALDO SANTOS REIS | D27: 8263008808 | E27: 292 | F27: 43168 | G27: APROVADO | H27: 43182 | L27: 318 | O27: 292 | P27: =COUNTIF(OFÍCIOS!E:E,O27) -> 233 | Q27: =COUNTIFS(OFÍCIOS!$E:$E,$O27,OFÍCIOS!$G:$G,"APROVADO") -> 212 | R27: =COUNTIFS(OFÍCIOS!$E:$E,$O27,OFÍCIOS!$G:$G,"REPROVADO") -> 9 | S27: =COUNTIFS(OFÍCIOS!$E:$E,$O27,OFÍCIOS!$G:$G,"PENDENCIA") -> 0 | T27: =COUNTIFS(OFÍCIOS!$E:$E,$O27,OFÍCIOS!$G:$G,"") -> 12 | U27: =SUM(Q27:T27) -> 233
A28: ADONES FERREIRA JORGE | B28: 43026389587 | C28: EUNICE FELICIANA BRITO JORGE | D28: 29124464813 | E28: 485 | F28: 43196 | H28: 43206 | L28: 483 | O28: 573 | P28: =COUNTIF(OFÍCIOS!E:E,O28) -> 43 | Q28: =COUNTIFS(OFÍCIOS!$E:$E,$O28,OFÍCIOS!$G:$G,"APROVADO") -> 0 | R28: =COUNTIFS(OFÍCIOS!$E:$E,$O28,OFÍCIOS!$G:$G,"REPROVADO") -> 0 | S28: =COUNTIFS(OFÍCIOS!$E:$E,$O28,OFÍCIOS!$G:$G,"PENDENCIA") -> 0 | T28: =COUNTIFS(OFÍCIOS!$E:$E,$O28,OFÍCIOS!$G:$G,"") -> 43 | U28: =SUM(Q28:T28) -> 43
A29: ADRIANA ALVES DA SILVA | B29: 26245112885 | E29: 262 | F29: 43160 | G29: REPROVADO | H29: 43164 | L29: 255 | O29: 563 | P29: =COUNTIF(OFÍCIOS!E:E,O29) -> 64 | Q29: =COUNTIFS(OFÍCIOS!$E:$E,$O29,OFÍCIOS!$G:$G,"APROVADO") -> 0 | R29: =COUNTIFS(OFÍCIOS!$E:$E,$O29,OFÍCIOS!$G:$G,"REPROVADO") -> 0 | S29: =COUNTIFS(OFÍCIOS!$E:$E,$O29,OFÍCIOS!$G:$G,"PENDENCIA") -> 0 | T29: =COUNTIFS(OFÍCIOS!$E:$E,$O29,OFÍCIOS!$G:$G,"") -> 64 | U29: =SUM(Q29:T29) -> 64
A30: ADRIANA ALVES FERREIRA | B30: 36531080809 | C30: MARCIO ROSA DE MIRA | D30: 22485483892 | E30: 1489 | F30: 43038 | G30: APROVADO | L30: 1647-17 | O30: 443 | P30: =COUNTIF(OFÍCIOS!E:E,O30) -> 66 | Q30: =COUNTIFS(OFÍCIOS!$E:$E,$O30,OFÍCIOS!$G:$G,"APROVADO") -> 0 | R30: =COUNTIFS(OFÍCIOS!$E:$E,$O30,OFÍCIOS!$G:$G,"REPROVADO") -> 0 | S30: =COUNTIFS(OFÍCIOS!$E:$E,$O30,OFÍCIOS!$G:$G,"PENDENCIA") -> 0 | T30: =COUNTIFS(OFÍCIOS!$E:$E,$O30,OFÍCIOS!$G:$G,"") -> 66 | U30: =SUM(Q30:T30) -> 66
A31: ADRIANA APARECIDA ROBERTO | B31: 28147186819 | C31: CARLOS ANTONIO BATISTA DOS SANTOS | D31: 24499714400 | O31: 423 | P31: =COUNTIF(OFÍCIOS!E:E,O31) -> 9 | Q31: =COUNTIFS(OFÍCIOS!$E:$E,$O31,OFÍCIOS!$G:$G,"APROVADO") -> 7 | R31: =COUNTIFS(OFÍCIOS!$E:$E,$O31,OFÍCIOS!$G:$G,"REPROVADO") -> 1 | S31: =COUNTIFS(OFÍCIOS!$E:$E,$O31,OFÍCIOS!$G:$G,"PENDENCIA") -> 0 | T31: =COUNTIFS(OFÍCIOS!$E:$E,$O31,OFÍCIOS!$G:$G,"") -> 1 | U31: =SUM(Q31:T31) -> 9
A32: ADRIANA ARAUJO DE LIMA | B32: 37559228860 | C32: ALEXANDRO ARAUJO DE LIMA | D32: 28072024892 | E32: 1555 | F32: 43049 | G32: APROVADO | O32: 229 | P32: =COUNTIF(OFÍCIOS!E:E,O32) -> 89 | Q32: =COUNTIFS(OFÍCIOS!$E:$E,$O32,OFÍCIOS!$G:$G,"APROVADO") -> 81 | R32: =COUNTIFS(OFÍCIOS!$E:$E,$O32,OFÍCIOS!$G:$G,"REPROVADO") -> 2 | S32: =COUNTIFS(OFÍCIOS!$E:$E,$O32,OFÍCIOS!$G:$G,"PENDENCIA") -> 5 | T32: =COUNTIFS(OFÍCIOS!$E:$E,$O32,OFÍCIOS!$G:$G,"") -> 1 | U32: =SUM(Q32:T32) -> 89
A33: ADRIANA CORDEIRO MACHADO | B33: 23635229822 | C33: ANDERSON DE MORAIS SANTOS | D33: 21668057875 | E33: 262 | F33: 43160 | G33: APROVADO | H33: 43164 | L33: 255 | O33: 262 | P33: =COUNTIF(OFÍCIOS!E:E,O33) -> 224 | Q33: =COUNTIFS(OFÍCIOS!$E:$E,$O33,OFÍCIOS!$G:$G,"APROVADO") -> 181 | R33: =COUNTIFS(OFÍCIOS!$E:$E,$O33,OFÍCIOS!$G:$G,"REPROVADO") -> 15 | S33: =COUNTIFS(OFÍCIOS!$E:$E,$O33,OFÍCIOS!$G:$G,"PENDENCIA") -> 0 | T33: =COUNTIFS(OFÍCIOS!$E:$E,$O33,OFÍCIOS!$G:$G,"") -> 28 | U33: =SUM(Q33:T33) -> 224
A34: ADRIANA DA SILVA | O34: 117 | P34: =COUNTIF(OFÍCIOS!E:E,O34) -> 91 | Q34: =COUNTIFS(OFÍCIOS!$E:$E,$O34,OFÍCIOS!$G:$G,"APROVADO") -> 77 | R34: =COUNTIFS(OFÍCIOS!$E:$E,$O34,OFÍCIOS!$G:$G,"REPROVADO") -> 7 | S34: =COUNTIFS(OFÍCIOS!$E:$E,$O34,OFÍCIOS!$G:$G,"PENDENCIA") -> 5 | T34: =COUNTIFS(OFÍCIOS!$E:$E,$O34,OFÍCIOS!$G:$G,"") -> 2 | U34: =SUM(Q34:T34) -> 91
A35: ADRIANA DA SILVA SANTOS | B35: 40902634844 | C35: GUILHERME DE OLIVEIRA SOUZA | D35: 23795007895 | E35: 117 | F35: 43117 | G35: APROVADO | H35: 43151 | L35: 118-18 | O35: 485 | P35: =COUNTIF(OFÍCIOS!E:E,O35) -> 23 | Q35: =COUNTIFS(OFÍCIOS!$E:$E,$O35,OFÍCIOS!$G:$G,"APROVADO") -> 0 | R35: =COUNTIFS(OFÍCIOS!$E:$E,$O35,OFÍCIOS!$G:$G,"REPROVADO") -> 3 | S35: =COUNTIFS(OFÍCIOS!$E:$E,$O35,OFÍCIOS!$G:$G,"PENDENCIA") -> 0 | T35: =COUNTIFS(OFÍCIOS!$E:$E,$O35,OFÍCIOS!$G:$G,"") -> 20 | U35: =SUM(Q35:T35) -> 23
A36: ADRIANA DE SA ROCHA | B36: 39615629898 | C36: MARCELO FERNANDES LIMA | D36: 43328275894 | E36: 423 | F36: 43182 | G36: APROVADO | O36: 85 | P36: =COUNTIF(OFÍCIOS!E:E,O36) -> 93 | Q36: =COUNTIFS(OFÍCIOS!$E:$E,$O36,OFÍCIOS!$G:$G,"APROVADO") -> 86 | R36: =COUNTIFS(OFÍCIOS!$E:$E,$O36,OFÍCIOS!$G:$G,"REPROVADO") -> 4 | S36: =COUNTIFS(OFÍCIOS!$E:$E,$O36,OFÍCIOS!$G:$G,"PENDENCIA") -> 3 | T36: =COUNTIFS(OFÍCIOS!$E:$E,$O36,OFÍCIOS!$G:$G,"") -> 0 | U36: =SUM(Q36:T36) -> 93
A37: ADRIANA DOS SANTOS | P37: =COUNTIF(OFÍCIOS!E:E,O37) -> 0 | Q37: =COUNTIFS(OFÍCIOS!$E:$E,$O37,OFÍCIOS!$G:$G,"APROVADO") -> 0 | R37: =COUNTIFS(OFÍCIOS!$E:$E,$O37,OFÍCIOS!$G:$G,"REPROVADO") -> 0 | S37: =COUNTIFS(OFÍCIOS!$E:$E,$O37,OFÍCIOS!$G:$G,"PENDENCIA") -> 0 | T37: =COUNTIFS(OFÍCIOS!$E:$E,$O37,OFÍCIOS!$G:$G,"") -> 0 | U37: =SUM(Q37:T37) -> 0
A38: ADRIANA FERREIRA DA SILVA | C38: LOURIVAL CANDIDO SILVA | P38: =COUNTIF(OFÍCIOS!E:E,O38) -> 0 | Q38: =COUNTIFS(OFÍCIOS!$E:$E,$O38,OFÍCIOS!$G:$G,"APROVADO") -> 0 | R38: =COUNTIFS(OFÍCIOS!$E:$E,$O38,OFÍCIOS!$G:$G,"REPROVADO") -> 0 | S38: =COUNTIFS(OFÍCIOS!$E:$E,$O38,OFÍCIOS!$G:$G,"PENDENCIA") -> 0 | T38: =COUNTIFS(OFÍCIOS!$E:$E,$O38,OFÍCIOS!$G:$G,"") -> 0 | U38: =SUM(Q38:T38) -> 0
A39: ADRIANA HELENA DE MORAIS | B39: 14268808809 | E39: 262 | F39: 43160 | G39: APROVADO | H39: 43164 | L39: 255 | P39: =COUNTIF(OFÍCIOS!E:E,O39) -> 0 | Q39: =COUNTIFS(OFÍCIOS!$E:$E,$O39,OFÍCIOS!$G:$G,"APROVADO") -> 0 | R39: =COUNTIFS(OFÍCIOS!$E:$E,$O39,OFÍCIOS!$G:$G,"REPROVADO") -> 0 | S39: =COUNTIFS(OFÍCIOS!$E:$E,$O39,OFÍCIOS!$G:$G,"PENDENCIA") -> 0 | T39: =COUNTIFS(OFÍCIOS!$E:$E,$O39,OFÍCIOS!$G:$G,"") -> 0 | U39: =SUM(Q39:T39) -> 0
A40: ADRIANA JESUS DA CUNHA | B40: 29628693867 | E40: 292 | F40: 43168 | G40: APROVADO | H40: 43182 | L40: 318 | P40: =COUNTIF(OFÍCIOS!E:E,O40) -> 0 | Q40: =COUNTIFS(OFÍCIOS!$E:$E,$O40,OFÍCIOS!$G:$G,"APROVADO") -> 0 | R40: =COUNTIFS(OFÍCIOS!$E:$E,$O40,OFÍCIOS!$G:$G,"REPROVADO") -> 0 | S40: =COUNTIFS(OFÍCIOS!$E:$E,$O40,OFÍCIOS!$G:$G,"PENDENCIA") -> 0 | T40: =COUNTIFS(OFÍCIOS!$E:$E,$O40,OFÍCIOS!$G:$G,"") -> 0 | U40: =SUM(Q40:T40) -> 0
...

Sheet Planilha2
M2: 6014.2022/0003314-1 | R2: SELO | S2: PROPRIETÁRIO | T2: CPF
B3: PARAISÓPOLIS/ANTONICO | C3: 4 | D3: 029/0023/B | E3: FRANCISCO WILLIAN GOMES DO NASCIMENTO | F3: 58.276.710-6 | G3: 519.576.918-40 | M3: 6014.2022/0003318-4 | R3: 025/0005/D | S3: DAIANA DE MOURA BATISTA | T3: 465.961.548-07
B4: PARAISÓPOLIS/ANTONICO | C4: 4 | D4: 029/0036/G | E4: JANAINA SANTOS DE MELO | F4: 52.949.011-0 | G4: 417.618.098-65 | M4: 6014.2022/0003489-0 | R4: 025/0005/F | S4: ALESSANDRA CLEMENTE DA SILVA | T4: 383.679.488-82
B5: PARAISÓPOLIS/ANTONICO | C5: 4 | D5: 029/0036/H | E5: DJAILSON FREITAS DE LIMA | F5: 57.410.954-7 | G5: 105.534.934-00 | M5: 6014.2022/0003413-0 | R5: 025/0006/E | S5: LUANA CANDIDA DA SILVA | T5: 422.356.908/23
B6: PARAISÓPOLIS/ANTONICO | C6: 4 | D6: 029/0043/B | E6: MARIVANEIDE MOREIRA SILVA | F6: 50.175.775-2 | G6: 371.473.818-58 | M6: 6014.2022/0003286-2 | R6: 025/0007/B | S6: MARIANA PEREIRA DUARTE | T6: 484.098.078-07
B7: PARAISÓPOLIS/ANTONICO | C7: 4 | D7: 029/0049/A | E7: FLAVIA SANTOS SOUZA | F7: 49.345.172-9 | G7: 435.377.298-80 | M7: 6014.2022/0003320-6 | R7: 025/0010/C | S7: CLOVIS RODRIGUES DA SILVA | T7: 060.045.884-90
B8: PARAISÓPOLIS/ANTONICO | C8: 4 | D8: 029/0055/A | E8: GLEICON CARLOS CESAR GOMES | F8: 49.183.499-8 | G8: 344.351.508-83 | M8: 6014.2022/0002870-9 | R8: 025/0012/B | S8: JAQUELINE DE JESUS SANTOS | T8: 057.048.705-62
B9: PARAISÓPOLIS/ANTONICO | C9: 4 | D9: 029/0056/A | E9: MARIA GERLANE DE SOUZA BOÍBA | F9: 57.816.422-X | G9: 494.665.018-01 | M9: 6014.2022/0003634-5 | R9: 025/0013/D | S9: MARLENE PORTO DA SILVA | T9: 324.983.298-70
B10: PARAISÓPOLIS/ANTONICO | C10: 4 | D10: 029/0056/B | E10: MAICO JONHATAS ALVARES PINTO | F10: 53.032.399-0 | G10: 428.355.978-40 | M10: 6014.2022/0003262-5 | R10: 025/0022/A | S10: VERA LUCIA SILVA | T10: 191.039.398-39
B11: PARAISÓPOLIS/ANTONICO | C11: 4 | D11: 029/0085/F | E11: ORLANDO CONCEIÇÃO SANTIAGO | F11: 41.041.836-5 | G11: 353.178.248-77 | M11: 6014.2022/0003332-0 | R11: 027/0004/B | S11: GILMARIO RODRIGUES FERREIRA | T11: 313.783.998-03
M12: 6014.2022/0003263-3 | R12: 027/0005/A | S12: JOSÉ LAILTON DOS SANTOS | T12: 406.718.788-24
D13: 024/0041/D | E13: MARICÉLIA OLIMPIO DE OLIVEIRA | M13: 6014.2022/0003352-4 | R13: 027/0005/C | S13: CARLITO IZIDORIO BISPO | T13: 022.817.018-40
D14: 024/0069/A | E14: LOURISMAR LIMA BRAGA | M14: 6014.2022/0003161-0 | R14: 027/0005/D | S14: MATEUS LEITE DE MELO | T14: 102.388.884-01
M15: 6014.2022/0002739-7 | R15: 027/0005/F | S15: CRISTIAN DE JESUS DIAS | T15: 101.526.245-70
M16: 6014.2022/0003157-2 | R16: 027/0005/G | S16: VINICIUS LINS MELO | T16: 509.886.698-70
M17: 6014.2022/0003160-2 | R17: 027/0005/H | S17: CRICIELTON MARQUES DA SILVA PEREIRA | T17: 482.097.038-03
M18: 6014.2022/0003353-2 | R18: 027/0005/I | S18: LUCAS ALVES DE ANDRADE FERREIRA | T18: 469.732.328-92
E19: 6014.2022/0002993-4 | M19: 6014.2022/0002844-0 | R19: 027/0005/J | S19: LUIS HENRIQUE DE CARVALHO BARBOSA | T19: 506.599.238-07
E20: 6014.2022/0003157-2 | M20: 6014.2022/0002952-7 | R20: 027/0006/A | S20: NILANDE DA SILVA SOUZA | T20: 333.539.708-86
E21: 6014.2022/0002667-6 | M21: 6014.2022/0003496-2 | R21: 027/0016/A | S21: DANILO DA SILVA MIRANDA | T21: 432.676.048-69
M22: 6014.2022/0002687-0 | R22: 027/0016/B | S22: EDNADYJA ANDRELLI VITAL | T22: 371.476.568-90
M23: 6014.2022/0002677-3 | R23: 027/0016/C | S23: SEVERINO MIRANDA DE SOUSA | T23: 170.908.718-86
M24: 6014.2022/0003638-8 | R24: 027/0016/D | S24: VALMIRA SILVA ARAUJO | T24: 014.002.428-00
M25: 6014.2022/0002747-8 | R25: 027/0018/C | S25: LUCILÉIA DE ARAUJO LIMA | T25: 282.762.598-98
M26: 6014.2022/0003196-3 | R26: 027/0018/D | S26: REGINALDO NASCIMENTO DA SILVA | T26: 157.653.378-64
M27: 6014.2022/0002665-0 | R27: 027/0018/F | S27: ALBERT DE ARAUJO KELLER | T27: 435.878.808-40
M28: 6014.2022/0003497-0 | R28: 027/0018/H | S28: CRISTIANE DE ARAÚJO KELLER | T28: 403.961.018-01
M29: 6014.2022/0002834-2 | R29: 027/0019/A | S29: DANIELA MARIA DE JESUS | T29: 330.092.718-83
M30: 6014.2022/0003298-6
M31: 6014.2022/0002673-0
M32: 6014.2022/0002683-8
M33: 6014.2022/0003261-7
M34: 6014.2022/0002679-0
M35: 6014.2022/0002894-6
M36: 6014.2022/0002901-2
M37: 6014.2022/0002681-1
M38: 6014.2022/0003047-9
M39: 6014.2022/0003641-8
M40: 6014.2022/0003347-8
M41: 6014.2022/0003350-8
...

Sheet Planilha3
B3: ÁREA | C3: SELO | D3: PROPRIETÁRIO | E3: CPF | F3: PROCESSO | G3: STATUS ATUAL
B4: ESPERANÇA | C4: 002/0013/A | D4: WILLIAM DE LIMA DOS SANTOS | E4: 401.616.058-85 | F4: 6014.2024/0005868-7
B12: PARAISÓPOLIS/ANTONICO | C12: 024/0047/F | D12: ROSA HELENA DE SOUZA | E12: 291.466.998-48 | F12: RECUSA
B13: PARAISÓPOLIS/ANTONICO | C13: 024/0053/A | D13: SELMA SOARES SANTOS DE OLIVEIRA | E13: 324.973.128-50 | F13: RECUSA
B14: PARAISÓPOLIS/ANTONICO | C14: 024/0071/B | D14: LUANA BRITO | E14: 021.848.845-96 | F14: RECUSA
B15: PARAISÓPOLIS/ANTONICO | C15: 024/0071/C | D15: JOSE FRANCISCO DIAS SOUSA | E15: 000.683.393-48 | F15: RECUSA
B16: PARAISÓPOLIS/ANTONICO | C16: 024/0075/B | D16: MANOEL ANTONIO DE LIMA | E16: 259.336.715-68 | F16: RECUSA
B17: PARAISÓPOLIS/ANTONICO | C17: 024/0076/A | D17: MÁRCIA PANTALEÃO DA SILVA | E17: 265.751.438-30 | F17: ESTUDO DE CASO
B18: PARAISÓPOLIS/ANTONICO | C18: 024/0076/B | D18: MÁRCIA PANTALEÃO DA SILVA | E18: 265.751.438-30 | F18: ESTUDO DE CASO
B19: PARAISÓPOLIS/ANTONICO | C19: 024/0076/C | D19: MÁRCIA PANTALEÃO DA SILVA | E19: 265.751.438-30 | F19: ESTUDO DE CASO
B20: PARAISÓPOLIS/ANTONICO | C20: 024/0077/A | D20: PROPRIETÁRIO NÃO IDENTIFICADO | F20: RECUSA
B21: PARAISÓPOLIS/ANTONICO | C21: 024/0077/B | D21: LUCIANA FRANCILINO DE LIMA | E21: 296.566.438-60 | F21: RECUSA
B22: PARAISÓPOLIS/ANTONICO | C22: 024/0079/B | D22: ANOILSON SANTOS GOMES | E22: 352.811.788-57 | F22: RECUSA
B23: PARAISÓPOLIS/ANTONICO | C23: 024/0079/D | D23: EUDES GONÇALVES CAVALCANTE | E23: 064.025.638-46 | F23: ESTUDO DE CASO
B24: PARAISÓPOLIS/ANTONICO | C24: 024/0079/E | D24: DANIELE COSTA | E24: 374.435.458-00 | F24: ESTUDO DE CASO
B25: PARAISÓPOLIS/ANTONICO | C25: 024/0079/F | F25: ESTUDO DE CASO
B26: PARAISÓPOLIS/ANTONICO | C26: 024/0079/G | D26: EUDES GONÇALVES CAVALCANTI | E26: 064.025.638-46 | F26: ESTUDO DE CASO
B27: PARAISÓPOLIS/ANTONICO | C27: 024/0079/J | D27: ELIO NEVES DE SOUZA | E27: 350.318.858-40 | F27: RECUSA
B28: PARAISÓPOLIS/ANTONICO | C28: 024/0082/A | D28: IVÃ CERQUEIRA LENARES | E28: 006.868.775-35 | F28: PENDENTE
B29: PARAISÓPOLIS/ANTONICO | C29: 024/0082/D | D29: JOÃO VITOR DE SANTANA | E29: 534.193.048-70 | F29: ESTUDO DE CASO
B30: PARAISÓPOLIS/ANTONICO | C30: 024/0088/K | D30: MARIA APARECIDA FLECKENSTEIN VIEIRA | E30: 304.821.048-21 | F30: ESTUDO DE CASO
B31: PARAISÓPOLIS/ANTONICO | C31: 024/0088/M | D31: PROPRIETÁRIO NÃO IDENTIFICADO | E31: N/A | F31: PROPRIETÁRIO NÃO IDENTIFICADO
B32: PARAISÓPOLIS/ANTONICO | C32: 027/0002/E | F32: PROPRIETÁRIO NÃO IDENTIFICADO
B33: PARAISÓPOLIS/ANTONICO | C33: 027/0012/C | F33: PROPRIETÁRIO NÃO IDENTIFICADO

Sheet Planilha4
B2: 20 | C2: ÁRVORE SÃO TOMÁS | D2: 1 | E2: - | F2: - | G2: 003/0057/A | H2: OCUPADO | I2: RESIDENCIAL | J2: INQUILINO | K2: JOYCE DA SILVA PINTO | L2: 49.297.973-X | M2: 437.747.388-31 | N2: CADASTRADO | O2: AUXÍLIO ALUGUEL UH | P2: 45210 | Q2: 45210 | R2: 6014.2023/0003397-6 | S2: FINALIZADO | T2: FINALIZADO | U2: FINALIZADO | V2: 45267 | W2: FINALIZADO | X2: FINALIZADO | Y2: 45280 | Z2: 45281 | AA2: 45307 | AC2: CLÁUDIO VENTURA MACHADO | AD2: 54.530.310-2 | AE2: 430.448.778-45 | AF2: PROPRIETÁRIO RESIDENTE | AG2: R$ 47.240,74 | AH2: R$ 60.000,00 | AI2: UH | AJ2: FINALIZADO | AK2: CADASTRADO | AL2: N/A | AM2: N/A | AN2: N/A | AP2: N/A | AQ2: N/A | AR2: N/A | AS2: N/A | AT2: N/A | AU2: N/A | AV2: N/A | AW2: N/A | AX2: =Y2 -> 45280 | AY2: =Z2 -> 45281 | AZ2: 45307 | BA2: DEMOLIDO | BB2: FINALIZADO
B3: 21 | C3: ÁRVORE SÃO TOMÁS | D3: 1 | E3: - | F3: - | G3: 003/0057/A | H3: OCUPADO | I3: RESIDENCIAL | J3: PROPRIETÁRIO NÃO RESIDENTE | K3: CLAUDIO VENTURA MACHADO | L3: 54.530.310-2 | M3: 430.448.788-45 | N3: CADASTRADO | O3: INDENIZAÇÃO | P3: 45226 | Q3: N/A | R3: N/A | S3: N/A | T3: N/A | U3: N/A | V3: N/A | W3: N/A | X3: N/A | Y3: N/A | Z3: N/A | AA3: N/A | AC3: CLÁUDIO VENTURA MACHADO | AD3: 54.530.310-2 | AE3: 430.448.778-45 | AF3: PROPRIETÁRIO NÃO RESIDENTE | AG3: R$ 47.240,74 | AH3: R$ 60.000,00 | AI3: SIM | AJ3: FINALIZADO | AK3: CADASTRADO | AL3: FINALIZADO | AM3: FINALIZADO | AN3: SEM PENDÊNCIA | AP3: 6014.2023/0004914-7 | AQ3: FINALIZADO | AR3: FINALIZADO | AS3: FINALIZADO | AT3: FINALIZADO | AU3: 45282 | AV3: FINALIZADO | AW3: FINALIZADO | AX3: 45295 | AY3: 45300 | AZ3: 45307 | BA3: DEMOLIDO | BB3: FINALIZADO
C6: ORDEM | D6: SELO | E6: DATA PAGAMENTO | F6: DATA ENTREGA IMÓVEL | G6: SITUAÇÃO ATUAL IMÓVEL
C7: 1 | D7: 024/0049/B | E7: 45068 | F7: AGUARDANDO | G7: LIBERADO DEMOLIÇÃO
C8: 2 | D8: 029/0036/O | E8: 45068 | F8: AGUARDANDO | G8: LIBERADO DEMOLIÇÃO
C9: 3 | D9: 031/0028/D | E9: 45068 | F9: 44894 | G9: DESCARACTERIZADO
C10: 4 | D10: 031/0034/H | E10: 45068 | F10: AGUARDANDO | G10: LIBERADO DEMOLIÇÃO
C11: 5 | D11: 024/0093/B | E11: 45065 | F11: AGUARDANDO | G11: LIBERADO DEMOLIÇÃO
C12: 6 | D12: 029/0036/P | E12: 45065 | F12: AGUARDANDO | G12: LIBERADO DEMOLIÇÃO
C13: 7 | D13: 029/0042/A | E13: 45065 | F13: AGUARDANDO | G13: LIBERADO DEMOLIÇÃO
C14: 8 | D14: 029/0081/A | E14: 45065 | F14: 44526 | G14: DEMOLIDO
C15: 9 | D15: 029/0083/A | E15: 45065 | F15: 44642 | G15: DEMOLIDO
C16: 10 | D16: 031/0020/B | E16: 45065 | F16: 44694 | G16: DESCARACTERIZADO
C17: 11 | D17: 031/0023/B | E17: 45065 | F17: AGUARDANDO | G17: LIBERADO DEMOLIÇÃO
C18: 12 | D18: 031/0024/A | E18: 45065 | F18: 44659 | G18: DESCARACTERIZADO
C19: 13 | D19: 024/0079/A | E19: 45064 | F19: AGUARDANDO | G19: LIBERADO DEMOLIÇÃO
C20: 14 | D20: 024/0082/H | E20: 45064 | F20: AGUARDANDO | G20: LIBERADO DEMOLIÇÃO
C21: 15 | D21: 029/0022/A | E21: 45064 | F21: AGUARDANDO | G21: LIBERADO DEMOLIÇÃO
C22: 16 | D22: 029/0022/D | E22: 45064 | F22: AGUARDANDO | G22: LIBERADO DEMOLIÇÃO
C23: 17 | D23: 029/0035/A | E23: 45064 | F23: 44859 | G23: DEMOLIDO
C24: 18 | D24: 029/0036/L | E24: 45064 | F24: AGUARDANDO | G24: LIBERADO DEMOLIÇÃO
C25: 19 | D25: 029/0036/N | E25: 45064 | F25: AGUARDANDO | G25: LIBERADO DEMOLIÇÃO
C26: 20 | D26: 031/0035/A | E26: 45064 | F26: 44643 | G26: DESCARACTERIZADO
C27: 21 | D27: 031/0035/F | E27: 45064 | F27: 44638 | G27: DESCARACTERIZADO
C28: 22 | D28: 031/0058/E | E28: 45064 | F28: AGUARDANDO | G28: LIBERADO DEMOLIÇÃO
C29: 23 | D29: 031/0058/H | E29: 45064 | F29: AGUARDANDO | G29: LIBERADO DEMOLIÇÃO
C30: 24 | D30: 031/0078/G | E30: 45064 | F30: AGUARDANDO | G30: LIBERADO DEMOLIÇÃO
C31: 25 | D31: 024/0004/B | E31: 45063 | F31: AGUARDANDO | G31: LIBERADO DEMOLIÇÃO
C32: 26 | D32: 024/0050/B | E32: 45063 | F32: AGUARDANDO | G32: LIBERADO DEMOLIÇÃO
C33: 27 | D33: 024/0074/A | E33: 45063 | F33: AGUARDANDO | G33: LIBERADO DEMOLIÇÃO
C34: 28 | D34: 024/0074/D | E34: 45063 | F34: AGUARDANDO | G34: LIBERADO DEMOLIÇÃO
C35: 29 | D35: 024/0078/B | E35: 45063 | F35: AGUARDANDO | G35: LIBERADO DEMOLIÇÃO
C36: 30 | D36: 024/0082/C | E36: 45063 | F36: AGUARDANDO | G36: LIBERADO DEMOLIÇÃO
C37: 31 | D37: 024/0093/A | E37: 45063 | F37: AGUARDANDO | G37: LIBERADO DEMOLIÇÃO
C38: 32 | D38: 031/0022/B | E38: 45063 | F38: 44655 | G38: DESCARACTERIZADO
C39: 33 | D39: 031/0028/L | E39: 45063 | F39: 44659 | G39: DESCARACTERIZADO
C40: 34 | D40: 031/0030/B | E40: 45063 | F40: AGUARDANDO | G40: LIBERADO DEMOLIÇÃO
C41: 35 | D41: 031/0030/C | E41: 45063 | F41: 44642 | G41: DESCARACTERIZADO
C42: 36 | D42: 031/0033/E | E42: 45063 | F42: 44638 | G42: DESCARACTERIZADO
C43: 37 | D43: 031/0034/A | E43: 45063 | F43: AGUARDANDO | G43: LIBERADO DEMOLIÇÃO
...
