Workbook
Name Adequacao_Imovel: 'Listas (não utilizar)'!$G$2:$G$7
Name ADEQUAR: 'Listas (não utilizar)'!$G$2:$G$7
Name Apartamento: 'Listas (não utilizar)'!$D$2:$D$21
Name APROVCEF: #REF!
Name Área: 'Listas (não utilizar)'!$A$2:$A$28
Name AREAS: #REF!
Name AVILDATA: #REF!
Name AVILDATA1: #REF!
Name BARCDATA: #REF!
Name BILBDATA: #REF!
Name Bloco: 'Listas (não utilizar)'!$C$2:$C$16
Name CEF: #REF!
Name CEUTDATA: #REF!
Name Condomínio: 'Listas (não utilizar)'!$B$2:$B$15
Name INDDEMAND: #REF!
Name INDEMAND: #REF!
Name it: #REF!
Name Pendência: 'Listas (não utilizar)'!$I$2:$I$7
Name PLANCCO: #REF!
Name Renúncia: 'Listas (não utilizar)'!$H$2:$H$6
Name RetornoSMADS: '[1]Listas (não utilizar)'!$E$2:$E$3
Name selogo: #REF!
Name selomv: #REF!
Name selos_go: #REF!
Name selosgo: #REF!
Name selosgo1: #REF!
Name SITAH_CAIXA: 'Listas (não utilizar)'!$E$2:$E$9
Name StatusCAIXA: 'Listas (não utilizar)'!$F$2:$F$5
Name TEPROC: #REF!
Name TEPROC1: #REF!

Sheet PRIORIDADES
C3: 2 | D3: PRIORITÁRIO | G3: OCUPADO | H3: RESIDENCIAL | I3: PROPRIETÁRIO NÃO RESIDENTE | M3: CADASTRADO | N3: INDENIZAÇÃO | P3: SIM | R3: SIM | X3: SAQUE PENDENTE | AE3: PROPRIETÁRIO NÃO RESIDENTE | AI3: SIM | AJ3: SIM | AK3: CADASTRADO | AM3: COMPLETA | AN3: SEM PENDÊNCIAS
C4: 4 | G4: VAZIO | H4: COMERCIAL | I4: PROPRIETÁRIO RESIDENTE | M4: NÃO CADASTRADO | N4: AUXÍLIO ALUGUEL UH | P4: NÃO | R4: NÃO | AE4: PROPRIETÁRIO RESIDENTE | AI4: NÃO | AJ4: NÃO | AK4: NÃO CADASTRADO | AM4: PENDENTE | AN4: FALTA TERMO
G5: OCUPADO/RISCO | H5: MISTO | I5: INQULINO | N5: RECUSA AUXÍLIO ALUGUEL UH | AI5: UH | AJ5: N/A | AN5: FALTA DOCS
G6: CONSTRUÇÃO | N6: NÃO TEM DIREITO ATENDIMENTO | AI6: ESTUDO DE CASO | AJ6: PENDENTE | AN6: FALTA TERMO E DOCS
G7: DEMOLIDO
G8: DESCARACTERIZADO
G9: DESABADO
AP10: AGUARDANDO
A12: INFORMAÇÕES INICIAIS | P12: INFORMAÇÕES AUXÍLIO ALUGUEL | AB12: INFORMAÇÕES INDENIZAÇÃO | BB12: PROCESSO ATENDIMENTO HABITACIONAL
A13: ORDEM | B13: ÁREA | C13: FASE | D13: TRECHO | E13: PRIORIDADE | F13: SELO | G13: SITUAÇÃO INICIAL IMÓVEL | H13: USO IMÓVEL | I13: SITUAÇÃO DO RESIDENTE | J13: TITULAR | K13: RG | L13: CPF | M13: CADASTRO HABITA SAMPA | N13: OPÇÃO DE ATENDIMENTO HABITACIONAL | O13: ENVIO DADOS | P13: SOLICITAÇÃO AUXÍLIO ALUGUEL ÁREA | Q13: No PROCESSO SEI (AUXÍLIO ALUGUEL) | R13: ANÁLISE DTS CADASTRO + CHECAGEM DUPLO | S13: INSTRUÇÃO PROCESSO SEI DTS | T13: ANÁLISE CTS ASSINATURA GABINETE | U13: DATA PUBLICAÇÃO DIÁRIO OFICIAL | V13: CONFECÇÃO TERMO | W13: ENVIO TERMO CARTÃO | X13: PREVISÃO PAGAMENTO | Y13: DATA SAQUE | Z13: DATA MUDANÇA | AA13: OBSERVAÇÕES AA | AB13: PROPRIETÁRIO | AC13: RG | AD13: CPF | AE13: SITUAÇÃO DO PROPRIETÁRIO | AF13: CADASTRO HABITASAMPA | AG13: VALOR AVALIAÇÃO | AH13: VALOR INDENIZAÇÃO | AI13: ACEITA VALOR INDENIZAÇÃO | AJ13: Nº SEI LAUDOS AVALIAÇÃO | AK13: Nº DOCUMENTO LAUDO | AL13: TERMO INDENIZAÇÃO | AM13: DOSSIÊ | AN13: PENDÊNCIA | AO13: OBSERVAÇÕES INDENIZAÇÃO | AP13: No PROCESSO SEI (INDENIZAÇÃO) | AQ13: INSTRUÇÃO PROCESSO SEI DTS | AR13: ASSINATURA DIRETOR DTS | AS13: ELABORAÇÃO DESPACHO CTS | AT13: ASSINATURA DESPACHO GABINETE | AU13: PUBLICAÇÃO DIÁRIO OFICIAL | AV13: ENCAMINHAMENTO DAF/DIF CTS | AW13: LIBERAÇÃO PAGAMENTO DAF/DIF | AX13: PREVISÃO PAGAMENTO | AY13: DATA PAGAMENTO | AZ13: DATA ENTREGA IMÓVEL | BA13: SITUAÇÃO ATUAL IMÓVEL | BB13: STATUS | BC13: DIAS TOTAIS | BD13: OPÇÃO ATENDIMENTO | BE13: NECESSITA BLOQUEIO AA | BF13: SOLICITAÇÃO BLOQUEIO AA DTS | BG13: SOLICITAÇÃO BLOQUEIO AA | BH13: DATA BLOQUEIO AA | BI13: DESPACHO EXCLUSÃO GABINETE | BJ13: ASSINATURA DESPACHO GABINETE | BK13: PUBLICAÇÃO DOC | BL13: ENCAMINHAMENTO SOLICITAÇÃO EXCLUSÃO DEPLAN | BM13: ENCERRAMENTO PROCESSO DTS
A14: 1 | B14: JD. VITÓRIA | C14: FASE 1 - CÓRREGO | D14: -- | E14: -- | F14: 002/0001/A | G14: OCUPADO | H14: CONSTRUÇÃO | I14: PROPRIETARIO NÃO RESIDENTE | J14: - | K14: - | L14: - | M14: NÃO | AJ14: 6014.2024/0006500-4 | BC14: =IF(AY14-KG14=0,"",AY14-O14) | BD14: =IF(AND(AI14<>"SIM",AI14="UH"),"AA","INDENIZAÇÃO") -> INDENIZAÇÃO | BE14: =IF(AND(AY14<>"AGUARDANDO",AY14<>"",N14="AUXÍLIO ALUGUEL ATÉ INDENIZAÇÃO"),"SIM","NÃO") -> NÃO
A15: 2 | B15: JD. VITÓRIA | C15: FASE 1 - CÓRREGO | D15: -- | E15: -- | F15: 002/0002/A | G15: OCUPADO | H15: COMERCIAL | I15: PROPRIETÁRIO RESIDENTE | J15: ELIAS FERREIRA DE SOUSA | K15: 39.826.994-4 | L15: 530.102.098-60 | M15: CONCLUÍDO | N15: INDENIZAÇÃO | O15: 45859 | P15: N/A | Q15: NA | R15: NA | S15: NA | T15: NA | U15: NA | V15: NA | W15: NA | X15: NA | Y15: NA | Z15: NA | AB15: ELIAS FERREIRA DE SOUSA | AC15: 39.826.994-4 | AD15: 530.102.098-60 | AE15: PROPRIETÁRIO RESIDENTE | AF15: CONCLUÍDO | AG15: 14192.93 | AH15: =AG15+30000 -> 44192.93 | AI15: SIM | AJ15: 6014.2024/0006500-4 | AK15: 125243277 | AL15: FINALIZADO | AM15: FINALIZADO | AN15: SEM PENDÊNCIA | AP15: 6014.2025/0004924-8 | AQ15: FINALIZADO | AR15: FINALIZADO | AS15: FINALIZADO | AT15: FINALIZADO | AU15: 45978 | AV15: FINALIZADO | AW15: FINALIZADO | AX15: 45985 | AY15: 45985 | AZ15: 46029 | BA15: LIBERADO DEMOLIÇÃO | BB15: FINALIZADO | BC15: =IF(AY15-KG15=0,"",AY15-O15) -> 126 | BD15: =IF(AND(AI15<>"SIM",AI15="UH"),"AA","INDENIZAÇÃO") -> INDENIZAÇÃO | BE15: =IF(AND(AY15<>"AGUARDANDO",AY15<>"",N15="AUXÍLIO ALUGUEL ATÉ INDENIZAÇÃO"),"SIM","NÃO") -> NÃO | BF15: N/A | BG15: N/A | BH15: N/A | BI15: FINALIZADO | BJ15: FINALIZADO | BK15: 46112 | BL15: FINALIZADO | BM15: AGUARDANDO
A16: 3 | B16: JD. VITÓRIA | C16: FASE 2 - RISCO E URBANIZAÇÃO | D16: -- | E16: -- | F16: 007/0057/A | G16: OCUPADO | H16: RESIDENCIAL | I16: PROPRIETÁRIO RESIDENTE | J16: CLAUDETE DOS SANTOS BONFIM | K16: 38.849.113-9 | L16: 308.753.998-86 | N16: INDENIZAÇÃO | O16: 46161 | P16: N/A | Q16: N/A | R16: N/A | S16: N/A | T16: N/A | U16: N/A | V16: N/A | W16: N/A | X16: N/A | Y16: N/A | Z16: N/A | AB16: CLAUDETE DOS SANTOS BONFIM | AC16: 38.849.113-9 | AD16: 308.753.998-86 | AE16: PROPRIETÁRIO RESIDENTE | AF16: CONCLUÍDO | AG16: 66944.06 | AH16: 66944.06 | AI16: SIM | AJ16: 6014.2024/0006500-4 | AK16: 150716185 | AL16: FINALIZADO | AM16: FINALIZADO | AN16: SEM PENDÊNCIA | AP16: 6014.2026/0004264-4 | AQ16: FINALIZADO | AR16: FINALIZADO | AS16: FINALIZADO | AT16: FINALIZADO | AU16: 46226 | AV16: FINALIZADO | AW16: FINALIZADO | AX16: 46233 | AY16: 46233 | AZ16: AGUARDANDO | BA16: LIBERADO DEMOLIÇÃO | BB16: FINALIZADO | BC16: =IF(AY16-KG16=0,"",AY16-O16) -> 72 | BD16: =IF(AND(AI16<>"SIM",AI16="UH"),"AA","INDENIZAÇÃO") -> INDENIZAÇÃO | BE16: =IF(AND(AY16<>"AGUARDANDO",AY16<>"",N16="AUXÍLIO ALUGUEL ATÉ INDENIZAÇÃO"),"SIM","NÃO") -> NÃO | BF16: N/A | BG16: N/A | BH16: N/A | BI16: AGUARDANDO ELABORAÇÃO
A17: 4 | B17: JD. VITÓRIA | C17: FASE 1 - CÓRREGO | D17: -- | E17: -- | F17: 002/0013/A | G17: OCUPADO | H17: RESIDENCIAL | I17: PROPRIETÁRIO RESIDENTE | J17: ANDRESSA RAQUEL FERNANDES DA COSTA | K17: 49.597.936-3 | L17: 398.166.698-46 | M17: CONCLUÍDO | N17: AUXILIO ALUGUEL UH | O17: 45726 | P17: 03-abr-25 | Q17: 6014.2024/0005020-1 | R17: 45728 | S17: 45750 | AJ17: 6014.2024/0006500-4 | BC17: =IF(AY17-KG17=0,"",AY17-O17) | BD17: =IF(AND(AI17<>"SIM",AI17="UH"),"AA","INDENIZAÇÃO") -> INDENIZAÇÃO | BE17: =IF(AND(AY17<>"AGUARDANDO",AY17<>"",N17="AUXÍLIO ALUGUEL ATÉ INDENIZAÇÃO"),"SIM","NÃO") -> NÃO
A18: 5 | B18: JD. VITÓRIA | C18: FASE 1 - CÓRREGO | D18: -- | E18: -- | F18: 002/0025/A | G18: OCUPADO | H18: RESIDENCIAL | I18: PROPRIETÁRIO RESIDENTE | J18: JOSÉ CARLOS LIMA DOS SANTOS | K18: 229681578 | L18: 16310451804 | AJ18: 6014.2024/0006500-4 | BC18: =IF(AY18-KG18=0,"",AY18-O18) | BD18: =IF(AND(AI18<>"SIM",AI18="UH"),"AA","INDENIZAÇÃO") -> INDENIZAÇÃO | BE18: =IF(AND(AY18<>"AGUARDANDO",AY18<>"",N18="AUXÍLIO ALUGUEL ATÉ INDENIZAÇÃO"),"SIM","NÃO") -> NÃO
A19: 6 | B19: JD. VITÓRIA | C19: FASE 1 - CÓRREGO | D19: -- | E19: -- | F19: 002/0028/B | G19: OCUPADO | H19: RESIDENCIAL | I19: PROPRIETÁRIO RESIDENTE | J19: MARIA IVANETE FERNANDES DE SOUZA | K19: 27.928.247-3 | L19: 814.354.284-04 | AJ19: 6014.2024/0006500-4 | BC19: =IF(AY19-KG19=0,"",AY19-O19) | BD19: =IF(AND(AI19<>"SIM",AI19="UH"),"AA","INDENIZAÇÃO") -> INDENIZAÇÃO | BE19: =IF(AND(AY19<>"AGUARDANDO",AY19<>"",N19="AUXÍLIO ALUGUEL ATÉ INDENIZAÇÃO"),"SIM","NÃO") -> NÃO
A20: 7 | B20: JD. VITÓRIA | C20: FASE 1 - CÓRREGO | D20: -- | E20: -- | F20: 002/0029/A | G20: OCUPADO | H20: RESIDENCIAL | I20: PROPRIETÁRIO RESIDENTE | J20: SIMONE DE SOUSA RODRIGUES | K20: 57.540.706-2 | L20: 352.449.708-01 | AJ20: 6014.2024/0006500-4 | BC20: =IF(AY20-KG20=0,"",AY20-O20) | BD20: =IF(AND(AI20<>"SIM",AI20="UH"),"AA","INDENIZAÇÃO") -> INDENIZAÇÃO | BE20: =IF(AND(AY20<>"AGUARDANDO",AY20<>"",N20="AUXÍLIO ALUGUEL ATÉ INDENIZAÇÃO"),"SIM","NÃO") -> NÃO
A21: 8 | B21: JD. VITÓRIA | C21: FASE 1 - CÓRREGO | D21: -- | E21: -- | F21: 002/0039/B | G21: OCUPADO | H21: RESIDENCIAL | I21: PROPRIETÁRIO RESIDENTE | J21: CRISTINA DA CONSOLAÇÃO ASSIS | K21: 35.880.213-1 | L21: 225.601.888-14 | AJ21: 6014.2024/0006500-4 | BC21: =IF(AY21-KG21=0,"",AY21-O21) | BD21: =IF(AND(AI21<>"SIM",AI21="UH"),"AA","INDENIZAÇÃO") -> INDENIZAÇÃO | BE21: =IF(AND(AY21<>"AGUARDANDO",AY21<>"",N21="AUXÍLIO ALUGUEL ATÉ INDENIZAÇÃO"),"SIM","NÃO") -> NÃO
A22: 9 | B22: JD. VITÓRIA | C22: FASE 1 - CÓRREGO | D22: -- | E22: -- | F22: 002/0052/B | G22: OCUPADO | H22: RESIDENCIAL | I22: PROPRIETÁRIO RESIDENTE | J22: MARIANA SANTOS RAMOS DA SILVA MIRAVETE | K22: 52.955.950-X | L22: 457.182.918-37 | M22: CONCLUÍDO | N22: INDENIZAÇÃO | O22: 45838 | P22: N/A | Q22: N/A | R22: N/A | S22: N/A | T22: N/A | U22: N/A | V22: N/A | W22: N/A | X22: N/A | Y22: N/A | Z22: N/A | AB22: MARIANA SANTOS RAMOS DA SILVA MIRAVETE | AC22: 52.955.950-X | AD22: 457.182.918-37 | AE22: PROPRIETÁRIO RESIDENTE | AF22: CONCLUÍDO | AG22: 35088.83 | AH22: 60000 | AI22: SIM | AJ22: 6014.2024/0006500-4 | AK22: 123202718 | AL22: FINALIZADO | AM22: FINALIZADO | AN22: SEM PENDÊNCIA | AP22: 6014.2025/0004708-3 | AQ22: FINALIZADO | AR22: FINALIZADO | AS22: FINALIZADO | AT22: FINALIZADO | AU22: 45909 | AV22: FINALIZADO | AW22: FINALIZADO | AX22: 45915 | AY22: 45915 | AZ22: 45957 | BA22: LIBERADO DEMOLIÇÃO | BB22: FINALIZADO | BC22: =IF(AY22-KG22=0,"",AY22-O22) -> 77 | BD22: =IF(AND(AI22<>"SIM",AI22="UH"),"AA","INDENIZAÇÃO") -> INDENIZAÇÃO | BE22: =IF(AND(AY22<>"AGUARDANDO",AY22<>"",N22="AUXÍLIO ALUGUEL ATÉ INDENIZAÇÃO"),"SIM","NÃO") -> NÃO | BF22: N/A | BG22: N/A | BH22: N/A | BI22: FINALIZADO | BJ22: FINALIZADO | BK22: 45937 | BL22: FINALIZADO | BM22: AGUARDANDO
A23: 10 | B23: JD. VITÓRIA | C23: FASE 1 - CÓRREGO | D23: -- | E23: -- | F23: 002/0053/A | G23: OCUPADO | H23: RESIDENCIAL | I23: PROPRIETÁRIO RESIDENTE | J23: GEOVANE SOUZA SANTOS | K23: 37.985.888-5 | L23: 429.418.998-39 | M23: CONCLUÍDO | N23: INDENIZAÇÃO | O23: 45954 | P23: N/A | Q23: N/A | R23: N/A | S23: N/A | T23: N/A | U23: N/A | V23: N/A | W23: N/A | X23: N/A | Y23: N/A | Z23: N/A | AB23: GEOVANE SOUZA SANTOS | AC23: 37.985.888-5 | AD23: 429.418.998-39 | AE23: PROPRIETÁRIO RESIDENTE | AF23: CONCLUÍDO | AG23: 121242.56 | AH23: 121242.56 | AI23: SIM | AJ23: 6014.2024/0006500-4 | AK23: 128252519 | AL23: FINALIZADO | AM23: FINALIZADO | AN23: SEM PENDÊNCIA | AP23: 6014.2025/0008040-4 | AQ23: FINALIZADO | AR23: FINALIZADO | AS23: FINALIZADO | AT23: FINALIZADO | AU23: 46024 | AV23: FINALIZADO | AW23: FINALIZADO | AX23: 46038 | AY23: 46038 | AZ23: 46085 | BA23: LIBERADO DEMOLIÇÃO | BB23: FINALIZADO | BC23: =IF(AY23-KG23=0,"",AY23-O23) -> 84 | BD23: =IF(AND(AI23<>"SIM",AI23="UH"),"AA","INDENIZAÇÃO") -> INDENIZAÇÃO | BE23: =IF(AND(AY23<>"AGUARDANDO",AY23<>"",N23="AUXÍLIO ALUGUEL ATÉ INDENIZAÇÃO"),"SIM","NÃO") -> NÃO | BF23: N/A | BG23: N/A | BH23: N/A | BI23: FINALIZADO | BJ23: FINALIZADO | BK23: 46112 | BL23: FINALIZADO | BM23: AGUARDANDO
A24: 11 | B24: JD. VITÓRIA | C24: FASE 1 - CÓRREGO | D24: -- | E24: -- | F24: 003/0001/A | G24: OCUPADO | H24: INSTITUCIONAL | I24: NA | J24: - | K24: - | L24: - | M24: NÃO | AJ24: 6014.2024/0006500-4 | BC24: =IF(AY24-KG24=0,"",AY24-O24) | BD24: =IF(AND(AI24<>"SIM",AI24="UH"),"AA","INDENIZAÇÃO") -> INDENIZAÇÃO | BE24: =IF(AND(AY24<>"AGUARDANDO",AY24<>"",N24="AUXÍLIO ALUGUEL ATÉ INDENIZAÇÃO"),"SIM","NÃO") -> NÃO
A25: 12 | B25: JD. VITÓRIA | C25: FASE 1 - CÓRREGO | D25: -- | E25: -- | F25: 003/0013/A | G25: OCUPADO | H25: RESIDENCIAL | I25: PROPRIETÁRIO RESIDENTE | J25: ANGELA NETTO | K25: 34164013 | L25: 312.549.168.14 | M25: NÃO | AJ25: 6014.2024/0006500-4 | BC25: =IF(AY25-KG25=0,"",AY25-O25) | BD25: =IF(AND(AI25<>"SIM",AI25="UH"),"AA","INDENIZAÇÃO") -> INDENIZAÇÃO | BE25: =IF(AND(AY25<>"AGUARDANDO",AY25<>"",N25="AUXÍLIO ALUGUEL ATÉ INDENIZAÇÃO"),"SIM","NÃO") -> NÃO
A26: 13 | B26: JD. VITÓRIA | C26: FASE 1 - CÓRREGO | D26: -- | E26: -- | F26: 003/0014/A | G26: OCUPADO | H26: RESIDENCIAL | I26: PROPRIETÁRIO RESIDENTE | J26: LAURINDA SILVA DO NASCIMENTO | K26: 331023 | L26: 336.719.233-34 | M26: CONCLUÍDO | N26: INDENIZAÇÃO | O26: 46161 | P26: N/A | Q26: N/A | R26: N/A | S26: N/A | T26: N/A | U26: N/A | V26: N/A | W26: N/A | X26: N/A | Y26: N/A | Z26: N/A | AB26: LAURINDA SILVA DO NASCIMENTO | AC26: 331023 | AD26: 336.719.233-34 | AE26: PROPRIETÁRIO RESIDENTE | AF26: CONCLUÍDO | AG26: 30923.52 | AH26: 60000 | AI26: SIM | AJ26: 6014.2024/0006500-4 | AK26: 149303607 | AL26: FINALIZADO | AM26: FINALIZADO | AN26: SEM PENDÊNCIA | AP26: 6014.2026/0004251-2 | AQ26: FINALIZADO | AR26: FINALIZADO | AS26: FINALIZADO | AT26: FINALIZADO | AU26: 46226 | AV26: FINALIZADO | AW26: FINALIZADO | AX26: 46233 | AY26: 46233 | AZ26: AGUARDANDO | BA26: LIBERADO DEMOLIÇÃO | BB26: FINALIZADO | BC26: =IF(AY26-KG26=0,"",AY26-O26) -> 72 | BD26: =IF(AND(AI26<>"SIM",AI26="UH"),"AA","INDENIZAÇÃO") -> INDENIZAÇÃO | BE26: =IF(AND(AY26<>"AGUARDANDO",AY26<>"",N26="AUXÍLIO ALUGUEL ATÉ INDENIZAÇÃO"),"SIM","NÃO") -> NÃO | BF26: N/A | BG26: N/A | BH26: N/A | BI26: AGUARDANDO ELABORAÇÃO
A27: 14 | B27: JD. VITÓRIA | C27: FASE 1 - CÓRREGO | D27: -- | E27: -- | F27: 003/0015/A | G27: OCUPADO | H27: RESIDENCIAL | I27: PROPRIETÁRIO RESIDENTE | J27: ALEXANDRE NETTO | K27: 284659812 | L27: 19342655866 | M27: NÃO | AJ27: 6014.2024/0006500-4 | BC27: =IF(AY27-KG27=0,"",AY27-O27) | BD27: =IF(AND(AI27<>"SIM",AI27="UH"),"AA","INDENIZAÇÃO") -> INDENIZAÇÃO | BE27: =IF(AND(AY27<>"AGUARDANDO",AY27<>"",N27="AUXÍLIO ALUGUEL ATÉ INDENIZAÇÃO"),"SIM","NÃO") -> NÃO
A28: 15 | B28: JD. VITÓRIA | C28: FASE 1 - CÓRREGO | D28: -- | E28: -- | F28: 003/0016/A | G28: OCUPADO | H28: RESIDENCIAL | I28: PROPRIETÁRIO RESIDENTE | J28: ANA LÚCIA RODRIGUES CAVALCANTE | K28: 390508299 | L28: 17016043886 | M28: NÃO | AJ28: 6014.2024/0006500-4 | BC28: =IF(AY28-KG28=0,"",AY28-O28) | BD28: =IF(AND(AI28<>"SIM",AI28="UH"),"AA","INDENIZAÇÃO") -> INDENIZAÇÃO | BE28: =IF(AND(AY28<>"AGUARDANDO",AY28<>"",N28="AUXÍLIO ALUGUEL ATÉ INDENIZAÇÃO"),"SIM","NÃO") -> NÃO
A29: 16 | B29: JD. VITÓRIA | C29: FASE 1 - CÓRREGO | D29: -- | E29: -- | F29: 003/0017/A | G29: OCUPADO | H29: RESIDENCIAL | I29: PROPRIETÁRIO RESIDENTE | J29: VERA LUCIA DA SILVA ROCHA | K29: 383588790 | L29: 352.816.568.56 | M29: CONCLUÍDO | N29: AUXILIO ALUGUEL UH | O29: 45726 | P29: 03-ABR-25 | Q29: 6014.2024/0005020-1 | R29: 45744 | S29: 45750 | AJ29: 6014.2024/0006500-4 | BC29: =IF(AY29-KG29=0,"",AY29-O29) | BD29: =IF(AND(AI29<>"SIM",AI29="UH"),"AA","INDENIZAÇÃO") -> INDENIZAÇÃO | BE29: =IF(AND(AY29<>"AGUARDANDO",AY29<>"",N29="AUXÍLIO ALUGUEL ATÉ INDENIZAÇÃO"),"SIM","NÃO") -> NÃO
A30: 17 | B30: JD. VITÓRIA | C30: FASE 2 - RISCO E URBANIZAÇÃO | D30: -- | E30: -- | F30: 003/0018/A | G30: OCUPADO | H30: RESIDENCIAL | I30: PROPRIETÁRIO RESIDENTE | J30: FRANCISCO EUGÊNIO | M30: NÃO | AJ30: 6014.2024/0006500-4 | BC30: =IF(AY30-KG30=0,"",AY30-O30) | BD30: =IF(AND(AI30<>"SIM",AI30="UH"),"AA","INDENIZAÇÃO") -> INDENIZAÇÃO | BE30: =IF(AND(AY30<>"AGUARDANDO",AY30<>"",N30="AUXÍLIO ALUGUEL ATÉ INDENIZAÇÃO"),"SIM","NÃO") -> NÃO
A31: 18 | B31: JD. VITÓRIA | C31: FASE 2 - RISCO E URBANIZAÇÃO | D31: -- | E31: -- | F31: 003/0019/A | G31: OCUPADO | H31: RESIDENCIAL | I31: PROPRIETÁRIO RESIDENTE | J31: STEFANIE FERNANDES ORTEGA | K31: 572846733 | L31: 46653357880 | M31: NÃO | AJ31: 6014.2024/0006500-4 | BC31: =IF(AY31-KG31=0,"",AY31-O31) | BD31: =IF(AND(AI31<>"SIM",AI31="UH"),"AA","INDENIZAÇÃO") -> INDENIZAÇÃO | BE31: =IF(AND(AY31<>"AGUARDANDO",AY31<>"",N31="AUXÍLIO ALUGUEL ATÉ INDENIZAÇÃO"),"SIM","NÃO") -> NÃO
A32: 19 | B32: JD. VITÓRIA | C32: FASE 2 - RISCO E URBANIZAÇÃO | D32: -- | E32: -- | F32: 003/0021/A | G32: OCUPADO | H32: OUTROS | I32: NA | J32: - | K32: - | L32: - | M32: NÃO | AJ32: 6014.2024/0006500-4 | BC32: =IF(AY32-KG32=0,"",AY32-O32) | BD32: =IF(AND(AI32<>"SIM",AI32="UH"),"AA","INDENIZAÇÃO") -> INDENIZAÇÃO | BE32: =IF(AND(AY32<>"AGUARDANDO",AY32<>"",N32="AUXÍLIO ALUGUEL ATÉ INDENIZAÇÃO"),"SIM","NÃO") -> NÃO
A33: 20 | B33: JD. VITÓRIA | C33: FASE 1 - CÓRREGO | D33: -- | E33: -- | F33: 004/0001/A | G33: OCUPADO | H33: RESIDENCIAL | I33: PROPRIETÁRIO RESIDENTE | J33: ADRIANA DIAS NARRERO | K33: 229657904 | L33: 130.085.138.40 | AJ33: 6014.2024/0006500-4 | BC33: =IF(AY33-KG33=0,"",AY33-O33) | BD33: =IF(AND(AI33<>"SIM",AI33="UH"),"AA","INDENIZAÇÃO") -> INDENIZAÇÃO | BE33: =IF(AND(AY33<>"AGUARDANDO",AY33<>"",N33="AUXÍLIO ALUGUEL ATÉ INDENIZAÇÃO"),"SIM","NÃO") -> NÃO
A34: 21 | B34: JD. VITÓRIA | C34: FASE 1 - CÓRREGO | D34: -- | E34: -- | F34: 004/0008/A | G34: OCUPADO | H34: RESIDENCIAL | I34: PROPRIETÁRIO RESIDENTE | J34: EMILIO DE ALMEIDA SANTOS | K34: 25.164.457-1 | L34: 146.239.288-10 | M34: CONCLUÍDO | N34: INDENIZAÇÃO | O34: 46097 | P34: N/A | Q34: N/A | R34: N/A | S34: N/A | T34: N/A | U34: N/A | V34: N/A | W34: N/A | X34: N/A | Y34: N/A | Z34: N/A | AB34: EMILIO DE ALMEIDA SANTOS | AC34: 25.164.457-1 | AD34: 146.239.288-10 | AE34: PROPRIETÁRIO RESIDENTE | AF34: CONCLUÍDO | AG34: 92014.59 | AH34: 92014.59 | AI34: SIM | AJ34: 6014.2024/0006500-4 | AK34: 152010700 | AL34: FINALIZADO | AM34: FINALIZADO | AN34: SEM PENDÊNCIA | AP34: 6014.2026/0001191-9 | AQ34: FINALIZADO | AR34: FINALIZADO | AS34: FINALIZADO | AT34: FINALIZADO | AU34: 46174 | AV34: FINALIZADO | AW34: FINALIZADO | AX34: 46182 | AY34: 46182 | AZ34: AGUARDANDO | BA34: LIBERADO DEMOLIÇÃO | BB34: FINALIZADO | BC34: =IF(AY34-KG34=0,"",AY34-O34) -> 85 | BD34: =IF(AND(AI34<>"SIM",AI34="UH"),"AA","INDENIZAÇÃO") -> INDENIZAÇÃO | BE34: =IF(AND(AY34<>"AGUARDANDO",AY34<>"",N34="AUXÍLIO ALUGUEL ATÉ INDENIZAÇÃO"),"SIM","NÃO") -> NÃO | BF34: N/A | BG34: N/A | BH34: N/A | BI34: FINALIZADO | BJ34: FINALIZADO | BK34: 46224 | BL34: AGUARDANDO PUBLICAÇÃO DOC
A35: 22 | B35: JD. VITÓRIA | C35: FASE 1 - CÓRREGO | D35: -- | E35: -- | F35: 004/0010/A | G35: OCUPADO | H35: RESIDENCIAL | I35: PROPRIETÁRIO RESIDENTE | J35: ARLETE ALMEIDA SANTOS | K35: 44.022.838-4 | L35: 347.356.388-90 | M35: CONCLUÍDO | N35: INDENIZAÇÃO | O35: 45999 | P35: N/A | Q35: N/A | R35: N/A | S35: N/A | T35: N/A | U35: N/A | V35: N/A | W35: N/A | X35: N/A | Y35: N/A | Z35: N/A | AB35: ARLETE ALMEIDA SANTOS | AC35: 44.022.838-4 | AD35: 347.356.388-90 | AE35: PROPRIETÁRIO RESIDENTE | AF35: CONCLUÍDO | AG35: 47925.28 | AH35: 60000 | AI35: SIM | AJ35: 6014.2024/0006500-4 | AK35: 125262584 | AL35: FINALIZADO | AM35: FINALIZADO | AN35: SEM PENDÊNCIA | AP35: 6014.2025/0008120-6 | AQ35: FINALIZADO | AR35: FINALIZADO | AS35: FINALIZADO | AT35: FINALIZADO | AU35: 46071 | AV35: FINALIZADO | AW35: FINALIZADO | AX35: 46087 | AY35: 46087 | AZ35: AGUARDANDO | BA35: LIBERADO DEMOLIÇÃO | BB35: FINALIZADO | BC35: =IF(AY35-KG35=0,"",AY35-O35) -> 88 | BD35: =IF(AND(AI35<>"SIM",AI35="UH"),"AA","INDENIZAÇÃO") -> INDENIZAÇÃO | BE35: =IF(AND(AY35<>"AGUARDANDO",AY35<>"",N35="AUXÍLIO ALUGUEL ATÉ INDENIZAÇÃO"),"SIM","NÃO") -> NÃO | BF35: N/A | BG35: N/A | BH35: N/A | BI35: FINALIZADO | BJ35: FINALIZADO | BK35: 46139 | BL35: AGUARDANDO PUBLICAÇÃO DOC
A36: 23 | B36: JD. VITÓRIA | C36: FASE 2 - RISCO E URBANIZAÇÃO | D36: -- | E36: -- | F36: 007/0041/A | G36: OCUPADO | H36: RESIDENCIAL | I36: PROPRIETÁRIO RESIDENTE | J36: REINALDO MOREIRA SILVA | K36: 23.098.114-32 | L36: 702.612.337-72 | M36: CONCLUÍDO | N36: INDENIZAÇÃO | O36: 45999 | P36: N/A | Q36: N/A | R36: N/A | S36: N/A | T36: N/A | U36: N/A | V36: N/A | W36: N/A | X36: N/A | Y36: N/A | Z36: N/A | AB36: REINALDO MOREIRA SILVA | AC36: 23.098.114-32 | AD36: 702.612.337-72 | AE36: PROPRIETÁRIO RESIDENTE | AF36: CONCLUÍDO | AG36: 20411.84 | AH36: =AG36+30000 -> 50411.84 | AI36: SIM | AJ36: 6014.2024/0006500-4 | AK36: 130899556 | AL36: FINALIZADO | AM36: FINALIZADO | AN36: SEM PENDÊNCIA | AP36: 6014.2025/0008179-6 | AQ36: FINALIZADO | AR36: FINALIZADO | AS36: FINALIZADO | AT36: FINALIZADO | AU36: 46024 | AV36: FINALIZADO | AW36: FINALIZADO | AX36: 46038 | AY36: 46038 | AZ36: 46085 | BA36: LIBERADO DEMOLIÇÃO | BB36: FINALIZADO | BC36: =IF(AY36-KG36=0,"",AY36-O36) -> 39 | BD36: =IF(AND(AI36<>"SIM",AI36="UH"),"AA","INDENIZAÇÃO") -> INDENIZAÇÃO | BE36: =IF(AND(AY36<>"AGUARDANDO",AY36<>"",N36="AUXÍLIO ALUGUEL ATÉ INDENIZAÇÃO"),"SIM","NÃO") -> NÃO | BF36: N/A | BG36: N/A | BH36: N/A | BI36: FINALIZADO | BJ36: FINALIZADO | BK36: 46112 | BL36: FINALIZADO | BM36: AGUARDANDO
A37: 24 | B37: JD. VITÓRIA | C37: FASE 2 - RISCO E URBANIZAÇÃO | D37: -- | E37: -- | F37: 007/0047/A | G37: OCUPADO | H37: RESIDENCIAL | I37: PROPRIETÁRIO RESIDENTE | J37: CRISTIANE BISPO DOS SANTOS | K37: 34.628.281-0 | L37: 306.344.508-83 | M37: CONCLUÍDO | N37: INDENIZAÇÃO | O37: 46097 | P37: N/A | Q37: N/A | R37: N/A | S37: N/A | T37: N/A | U37: N/A | V37: N/A | W37: N/A | X37: N/A | Y37: N/A | Z37: N/A | AB37: CRISTIANE BISPO DOS SANTOS | AC37: 34.628.281-0 | AD37: 306.344.508-83 | AE37: PROPRIETÁRIO RESIDENTE | AF37: CONCLUÍDO | AG37: 12575.25 | AH37: 42575.25 | AI37: SIM | AJ37: 6014.2024/0006500-4 | AK37: 141878559 | AL37: FINALIZADO | AM37: FINALIZADO | AN37: SEM PENDÊNCIA | AP37: 6014.2026/0002500-6 | AQ37: FINALIZADO | AR37: FINALIZADO | AS37: FINALIZADO | AT37: FINALIZADO | AU37: 46174 | AV37: FINALIZADO | AW37: FINALIZADO | AX37: 46182 | AY37: 46182 | AZ37: AGUARDANDO | BA37: LIBERADO DEMOLIÇÃO | BB37: FINALIZADO | BC37: =IF(AY37-KG37=0,"",AY37-O37) -> 85 | BD37: =IF(AND(AI37<>"SIM",AI37="UH"),"AA","INDENIZAÇÃO") -> INDENIZAÇÃO | BE37: =IF(AND(AY37<>"AGUARDANDO",AY37<>"",N37="AUXÍLIO ALUGUEL ATÉ INDENIZAÇÃO"),"SIM","NÃO") -> NÃO | BF37: N/A | BG37: N/A | BH37: N/A | BI37: FINALIZADO | BJ37: FINALIZADO | BK37: 46224 | BL37: AGUARDANDO PUBLICAÇÃO DOC
A38: 25 | B38: JD. VITÓRIA | C38: FASE 2 - RISCO E URBANIZAÇÃO | D38: -- | E38: -- | F38: 007/0048/A | G38: OCUPADO | H38: RESIDENCIAL | I38: PROPRIETÁRIO RESIDENTE | J38: GABRIEL CRUZ DE OLIVEIRA | L38: 46115804825 | AJ38: 6014.2024/0006500-4 | BC38: =IF(AY38-KG38=0,"",AY38-O38) | BD38: =IF(AND(AI38<>"SIM",AI38="UH"),"AA","INDENIZAÇÃO") -> INDENIZAÇÃO | BE38: =IF(AND(AY38<>"AGUARDANDO",AY38<>"",N38="AUXÍLIO ALUGUEL ATÉ INDENIZAÇÃO"),"SIM","NÃO") -> NÃO
A39: 26 | B39: JD. VITÓRIA | C39: FASE 2 - RISCO E URBANIZAÇÃO | D39: -- | E39: -- | F39: 007/0049/A | G39: OCUPADO | H39: MISTO | I39: PROPRIETÁRIO RESIDENTE | J39: SIMONE SOUSA GONÇALVES | K39: 234277105 | L39: 142.791.268.09 | AJ39: 6014.2024/0006500-4 | BC39: =IF(AY39-KG39=0,"",AY39-O39) | BD39: =IF(AND(AI39<>"SIM",AI39="UH"),"AA","INDENIZAÇÃO") -> INDENIZAÇÃO | BE39: =IF(AND(AY39<>"AGUARDANDO",AY39<>"",N39="AUXÍLIO ALUGUEL ATÉ INDENIZAÇÃO"),"SIM","NÃO") -> NÃO
A40: 27 | B40: JD. VITÓRIA | C40: FASE 2 - RISCO E URBANIZAÇÃO | D40: -- | E40: -- | F40: 007/0050/A | G40: OCUPADO | H40: RESIDENCIAL | I40: PROPRIETÁRIO RESIDENTE | J40: FRANCISCA ROSEANE DA CONCEIÇÃO OLIVEIRA | AJ40: 6014.2024/0006500-4 | BC40: =IF(AY40-KG40=0,"",AY40-O40) | BD40: =IF(AND(AI40<>"SIM",AI40="UH"),"AA","INDENIZAÇÃO") -> INDENIZAÇÃO | BE40: =IF(AND(AY40<>"AGUARDANDO",AY40<>"",N40="AUXÍLIO ALUGUEL ATÉ INDENIZAÇÃO"),"SIM","NÃO") -> NÃO
A41: 28 | B41: JD. VITÓRIA | C41: FASE 2 - RISCO E URBANIZAÇÃO | D41: -- | E41: -- | F41: 007/0051/A | G41: OCUPADO | H41: RESIDENCIAL | I41: PROPRIETÁRIO RESIDENTE | J41: EDVANIA GOMES DA ROCHA | K41: 47.302.049-x | L41: 369.927.308-35 | M41: CONCLUÍDO | N41: INDENIZAÇÃO | O41: 46077 | P41: N/A | Q41: N/A | R41: N/A | S41: N/A | T41: N/A | U41: N/A | V41: N/A | W41: N/A | X41: N/A | Y41: N/A | Z41: N/A | AB41: EDVANIA GOMES DA ROCHA | AC41: 47.302.049-x | AD41: 369.927.308-35 | AE41: PROPRIETÁRIO RESIDENTE | AF41: CONCLUÍDO | AG41: 39862.27 | AH41: 60000 | AI41: SIM | AJ41: 6014.2024/0006500-4 | AK41: 125233430 | AL41: FINALIZADO | AM41: FINALIZADO | AN41: SEM PENDÊNCIA | AP41: 6014.2026/0000666-4 | AQ41: FINALIZADO | AR41: FINALIZADO | AS41: FINALIZADO | AT41: FINALIZADO | AU41: 46174 | AV41: FINALIZADO | AW41: FINALIZADO | AX41: 46182 | AY41: 46182 | AZ41: AGUARDANDO | BA41: LIBERADO DEMOLIÇÃO | BB41: FINALIZADO | BC41: =IF(AY41-KG41=0,"",AY41-O41) -> 105 | BD41: =IF(AND(AI41<>"SIM",AI41="UH"),"AA","INDENIZAÇÃO") -> INDENIZAÇÃO | BE41: =IF(AND(AY41<>"AGUARDANDO",AY41<>"",N41="AUXÍLIO ALUGUEL ATÉ INDENIZAÇÃO"),"SIM","NÃO") -> NÃO | BF41: N/A | BG41: N/A | BH41: N/A | BI41: FINALIZADO | BJ41: FINALIZADO | BK41: 46224 | BL41: AGUARDANDO PUBLICAÇÃO DOC
A42: 29 | B42: JD. VITÓRIA | C42: FASE 2 - RISCO E URBANIZAÇÃO | D42: -- | E42: -- | F42: 007/0052/A | G42: OCUPADO | H42: RESIDENCIAL | I42: PROPRIETÁRIO RESIDENTE | J42: ADÃO FERNANDES GUIMARÃES | K42: 55.256.402.3 | L42: 266.274.968-79 | M42: CONCLUÍDO | N42: INDENIZAÇÃO | O42: 45999 | P42: N/A | Q42: N/A | R42: N/A | S42: N/A | T42: N/A | U42: N/A | V42: N/A | W42: N/A | X42: N/A | Y42: N/A | Z42: N/A | AB42: ADÃO FERNANDES GUIMARÃES | AC42: 55.256.402.3 | AD42: 266.274.968-79 | AE42: PROPRIETÁRIO RESIDENTE | AF42: CONCLUÍDO | AG42: 39309.12 | AH42: 60000 | AI42: SIM | AJ42: 6014.2024/0006500-4 | AK42: 146194147 | AL42: FINALIZADO | AM42: FINALIZADO | AN42: SEM PENDÊNCIA | AP42: 6014.2025/0008191-5 | AQ42: FINALIZADO | AR42: FINALIZADO | AS42: FINALIZADO | AT42: FINALIZADO | AU42: 46024 | AV42: FINALIZADO | AW42: FINALIZADO | AX42: 45798 | AY42: 46163 | AZ42: AGUARDANDO | BA42: LIBERADO DEMOLIÇÃO | BB42: FINALIZADO | BC42: =IF(AY42-KG42=0,"",AY42-O42) -> 164 | BD42: =IF(AND(AI42<>"SIM",AI42="UH"),"AA","INDENIZAÇÃO") -> INDENIZAÇÃO | BE42: =IF(AND(AY42<>"AGUARDANDO",AY42<>"",N42="AUXÍLIO ALUGUEL ATÉ INDENIZAÇÃO"),"SIM","NÃO") -> NÃO | BF42: N/A | BG42: N/A | BH42: N/A | BI42: FINALIZADO | BJ42: FINALIZADO | BK42: 46224 | BL42: AGUARDANDO PUBLICAÇÃO DOC
A43: 30 | B43: JD. VITÓRIA | C43: FASE 2 - RISCO E URBANIZAÇÃO | D43: -- | E43: -- | F43: 007/0053/A | G43: OCUPADO | H43: RESIDENCIAL | I43: PROPRIETÁRIO RESIDENTE | J43: LEIDIANE DE CARVALHO RODRIGUES | K43: 66.820.449-1 | L43: 038.409.453-80 | M43: CONCLUÍDO | N43: INDENIZAÇÃO | O43: 46073 | P43: N/A | Q43: N/A | R43: N/A | S43: N | T43: N/A | U43: N/A | V43: N/A | W43: N/A | X43: N/A | Y43: N/A | Z43: N/A | AB43: LEIDIANE DE CARVALHO RODRIGUES | AC43: 66.820.449-1 | AD43: 038.409.453-80 | AE43: PROPRIETÁRIO RESIDENTE | AF43: CONCLUÍDO | AG43: 69699.33 | AH43: 69699.33 | AI43: SIM | AJ43: 6014.2024/0006500-4 | AK43: 125286282 | AL43: FINALIZADO | AM43: FINALIZADO | AN43: SEM PENDÊNCIA | AP43: 6014.2026/0002516-2 | AQ43: FINALIZADO | AR43: FINALIZADO | AS43: FINALIZADO | AT43: FINALIZADO | AU43: 46174 | AV43: FINALIZADO | AW43: FINALIZADO | AX43: 46182 | AY43: 46182 | AZ43: AGUARDANDO | BA43: LIBERADO DEMOLIÇÃO | BB43: FINALIZADO | BC43: =IF(AY43-KG43=0,"",AY43-O43) -> 109 | BD43: =IF(AND(AI43<>"SIM",AI43="UH"),"AA","INDENIZAÇÃO") -> INDENIZAÇÃO | BE43: =IF(AND(AY43<>"AGUARDANDO",AY43<>"",N43="AUXÍLIO ALUGUEL ATÉ INDENIZAÇÃO"),"SIM","NÃO") -> NÃO | BF43: N/A | BG43: N/A | BH43: N/A | BI43: FINALIZADO | BJ43: FINALIZADO | BK43: 46224 | BL43: AGUARDANDO PUBLICAÇÃO DOC
...

Sheet EMAIL
E2: PUBLICAÇÃO DOC
E3: PREVISÃO PAGAMENTO | F3: 024/0030/B | H3: 029/0024/C
A4: ÁREA | B4: SELO | C4: TITULAR | D4: PREVISÃO PAGAMENTO | E4: CONFIRMAÇÃO PAGAMENTO | F4: 024/0041/A | H4: 029/0023/E
A5: JD. VITÓRIA | B5: 016/0026/B | C5: LUZINETE GUILHERME ALVES FERREIRA | D5: 46259 | F5: 029/0007/A | H5: 029/0022/B
F6: 024/0052/A | H6: 031/0033/Q
F7: 024/0070/E | H7: 031/0022/E
F8: 024/0079/C | H8: 031/0020/C
F9: 024/0088/B | H9: 029/0069/D
F10: 024/0099/A | H10: 031/0033/K
F11: 024/0102/D | H11: 029/0016/B
F12: 024/0105/B | H12: 024/0099/A
A14: JD. VITÓRIA | B14: 010/0019/A | C14: MANOEL LUÍS GOMES | D14: 46183 | F14: 029/0007/B | H14: 031/0039/C
A15: JD. VITÓRIA | B15: 010/0020/A | C15: SIONE PINHEIRO ROSA | D15: 46183 | F15: 029/0016/B | H15: 029/0081/A
F16: 029/0022/B | H16: 024/0052/A
F17: 029/0023/E | H17: 029/0035/B
F18: 029/0024/C | H18: 029/0027/A
F19: 029/0035/B | H19: 029/0069/B
A20: JD. VITÓRIA | B20: 015/0022/A | C20: GABRIEL FREITAS DA SILVA | D20: 45915 | F20: 029/0036/F | H20: 031/0028/D
A21: JD. VITÓRIA | B21: 016/0005/A | C21: RAIMUNDO DE OLIVEIRA | D21: 45915 | F21: 029/0039/B | H21: 029/0067/A
A22: JD. VITÓRIA | B22: 016/0010/A | C22: MONICA DE MELO LINO | D22: 45915 | F22: 029/0045/A | H22: 029/0007/A
A23: JD. VITÓRIA | B23: 016/0019/B | C23: MAIARA RIBEIRO DIAS | D23: 45915 | F23: 029/0061/A | H23: 029/0070/C
A24: JD. VITÓRIA | B24: 016/0019/C | C24: FRANCISCO PAULINO DIAS | D24: 45915 | F24: 029/0064/A | H24: 029/0007/B
A25: JD. VITÓRIA | B25: 016/0021/A | C25: DANIELLE DOS ANJOS RIPARDO | D25: 45915 | F25: 029/0064/F | H25: 029/0070/B
A26: JD. VITÓRIA | B26: 016/0021/B | C26: JOSÉ MARIA RIPARDO | D26: 45916 | F26: 029/0066/A | H26: 029/0045/A
A27: JD. VITÓRIA | B27: 016/0024/A | C27: MICAELA ARAGÃO FELIX DA SILVA | D27: 45915 | F27: 029/0066/B | H27: 024/0102/D
A28: JD. VITÓRIA | B28: 016/0025/A | C28: CLAUDIANA BISPO DOS SANTOS | D28: 45915 | F28: 029/0066/E | H28: 024/0041/A
A29: JD. VITÓRIA | B29: 016/0025/B | C29: KAUÊ DOS SANTOS SANTANA | D29: 45915 | F29: 029/0067/A | H29: 031/0035/A
A30: JD. VITÓRIA | B30: 016/0027/A | C30: JANAINA GOMES DE OLIVEIRA | D30: 45915 | F30: 029/0067/F | H30: 031/0067/B
A31: JD. VITÓRIA | B31: 016/0031/A | C31: FERNANDA DE PONTES | D31: 45917 | F31: 029/0069/B | H31: 024/0077/B
F32: 029/0069/C | H32: 033/0016/C
F33: 029/0069/D | H33: 029/0069/C
F34: 029/0070/B | H34: 029/0061/A
F35: 029/0070/C | H35: 029/0066/B
F36: 029/0071/B | H36: 029/0071/D
F37: 029/0071/D | H37: 031/0058/A
F38: 029/0071/E | H38: 029/0036/F
F39: 029/0080/E | H39: 031/0067/A
F40: 029/0081/A | H40: 031/0028/L
F41: 029/0083/A | H41: 024/0105/A
A42: PARAISÓPOLIS/ANTONICO | B42: 025/0006/L | C42: DENISE SILVA COSTA | D42: 44840 | F42: 029/0085/G | H42: 029/0064/F
...

Sheet Listas (não utilizar)
A1: Área | B1: Condomínio | C1: Bloco | D1: Apartamento | E1: SITAH / CAIXA | F1: Status CAIXA | G1: Adequacao Imovel | H1: Renúncia | I1: Pendência | J1: Pendências / Reprovados caixa
A2: ALTO DA ALEGRIA | B2: AVILA | C2: 1 | D2: 101 | E2: AGENDADO | F2: APROVADO | G2: NÃO | H2: NÃO | I2: CRAS | J2: RENDA SUPERIOR
A3: ALTO DA ALEGRIA (OBRAS) | B3: BARCELONA | C3: 2 | D3: 102 | E3: AGUARDANDO OFICIO | F3: REPROVADO | G3: FÍSICA | H3: RENDA | I3: CRAS + DOCUMENTOS | J3: CADMUT
A4: ALTO DA ALEGRIA (RESERVA) | B4: BILBAO | C4: 3 | D4: 103 | E4: ATENDIMENTO CANCELADO | F4: PENDENCIA | G4: VISUAL | H4: CADIN | I4: DOCUMENTOS | J4: CADIN
A5: ANTERO GOMES | B5: CEUTA | C5: 4 | D5: 104 | E5: CADMUT | F5: SEM DOSSIE | G5: INTELECTUAL | H5: ESTADO CIVIL | I5: CADIN
A6: CANTINHO DO CEU / GAIVOTAS | B6: IBIZA | C6: 5 | D6: 201 | E6: CHACARA DO CONDE | G6: AUDITIVA | H6: SEPARACAO | I6: CRAS + CADIN
A7: CANTINHO DO CEU / OBRAS | B7: LEAO | C7: 6 | D7: 202 | E7: CONFLITO | G7: NANISMO | I7: R.LI.AV.
A8: CASTRO ALVES | B8: MADRID | C8: 7 | D8: 203 | E8: ENVIADO CAIXA | I8: IEME
A9: COCAIA | B9: MELILLA | C9: 8 | D9: 204 | E9: FALECEU
A10: ERUNDINA | B10: PAMPLONA | C10: 9 | D10: 301 | E10: FALTANTE DOSSIÊ
A11: FUMACA | B11: SALAMANCA | C11: 10 | D11: 302 | E11: HABISP ACERTO DE ÁREA
A12: GUAICURI (OBRAS) | B12: TERUEL | C12: 11 | D12: 303 | E12: HABISP AGUARDANDO CRÍTICA
A13: GUAICURI / CIDADE JULIA | B13: VALENCIA | C13: 12 | D13: 304 | E13: HABISP PEND DE ATUALIZ CADASTRAL
A14: JARDIM MIRNA | B14: VALVERDE | C14: 13 | D14: 401 | E14: INDENIZACAO
A15: JARDIM SELMA II | B15: VITORIA | C15: 14 | D15: 402 | E15: PENDENCIA
A16: JARDIM TUBO | C16: 15 | D16: 403 | E16: PERMUTA
A17: LEBLON | D17: 404 | E17: PESQUISA SMADS
A18: MARGINAL DOIS / FUNDAO | D18: 501 | E18: REANALISE
A19: MATA VIRGEM / JD ELDORADO | D19: 502 | E19: RECLUSO
A20: NEBLINA | D20: 503 | E20: RELATÓRIO SOCIAL
A21: NORONHA | D21: 504 | E21: RENDA SUPERIOR
A22: NOVA GRAJAU | E22: RESISTENTE
A23: NOVA MARILDA | E23: TROCA DE TITULARIDADE
A24: NOVA VARGINHA
A25: PABREU / PRAINHA
A26: PENDENCIA GABINETE
A27: PILAO / APURA
A28: PILAO / DOIS
A29: PILAO / PAULISTAS
A30: SANTA AMELIA
A31: VALE VERDE / MONTE VERDE
A32: VILA BREJINHO
A33: VILA NASCENTE
A34: ZR / COSTA BRANCA
A35: VILA RUBI

Sheet QUANT COND
A1: CONDOMINIOS | B1: QUANT
A2: AVILA | B2: =COUNTIF(#REF!,'QUANT COND'!A2) -> #REF!
A3: BARCELONA | B3: =COUNTIF(#REF!,'QUANT COND'!A3) -> #REF!
A4: BILBAO | B4: =COUNTIF(#REF!,'QUANT COND'!A4) -> #REF!
A5: CEUTA | B5: =COUNTIF(#REF!,'QUANT COND'!A5) -> #REF!
A6: IBIZA | B6: =COUNTIF(#REF!,'QUANT COND'!A6) -> #REF!
A7: LEAO | B7: =COUNTIF(#REF!,'QUANT COND'!A7) -> #REF!
A8: MADRID | B8: =COUNTIF(#REF!,'QUANT COND'!A8) -> #REF!
A9: MELILLA | B9: =COUNTIF(#REF!,'QUANT COND'!A9) -> #REF!
A10: PAMPLONA | B10: =COUNTIF(#REF!,'QUANT COND'!A10) -> #REF!
A11: SALAMANCA | B11: =COUNTIF(#REF!,'QUANT COND'!A11) -> #REF!
A12: TERUEL | B12: =COUNTIF(#REF!,'QUANT COND'!A12) -> #REF!
A13: VALENCIA | B13: =COUNTIF(#REF!,'QUANT COND'!A13) -> #REF!
... A15: VITORIA | B15: =COUNTIF(#REF!,'QUANT COND'!A15) -> #REF!

Sheet OFÍCIOS
A1: PLANILHA DE CONFRONTO OFÍCIOS DE INDICAÇÃO COM ENVIADOS CAIXA ECONÔMICA FEDERAL - CEF
A2: TITULAR | B2: CPF | C2: Cônjuge | D2: CPF | E2: OFÍCIO | F2: DATA | G2: STATUS CEF | H2: DATA ENVIO CAIXA | I2: DUPLICIDADE OFÍCIO | J2: DATA | K2: DATA ENVIO CAIXA | L2: OFÍCIO DE INDICAÇÃO | M2: DATA OFÍCIO INDICAÇÃO | O2: NR OFICIO | P2: QUANT | Q2: APROV | R2: REPROV | S2: PEND | T2: SEM STATUS (ANÁLISE) | Y2: CEF BD | Z2: CEF OFICIOS | AA2: CEF PLANILHA
A3: ABEL MEDEIROS FILHO | B3: 27140979871 | E3: 1128 | F3: 42972 | G3: APROVADO | H3: 42979 | O3: 810 | P3: =COUNTIF(OFÍCIOS!E:E,O3) -> 156 | Q3: =COUNTIFS(OFÍCIOS!$E:$E,$O3,OFÍCIOS!$G:$G,"APROVADO") -> 149 | R3: =COUNTIFS(OFÍCIOS!$E:$E,$O3,OFÍCIOS!$G:$G,"REPROVADO") -> 3 | S3: =COUNTIFS(OFÍCIOS!$E:$E,$O3,OFÍCIOS!$G:$G,"PENDENCIA") -> 2 | T3: =COUNTIFS(OFÍCIOS!$E:$E,$O3,OFÍCIOS!$G:$G,"") -> 2 | U3: =SUM(Q3:T3) -> 156 | X3: FEITOS | Y3: 1850 | Z3: 1827 | AA3: =SUM(AA4:AA7) -> 1615
A4: ABELINA FERREIRA DOS SANTOS | B4: 39200633846 | O4: 1417 | P4: =COUNTIF(OFÍCIOS!E:E,O4) -> 42 | Q4: =COUNTIFS(OFÍCIOS!$E:$E,$O4,OFÍCIOS!$G:$G,"APROVADO") -> 36 | R4: =COUNTIFS(OFÍCIOS!$E:$E,$O4,OFÍCIOS!$G:$G,"REPROVADO") -> 3 | S4: =COUNTIFS(OFÍCIOS!$E:$E,$O4,OFÍCIOS!$G:$G,"PENDENCIA") -> 3 | T4: =COUNTIFS(OFÍCIOS!$E:$E,$O4,OFÍCIOS!$G:$G,"") -> 0 | U4: =SUM(Q4:T4) -> 42 | X4: APROVADOS | Y4: 1517 | Z4: 1427 | AA4: 1559
A5: ABIGAIL DE OLIVEIRA PAULINO | B5: 75489104872 | E5: 1752 | F5: 43051 | G5: APROVADO | H5: 43089 | L5: 1759 | O5: 1359 | P5: =COUNTIF(OFÍCIOS!E:E,O5) -> 14 | Q5: =COUNTIFS(OFÍCIOS!$E:$E,$O5,OFÍCIOS!$G:$G,"APROVADO") -> 13 | R5: =COUNTIFS(OFÍCIOS!$E:$E,$O5,OFÍCIOS!$G:$G,"REPROVADO") -> 1 | S5: =COUNTIFS(OFÍCIOS!$E:$E,$O5,OFÍCIOS!$G:$G,"PENDENCIA") -> 0 | T5: =COUNTIFS(OFÍCIOS!$E:$E,$O5,OFÍCIOS!$G:$G,"") -> 0 | U5: =SUM(Q5:T5) -> 14 | X5: REPROVADOS | Y5: 73 | Z5: 79 | AA5: 28
A6: ABILIO OLIVEIRA SANTOS | B6: 43286003620 | O6: 1350 | P6: =COUNTIF(OFÍCIOS!E:E,O6) -> 79 | Q6: =COUNTIFS(OFÍCIOS!$E:$E,$O6,OFÍCIOS!$G:$G,"APROVADO") -> 75 | R6: =COUNTIFS(OFÍCIOS!$E:$E,$O6,OFÍCIOS!$G:$G,"REPROVADO") -> 3 | S6: =COUNTIFS(OFÍCIOS!$E:$E,$O6,OFÍCIOS!$G:$G,"PENDENCIA") -> 0 | T6: =COUNTIFS(OFÍCIOS!$E:$E,$O6,OFÍCIOS!$G:$G,"") -> 1 | U6: =SUM(Q6:T6) -> 79 | X6: PENDENCIAS | Y6: 36 | Z6: 32 | AA6: 11
A7: ABRAHAO SANTOS SILVA | O7: 1343 | P7: =COUNTIF(OFÍCIOS!E:E,O7) -> 6 | Q7: =COUNTIFS(OFÍCIOS!$E:$E,$O7,OFÍCIOS!$G:$G,"APROVADO") -> 5 | R7: =COUNTIFS(OFÍCIOS!$E:$E,$O7,OFÍCIOS!$G:$G,"REPROVADO") -> 0 | S7: =COUNTIFS(OFÍCIOS!$E:$E,$O7,OFÍCIOS!$G:$G,"PENDENCIA") -> 0 | T7: =COUNTIFS(OFÍCIOS!$E:$E,$O7,OFÍCIOS!$G:$G,"") -> 1 | U7: =SUM(Q7:T7) -> 6 | X7: SS / ANALISE | Y7: 224 | Z7: 275 | AA7: 17
A8: ADAIR DA SILVA BARROS | B8: 97443271620 | E8: 1106 | F8: 42965 | G8: APROVADO | H8: 42978 | O8: 1267 | P8: =COUNTIF(OFÍCIOS!E:E,O8) -> 34 | Q8: =COUNTIFS(OFÍCIOS!$E:$E,$O8,OFÍCIOS!$G:$G,"APROVADO") -> 28 | R8: =COUNTIFS(OFÍCIOS!$E:$E,$O8,OFÍCIOS!$G:$G,"REPROVADO") -> 5 | S8: =COUNTIFS(OFÍCIOS!$E:$E,$O8,OFÍCIOS!$G:$G,"PENDENCIA") -> 1 | T8: =COUNTIFS(OFÍCIOS!$E:$E,$O8,OFÍCIOS!$G:$G,"") -> 0 | U8: =SUM(Q8:T8) -> 34
A9: ADALBERTO CARVALHO DE OLIVEIRA | B9: 98058690597 | E9: 423 | F9: 43182 | G9: APROVADO | O9: 1262 | P9: =COUNTIF(OFÍCIOS!E:E,O9) -> 8 | Q9: =COUNTIFS(OFÍCIOS!$E:$E,$O9,OFÍCIOS!$G:$G,"APROVADO") -> 7 | R9: =COUNTIFS(OFÍCIOS!$E:$E,$O9,OFÍCIOS!$G:$G,"REPROVADO") -> 1 | S9: =COUNTIFS(OFÍCIOS!$E:$E,$O9,OFÍCIOS!$G:$G,"PENDENCIA") -> 0 | T9: =COUNTIFS(OFÍCIOS!$E:$E,$O9,OFÍCIOS!$G:$G,"") -> 0 | U9: =SUM(Q9:T9) -> 8
A10: ADALBERTO CAVALCANTE DOS SANTOS | B10: 38088438888 | O10: 1106 | P10: =COUNTIF(OFÍCIOS!E:E,O10) -> 78 | Q10: =COUNTIFS(OFÍCIOS!$E:$E,$O10,OFÍCIOS!$G:$G,"APROVADO") -> 73 | R10: =COUNTIFS(OFÍCIOS!$E:$E,$O10,OFÍCIOS!$G:$G,"REPROVADO") -> 5 | S10: =COUNTIFS(OFÍCIOS!$E:$E,$O10,OFÍCIOS!$G:$G,"PENDENCIA") -> 0 | T10: =COUNTIFS(OFÍCIOS!$E:$E,$O10,OFÍCIOS!$G:$G,"") -> 0 | U10: =SUM(Q10:T10) -> 78
A11: ADALMA MOREIRA DA ROCHA | B11: 26939799869 | E11: 573 | F11: 43224 | O11: 1128 | P11: =COUNTIF(OFÍCIOS!E:E,O11) -> 92 | Q11: =COUNTIFS(OFÍCIOS!$E:$E,$O11,OFÍCIOS!$G:$G,"APROVADO") -> 91 | R11: =COUNTIFS(OFÍCIOS!$E:$E,$O11,OFÍCIOS!$G:$G,"REPROVADO") -> 1 | S11: =COUNTIFS(OFÍCIOS!$E:$E,$O11,OFÍCIOS!$G:$G,"PENDENCIA") -> 0 | T11: =COUNTIFS(OFÍCIOS!$E:$E,$O11,OFÍCIOS!$G:$G,"") -> 0 | U11: =SUM(Q11:T11) -> 92
A12: ADAMILTON PEREIRA DA SILVA ( ALANA ) | B12: 34470559873 | E12: 292 | F12: 43168 | G12: APROVADO | H12: 43182 | L12: 318 | O12: 1214 | P12: =COUNTIF(OFÍCIOS!E:E,O12) -> 76 | Q12: =COUNTIFS(OFÍCIOS!$E:$E,$O12,OFÍCIOS!$G:$G,"APROVADO") -> 71 | R12: =COUNTIFS(OFÍCIOS!$E:$E,$O12,OFÍCIOS!$G:$G,"REPROVADO") -> 3 | S12: =COUNTIFS(OFÍCIOS!$E:$E,$O12,OFÍCIOS!$G:$G,"PENDENCIA") -> 0 | T12: =COUNTIFS(OFÍCIOS!$E:$E,$O12,OFÍCIOS!$G:$G,"") -> 2 | U12: =SUM(Q12:T12) -> 76
A13: ADAO MENDES AGOSTINHO | B13: 14369564808 | O13: 1241 | P13: =COUNTIF(OFÍCIOS!E:E,O13) -> 33 | Q13: =COUNTIFS(OFÍCIOS!$E:$E,$O13,OFÍCIOS!$G:$G,"APROVADO") -> 32 | R13: =COUNTIFS(OFÍCIOS!$E:$E,$O13,OFÍCIOS!$G:$G,"REPROVADO") -> 0 | S13: =COUNTIFS(OFÍCIOS!$E:$E,$O13,OFÍCIOS!$G:$G,"PENDENCIA") -> 1 | T13: =COUNTIFS(OFÍCIOS!$E:$E,$O13,OFÍCIOS!$G:$G,"") -> 0 | U13: =SUM(Q13:T13) -> 33
A14: ADEGMARIO DOS SANTOS | B14: 39544185844 | E14: 810 | F14: 42915 | G14: APROVADO | H14: 42921 | L14: 568-17 | O14: 1422 | P14: =COUNTIF(OFÍCIOS!E:E,O14) -> 7 | Q14: =COUNTIFS(OFÍCIOS!$E:$E,$O14,OFÍCIOS!$G:$G,"APROVADO") -> 7 | R14: =COUNTIFS(OFÍCIOS!$E:$E,$O14,OFÍCIOS!$G:$G,"REPROVADO") -> 0 | S14: =COUNTIFS(OFÍCIOS!$E:$E,$O14,OFÍCIOS!$G:$G,"PENDENCIA") -> 0 | T14: =COUNTIFS(OFÍCIOS!$E:$E,$O14,OFÍCIOS!$G:$G,"") -> 0 | U14: =SUM(Q14:T14) -> 7
A15: ADEILDA GABRIELA CAITANO SILVA | B15: 38772276860 | C15: LUCIANO MANOEL DA SILVA | D15: 3808243457 | O15: 1439 | P15: =COUNTIF(OFÍCIOS!E:E,O15) -> 16 | Q15: =COUNTIFS(OFÍCIOS!$E:$E,$O15,OFÍCIOS!$G:$G,"APROVADO") -> 14 | R15: =COUNTIFS(OFÍCIOS!$E:$E,$O15,OFÍCIOS!$G:$G,"REPROVADO") -> 1 | S15: =COUNTIFS(OFÍCIOS!$E:$E,$O15,OFÍCIOS!$G:$G,"PENDENCIA") -> 1 | T15: =COUNTIFS(OFÍCIOS!$E:$E,$O15,OFÍCIOS!$G:$G,"") -> 0 | U15: =SUM(Q15:T15) -> 16
A16: ADEILDA RODRIGUES DE OLIVEIRA | B16: 21538837846 | C16: PEDRO LUIZ SANTOS OLIVEIRA | D16: 94203180520 | E16: 810 | F16: 42915 | G16: APROVADO | H16: 42921 | L16: 568-17 | O16: 1451 | P16: =COUNTIF(OFÍCIOS!E:E,O16) -> 4 | Q16: =COUNTIFS(OFÍCIOS!$E:$E,$O16,OFÍCIOS!$G:$G,"APROVADO") -> 3 | R16: =COUNTIFS(OFÍCIOS!$E:$E,$O16,OFÍCIOS!$G:$G,"REPROVADO") -> 1 | S16: =COUNTIFS(OFÍCIOS!$E:$E,$O16,OFÍCIOS!$G:$G,"PENDENCIA") -> 0 | T16: =COUNTIFS(OFÍCIOS!$E:$E,$O16,OFÍCIOS!$G:$G,"") -> 0 | U16: =SUM(Q16:T16) -> 4
A17: ADEILDO ADELINO DE CARVALHO | B17: 57455392591 | O17: 1470 | P17: =COUNTIF(OFÍCIOS!E:E,O17) -> 4 | Q17: =COUNTIFS(OFÍCIOS!$E:$E,$O17,OFÍCIOS!$G:$G,"APROVADO") -> 4 | R17: =COUNTIFS(OFÍCIOS!$E:$E,$O17,OFÍCIOS!$G:$G,"REPROVADO") -> 0 | S17: =COUNTIFS(OFÍCIOS!$E:$E,$O17,OFÍCIOS!$G:$G,"PENDENCIA") -> 0 | T17: =COUNTIFS(OFÍCIOS!$E:$E,$O17,OFÍCIOS!$G:$G,"") -> 0 | U17: =SUM(Q17:T17) -> 4
A18: ADELCIDES DA CONCEICAO ALMEIDA | B18: 5304941594 | E18: 1106 | F18: 42965 | G18: APROVADO | H18: 42978 | O18: 1489 | P18: =COUNTIF(OFÍCIOS!E:E,O18) -> 35 | Q18: =COUNTIFS(OFÍCIOS!$E:$E,$O18,OFÍCIOS!$G:$G,"APROVADO") -> 34 | R18: =COUNTIFS(OFÍCIOS!$E:$E,$O18,OFÍCIOS!$G:$G,"REPROVADO") -> 0 | S18: =COUNTIFS(OFÍCIOS!$E:$E,$O18,OFÍCIOS!$G:$G,"PENDENCIA") -> 1 | T18: =COUNTIFS(OFÍCIOS!$E:$E,$O18,OFÍCIOS!$G:$G,"") -> 0 | U18: =SUM(Q18:T18) -> 35
A19: ADELIA MARIA DE OLIVEIRA | B19: 21600057896 | E19: 262 | F19: 43160 | G19: REPROVADO | H19: 43164 | L19: 255 | O19: 1555 | P19: =COUNTIF(OFÍCIOS!E:E,O19) -> 25 | Q19: =COUNTIFS(OFÍCIOS!$E:$E,$O19,OFÍCIOS!$G:$G,"APROVADO") -> 22 | R19: =COUNTIFS(OFÍCIOS!$E:$E,$O19,OFÍCIOS!$G:$G,"REPROVADO") -> 1 | S19: =COUNTIFS(OFÍCIOS!$E:$E,$O19,OFÍCIOS!$G:$G,"PENDENCIA") -> 2 | T19: =COUNTIFS(OFÍCIOS!$E:$E,$O19,OFÍCIOS!$G:$G,"") -> 0 | U19: =SUM(Q19:T19) -> 25
A20: ADEMARIO FERREIRA DOS SANTOS | B20: 18419589802 | O20: 1570 | P20: =COUNTIF(OFÍCIOS!E:E,O20) -> 24 | Q20: =COUNTIFS(OFÍCIOS!$E:$E,$O20,OFÍCIOS!$G:$G,"APROVADO") -> 23 | R20: =COUNTIFS(OFÍCIOS!$E:$E,$O20,OFÍCIOS!$G:$G,"REPROVADO") -> 1 | S20: =COUNTIFS(OFÍCIOS!$E:$E,$O20,OFÍCIOS!$G:$G,"PENDENCIA") -> 0 | T20: =COUNTIFS(OFÍCIOS!$E:$E,$O20,OFÍCIOS!$G:$G,"") -> 0 | U20: =SUM(Q20:T20) -> 24
A21: ADEMIR DA SILVA LIMA | B21: 15538537846 | E21: 573 | F21: 43224 | O21: 1752 | P21: =COUNTIF(OFÍCIOS!E:E,O21) -> 89 | Q21: =COUNTIFS(OFÍCIOS!$E:$E,$O21,OFÍCIOS!$G:$G,"APROVADO") -> 80 | R21: =COUNTIFS(OFÍCIOS!$E:$E,$O21,OFÍCIOS!$G:$G,"REPROVADO") -> 2 | S21: =COUNTIFS(OFÍCIOS!$E:$E,$O21,OFÍCIOS!$G:$G,"PENDENCIA") -> 5 | T21: =COUNTIFS(OFÍCIOS!$E:$E,$O21,OFÍCIOS!$G:$G,"") -> 2 | U21: =SUM(Q21:T21) -> 89
A22: ADENILDE SANTOS DA SILVA | B22: 899837506 | E22: 1824 | F22: 43091 | G22: APROVADO | H22: 43097 | L22: 1828 | O22: 1824 | P22: =COUNTIF(OFÍCIOS!E:E,O22) -> 81 | Q22: =COUNTIFS(OFÍCIOS!$E:$E,$O22,OFÍCIOS!$G:$G,"APROVADO") -> 67 | R22: =COUNTIFS(OFÍCIOS!$E:$E,$O22,OFÍCIOS!$G:$G,"REPROVADO") -> 7 | S22: =COUNTIFS(OFÍCIOS!$E:$E,$O22,OFÍCIOS!$G:$G,"PENDENCIA") -> 6 | T22: =COUNTIFS(OFÍCIOS!$E:$E,$O22,OFÍCIOS!$G:$G,"") -> 1 | U22: =SUM(Q22:T22) -> 81
A23: ADENILSON DA CONCEICAO | B23: 36197160803 | E23: 229 | F23: 43151 | G23: APROVADO | L23: 232 | O23: 1628 | P23: =COUNTIF(OFÍCIOS!E:E,O23) -> 6 | Q23: =COUNTIFS(OFÍCIOS!$E:$E,$O23,OFÍCIOS!$G:$G,"APROVADO") -> 5 | R23: =COUNTIFS(OFÍCIOS!$E:$E,$O23,OFÍCIOS!$G:$G,"REPROVADO") -> 1 | S23: =COUNTIFS(OFÍCIOS!$E:$E,$O23,OFÍCIOS!$G:$G,"PENDENCIA") -> 0 | T23: =COUNTIFS(OFÍCIOS!$E:$E,$O23,OFÍCIOS!$G:$G,"") -> 0 | U23: =SUM(Q23:T23) -> 6
A24: ADENIR MODESTO RIBEIRO | B24: 39248826814 | E24: 292 | F24: 43168 | G24: APROVADO | H24: 43182 | L24: 318 | O24: 608 | P24: =COUNTIF(OFÍCIOS!E:E,O24) -> 35 | Q24: =COUNTIFS(OFÍCIOS!$E:$E,$O24,OFÍCIOS!$G:$G,"APROVADO") -> 31 | R24: =COUNTIFS(OFÍCIOS!$E:$E,$O24,OFÍCIOS!$G:$G,"REPROVADO") -> 3 | S24: =COUNTIFS(OFÍCIOS!$E:$E,$O24,OFÍCIOS!$G:$G,"PENDENCIA") -> 1 | T24: =COUNTIFS(OFÍCIOS!$E:$E,$O24,OFÍCIOS!$G:$G,"") -> 0 | U24: =SUM(Q24:T24) -> 35
A25: ADILINA FARIAS DO NASCIMENTO | B25: 48925276534 | E25: 229 | F25: 43151 | L25: 232 | O25: 527 | P25: =COUNTIF(OFÍCIOS!E:E,O25) -> 29 | Q25: =COUNTIFS(OFÍCIOS!$E:$E,$O25,OFÍCIOS!$G:$G,"APROVADO") -> 0 | R25: =COUNTIFS(OFÍCIOS!$E:$E,$O25,OFÍCIOS!$G:$G,"REPROVADO") -> 0 | S25: =COUNTIFS(OFÍCIOS!$E:$E,$O25,OFÍCIOS!$G:$G,"PENDENCIA") -> 0 | T25: =COUNTIFS(OFÍCIOS!$E:$E,$O25,OFÍCIOS!$G:$G,"") -> 29 | U25: =SUM(Q25:T25) -> 29
A26: ADILSON SOARES DA COSTA | O26: 509 | P26: =COUNTIF(OFÍCIOS!E:E,O26) -> 14 | Q26: =COUNTIFS(OFÍCIOS!$E:$E,$O26,OFÍCIOS!$G:$G,"APROVADO") -> 0 | R26: =COUNTIFS(OFÍCIOS!$E:$E,$O26,OFÍCIOS!$G:$G,"REPROVADO") -> 0 | S26: =COUNTIFS(OFÍCIOS!$E:$E,$O26,OFÍCIOS!$G:$G,"PENDENCIA") -> 0 | T26: =COUNTIFS(OFÍCIOS!$E:$E,$O26,OFÍCIOS!$G:$G,"") -> 14 | U26: =SUM(Q26:T26) -> 14
A27: ADMEIA BARBOSA DE SOUZA | B27: 25894152810 | C27: REINALDO SANTOS REIS | D27: 8263008808 | E27: 292 | F27: 43168 | G27: APROVADO | H27: 43182 | L27: 318 | O27: 292 | P27: =COUNTIF(OFÍCIOS!E:E,O27) -> 233 | Q27: =COUNTIFS(OFÍCIOS!$E:$E,$O27,OFÍCIOS!$G:$G,"APROVADO") -> 212 | R27: =COUNTIFS(OFÍCIOS!$E:$E,$O27,OFÍCIOS!$G:$G,"REPROVADO") -> 9 | S27: =COUNTIFS(OFÍCIOS!$E:$E,$O27,OFÍCIOS!$G:$G,"PENDENCIA") -> 0 | T27: =COUNTIFS(OFÍCIOS!$E:$E,$O27,OFÍCIOS!$G:$G,"") -> 12 | U27: =SUM(Q27:T27) -> 233
A28: ADONES FERREIRA JORGE | B28: 43026389587 | C28: EUNICE FELICIANA BRITO JORGE | D28: 29124464813 | E28: 485 | F28: 43196 | H28: 43206 | L28: 483 | O28: 573 | P28: =COUNTIF(OFÍCIOS!E:E,O28) -> 43 | Q28: =COUNTIFS(OFÍCIOS!$E:$E,$O28,OFÍCIOS!$G:$G,"APROVADO") -> 0 | R28: =COUNTIFS(OFÍCIOS!$E:$E,$O28,OFÍCIOS!$G:$G,"REPROVADO") -> 0 | S28: =COUNTIFS(OFÍCIOS!$E:$E,$O28,OFÍCIOS!$G:$G,"PENDENCIA") -> 0 | T28: =COUNTIFS(OFÍCIOS!$E:$E,$O28,OFÍCIOS!$G:$G,"") -> 43 | U28: =SUM(Q28:T28) -> 43
A29: ADRIANA ALVES DA SILVA | B29: 26245112885 | E29: 262 | F29: 43160 | G29: REPROVADO | H29: 43164 | L29: 255 | O29: 563 | P29: =COUNTIF(OFÍCIOS!E:E,O29) -> 64 | Q29: =COUNTIFS(OFÍCIOS!$E:$E,$O29,OFÍCIOS!$G:$G,"APROVADO") -> 0 | R29: =COUNTIFS(OFÍCIOS!$E:$E,$O29,OFÍCIOS!$G:$G,"REPROVADO") -> 0 | S29: =COUNTIFS(OFÍCIOS!$E:$E,$O29,OFÍCIOS!$G:$G,"PENDENCIA") -> 0 | T29: =COUNTIFS(OFÍCIOS!$E:$E,$O29,OFÍCIOS!$G:$G,"") -> 64 | U29: =SUM(Q29:T29) -> 64
A30: ADRIANA ALVES FERREIRA | B30: 36531080809 | C30: MARCIO ROSA DE MIRA | D30: 22485483892 | E30: 1489 | F30: 43038 | G30: APROVADO | L30: 1647-17 | O30: 443 | P30: =COUNTIF(OFÍCIOS!E:E,O30) -> 66 | Q30: =COUNTIFS(OFÍCIOS!$E:$E,$O30,OFÍCIOS!$G:$G,"APROVADO") -> 0 | R30: =COUNTIFS(OFÍCIOS!$E:$E,$O30,OFÍCIOS!$G:$G,"REPROVADO") -> 0 | S30: =COUNTIFS(OFÍCIOS!$E:$E,$O30,OFÍCIOS!$G:$G,"PENDENCIA") -> 0 | T30: =COUNTIFS(OFÍCIOS!$E:$E,$O30,OFÍCIOS!$G:$G,"") -> 66 | U30: =SUM(Q30:T30) -> 66
A31: ADRIANA APARECIDA ROBERTO | B31: 28147186819 | C31: CARLOS ANTONIO BATISTA DOS SANTOS | D31: 24499714400 | O31: 423 | P31: =COUNTIF(OFÍCIOS!E:E,O31) -> 9 | Q31: =COUNTIFS(OFÍCIOS!$E:$E,$O31,OFÍCIOS!$G:$G,"APROVADO") -> 7 | R31: =COUNTIFS(OFÍCIOS!$E:$E,$O31,OFÍCIOS!$G:$G,"REPROVADO") -> 1 | S31: =COUNTIFS(OFÍCIOS!$E:$E,$O31,OFÍCIOS!$G:$G,"PENDENCIA") -> 0 | T31: =COUNTIFS(OFÍCIOS!$E:$E,$O31,OFÍCIOS!$G:$G,"") -> 1 | U31: =SUM(Q31:T31) -> 9
A32: ADRIANA ARAUJO DE LIMA | B32: 37559228860 | C32: ALEXANDRO ARAUJO DE LIMA | D32: 28072024892 | E32: 1555 | F32: 43049 | G32: APROVADO | O32: 229 | P32: =COUNTIF(OFÍCIOS!E:E,O32) -> 89 | Q32: =COUNTIFS(OFÍCIOS!$E:$E,$O32,OFÍCIOS!$G:$G,"APROVADO") -> 81 | R32: =COUNTIFS(OFÍCIOS!$E:$E,$O32,OFÍCIOS!$G:$G,"REPROVADO") -> 2 | S32: =COUNTIFS(OFÍCIOS!$E:$E,$O32,OFÍCIOS!$G:$G,"PENDENCIA") -> 5 | T32: =COUNTIFS(OFÍCIOS!$E:$E,$O32,OFÍCIOS!$G:$G,"") -> 1 | U32: =SUM(Q32:T32) -> 89
A33: ADRIANA CORDEIRO MACHADO | B33: 23635229822 | C33: ANDERSON DE MORAIS SANTOS | D33: 21668057875 | E33: 262 | F33: 43160 | G33: APROVADO | H33: 43164 | L33: 255 | O33: 262 | P33: =COUNTIF(OFÍCIOS!E:E,O33) -> 224 | Q33: =COUNTIFS(OFÍCIOS!$E:$E,$O33,OFÍCIOS!$G:$G,"APROVADO") -> 181 | R33: =COUNTIFS(OFÍCIOS!$E:$E,$O33,OFÍCIOS!$G:$G,"REPROVADO") -> 15 | S33: =COUNTIFS(OFÍCIOS!$E:$E,$O33,OFÍCIOS!$G:$G,"PENDENCIA") -> 0 | T33: =COUNTIFS(OFÍCIOS!$E:$E,$O33,OFÍCIOS!$G:$G,"") -> 28 | U33: =SUM(Q33:T33) -> 224
A34: ADRIANA DA SILVA | O34: 117 | P34: =COUNTIF(OFÍCIOS!E:E,O34) -> 91 | Q34: =COUNTIFS(OFÍCIOS!$E:$E,$O34,OFÍCIOS!$G:$G,"APROVADO") -> 77 | R34: =COUNTIFS(OFÍCIOS!$E:$E,$O34,OFÍCIOS!$G:$G,"REPROVADO") -> 7 | S34: =COUNTIFS(OFÍCIOS!$E:$E,$O34,OFÍCIOS!$G:$G,"PENDENCIA") -> 5 | T34: =COUNTIFS(OFÍCIOS!$E:$E,$O34,OFÍCIOS!$G:$G,"") -> 2 | U34: =SUM(Q34:T34) -> 91
A35: ADRIANA DA SILVA SANTOS | B35: 40902634844 | C35: GUILHERME DE OLIVEIRA SOUZA | D35: 23795007895 | E35: 117 | F35: 43117 | G35: APROVADO | H35: 43151 | L35: 118-18 | O35: 485 | P35: =COUNTIF(OFÍCIOS!E:E,O35) -> 23 | Q35: =COUNTIFS(OFÍCIOS!$E:$E,$O35,OFÍCIOS!$G:$G,"APROVADO") -> 0 | R35: =COUNTIFS(OFÍCIOS!$E:$E,$O35,OFÍCIOS!$G:$G,"REPROVADO") -> 3 | S35: =COUNTIFS(OFÍCIOS!$E:$E,$O35,OFÍCIOS!$G:$G,"PENDENCIA") -> 0 | T35: =COUNTIFS(OFÍCIOS!$E:$E,$O35,OFÍCIOS!$G:$G,"") -> 20 | U35: =SUM(Q35:T35) -> 23
A36: ADRIANA DE SA ROCHA | B36: 39615629898 | C36: MARCELO FERNANDES LIMA | D36: 43328275894 | E36: 423 | F36: 43182 | G36: APROVADO | O36: 85 | P36: =COUNTIF(OFÍCIOS!E:E,O36) -> 93 | Q36: =COUNTIFS(OFÍCIOS!$E:$E,$O36,OFÍCIOS!$G:$G,"APROVADO") -> 86 | R36: =COUNTIFS(OFÍCIOS!$E:$E,$O36,OFÍCIOS!$G:$G,"REPROVADO") -> 4 | S36: =COUNTIFS(OFÍCIOS!$E:$E,$O36,OFÍCIOS!$G:$G,"PENDENCIA") -> 3 | T36: =COUNTIFS(OFÍCIOS!$E:$E,$O36,OFÍCIOS!$G:$G,"") -> 0 | U36: =SUM(Q36:T36) -> 93
A37: ADRIANA DOS SANTOS | P37: =COUNTIF(OFÍCIOS!E:E,O37) -> 0 | Q37: =COUNTIFS(OFÍCIOS!$E:$E,$O37,OFÍCIOS!$G:$G,"APROVADO") -> 0 | R37: =COUNTIFS(OFÍCIOS!$E:$E,$O37,OFÍCIOS!$G:$G,"REPROVADO") -> 0 | S37: =COUNTIFS(OFÍCIOS!$E:$E,$O37,OFÍCIOS!$G:$G,"PENDENCIA") -> 0 | T37: =COUNTIFS(OFÍCIOS!$E:$E,$O37,OFÍCIOS!$G:$G,"") -> 0 | U37: =SUM(Q37:T37) -> 0
A38: ADRIANA FERREIRA DA SILVA | C38: LOURIVAL CANDIDO SILVA | P38: =COUNTIF(OFÍCIOS!E:E,O38) -> 0 | Q38: =COUNTIFS(OFÍCIOS!$E:$E,$O38,OFÍCIOS!$G:$G,"APROVADO") -> 0 | R38: =COUNTIFS(OFÍCIOS!$E:$E,$O38,OFÍCIOS!$G:$G,"REPROVADO") -> 0 | S38: =COUNTIFS(OFÍCIOS!$E:$E,$O38,OFÍCIOS!$G:$G,"PENDENCIA") -> 0 | T38: =COUNTIFS(OFÍCIOS!$E:$E,$O38,OFÍCIOS!$G:$G,"") -> 0 | U38: =SUM(Q38:T38) -> 0
A39: ADRIANA HELENA DE MORAIS | B39: 14268808809 | E39: 262 | F39: 43160 | G39: APROVADO | H39: 43164 | L39: 255 | P39: =COUNTIF(OFÍCIOS!E:E,O39) -> 0 | Q39: =COUNTIFS(OFÍCIOS!$E:$E,$O39,OFÍCIOS!$G:$G,"APROVADO") -> 0 | R39: =COUNTIFS(OFÍCIOS!$E:$E,$O39,OFÍCIOS!$G:$G,"REPROVADO") -> 0 | S39: =COUNTIFS(OFÍCIOS!$E:$E,$O39,OFÍCIOS!$G:$G,"PENDENCIA") -> 0 | T39: =COUNTIFS(OFÍCIOS!$E:$E,$O39,OFÍCIOS!$G:$G,"") -> 0 | U39: =SUM(Q39:T39) -> 0
A40: ADRIANA JESUS DA CUNHA | B40: 29628693867 | E40: 292 | F40: 43168 | G40: APROVADO | H40: 43182 | L40: 318 | P40: =COUNTIF(OFÍCIOS!E:E,O40) -> 0 | Q40: =COUNTIFS(OFÍCIOS!$E:$E,$O40,OFÍCIOS!$G:$G,"APROVADO") -> 0 | R40: =COUNTIFS(OFÍCIOS!$E:$E,$O40,OFÍCIOS!$G:$G,"REPROVADO") -> 0 | S40: =COUNTIFS(OFÍCIOS!$E:$E,$O40,OFÍCIOS!$G:$G,"PENDENCIA") -> 0 | T40: =COUNTIFS(OFÍCIOS!$E:$E,$O40,OFÍCIOS!$G:$G,"") -> 0 | U40: =SUM(Q40:T40) -> 0
...

Sheet DEPLAN
E4: ÁREA | F4: SELO | G4: PROPRIETÁRIO | H4: CPF | I4: No PROCESSO SEI (INDENIZAÇÃO)
E5: JD. VITÓRIA | F5: 002/0002/A | G5: ELIAS FERREIRA DE SOUSA | H5: 530.102.098-60 | I5: 6014.2025/0004924-8
E6: JD. VITÓRIA | F6: 002/0053/A | G6: GEOVANE SOUZA SANTOS | H6: 429.418.998-39 | I6: 6014.2025/0008040-4
E7: JD. VITÓRIA | F7: 007/0041/A | G7: REINALDO MOREIRA SILVA | H7: 702.612.337-72 | I7: 6014.2025/0008179-6
E8: JD. VITÓRIA | F8: 007/0055/A | G8: IVANILDA PEREIRA DE SOUZA | H8: 346.774.738-89 | I8: 6014.2025/0005014-9
E9: JD. VITÓRIA | F9: 009/0012/A | G9: JACKSON NASCIMENTO DOS SANTOS | H9: 433.472.938-00 | I9: 6014.2025/0006392-5
E10: JD. VITÓRIA | F10: 009/0012/B | G10: ELIANE MARIA NASCIMENTO DOS SANTOS | H10: 012.722.274-05 | I10: 6014.2025/0006669-0
E11: JD. VITÓRIA | F11: 009/0012/C | G11: JOICE NASCIMENTO DOS SANTOS | H11: 506.567.788-30 | I11: 6014.2025/0006662-2
E12: JD. VITÓRIA | F12: 009/0020/A | G12: MILTON PEREIRA DOS SANTOS | H12: 011.914.478-63 | I12: 6014.2025/0005381-4
E13: JD. VITÓRIA | F13: 009/0023/A | G13: ELIZABETH DE MENDONÇA ALMEIDA SANTANA | H13: 064.108.154-50 | I13: 6014.2025/0007987-2
E14: JD. VITÓRIA | F14: 010/0009/A | G14: LUCIENE CARDOSO PEREIRA | H14: 256.444.508-06 | I14: 6014.2025/0006290-2
E15: JD. VITÓRIA | F15: 010/0012/A | G15: GLAUSIEL DE JESUS MACIEL | H15: 041.406.735.59 | I15: 6014.2025/0006005-5
... E26: JD. VITÓRIA | F26: 016/0029/A | G26: EDNA MARIA BEZERRA DOS REIS | H26: 316.803.158-54 | I26: 6014.2025/0005958-8
E43: JD. VITÓRIA
E44: JD. VITÓRIA
E45: JD. VITÓRIA
E46: JD. VITÓRIA
E47: JD. VITÓRIA
E48: JD. VITÓRIA
E49: JD. VITÓRIA
E50: JD. VITÓRIA
E51: JD. VITÓRIA
E52: JD. VITÓRIA
E53: JD. VITÓRIA

Sheet Quantitativo Fora da Demanda
A1: REPROVADOS QUE NÃO DEVERÃO SER REASSENTADOS NO ESPANHA | E1: APROVADOS SEM CONDOMÍNIO QUE DEVERÃO SER REASSENTADOS NO CHÁCARA DO CONDE
A2: ÁREA | B2: QTD | E2: ÁREA | F2: QTD
A3: AUXÍLIO ALUGUEL | B3: 39 | E3: AUXÍLIO ALUGUEL | F3: 54
A4: CANTINHO DO CÉU (OBRAS) | B4: 15 | E4: CANTINHO DO CÉU (OBRAS) SETORES: 138 E 140 | F4: 13
A5: FUMAÇA | B5: 7 | E5: FUMAÇA | F5: 15
A6: NEBLINA | B6: 2 | E6: NEBLINA | F6: 9
A7: LEBLON | B7: 0 | E7: LEBLON | F7: 9
A8: PABREU / PRAINHA | B8: 15 | E8: PABREU / PRAINHA | F8: 21
A9: TOTAL | B9: =SUM(B3:B8) -> 78 | E9: TOTAL | F9: =SUM(F3:F8) -> 121

Sheet Planilha3
B3: ÁREA | C3: FASE | D3: SELO | E3: PROPRIETÁRIO | F3: CPF | G3: STATUS | H3: VALOR INDENIZAÇÃO
B4: PARAISÓPOLIS/ANTONICO | C4: 2 | D4: 024/0005/B | E4: MARIA JOSE HONORIO SILVA | F4: 397.255.294-72 | G4: RECUSA INDENIZAÇÃO | H4: 66528.26
B5: PARAISÓPOLIS/ANTONICO | C5: 2 | D5: 024/0005/C | E5: DOUGLAS FELIX DA SILVA | F5: 350.792.428-50 | G5: RECUSA INDENIZAÇÃO | H5: 60000
B6: PARAISÓPOLIS/ANTONICO | C6: 2 | D6: 024/0005/D | E6: DOUGLAS FELIX DA SILVA | F6: 350.792.428-50 | G6: RECUSA INDENIZAÇÃO | H6: 60000
B7: PARAISÓPOLIS/ANTONICO | C7: 2 | D7: 024/0045/A | E7: JOVINA DE JESUS SANTANA | F7: 252.848.568-99 | G7: RECUSA INDENIZAÇÃO | H7: 71112.51
B8: PARAISÓPOLIS/ANTONICO | C8: 2 | D8: 024/0046/A | E8: JOÃO BRASILINO DE SOUSA | F8: 014.102.728-26 | G8: RECUSA INDENIZAÇÃO | H8: 100370.59
B9: PARAISÓPOLIS/ANTONICO | C9: 2 | D9: 024/0047/F | E9: ROSA HELENA DE SOUZA | F9: 291.466.998-48 | G9: RECUSA INDENIZAÇÃO | H9: 60000
B10: PARAISÓPOLIS/ANTONICO | C10: 2 | D10: 024/0053/A | E10: SELMA SOARES SANTOS DE OLIVEIRA | F10: 324.973.128-50 | G10: RECUSA INDENIZAÇÃO | H10: 60000
B11: PARAISÓPOLIS/ANTONICO | C11: 2 | D11: 024/0077/A | E11: PROPRIETÁRIO NÃO IDENTIFICADO | F11: -- | G11: RECUSA INDENIZAÇÃO | H11: 60000
B12: PARAISÓPOLIS/ANTONICO | C12: 2 | D12: 024/0077/B | E12: LUCIANA FRANCILINO DE LIMA | F12: 296.566.438-60 | G12: RECUSA INDENIZAÇÃO | H12: 87351.82
B13: PARAISÓPOLIS/ANTONICO | C13: 2 | D13: 024/0079/D | E13: EUDES GONÇALVES CAVALCANTE | F13: 064.025.638-46 | G13: RECUSA INDENIZAÇÃO | H13: 56418.89
B14: PARAISÓPOLIS/ANTONICO | C14: 2 | D14: 024/0079/G | E14: EUDES GONÇALVES CAVALCANTI | F14: 064.025.638-46 | G14: RECUSA INDENIZAÇÃO | H14: 60000
B15: PARAISÓPOLIS/ANTONICO | C15: 4 | D15: 029/0016/C | E15: ADINALDO GOMES DA SILVA | F15: 975.984.883-04 | G15: RECUSA INDENIZAÇÃO | H15: 60000
... B17: PARAISÓPOLIS/ANTONICO | C17: 4 | D17: 029/0086/D | E17: EDUARDO FERNANDES | F17: -- | G17: RECUSA INDENIZAÇÃO | H17: 60000
B23: PARAISÓPOLIS/ANTONICO | C23: 2 | D23: 024/0079/D | E23: EUDES GONÇALVES CAVALCANTE | F23: 064.025.638-46 | G23: ESTUDO DE CASO
B24: PARAISÓPOLIS/ANTONICO | C24: 2 | D24: 024/0079/E | E24: DANIELE COSTA | F24: 374.435.458-00 | G24: ESTUDO DE CASO
B25: PARAISÓPOLIS/ANTONICO | C25: 2 | D25: 024/0079/F | G25: ESTUDO DE CASO
B26: PARAISÓPOLIS/ANTONICO | C26: 2 | D26: 024/0079/G | E26: EUDES GONÇALVES CAVALCANTI | F26: 064.025.638-46 | G26: ESTUDO DE CASO
B27: PARAISÓPOLIS/ANTONICO | C27: 2 | D27: 024/0079/J | E27: ELIO NEVES DE SOUZA | F27: 350.318.858-40 | G27: RECUSA
B28: PARAISÓPOLIS/ANTONICO | C28: 2 | D28: 024/0082/A | E28: IVÃ CERQUEIRA LENARES | F28: 006.868.775-35 | G28: PENDENTE
B29: PARAISÓPOLIS/ANTONICO | C29: 2 | D29: 024/0082/D | E29: JOÃO VITOR DE SANTANA | F29: 534.193.048-70 | G29: ESTUDO DE CASO
B30: PARAISÓPOLIS/ANTONICO | C30: 2 | D30: 024/0088/K | E30: MARIA APARECIDA FLECKENSTEIN VIEIRA | F30: 304.821.048-21 | G30: ESTUDO DE CASO
B31: PARAISÓPOLIS/ANTONICO | C31: 2 | D31: 024/0088/M | E31: PROPRIETÁRIO NÃO IDENTIFICADO | F31: N/A | G31: PROPRIETÁRIO NÃO IDENTIFICADO
B32: PARAISÓPOLIS/ANTONICO | C32: 2 | D32: 027/0002/E | G32: PROPRIETÁRIO NÃO IDENTIFICADO
B33: PARAISÓPOLIS/ANTONICO | C33: 2 | D33: 027/0012/C | G33: PROPRIETÁRIO NÃO IDENTIFICADO

Sheet Planilha4
C6: ORDEM | D6: SELO | E6: DATA PAGAMENTO | F6: DATA ENTREGA IMÓVEL | G6: SITUAÇÃO ATUAL IMÓVEL
C7: 1 | D7: 024/0049/B | E7: 45068 | F7: AGUARDANDO | G7: LIBERADO DEMOLIÇÃO
C8: 2 | D8: 029/0036/O | E8: 45068 | F8: AGUARDANDO | G8: LIBERADO DEMOLIÇÃO
C9: 3 | D9: 031/0028/D | E9: 45068 | F9: 44894 | G9: DESCARACTERIZADO
C10: 4 | D10: 031/0034/H | E10: 45068 | F10: AGUARDANDO | G10: LIBERADO DEMOLIÇÃO
C11: 5 | D11: 024/0093/B | E11: 45065 | F11: AGUARDANDO | G11: LIBERADO DEMOLIÇÃO
C12: 6 | D12: 029/0036/P | E12: 45065 | F12: AGUARDANDO | G12: LIBERADO DEMOLIÇÃO
C13: 7 | D13: 029/0042/A | E13: 45065 | F13: AGUARDANDO | G13: LIBERADO DEMOLIÇÃO
C14: 8 | D14: 029/0081/A | E14: 45065 | F14: 44526 | G14: DEMOLIDO
C15: 9 | D15: 029/0083/A | E15: 45065 | F15: 44642 | G15: DEMOLIDO
C16: 10 | D16: 031/0020/B | E16: 45065 | F16: 44694 | G16: DESCARACTERIZADO
C17: 11 | D17: 031/0023/B | E17: 45065 | F17: AGUARDANDO | G17: LIBERADO DEMOLIÇÃO
C18: 12 | D18: 031/0024/A | E18: 45065 | F18: 44659 | G18: DESCARACTERIZADO
C19: 13 | D19: 024/0079/A | E19: 45064 | F19: AGUARDANDO | G19: LIBERADO DEMOLIÇÃO
C20: 14 | D20: 024/0082/H | E20: 45064 | F20: AGUARDANDO | G20: LIBERADO DEMOLIÇÃO
C21: 15 | D21: 029/0022/A | E21: 45064 | F21: AGUARDANDO | G21: LIBERADO DEMOLIÇÃO
C22: 16 | D22: 029/0022/D | E22: 45064 | F22: AGUARDANDO | G22: LIBERADO DEMOLIÇÃO
C23: 17 | D23: 029/0035/A | E23: 45064 | F23: 44859 | G23: DEMOLIDO
C24: 18 | D24: 029/0036/L | E24: 45064 | F24: AGUARDANDO | G24: LIBERADO DEMOLIÇÃO
C25: 19 | D25: 029/0036/N | E25: 45064 | F25: AGUARDANDO | G25: LIBERADO DEMOLIÇÃO
C26: 20 | D26: 031/0035/A | E26: 45064 | F26: 44643 | G26: DESCARACTERIZADO
C27: 21 | D27: 031/0035/F | E27: 45064 | F27: 44638 | G27: DESCARACTERIZADO
C28: 22 | D28: 031/0058/E | E28: 45064 | F28: AGUARDANDO | G28: LIBERADO DEMOLIÇÃO
C29: 23 | D29: 031/0058/H | E29: 45064 | F29: AGUARDANDO | G29: LIBERADO DEMOLIÇÃO
C30: 24 | D30: 031/0078/G | E30: 45064 | F30: AGUARDANDO | G30: LIBERADO DEMOLIÇÃO
C31: 25 | D31: 024/0004/B | E31: 45063 | F31: AGUARDANDO | G31: LIBERADO DEMOLIÇÃO
C32: 26 | D32: 024/0050/B | E32: 45063 | F32: AGUARDANDO | G32: LIBERADO DEMOLIÇÃO
C33: 27 | D33: 024/0074/A | E33: 45063 | F33: AGUARDANDO | G33: LIBERADO DEMOLIÇÃO
C34: 28 | D34: 024/0074/D | E34: 45063 | F34: AGUARDANDO | G34: LIBERADO DEMOLIÇÃO
C35: 29 | D35: 024/0078/B | E35: 45063 | F35: AGUARDANDO | G35: LIBERADO DEMOLIÇÃO
C36: 30 | D36: 024/0082/C | E36: 45063 | F36: AGUARDANDO | G36: LIBERADO DEMOLIÇÃO
C37: 31 | D37: 024/0093/A | E37: 45063 | F37: AGUARDANDO | G37: LIBERADO DEMOLIÇÃO
C38: 32 | D38: 031/0022/B | E38: 45063 | F38: 44655 | G38: DESCARACTERIZADO
C39: 33 | D39: 031/0028/L | E39: 45063 | F39: 44659 | G39: DESCARACTERIZADO
C40: 34 | D40: 031/0030/B | E40: 45063 | F40: AGUARDANDO | G40: LIBERADO DEMOLIÇÃO
C41: 35 | D41: 031/0030/C | E41: 45063 | F41: 44642 | G41: DESCARACTERIZADO
C42: 36 | D42: 031/0033/E | E42: 45063 | F42: 44638 | G42: DESCARACTERIZADO
C43: 37 | D43: 031/0034/A | E43: 45063 | F43: AGUARDANDO | G43: LIBERADO DEMOLIÇÃO
C44: 38 | D44: 031/0034/B | E44: 45063 | F44: AGUARDANDO | G44: LIBERADO DEMOLIÇÃO
C45: 39 | D45: 031/0034/E | E45: 45063 | F45: AGUARDANDO | G45: LIBERADO DEMOLIÇÃO
...

Sheet Planilha5
D3: ÁREA | E3: No PROCESSO SEI (INDENIZAÇÃO) | F3: VALOR COM BONIFICAÇÃO
D4: PARAISÓPOLIS/ANTONICO | E4: 6014.2023/0002356-3 | F4: 60000
D5: PARAISÓPOLIS/ANTONICO | E5: 6014.2023/0001968-0 | F5: 53382.82
D6: PARAISÓPOLIS/ANTONICO | E6: 6014.2023/0001973-6 | F6: 55091.16
D7: PARAISÓPOLIS/ANTONICO | E7: 6014.2023/0001445-9 | F7: 71112.51
D8: PARAISÓPOLIS/ANTONICO | E8: 6014.2023/0002108-0 | F8: 60000
D9: PARAISÓPOLIS/ANTONICO | E9: 6014.2023/0001334-7 | F9: 60000
D10: PARAISÓPOLIS/ANTONICO | E10: 6014.2023/0001523-4 | F10: 60000
D11: PARAISÓPOLIS/ANTONICO | E11: 6014.2023/0001799-7 | F11: 60000
D12: PARAISÓPOLIS/ANTONICO | E12: 6014.2023/0000796-7 | F12: 48801.81
D13: PARAISÓPOLIS/ANTONICO | E13: 6014.2023/0003032-2 | F13: 60000
D14: PARAISÓPOLIS/ANTONICO | E14: 6014.2023/0001144-1 | F14: 48087.05
