Workbook
Name Adequacao_Imovel: 'Listas (não utilizar)'!$G$2:$G$7
Name ADEQUAR: 'Listas (não utilizar)'!$G$2:$G$7
Name Apartamento: 'Listas (não utilizar)'!$D$2:$D$21
Name APROVCEF: #REF!
Name Área: 'Listas (não utilizar)'!$A$2:$A$28
Name AREAS: #REF!
Name AVILDATA: #REF!
Name AVILDATA1: #REF!
Name BARCDATA: #REF!
Name BILBDATA: #REF!
Name Bloco: 'Listas (não utilizar)'!$C$2:$C$16
Name CEF: #REF!
Name CEUTDATA: #REF!
Name Condomínio: 'Listas (não utilizar)'!$B$2:$B$15
Name INDDEMAND: #REF!
Name INDEMAND: #REF!
Name it: #REF!
Name Pendência: 'Listas (não utilizar)'!$I$2:$I$7
Name PLANCCO: #REF!
Name Renúncia: 'Listas (não utilizar)'!$H$2:$H$6
Name RetornoSMADS: '[1]Listas (não utilizar)'!$E$2:$E$3
Name selogo: #REF!
Name selomv: #REF!
Name selos_go: #REF!
Name selosgo: #REF!
Name selosgo1: #REF!
Name SITAH_CAIXA: 'Listas (não utilizar)'!$E$2:$E$9
Name StatusCAIXA: 'Listas (não utilizar)'!$F$2:$F$5
Name TEPROC: #REF!
Name TEPROC1: #REF!

Sheet PRIORIDADES
C3: 2 | D3: PRIORITÁRIO | G3: OCUPADO | H3: RESIDENCIAL | I3: PROPRIETÁRIO NÃO RESIDENTE | M3: CADASTRADO | N3: INDENIZAÇÃO | P3: SIM | R3: SIM | X3: SAQUE PENDENTE | AE3: PROPRIETÁRIO NÃO RESIDENTE | AF3: CADASTRADO | AI3: SIM | AK3: SIM | AM3: COMPLETA | AN3: SEM PENDÊNCIAS
C4: 4 | G4: VAZIO | H4: COMERCIAL | I4: PROPRIETÁRIO RESIDENTE | M4: NÃO CADASTRADO | N4: AUXÍLIO ALUGUEL UH | P4: NÃO | R4: NÃO | AE4: PROPRIETÁRIO RESIDENTE | AF4: NÃO CADASTRADO | AI4: NÃO | AK4: NÃO | AM4: PENDENTE | AN4: FALTA TERMO
G5: OCUPADO/RISCO | H5: MISTO | I5: INQULINO | N5: RECUSA AUXÍLIO ALUGUEL UH | AI5: UH | AK5: N/A | AN5: FALTA DOCS
G6: CONSTRUÇÃO | N6: NÃO TEM DIREITO ATENDIMENTO | AI6: ESTUDO DE CASO | AK6: PENDENTE | AN6: FALTA TERMO E DOCS
G7: DEMOLIDO
G8: DESCARACTERIZADO
G9: DESABADO
A12: INFORMAÇÕES INICIAIS | P12: INFORMAÇÕES AUXÍLIO ALUGUEL | AB12: INFORMAÇÕES INDENIZAÇÃO | BB12: PROCESSO | BD12: DEPLAN
A13: ORDEM | B13: ÁREA | C13: FASE | D13: TRECHO | E13: PRIORIDADE | F13: SELO | G13: SITUAÇÃO INICIAL IMÓVEL | H13: USO IMÓVEL | I13: SITUAÇÃO DO RESIDENTE | J13: TITULAR | K13: RG | L13: CPF | M13: CADASTRO HABITA SAMPA | N13: OPÇÃO DE ATENDIMENTO HABITACIONAL | O13: ENVIO PLANILHA DADOS | P13: SOLICITAÇÃO AUXÍLIO ALUGUEL ÁREA | Q13: No PROCESSO SEI (AUXÍLIO ALUGUEL) | R13: ANÁLISE DTS CADASTRO + CHECAGEM DUPLO | S13: INSTRUÇÃO PROCESSO SEI DTS | T13: ANÁLISE CTS ASSINATURA GABINETE | U13: DATA PUBLICAÇÃO DIÁRIO OFICIAL | V13: CONFECÇÃO TERMO | W13: ENVIO TERMO CARTÃO | X13: PREVISÃO PAGAMENTO | Y13: DATA SAQUE | Z13: DATA MUDANÇA | AA13: OBSERVAÇÕES AA | AB13: PROPRIETÁRIO | AC13: RG | AD13: CPF | AE13: SITUAÇÃO DO PROPRIETÁRIO | AF13: CADASTRO HABITASAMPA | AG13: VALOR AVALIAÇÃO | AH13: VALOR FINAL INDENIZAÇÃO | AI13: ACEITA VALOR INDENIZAÇÃO | AJ13: Nº SEI LAUDOS AVALIAÇÃO | AK13: Nº DOCUMENTO LAUDO | AL13: TERMO INDENIZAÇÃO | AM13: DOSSIÊ | AN13: PENDÊNCIA | AO13: OBSERVAÇÕES INDENIZAÇÃO | AP13: No PROCESSO SEI (INDENIZAÇÃO) | AQ13: INSTRUÇÃO PROCESSO SEI DTS | AR13: ASSINATURA DIRETOR DTS | AS13: ELABORAÇÃO DESPACHO CTS | AT13: ASSINATURA DESPACHO GABINETE | AU13: PUBLICAÇÃO DIÁRIO OFICIAL | AV13: ENCAMINHAMENTO DAF/DIF CTS | AW13: LIBERAÇÃO PAGAMENTO DAF/DIF | AX13: PREVISÃO PAGAMENTO | AY13: DATA PAGAMENTO | AZ13: DATA ENTREGA IMÓVEL | BA13: SITUAÇÃO ATUAL IMÓVEL | BB13: STATUS | BC13: DIAS TOTAIS | BD13: OPÇÃO ATENDIMENTO | BE13: NECESSITA BLOQUEIO AA | BF13: SOLICITAÇÃO BLOQUEIO AA DTS | BG13: SOLICITAÇÃO BLOQUEIO AA DTS | BH13: DATA BLOQUEIO AA | BI13: DESPACHO EXCLUSÃO GABINETE | BJ13: ASSINATURA DESPACHO GABINETE | BK13: PUBLICAÇÃO DOC | BL13: ENCAMINHAMENTO SOLICITAÇÃO EXCLUSÃO DEPLAN | BM13: ENCERRAMENTO PROCESSO DTS
A14: 1 | B14: ALFREDO ÁVILA | C14: 1 | D14: 0 | E14: 0 | F14: 001/0001/A | G14: OCUPADO | H14: MISTO | I14: PROPRIETÁRIO RESIDENTE | J14: ANTONIO CARLOS PEREIRA LIMAS | K14: 27.717.269-X | L14: 172.907.418-97 | M14: CADASTRADO | N14: INDENIZAÇÃO | O14: 44900 | P14: N/A | Q14: N/A | R14: N/A | S14: N/A | T14: N/A | U14: N/A | V14: N/A | W14: N/A | X14: N/A | Y14: N/A | Z14: N/A | AB14: ANTONIO CARLOS PEREIRA LIMAS | AC14: 27.717.269-X | AD14: 172.907.418-97 | AE14: PROPRIETÁRIO RESIDENTE | AF14: CADASTRADO | AG14: 39200 | AH14: 60000 | AI14: SIM | AJ14: 6014.2022/0003993-0 | AK14: FINALIZADO | AL14: FINALIZADO | AM14: FINALIZADO | AN14: SEM PENDÊNCIA | AP14: 6014.2023/0001314-2 | AQ14: FINALIZADO | AR14: FINALIZADO | AS14: FINALIZADO | AT14: FINALIZADO | AU14: 45104 | AV14: FINALIZADO | AW14: FINALIZADO | AX14: 45111 | AY14: 45111 | AZ14: 45124 | BA14: DEMOLIDO | BB14: FINALIZADO | BC14: =IF(AY14-ON14=0,"",AY14-O14) -> 211 | BD14: =IF(AND(AI14<>"SIM",AI14="UH"),"AA","INDENIZAÇÃO") -> INDENIZAÇÃO | BE14: =IF(AND(AY14<>"AGUARDANDO",AY14<>"",N14="AUXÍLIO ALUGUEL ATÉ INDENIZAÇÃO"),"SIM","NÃO") -> NÃO | BF14: N/A | BG14: N/A | BH14: N/A | BI14: FINALIZADO | BJ14: FINALIZADO | BK14: 45190 | BL14: FINALIZADO | BM14: FINALIZADO
A15: 2 | B15: ALFREDO ÁVILA | C15: 1 | D15: 0 | E15: 0 | F15: 001/0001/B | G15: OCUPADO | H15: RESIDENCIAL | I15: PROPRIETÁRIO RESIDENTE | J15: ANTONIO CARLOS PEREIRA LIMAS | K15: 27.717.269-X | L15: 172.907.418-97 | M15: CADASTRADO | N15: SELO EXCLUÍDO | O15: 44900 | P15: N/A | Q15: N/A | R15: N/A | S15: N/A | T15: N/A | U15: N/A | V15: N/A | W15: N/A | X15: N/A | Y15: N/A | Z15: N/A | AA15: SELO EXCLUÍDO | AB15: ANTONIO CARLOS PEREIRA LIMAS | AC15: 27.717.269-X | AD15: 172.907.418-97 | AE15: PROPRIETÁRIO RESIDENTE | AF15: N/A | AG15: 0 | AH15: 0 | AI15: SELO EXCLUÍDO | AJ15: 6014.2022/0003993-0 | AK15: N/A | AL15: N/A | AM15: N/A | AN15: N/A | AO15: SELO EXCLUÍDO | AP15: N/A | AQ15: N/A | AR15: N/A | AS15: N/A | AT15: N/A | AU15: N/A | AV15: N/A | AW15: N/A | AX15: N/A | AY15: N/A | AZ15: N/A | BA15: N/A | BB15: FINALIZADO | BC15: N/A | BD15: =IF(AND(AI15<>"SIM",AI15="UH"),"AA","INDENIZAÇÃO") -> INDENIZAÇÃO | BE15: =IF(AND(AY15<>"AGUARDANDO",AY15<>"",N15="AUXÍLIO ALUGUEL ATÉ INDENIZAÇÃO"),"SIM","NÃO") -> NÃO | BF15: N/A | BG15: N/A | BH15: N/A | BI15: N/A | BJ15: N/A | BK15: N/A | BL15: N/A | BM15: FINALIZADO
A16: 3 | B16: ALFREDO ÁVILA | C16: 1 | D16: 0 | E16: 0 | F16: 001/0002/A | G16: OCUPADO | H16: RESIDENCIAL | I16: PROPRIETÁRIO RESIDENTE | J16: WALLACE CARLOS DO NASCIMENTO | K16: 53.833.874-X | L16: 460.742.418-80 | M16: CADASTRADO | N16: AUXÍLIO ALUGUEL UH | O16: 44900 | P16: 44921 | Q16: 6014.2023/0000399-6 | R16: FINALIZADO | S16: FINALIZADO | T16: FINALIZADO | U16: 44992 | V16: FINALIZADO | W16: 44992 | X16: 45019 | Y16: 45019 | Z16: 45029 | AA16: Houve um problema na equipe do pagamento, sendo previsto para 03/04/2023 | AB16: WALLACE CARLOS DO NASCIMENTO | AC16: 53.833.874-X | AD16: 460.742.418-80 | AE16: PROPRIETÁRIO RESIDENTE | AF16: CADASTRADO | AG16: 15600 | AH16: 45600 | AI16: UH | AJ16: 6014.2022/0003993-0 | AK16: FINALIZADO | AL16: N/A | AM16: N/A | AN16: N/A | AP16: N/A | AQ16: N/A | AR16: N/A | AS16: N/A | AT16: N/A | AU16: N/A | AV16: N/A | AW16: N/A | AX16: 45019 | AY16: 45019 | AZ16: 45029 | BA16: DEMOLIDO | BB16: FINALIZADO | BC16: =IF(AY16-ON16=0,"",AY16-O16) -> 119 | BD16: =IF(AND(AI16<>"SIM",AI16="UH"),"AA","INDENIZAÇÃO") -> AA | BE16: =IF(AND(AY16<>"AGUARDANDO",AY16<>"",N16="AUXÍLIO ALUGUEL ATÉ INDENIZAÇÃO"),"SIM","NÃO") -> NÃO | BF16: N/A | BG16: N/A | BH16: N/A | BI16: N/A | BJ16: N/A | BK16: N/A | BL16: N/A | BM16: FINALIZADO
A17: 4 | B17: ALFREDO ÁVILA | C17: 1 | D17: 0 | E17: 0 | F17: 001/0002/B | G17: OCUPADO | H17: RESIDENCIAL | I17: PROPRIETÁRIO RESIDENTE | J17: VANESSA SANTOS DE MARIZ | K17: 54.110.071-3 | L17: 490.323.538-61 | M17: CADASTRADO | N17: AUXÍLIO ALUGUEL UH | O17: 44900 | P17: 44921 | Q17: 6014.2023/0000399-6 | R17: FINALIZADO | S17: FINALIZADO | T17: FINALIZADO | U17: 44992 | V17: FINALIZADO | W17: 44992 | X17: 45019 | Y17: 45020 | Z17: 45029 | AA17: Houve um problema na equipe do pagamento, sendo previsto para 03/04/2023 | AB17: VANESSA SANTOS DE MARIZ | AC17: 54.110.071-3 | AD17: 490.323.538-61 | AE17: PROPRIETÁRIO RESIDENTE | AF17: CADASTRADO | AG17: 14600 | AH17: 54600 | AI17: UH | AJ17: 6014.2022/0003993-0 | AK17: FINALIZADO | AL17: N/A | AM17: N/A | AN17: N/A | AP17: N/A | AQ17: N/A | AR17: N/A | AS17: N/A | AT17: N/A | AU17: N/A | AV17: N/A | AW17: N/A | AX17: 45019 | AY17: 45020 | AZ17: 45029 | BA17: DEMOLIDO | BB17: FINALIZADO | BC17: =IF(AY17-ON17=0,"",AY17-O17) -> 120 | BD17: =IF(AND(AI17<>"SIM",AI17="UH"),"AA","INDENIZAÇÃO") -> AA | BE17: =IF(AND(AY17<>"AGUARDANDO",AY17<>"",N17="AUXÍLIO ALUGUEL ATÉ INDENIZAÇÃO"),"SIM","NÃO") -> NÃO | BF17: N/A | BG17: N/A | BH17: N/A | BI17: N/A | BJ17: N/A | BK17: N/A | BL17: N/A | BM17: FINALIZADO
A18: 5 | B18: ALFREDO ÁVILA | C18: 1 | D18: 0 | E18: 0 | F18: 001/0003/A | G18: OCUPADO | H18: RESIDENCIAL | I18: INQUILINO | J18: JEFFERSON DA CRUZ CORRÊA | K18: 47.815.794-0 | L18: 409.715.758-27 | M18: CADASTRADO | N18: AUXÍLIO ALUGUEL UH | O18: 44900 | P18: 44921 | Q18: 6014.2023/0000399-6 | R18: FINALIZADO | S18: FINALIZADO | T18: FINALIZADO | U18: 44992 | V18: FINALIZADO | W18: 44992 | X18: 45019 | Y18: 45022 | Z18: 45057 | AA18: Houve um problema na equipe do pagamento, sendo previsto para 03/04/2023 | AB18: FRANCISCO MARQUES DE OLIVEIRA | AC18: 26.115..235-X | AD18: 185.112.418-76 | AE18: PROPRIETÁRIO NÃO RESIDENTE | AF18: CADASTRADO | AG18: 107600 | AH18: 107600 | AI18: SIM | AJ18: 6014.2022/0003993-0 | AK18: FINALIZADO | AL18: FINALIZADO | AM18: FINALIZADO | AN18: SEM PENDÊNCIA | AP18: 6014.2022/0003932-8 | AQ18: FINALIZADO | AR18: FINALIZADO | AS18: FINALIZADO | AT18: FINALIZADO | AU18: 44966 | AV18: FINALIZADO | AW18: FINALIZADO | AX18: 45041 | AY18: 45041 | AZ18: 45057 | BA18: DEMOLIDO | BB18: FINALIZADO | BC18: =IF(AY18-ON18=0,"",AY18-O18) -> 141 | BD18: =IF(AND(AI18<>"SIM",AI18="UH"),"AA","INDENIZAÇÃO") -> INDENIZAÇÃO | BE18: =IF(AND(AY18<>"AGUARDANDO",AY18<>"",N18="AUXÍLIO ALUGUEL ATÉ INDENIZAÇÃO"),"SIM","NÃO") -> NÃO | BF18: N/A | BG18: N/A | BH18: N/A | BI18: FINALIZADO | BJ18: FINALIZADO | BK18: 45190 | BL18: FINALIZADO | BM18: FINALIZADO
A19: 6 | B19: ALFREDO ÁVILA | C19: 1 | D19: 0 | E19: 0 | F19: 001/0004/A | G19: OCUPADO | H19: RESIDENCIAL | I19: INQUILINO | J19: ISABELLE LAISLA DA SILVA | K19: 62.680.901-0 | L19: 561.448.138-96 | M19: CADASTRADO | N19: AUXÍLIO ALUGUEL UH | O19: 44900 | P19: 44921 | Q19: 6014.2023/0000399-6 | R19: FINALIZADO | S19: FINALIZADO | T19: FINALIZADO | U19: 44992 | V19: FINALIZADO | W19: 44992 | X19: 45019 | Y19: 45019 | Z19: 45022 | AA19: Houve um problema na equipe do pagamento, sendo previsto para 03/04/2023 | AB19: ELENILDA RIBEIRO BARBOSA | AC19: 37.865.320-9 | AD19: 458.940.945-34 | AE19: PROPRIETÁRIO NÃO RESIDENTE | AF19: CADASTRADO | AG19: 27100 | AH19: 57100 | AI19: SIM | AJ19: 6014.2022/0003993-0 | AK19: FINALIZADO | AL19: FINALIZADO | AM19: FINALIZADO | AN19: SEM PENDÊNCIA | AP19: 6014.2022/0003936-0 | AQ19: FINALIZADO | AR19: FINALIZADO | AS19: FINALIZADO | AT19: FINALIZADO | AU19: 44966 | AV19: FINALIZADO | AW19: FINALIZADO | AX19: 45009 | AY19: 45009 | AZ19: 45022 | BA19: DEMOLIDO | BB19: FINALIZADO | BC19: =IF(AY19-ON19=0,"",AY19-O19) -> 109 | BD19: =IF(AND(AI19<>"SIM",AI19="UH"),"AA","INDENIZAÇÃO") -> INDENIZAÇÃO | BE19: =IF(AND(AY19<>"AGUARDANDO",AY19<>"",N19="AUXÍLIO ALUGUEL ATÉ INDENIZAÇÃO"),"SIM","NÃO") -> NÃO | BF19: N/A | BG19: N/A | BH19: N/A | BI19: FINALIZADO | BJ19: FINALIZADO | BK19: 45190 | BL19: FINALIZADO | BM19: FINALIZADO
A20: 7 | B20: ALFREDO ÁVILA | C20: 1 | D20: 0 | E20: 0 | F20: 001/0005/A | G20: EM CONSTRUÇÃO | H20: RESIDENCIAL | M20: CADASTRADO | N20: INDENIZAÇÃO | O20: 44900 | P20: N/A | Q20: N/A | R20: N/A | S20: N/A | T20: N/A | U20: N/A | V20: N/A | W20: N/A | X20: N/A | Y20: N/A | Z20: N/A | AB20: ANDRÉ VINICIUS DOS SANTOS | AC20: 54.531.709-5 | AD20: 485.192.658-80 | AE20: PROPRIETÁRIO NÃO RESIDENTE | AF20: CADASTRADO | AG20: 15900 | AH20: 45900 | AI20: SIM | AJ20: 6014.2022/0003993-0 | AK20: FINALIZADO | AL20: FINALIZADO | AM20: FINALIZADO | AN20: SEM PENDÊNCIA | AP20: 6014.2022/0003939-5 | AQ20: FINALIZADO | AR20: FINALIZADO | AS20: FINALIZADO | AT20: FINALIZADO | AU20: 44966 | AV20: FINALIZADO | AW20: FINALIZADO | AX20: 45009 | AY20: 45009 | AZ20: 45021 | BA20: DEMOLIDO | BB20: FINALIZADO | BC20: =IF(AY20-ON20=0,"",AY20-O20) -> 109 | BD20: =IF(AND(AI20<>"SIM",AI20="UH"),"AA","INDENIZAÇÃO") -> INDENIZAÇÃO | BE20: =IF(AND(AY20<>"AGUARDANDO",AY20<>"",N20="AUXÍLIO ALUGUEL ATÉ INDENIZAÇÃO"),"SIM","NÃO") -> NÃO | BF20: N/A | BG20: N/A | BH20: N/A | BI20: FINALIZADO | BJ20: FINALIZADO | BK20: 45190 | BL20: FINALIZADO | BM20: FINALIZADO
A21: 8 | B21: ALFREDO ÁVILA | C21: 1 | D21: 0 | E21: 0 | F21: 001/0006/A | G21: OCUPADO | H21: RESIDENCIAL | I21: PROPRIETÁRIO RESIDENTE | J21: MARIA DA GLORIA CARMO SANTOS | K21: 22.334.891-0 | L21: 128.114.308-14 | M21: CADASTRADO | N21: INDENIZAÇÃO | O21: 44900 | P21: N/A | Q21: N/A | R21: N/A | S21: N/A | T21: N/A | U21: N/A | V21: N/A | W21: N/A | X21: N/A | Y21: N/A | Z21: N/A | AB21: MARIA DA GLORIA CARMO SANTOS | AC21: 22.334.891-0 | AD21: 128.114.308-14 | AE21: PROPRIETÁRIO RESIDENTE | AF21: CADASTRADO | AG21: 48500 | AH21: 60000 | AI21: SIM | AJ21: 6014.2022/0003993-0 | AK21: FINALIZADO | AL21: FINALIZADO | AM21: FINALIZADO | AN21: SEM PENDÊNCIA | AP21: 6014.2022/0003947-6 | AQ21: FINALIZADO | AR21: FINALIZADO | AS21: FINALIZADO | AT21: FINALIZADO | AU21: 44966 | AV21: FINALIZADO | AW21: FINALIZADO | AX21: 45009 | AY21: 45009 | AZ21: 45033 | BA21: DEMOLIDO | BB21: FINALIZADO | BC21: =IF(AY21-ON21=0,"",AY21-O21) -> 109 | BD21: =IF(AND(AI21<>"SIM",AI21="UH"),"AA","INDENIZAÇÃO") -> INDENIZAÇÃO | BE21: =IF(AND(AY21<>"AGUARDANDO",AY21<>"",N21="AUXÍLIO ALUGUEL ATÉ INDENIZAÇÃO"),"SIM","NÃO") -> NÃO | BF21: N/A | BG21: N/A | BH21: N/A | BI21: FINALIZADO | BJ21: FINALIZADO | BK21: 45190 | BL21: FINALIZADO | BM21: FINALIZADO
A22: 9 | B22: ALFREDO ÁVILA | C22: 1 | D22: 0 | E22: 0 | F22: 001/0006/B | G22: OCUPADO | H22: RESIDENCIAL | I22: PROPRIETÁRIO RESIDENTE | J22: CINTIA CARMO MIRANDA DE OLIVEIRA | K22: 47.503.428-1 | L22: 394.343.598-99 | M22: CADASTRADO | N22: AUXÍLIO ALUGUEL UH | O22: 44900 | P22: 44921 | Q22: 6014.2023/0000399-6 | R22: FINALIZADO | S22: FINALIZADO | T22: FINALIZADO | U22: 44992 | V22: FINALIZADO | W22: 44992 | X22: 45019 | Y22: 45019 | Z22: 45033 | AA22: Houve um problema na equipe do pagamento, sendo previsto para 03/04/2023 | AB22: CINTIA CARMO MIRANDA DE OLIVEIRA | AC22: 47.503.428-1 | AD22: 394.343.598-99 | AE22: PROPRIETÁRIO RESIDENTE | AF22: CADASTRADO | AG22: 19900 | AH22: 49900 | AI22: UH | AJ22: 6014.2022/0003993-0 | AK22: FINALIZADO | AL22: N/A | AM22: N/A | AN22: N/A | AP22: N/A | AQ22: N/A | AR22: N/A | AS22: N/A | AT22: N/A | AU22: N/A | AV22: N/A | AW22: N/A | AX22: 45019 | AY22: 45019 | AZ22: 45033 | BA22: DEMOLIDO | BB22: FINALIZADO | BC22: =IF(AY22-ON22=0,"",AY22-O22) -> 119 | BD22: =IF(AND(AI22<>"SIM",AI22="UH"),"AA","INDENIZAÇÃO") -> AA | BE22: =IF(AND(AY22<>"AGUARDANDO",AY22<>"",N22="AUXÍLIO ALUGUEL ATÉ INDENIZAÇÃO"),"SIM","NÃO") -> NÃO | BF22: N/A | BG22: N/A | BH22: N/A | BI22: N/A | BJ22: N/A | BK22: N/A | BL22: N/A | BM22: FINALIZADO
A23: 10 | B23: ALFREDO ÁVILA | C23: 1 | D23: 0 | E23: 0 | F23: 001/0007/A | G23: OCUPADO | H23: RESIDENCIAL | I23: PROPRIETÁRIO RESIDENTE | J23: ELIANE RIBEIRO BARBOSA | K23: 58.837.007-1 | L23: 020.661.135-81 | M23: CADASTRADO | N23: INDENIZAÇÃO | O23: 44900 | P23: N/A | Q23: N/A | R23: N/A | S23: N/A | T23: N/A | U23: N/A | V23: N/A | W23: N/A | X23: N/A | Y23: N/A | Z23: N/A | AB23: ELIANE RIBEIRO BARBOSA | AC23: 58.837.007-1 | AD23: 020.661.135-81 | AE23: PROPRIETÁRIO RESIDENTE | AF23: CADASTRADO | AG23: 19800 | AH23: 49800 | AI23: SIM | AJ23: 6014.2022/0003993-0 | AK23: FINALIZADO | AL23: FINALIZADO | AM23: FINALIZADO | AN23: SEM PENDÊNCIA | AP23: 6014.2022/0004025-3 | AQ23: FINALIZADO | AR23: FINALIZADO | AS23: FINALIZADO | AT23: FINALIZADO | AU23: 44922 | AV23: FINALIZADO | AW23: FINALIZADO | AX23: 44924 | AY23: 44924 | AZ23: 44935 | BA23: DEMOLIDO | BB23: FINALIZADO | BC23: =IF(AY23-ON23=0,"",AY23-O23) -> 24 | BD23: =IF(AND(AI23<>"SIM",AI23="UH"),"AA","INDENIZAÇÃO") -> INDENIZAÇÃO | BE23: =IF(AND(AY23<>"AGUARDANDO",AY23<>"",N23="AUXÍLIO ALUGUEL ATÉ INDENIZAÇÃO"),"SIM","NÃO") -> NÃO | BF23: N/A | BG23: N/A | BH23: N/A | BI23: FINALIZADO | BJ23: FINALIZADO | BK23: 45057 | BL23: FINALIZADO | BM23: FINALIZADO
A24: 11 | B24: ALFREDO ÁVILA | C24: 1 | D24: 0 | E24: 0 | F24: 001/0008/A | G24: OCUPADO | H24: RESIDENCIAL | I24: PROPRIETÁRIO RESIDENTE | J24: NOELIA RIBEIRO BARBOSA | K24: 28.191.025-X | L24: 184.917.628-09 | M24: CADASTRADO | N24: INDENIZAÇÃO | O24: 44900 | P24: N/A | Q24: N/A | R24: N/A | S24: N/A | T24: N/A | U24: N/A | V24: N/A | W24: N/A | X24: N/A | Y24: N/A | Z24: N/A | AB24: NOELIA RIBEIRO BARBOSA | AC24: 28.191.025-X | AD24: 184.917.628-09 | AE24: PROPRIETÁRIO RESIDENTE | AF24: CADASTRADO | AG24: 30400 | AH24: 60000 | AI24: SIM | AJ24: 6014.2022/0003993-0 | AK24: FINALIZADO | AL24: FINALIZADO | AM24: FINALIZADO | AN24: SEM PENDÊNCIA | AP24: 6014.2022/0004026-1 | AQ24: FINALIZADO | AR24: FINALIZADO | AS24: FINALIZADO | AT24: FINALIZADO | AU24: 44922 | AV24: FINALIZADO | AW24: FINALIZADO | AX24: 44924 | AY24: 44924 | AZ24: 44935 | BA24: DEMOLIDO | BB24: FINALIZADO | BC24: =IF(AY24-ON24=0,"",AY24-O24) -> 24 | BD24: =IF(AND(AI24<>"SIM",AI24="UH"),"AA","INDENIZAÇÃO") -> INDENIZAÇÃO | BE24: =IF(AND(AY24<>"AGUARDANDO",AY24<>"",N24="AUXÍLIO ALUGUEL ATÉ INDENIZAÇÃO"),"SIM","NÃO") -> NÃO | BF24: N/A | BG24: N/A | BH24: N/A | BI24: FINALIZADO | BJ24: FINALIZADO | BK24: 45057 | BL24: FINALIZADO | BM24: FINALIZADO
A25: 12 | B25: ALFREDO ÁVILA | C25: 1 | D25: 0 | E25: 0 | F25: 001/0008/B | G25: OCUPADO | H25: RESIDENCIAL | I25: PROPRIETÁRIO RESIDENTE | J25: LUCAS DA SILVA PEREIRA | K25: 45.668.154-8 | L25: 459.407.808-73 | M25: CADASTRADO | N25: AUXÍLIO ALUGUEL UH | O25: 44900 | P25: 44921 | Q25: 6014.2023/0000399-6 | R25: FINALIZADO | S25: FINALIZADO | T25: FINALIZADO | U25: 44992 | V25: FINALIZADO | W25: 44992 | X25: 45019 | Y25: 45019 | Z25: 45203 | AA25: Houve um problema na equipe do pagamento, sendo previsto para 03/04/2023 | AB25: LUCAS DA SILVA PEREIRA | AC25: 45.668.154-8 | AD25: 459.407.808-73 | AE25: PROPRIETÁRIO RESIDENTE | AF25: CADASTRADO | AG25: 13000 | AH25: 43000 | AI25: UH | AJ25: 6014.2022/0003993-0 | AK25: FINALIZADO | AL25: N/A | AM25: N/A | AN25: N/A | AP25: N/A | AQ25: N/A | AR25: N/A | AS25: N/A | AT25: N/A | AU25: N/A | AV25: N/A | AW25: N/A | AX25: 45019 | AY25: 45019 | AZ25: 45026 | BA25: DEMOLIDO | BB25: FINALIZADO | BC25: =IF(AY25-ON25=0,"",AY25-O25) -> 119 | BD25: =IF(AND(AI25<>"SIM",AI25="UH"),"AA","INDENIZAÇÃO") -> AA | BE25: =IF(AND(AY25<>"AGUARDANDO",AY25<>"",N25="AUXÍLIO ALUGUEL ATÉ INDENIZAÇÃO"),"SIM","NÃO") -> NÃO | BF25: N/A | BG25: N/A | BH25: N/A | BI25: N/A | BJ25: N/A | BK25: N/A | BL25: N/A | BM25: FINALIZADO
A26: 13 | B26: ALFREDO ÁVILA | C26: 1 | D26: 0 | E26: 0 | F26: 001/0009/A | G26: OCUPADO | H26: RESIDENCIAL | I26: PROPRIETÁRIO RESIDENTE | J26: MIRNA ELIZABETH CABRERA CUEVA | K26: RNM G065972-9 | L26: 237.484.388-26 | M26: CADASTRADO | N26: AUXÍLIO ALUGUEL UH | O26: 44900 | P26: 44921 | Q26: 6014.2023/0000399-6 | R26: FINALIZADO | S26: FINALIZADO | T26: FINALIZADO | U26: 44992 | V26: FINALIZADO | W26: 44992 | X26: 45019 | Y26: 45019 | Z26: 45203 | AA26: Houve um problema na equipe do pagamento, sendo previsto para 03/04/2023 | AB26: MIRNA ELIZABETH CABRERA CUEVA | AC26: RNM G065972-9 | AD26: 237.484.388-26 | AE26: PROPRIETÁRIO RESIDENTE | AF26: CADASTRADO | AG26: 22700 | AH26: 52700 | AI26: UH | AJ26: 6014.2022/0003993-0 | AK26: FINALIZADO | AL26: N/A | AM26: N/A | AN26: N/A | AP26: N/A | AQ26: N/A | AR26: N/A | AS26: N/A | AT26: N/A | AU26: N/A | AV26: N/A | AW26: N/A | AX26: 45019 | AY26: 45019 | AZ26: 45026 | BA26: DEMOLIDO | BB26: FINALIZADO | BC26: =IF(AY26-ON26=0,"",AY26-O26) -> 119 | BD26: =IF(AND(AI26<>"SIM",AI26="UH"),"AA","INDENIZAÇÃO") -> AA | BE26: =IF(AND(AY26<>"AGUARDANDO",AY26<>"",N26="AUXÍLIO ALUGUEL ATÉ INDENIZAÇÃO"),"SIM","NÃO") -> NÃO | BF26: N/A | BG26: N/A | BH26: N/A | BI26: N/A | BJ26: N/A | BK26: N/A | BL26: N/A | BM26: FINALIZADO
A27: 14 | B27: ALFREDO ÁVILA | C27: 1 | D27: 0 | E27: 0 | F27: 001/0010/A | G27: OCUPADO | H27: RESIDENCIAL | I27: INQUILINO | O27: 44900 | P27: N/A | Q27: N/A | R27: N/A | S27: N/A | T27: N/A | U27: N/A | V27: N/A | W27: N/A | X27: N/A | Y27: N/A | Z27: N/A | AB27: ALEXSANDRO BARBOSA PEREIRA | AC27: 46.789.605-7 | AD27: 393.482.118-97 | AE27: PROPRIETÁRIO NÃO RESIDENTE | AF27: CADASTRADO | AG27: 21400 | AH27: 51400 | AI27: SIM | AJ27: 6014.2022/0003993-0 | AK27: FINALIZADO | AL27: FINALIZADO | AM27: FINALIZADO | AN27: SEM PENDÊNCIA | AP27: 6014.2022/0003940-9 | AQ27: FINALIZADO | AR27: FINALIZADO | AS27: FINALIZADO | AT27: FINALIZADO | AU27: 44966 | AV27: FINALIZADO | AW27: FINALIZADO | AX27: 45012 | AY27: 45012 | AZ27: 45035 | BA27: DEMOLIDO | BB27: FINALIZADO | BC27: =IF(AY27-ON27=0,"",AY27-O27) -> 112 | BD27: =IF(AND(AI27<>"SIM",AI27="UH"),"AA","INDENIZAÇÃO") -> INDENIZAÇÃO | BE27: =IF(AND(AY27<>"AGUARDANDO",AY27<>"",N27="AUXÍLIO ALUGUEL ATÉ INDENIZAÇÃO"),"SIM","NÃO") -> NÃO | BF27: N/A | BG27: N/A | BH27: N/A | BI27: FINALIZADO | BJ27: FINALIZADO | BK27: 45190 | BL27: FINALIZADO | BM27: FINALIZADO
A28: 15 | B28: ALFREDO ÁVILA | C28: 1 | D28: 0 | E28: 0 | F28: 001/0010/B | G28: OCUPADO | H28: RESIDENCIAL | I28: INQUILINO | J28: ANTONIO IZAU DOS SANTOS | K28: 38.478.412-4 | L28: 099.702.388-09 | M28: CADASTRADO | N28: AUXÍLIO ALUGUEL UH | O28: 44900 | P28: 44921 | Q28: 6014.2023/0000399-6 | R28: FINALIZADO | S28: FINALIZADO | T28: FINALIZADO | U28: 44992 | V28: FINALIZADO | W28: 44992 | X28: 45019 | Y28: 45019 | Z28: 45034 | AA28: Houve um problema na equipe do pagamento, sendo previsto para 03/04/2023 | AB28: ALEXSANDRO BARBOSA PEREIRA | AC28: 46.789.605-7 | AD28: 393.482.118-97 | AE28: PROPRIETÁRIO NÃO RESIDENTE | AF28: N/A | AG28: 18700 | AH28: 48700 | AI28: RECEBEU INDENIZAÇÃO PELO SELO 001/0010/A | AJ28: 6014.2022/0003993-0 | AK28: N/A | AL28: N/A | AM28: N/A | AN28: N/A | AP28: N/A | AQ28: N/A | AR28: N/A | AS28: N/A | AT28: N/A | AU28: N/A | AV28: N/A | AW28: N/A | AX28: N/A | AY28: N/A | AZ28: 45034 | BA28: DEMOLIDO | BB28: FINALIZADO | BC28: N/A | BD28: =IF(AND(AI28<>"SIM",AI28="UH"),"AA","INDENIZAÇÃO") -> INDENIZAÇÃO | BE28: =IF(AND(AY28<>"AGUARDANDO",AY28<>"",N28="AUXÍLIO ALUGUEL ATÉ INDENIZAÇÃO"),"SIM","NÃO") -> NÃO | BF28: N/A | BG28: N/A | BH28: N/A | BI28: N/A | BJ28: N/A | BK28: N/A | BL28: N/A | BM28: FINALIZADO
A29: 16 | B29: ALFREDO ÁVILA | C29: 1 | D29: 0 | E29: 0 | F29: 001/0011/A | G29: OCUPADO | H29: RESIDENCIAL | I29: INQUILINO | J29: DIVANI MARTINS DO SANTOS | K29: 34.812.789-3 | L29: 272.878.048-08 | M29: CADASTRADO | N29: AUXÍLIO ALUGUEL UH | O29: 44900 | P29: 44921 | Q29: 6014.2023/0000399-6 | R29: FINALIZADO | S29: FINALIZADO | T29: FINALIZADO | U29: 44992 | V29: FINALIZADO | W29: 44992 | X29: 45019 | Y29: 45019 | Z29: 45040 | AA29: Houve um problema na equipe do pagamento, sendo previsto para 03/04/2023 | AB29: IVONE FERREIRA MENDES | AC29: 54.246.610-7 | AD29: 060.155.126-52 | AE29: PROPRIETÁRIO NÃO RESIDENTE | AF29: CADASTRADO | AG29: 35900 | AH29: 60000 | AI29: SIM | AJ29: 6014.2022/0003993-0 | AK29: FINALIZADO | AL29: FINALIZADO | AM29: FINALIZADO | AN29: SEM PENDÊNCIA | AO29: Conta bancaria da Sra. Ivone Ferreira Mendes está ilegível e o termo de chaves está faltando um número no RG. Verificar com Cibele | AP29: 6014.2022/0004134-9 | AQ29: FINALIZADO | AR29: FINALIZADO | AS29: FINALIZADO | AT29: FINALIZADO | AU29: 45014 | AV29: FINALIZADO | AW29: FINALIZADO | AX29: 45022 | AY29: 45022 | AZ29: 45040 | BA29: DEMOLIDO | BB29: FINALIZADO | BC29: =IF(AY29-ON29=0,"",AY29-O29) -> 122 | BD29: =IF(AND(AI29<>"SIM",AI29="UH"),"AA","INDENIZAÇÃO") -> INDENIZAÇÃO | BE29: =IF(AND(AY29<>"AGUARDANDO",AY29<>"",N29="AUXÍLIO ALUGUEL ATÉ INDENIZAÇÃO"),"SIM","NÃO") -> NÃO | BF29: N/A | BG29: N/A | BH29: N/A | BI29: FINALIZADO | BJ29: FINALIZADO | BK29: 45190 | BL29: FINALIZADO | BM29: FINALIZADO
A30: 17 | B30: ALFREDO ÁVILA | C30: 1 | D30: 0 | E30: 0 | F30: 001/0012/A | G30: OCUPADO | H30: RESIDENCIAL | I30: PROPRIETÁRIO RESIDENTE | J30: VITORIA RAFAELA LIMA DA COSTA | K30: 60.076.130-7 | L30: 505.195.648-39 | M30: CADASTRADO | N30: AUXÍLIO ALUGUEL UH | O30: 44900 | P30: 44921 | Q30: 6014.2023/0000399-6 | R30: FINALIZADO | S30: FINALIZADO | T30: FINALIZADO | U30: 44992 | V30: FINALIZADO | W30: 44992 | X30: 45019 | Y30: 45019 | Z30: 45049 | AA30: Houve um problema na equipe do pagamento, sendo previsto para 03/04/2023 | AB30: VITORIA RAFAELA LIMA DA COSTA | AC30: 60.076.130-7 | AD30: 505.195.648-39 | AE30: PROPRIETÁRIO RESIDENTE | AF30: CADASTRADO | AG30: 20500 | AH30: 50500 | AI30: UH | AJ30: 6014.2022/0003993-0 | AK30: FINALIZADO | AL30: N/A | AM30: N/A | AN30: N/A | AP30: N/A | AQ30: N/A | AR30: N/A | AS30: N/A | AT30: N/A | AU30: N/A | AV30: N/A | AW30: N/A | AX30: 45019 | AY30: 45019 | AZ30: 45049 | BA30: DEMOLIDO | BB30: FINALIZADO | BC30: =IF(AY30-ON30=0,"",AY30-O30) -> 119 | BD30: =IF(AND(AI30<>"SIM",AI30="UH"),"AA","INDENIZAÇÃO") -> AA | BE30: =IF(AND(AY30<>"AGUARDANDO",AY30<>"",N30="AUXÍLIO ALUGUEL ATÉ INDENIZAÇÃO"),"SIM","NÃO") -> NÃO | BF30: N/A | BG30: N/A | BH30: N/A | BI30: N/A | BJ30: N/A | BK30: N/A | BL30: N/A | BM30: FINALIZADO
A31: 18 | B31: ALFREDO ÁVILA | C31: 1 | D31: 0 | E31: 0 | F31: 001/0012/B | G31: OCUPADO | H31: RESIDENCIAL | I31: PROPRIETÁRIO RESIDENTE | J31: CLAUDIO FERREIRA DE LIMA | K31: 37.095.609-6 | L31: 533.218.121-34 | M31: CADASTRADO | N31: INDENIZAÇÃO | O31: 44900 | P31: N/A | Q31: N/A | R31: N/A | S31: N/A | T31: N/A | U31: N/A | V31: N/A | W31: N/A | X31: N/A | Y31: N/A | Z31: N/A | AB31: CLAUDIO FERREIRA DE LIMA | AC31: 37.095.609-6 | AD31: 533.218.121-34 | AE31: PROPRIETÁRIO RESIDENTE | AF31: CADASTRADO | AG31: 20700 | AH31: 50700 | AI31: SIM | AJ31: 6014.2022/0003993-0 | AK31: FINALIZADO | AL31: FINALIZADO | AM31: FINALIZADO | AN31: SEM PENDÊNCIA | AP31: 6014.2022/0003941-7 | AQ31: FINALIZADO | AR31: FINALIZADO | AS31: FINALIZADO | AT31: FINALIZADO | AU31: 44966 | AV31: FINALIZADO | AW31: FINALIZADO | AX31: 45012 | AY31: 45012 | AZ31: 45048 | BA31: DEMOLIDO | BB31: FINALIZADO | BC31: =IF(AY31-ON31=0,"",AY31-O31) -> 112 | BD31: =IF(AND(AI31<>"SIM",AI31="UH"),"AA","INDENIZAÇÃO") -> INDENIZAÇÃO | BE31: =IF(AND(AY31<>"AGUARDANDO",AY31<>"",N31="AUXÍLIO ALUGUEL ATÉ INDENIZAÇÃO"),"SIM","NÃO") -> NÃO | BF31: N/A | BG31: N/A | BH31: N/A | BI31: FINALIZADO | BJ31: FINALIZADO | BK31: 45190 | BL31: FINALIZADO | BM31: FINALIZADO
A32: 19 | B32: ALFREDO ÁVILA | C32: 1 | D32: 0 | E32: 0 | F32: 001/0014/A | G32: OCUPADO | H32: RESIDENCIAL | I32: PROPRIETÁRIO RESIDENTE | J32: JAILSON SANTOS SILVA | K32: 34.302.386-6 | L32: 553.313.785-87 | M32: CADASTRADO | N32: INDENIZAÇÃO | O32: 44900 | P32: N/A | Q32: N/A | R32: N/A | S32: N/A | T32: N/A | U32: N/A | V32: N/A | W32: N/A | X32: N/A | Y32: N/A | Z32: N/A | AB32: JAILSON SANTOS SILVA | AC32: 34.302.386-6 | AD32: 553.313.785-87 | AE32: PROPRIETÁRIO RESIDENTE | AF32: CADASTRADO | AG32: 19800 | AH32: 39800 | AI32: SIM | AJ32: 6014.2022/0003993-0 | AK32: FINALIZADO | AL32: FINALIZADO | AM32: FINALIZADO | AN32: SEM PENDÊNCIA | AP32: 6014.2022/0004135-7 | AQ32: FINALIZADO | AR32: FINALIZADO | AS32: FINALIZADO | AT32: FINALIZADO | AU32: 44966 | AV32: FINALIZADO | AW32: FINALIZADO | AX32: 45012 | AY32: 45012 | AZ32: 45042 | BA32: DEMOLIDO | BB32: FINALIZADO | BC32: =IF(AY32-ON32=0,"",AY32-O32) -> 112 | BD32: =IF(AND(AI32<>"SIM",AI32="UH"),"AA","INDENIZAÇÃO") -> INDENIZAÇÃO | BE32: =IF(AND(AY32<>"AGUARDANDO",AY32<>"",N32="AUXÍLIO ALUGUEL ATÉ INDENIZAÇÃO"),"SIM","NÃO") -> NÃO | BF32: N/A | BG32: N/A | BH32: N/A | BI32: FINALIZADO | BJ32: FINALIZADO | BK32: 45190 | BL32: FINALIZADO | BM32: FINALIZADO
A33: 20 | B33: ALFREDO ÁVILA | C33: 1 | D33: 0 | E33: 0 | F33: 001/0017/A | G33: OCUPADO | H33: RESIDENCIAL | I33: PROPRIETÁRIO RESIDENTE | J33: CREUZA ROSA MARQUES | K33: 53.083.084-X | L33: 130.250.141-81 | M33: CADASTRADO | N33: INDENIZAÇÃO | O33: 44900 | P33: N/A | Q33: N/A | R33: N/A | S33: N/A | T33: N/A | U33: N/A | V33: N/A | W33: N/A | X33: N/A | Y33: N/A | Z33: N/A | AB33: CREUZA ROSA MARQUES | AC33: 53.083.084-X | AD33: 130.250.148-81 | AE33: PROPRIETÁRIO RESIDENTE | AF33: CADASTRADO | AG33: 92800 | AH33: 92800 | AI33: SIM | AJ33: 6014.2022/0003993-0 | AK33: FINALIZADO | AL33: FINALIZADO | AM33: FINALIZADO | AN33: SEM PENDÊNCIA | AP33: 6014.2022/0004030-0 | AQ33: FINALIZADO | AR33: FINALIZADO | AS33: FINALIZADO | AT33: FINALIZADO | AU33: 44966 | AV33: FINALIZADO | AW33: FINALIZADO | AX33: 45012 | AY33: 45012 | AZ33: 45040 | BA33: DEMOLIDO | BB33: FINALIZADO | BC33: =IF(AY33-ON33=0,"",AY33-O33) -> 112 | BD33: =IF(AND(AI33<>"SIM",AI33="UH"),"AA","INDENIZAÇÃO") -> INDENIZAÇÃO | BE33: =IF(AND(AY33<>"AGUARDANDO",AY33<>"",N33="AUXÍLIO ALUGUEL ATÉ INDENIZAÇÃO"),"SIM","NÃO") -> NÃO | BF33: N/A | BG33: N/A | BH33: N/A | BI33: FINALIZADO | BJ33: FINALIZADO | BK33: 45190 | BL33: FINALIZADO | BM33: FINALIZADO
A34: 21 | B34: ALFREDO ÁVILA | C34: 1 | D34: 0 | E34: 0 | F34: 001/0017/B | G34: OCUPADO | H34: RESIDENCIAL | I34: PROPRIETÁRIO RESIDENTE | J34: STELA MARQUES DA SILVA | K34: 39.626.761-0 | L34: 402.625.628-63 | M34: CADASTRADO | N34: INDENIZAÇÃO | O34: 44900 | P34: N/A | Q34: N/A | R34: N/A | S34: N/A | T34: N/A | U34: N/A | V34: N/A | W34: N/A | X34: N/A | Y34: N/A | Z34: N/A | AB34: STELA MARQUES DA SILVA | AC34: 39.626.761-0 | AD34: 402.625.628-63 | AE34: PROPRIETÁRIO RESIDENTE | AF34: CADASTRADO | AG34: 49800 | AH34: 60000 | AI34: SIM | AJ34: 6014.2022/0003993-0 | AK34: FINALIZADO | AL34: FINALIZADO | AM34: FINALIZADO | AN34: SEM PENDÊNCIA | AP34: 6014.2022/0004136-5 | AQ34: FINALIZADO | AR34: FINALIZADO | AS34: FINALIZADO | AT34: FINALIZADO | AU34: 44966 | AV34: FINALIZADO | AW34: FINALIZADO | AX34: 45012 | AY34: 45012 | AZ34: 45040 | BA34: DEMOLIDO | BB34: FINALIZADO | BC34: =IF(AY34-ON34=0,"",AY34-O34) -> 112 | BD34: =IF(AND(AI34<>"SIM",AI34="UH"),"AA","INDENIZAÇÃO") -> INDENIZAÇÃO | BE34: =IF(AND(AY34<>"AGUARDANDO",AY34<>"",N34="AUXÍLIO ALUGUEL ATÉ INDENIZAÇÃO"),"SIM","NÃO") -> NÃO | BF34: N/A | BG34: N/A | BH34: N/A | BI34: FINALIZADO | BJ34: FINALIZADO | BK34: 45190 | BL34: FINALIZADO | BM34: FINALIZADO
A35: 22 | B35: ALFREDO ÁVILA | C35: 1 | D35: 0 | E35: 0 | F35: 001/0019/A | G35: OCUPADO | H35: RESIDENCIAL | I35: PROPRIETÁRIO RESIDENTE | J35: SUELI GOMES DE SOUZA | K35: 19.370.643-X | L35: 087.913.138-13 | M35: CADASTRADO | N35: INDENIZAÇÃO | O35: 45065 | P35: N/A | Q35: N/A | R35: N/A | S35: N/A | T35: N/A | U35: N/A | V35: N/A | W35: N/A | X35: N/A | Y35: N/A | Z35: N/A | AB35: SUELI GOMES DE SOUZA | AC35: 19.370.643-X | AD35: 087.913.138-13 | AE35: PROPRIETÁRIO RESIDENTE | AF35: N/A | AG35: 0 | AH35: 60000 | AI35: RECEBEU INDENIZAÇÃO PELO SELO 001/0019/B | AJ35: 6014.2022/0003993-0 | AK35: N/A | AL35: N/A | AM35: N/A | AN35: N/A | AP35: N/A | AQ35: N/A | AR35: N/A | AS35: N/A | AT35: N/A | AU35: N/A | AV35: N/A | AW35: N/A | AX35: N/A | AY35: N/A | AZ35: AGUARDANDO | BA35: DEMOLIDO | BB35: FINALIZADO | BC35: N/A | BD35: =IF(AND(AI35<>"SIM",AI35="UH"),"AA","INDENIZAÇÃO") -> INDENIZAÇÃO | BE35: =IF(AND(AY35<>"AGUARDANDO",AY35<>"",N35="AUXÍLIO ALUGUEL ATÉ INDENIZAÇÃO"),"SIM","NÃO") -> NÃO | BF35: N/A | BG35: N/A | BH35: N/A | BI35: N/A | BJ35: N/A | BK35: N/A | BL35: N/A | BM35: FINALIZADO
A36: 23 | B36: ALFREDO ÁVILA | C36: 1 | D36: 0 | E36: 0 | F36: 001/0019/B | G36: OCUPADO | H36: RESIDENCIAL | I36: INQUILINO | J36: LUCAS DANIEL GOMES PEREIRA | K36: 52.281.364-1 | L36: 439.284.308-40 | M36: CADASTRADO | N36: AUXÍLIO ALUGUEL UH | O36: 44900 | P36: 44921 | Q36: 6014.2023/0000399-6 | R36: FINALIZADO | S36: FINALIZADO | T36: FINALIZADO | U36: 45128 | V36: 45135 | W36: 45135 | X36: 45160 | Y36: 45160 | Z36: 45180 | AB36: SUELI GOMES DE SOUZA | AC36: 19.370.643-X | AD36: 087.913.138-13 | AE36: PROPRIETÁRIO NÃO RESIDENTE | AF36: CADASTRADO | AG36: 110600 | AH36: 110600 | AI36: SIM | AJ36: 6014.2022/0003993-0 | AK36: FINALIZADO | AL36: FINALIZADO | AM36: FINALIZADO | AN36: SEM PENDÊNCIA | AP36: 6014.2023/0002325-3 | AQ36: FINALIZADO | AR36: FINALIZADO | AS36: FINALIZADO | AT36: FINALIZADO | AU36: 45146 | AV36: FINALIZADO | AW36: FINALIZADO | AX36: 45153 | AY36: 45153 | AZ36: 45179 | BA36: DEMOLIDO | BB36: FINALIZADO | BC36: =IF(AY36-ON36=0,"",AY36-O36) -> 253 | BD36: =IF(AND(AI36<>"SIM",AI36="UH"),"AA","INDENIZAÇÃO") -> INDENIZAÇÃO | BE36: =IF(AND(AY36<>"AGUARDANDO",AY36<>"",N36="AUXÍLIO ALUGUEL ATÉ INDENIZAÇÃO"),"SIM","NÃO") -> NÃO | BF36: N/A | BG36: N/A | BH36: N/A | BI36: FINALIZADO | BJ36: FINALIZADO | BK36: 45310 | BL36: FINALIZADO | BM36: FINALIZADO
A37: 24 | B37: ALFREDO ÁVILA | C37: 1 | D37: 0 | E37: 0 | F37: 001/0024/A | G37: OCUPADO | H37: RESIDENCIAL | I37: INQUILINO | J37: GLEDY MARISE DOS SANTOS ROSA | K37: 30.557.844-3 | L37: 301.750.188-47 | M37: CADASTRADO | N37: AUXÍLIO ALUGUEL UH | O37: 44900 | P37: 44921 | Q37: 6014.2023/0000399-6 | R37: FINALIZADO | S37: FINALIZADO | T37: FINALIZADO | U37: 45128 | V37: 45135 | W37: 45135 | X37: 45191 | Y37: 45194 | Z37: 45209 | AB37: CALINE DOS SANTOS CONVENTO | AC37: 43.781.566-3 | AD37: 229.019.538-32 | AE37: PROPRIETÁRIO NÃO RESIDENTE | AF37: CADASTRADO | AG37: 49000 | AH37: 60000 | AI37: SIM | AJ37: 6014.2022/0003993-0 | AK37: FINALIZADO | AL37: FINALIZADO | AM37: FINALIZADO | AN37: SEM PENDÊNCIA | AP37: 6014.2023/0001998-1 | AQ37: FINALIZADO | AR37: FINALIZADO | AS37: FINALIZADO | AT37: FINALIZADO | AU37: 45114 | AV37: FINALIZADO | AW37: FINALIZADO | AX37: 45152 | AY37: 45152 | AZ37: 45209 | BA37: DEMOLIDO | BB37: FINALIZADO | BC37: =IF(AY37-ON37=0,"",AY37-O37) -> 252 | BD37: =IF(AND(AI37<>"SIM",AI37="UH"),"AA","INDENIZAÇÃO") -> INDENIZAÇÃO | BE37: =IF(AND(AY37<>"AGUARDANDO",AY37<>"",N37="AUXÍLIO ALUGUEL ATÉ INDENIZAÇÃO"),"SIM","NÃO") -> NÃO | BF37: N/A | BG37: N/A | BH37: N/A | BI37: FINALIZADO | BJ37: FINALIZADO | BK37: 45246 | BL37: FINALIZADO | BM37: FINALIZADO
A38: 25 | B38: ALFREDO ÁVILA | C38: 1 | D38: 0 | E38: 0 | F38: 001/0025/A | G38: OCUPADO | H38: RESIDENCIAL | I38: INQUILINO | J38: RUANA PORTILLA | K38: 50.384.970-4 | L38: 461.003.518-97 | M38: CADASTRADO | N38: AUXÍLIO ALUGUEL UH | O38: 44900 | P38: 44921 | Q38: 6014.2023/0000399-6 | R38: FINALIZADO | S38: FINALIZADO | T38: FINALIZADO | U38: 44992 | V38: FINALIZADO | W38: 44992 | X38: 45019 | Y38: NÃO SACOU | Z38: 45127 | AA38: Equipe social não consegue entrar em contato para entregar o termo do cartão. AA Bloqueado | AB38: DANILO AUGUSTO DA SILVA SANTOS | AC38: 49.188.880-6 | AD38: 439.612.578-09 | AE38: PROPRIETÁRIO NÃO RESIDENTE | AF38: CADASTRADO | AG38: 46500 | AH38: 60000 | AI38: SIM | AJ38: 6014.2022/0003993-0 | AK38: FINALIZADO | AL38: FINALIZADO | AM38: FINALIZADO | AN38: SEM PENDÊNCIA | AP38: 6014.2022/0004083-0 | AQ38: FINALIZADO | AR38: FINALIZADO | AS38: FINALIZADO | AT38: FINALIZADO | AU38: 45014 | AV38: FINALIZADO | AW38: FINALIZADO | AX38: 45022 | AY38: 45022 | AZ38: 45134 | BA38: DEMOLIDO | BB38: FINALIZADO | BC38: =IF(AY38-ON38=0,"",AY38-O38) -> 122 | BD38: =IF(AND(AI38<>"SIM",AI38="UH"),"AA","INDENIZAÇÃO") -> INDENIZAÇÃO | BE38: =IF(AND(AY38<>"AGUARDANDO",AY38<>"",N38="AUXÍLIO ALUGUEL ATÉ INDENIZAÇÃO"),"SIM","NÃO") -> NÃO | BF38: N/A | BG38: N/A | BH38: N/A | BI38: FINALIZADO | BJ38: FINALIZADO | BK38: 45190 | BL38: FINALIZADO | BM38: FINALIZADO
A39: 26 | B39: ALFREDO ÁVILA | C39: 1 | D39: 0 | E39: 0 | F39: 001/0025/B | G39: OCUPADO | H39: RESIDENCIAL | I39: PROPRIETÁRIO RESIDENTE | J39: CARLOS ROBERTO BATISTA DE SOUZA | K39: 27.245.037-6 | L39: 564.518.226-04 | M39: CADASTRADO | N39: INDENIZAÇÃO | O39: 44900 | P39: N/A | Q39: N/A | R39: N/A | S39: N/A | T39: N/A | U39: N/A | V39: N/A | W39: N/A | X39: N/A | Y39: N/A | Z39: N/A | AB39: CARLOS ROBERTO BATISTA DE SOUZA | AC39: 27.245.037-6 | AD39: 564.518.226-04 | AE39: PROPRIETÁRIO RESIDENTE | AF39: CADASTRADO | AG39: 48100 | AH39: 60000 | AI39: SIM | AJ39: 6014.2022/0003993-0 | AK39: FINALIZADO | AL39: FINALIZADO | AM39: FINALIZADO | AN39: SEM PENDÊNCIA | AP39: 6014.2022/0004137-3 | AQ39: FINALIZADO | AR39: FINALIZADO | AS39: FINALIZADO | AT39: FINALIZADO | AU39: 44966 | AV39: FINALIZADO | AW39: FINALIZADO | AX39: 45012 | AY39: 45012 | AZ39: 45127 | BA39: DEMOLIDO | BB39: FINALIZADO | BC39: =IF(AY39-ON39=0,"",AY39-O39) -> 112 | BD39: =IF(AND(AI39<>"SIM",AI39="UH"),"AA","INDENIZAÇÃO") -> INDENIZAÇÃO | BE39: =IF(AND(AY39<>"AGUARDANDO",AY39<>"",N39="AUXÍLIO ALUGUEL ATÉ INDENIZAÇÃO"),"SIM","NÃO") -> NÃO | BF39: N/A | BG39: N/A | BH39: N/A | BI39: FINALIZADO | BJ39: FINALIZADO | BK39: 45190 | BL39: FINALIZADO | BM39: FINALIZADO
A40: 27 | B40: ALFREDO ÁVILA | C40: 1 | D40: 0 | E40: 0 | F40: 001/0026/A | G40: OCUPADO | H40: RESIDENCIAL | I40: PROPRIETÁRIO RESIDENTE | J40: RENATA RODRIGUES DA SILVA | K40: 39.316.490-1 | L40: 371.973.748-98 | M40: CADASTRADO | N40: INDENIZAÇÃO | O40: 44900 | P40: N/A | Q40: N/A | R40: N/A | S40: N/A | T40: N/A | U40: N/A | V40: N/A | W40: N/A | X40: N/A | Y40: N/A | Z40: N/A | AB40: RENATA RODRIGUES DA SILVA | AC40: 39.316.490-1 | AD40: 371.973.748-98 | AE40: PROPRIETÁRIO RESIDENTE | AF40: CADASTRADO | AG40: 27500 | AH40: 57500 | AI40: SIM | AJ40: 6014.2022/0003993-0 | AK40: FINALIZADO | AL40: FINALIZADO | AM40: FINALIZADO | AN40: SEM PENDÊNCIA | AP40: 6014.2022/0004081-4 | AQ40: FINALIZADO | AR40: FINALIZADO | AS40: FINALIZADO | AT40: FINALIZADO | AU40: 44966 | AV40: FINALIZADO | AW40: FINALIZADO | AX40: 45012 | AY40: 45012 | AZ40: 45063 | BA40: DEMOLIDO | BB40: FINALIZADO | BC40: =IF(AY40-ON40=0,"",AY40-O40) -> 112 | BD40: =IF(AND(AI40<>"SIM",AI40="UH"),"AA","INDENIZAÇÃO") -> INDENIZAÇÃO | BE40: =IF(AND(AY40<>"AGUARDANDO",AY40<>"",N40="AUXÍLIO ALUGUEL ATÉ INDENIZAÇÃO"),"SIM","NÃO") -> NÃO | BF40: N/A | BG40: N/A | BH40: N/A | BI40: FINALIZADO | BJ40: FINALIZADO | BK40: 45190 | BL40: FINALIZADO | BM40: FINALIZADO
A41: 28 | B41: ALFREDO ÁVILA | C41: 1 | D41: 0 | E41: 0 | F41: 001/0026/B | G41: OCUPADO | H41: RESIDENCIAL | I41: INQUILINO | J41: LAIS DA SILVA PEREIRA | K41: 57.273.865-1 | L41: 495.928.678-44 | M41: CADASTRADO | N41: AUXÍLIO ALUGUEL UH | O41: 44900 | P41: 44921 | Q41: 6014.2023/0000399-6 | R41: FINALIZADO | S41: FINALIZADO | T41: FINALIZADO | U41: 44992 | V41: FINALIZADO | W41: 44992 | X41: 45019 | Y41: 45020 | Z41: 45063 | AA41: Houve um problema na equipe do pagamento, sendo previsto para 03/04/2023 | AB41: GERINALDO RIBEIRO BARBOSA | AC41: 32.770.534-6 | AD41: 873.034.935-49 | AE41: PROPRIETÁRIO NÃO RESIDENTE | AF41: CADASTRADO | AG41: 0 | AH41: 60000 | AI41: RECEBEU INDENIZAÇÃO PELO SELO 001/0026/C | AJ41: 6014.2022/0003993-0 | AK41: FINALIZADO | AL41: N/A | AM41: N/A | AN41: N/A | AO41: MUNÍCIPE RECEBEU INDENIZAÇÃO PELO SELO 001/0026/C | AP41: N/A | AQ41: N/A | AR41: N/A | AS41: N/A | AT41: N/A | AU41: N/A | AV41: N/A | AW41: N/A | AX41: N/A | AY41: N/A | AZ41: 45063 | BA41: DEMOLIDO | BB41: FINALIZADO | BC41: =IF(AY41-ON41=0,"",AY41-O41) -> #VALUE! | BD41: =IF(AND(AI41<>"SIM",AI41="UH"),"AA","INDENIZAÇÃO") -> INDENIZAÇÃO | BE41: =IF(AND(AY41<>"AGUARDANDO",AY41<>"",N41="AUXÍLIO ALUGUEL ATÉ INDENIZAÇÃO"),"SIM","NÃO") -> NÃO
A42: 29 | B42: ALFREDO ÁVILA | C42: 1 | D42: 0 | E42: 0 | F42: 001/0026/C | G42: OCUPADO | H42: RESIDENCIAL | I42: INQUILINO | J42: MARILUCE DA SILVA | K42: 37.373.261-2 | L42: 271.024.958-89 | M42: CADASTRADO | N42: AUXÍLIO ALUGUEL UH | O42: 44900 | P42: 45081 | Q42: 6014.2023/0000399-6 | R42: FINALIZADO | S42: FINALIZADO | T42: FINALIZADO | U42: 02-mai-23 | V42: FINALIZADO | W42: 05-mai-23 | X42: 22-mai-23 | Y42: 23-mai-23 | Z42: 45063 | AB42: GERINALDO RIBEIRO BARBOSA | AC42: 32.770.534-6 | AD42: 873.034.935-49 | AE42: PROPRIETÁRIO NÃO RESIDENTE | AF42: CADASTRADO | AG42: 38000 | AH42: 60000 | AI42: SIM | AJ42: 6014.2022/0003993-0 | AK42: FINALIZADO | AL42: FINALIZADO | AM42: FINALIZADO | AN42: SEM PENDÊNCIA | AP42: 6014.2022/0004138-1 | AQ42: FINALIZADO | AR42: FINALIZADO | AS42: FINALIZADO | AT42: FINALIZADO | AU42: 45016 | AV42: FINALIZADO | AW42: FINALIZADO | AX42: 45022 | AY42: 45022 | AZ42: 45063 | BA42: DEMOLIDO | BB42: FINALIZADO | BC42: =IF(AY42-ON42=0,"",AY42-O42) -> 122 | BD42: =IF(AND(AI42<>"SIM",AI42="UH"),"AA","INDENIZAÇÃO") -> INDENIZAÇÃO | BE42: =IF(AND(AY42<>"AGUARDANDO",AY42<>"",N42="AUXÍLIO ALUGUEL ATÉ INDENIZAÇÃO"),"SIM","NÃO") -> NÃO | BF42: N/A | BG42: N/A | BH42: N/A | BI42: FINALIZADO | BJ42: FINALIZADO | BK42: 45190 | BL42: FINALIZADO | BM42: FINALIZADO
A43: 30 | B43: ALFREDO ÁVILA | C43: 1 | D43: 0 | E43: 0 | F43: 001/0027/A | G43: OCUPADO | H43: RESIDENCIAL | I43: PROPRIETÁRIO RESIDENTE | J43: JOSIELE DE OLIVEIRA SILVA | K43: 47.114.574-9 | L43: 388.201.958-10 | M43: CADASTRADO | N43: INDENIZAÇÃO | O43: 44900 | P43: N/A | Q43: N/A | R43: N/A | S43: N/A | T43: N/A | U43: N/A | V43: N/A | W43: N/A | X43: N/A | Y43: N/A | Z43: N/A | AB43: JOSIELE DE OLIVEIRA SILVA | AC43: 47.114.574-9 | AD43: 388.201.958-10 | AE43: PROPRIETÁRIO RESIDENTE | AF43: CADASTRADO | AG43: 37500 | AH43: 60000 | AI43: SIM | AJ43: 6014.2022/0003993-0 | AK43: FINALIZADO | AL43: FINALIZADO | AM43: FINALIZADO | AN43: SEM PENDÊNCIA | AP43: 6014.2022/0004029-6 | AQ43: FINALIZADO | AR43: FINALIZADO | AS43: FINALIZADO | AT43: FINALIZADO | AU43: 44922 | AV43: FINALIZADO | AW43: FINALIZADO | AX43: 44924 | AY43: 44924 | AZ43: 44936 | BA43: DEMOLIDO | BB43: FINALIZADO | BC43: =IF(AY43-ON43=0,"",AY43-O43) -> 24 | BD43: =IF(AND(AI43<>"SIM",AI43="UH"),"AA","INDENIZAÇÃO") -> INDENIZAÇÃO | BE43: =IF(AND(AY43<>"AGUARDANDO",AY43<>"",N43="AUXÍLIO ALUGUEL ATÉ INDENIZAÇÃO"),"SIM","NÃO") -> NÃO | BF43: N/A | BG43: N/A | BH43: N/A | BI43: FINALIZADO | BJ43: FINALIZADO | BK43: 45057 | BL43: FINALIZADO | BM43: FINALIZADO
A44: 31 | B44: ALFREDO ÁVILA | C44: 1 | D44: 0 | E44: 0 | F44: 001/0028/A | G44: OCUPADO | H44: RESIDENCIAL | I44: PROPRIETÁRIO RESIDENTE | J44: THAIS DE OLIVEIRA SILVA FERREIRA | K44: 34.615.609-9 | L44: 387.066.978-01 | M44: CADASTRADO | N44: AUXÍLIO ALUGUEL UH | O44: 44900 | P44: 44921 | Q44: 6014.2023/0000399-6 | R44: FINALIZADO | S44: FINALIZADO | T44: FINALIZADO | U44: 44992 | V44: FINALIZADO | W44: 44992 | X44: 45019 | Y44: 45019 | Z44: 45063 | AA44: Houve um problema na equipe do pagamento, sendo previsto para 03/04/2023 | AB44: THAIS DE OLIVEIRA SILVA FERREIRA | AC44: 34.615.609-9 | AD44: 387.066.978-01 | AE44: PROPRIETÁRIO RESIDENTE | AF44: CADASTRADO | AG44: 31100 | AH44: 60000 | AI44: UH | AJ44: 6014.2022/0003993-0 | AK44: FINALIZADO | AL44: N/A | AM44: N/A | AN44: N/A | AP44: N/A | AQ44: N/A | AR44: N/A | AS44: N/A | AT44: N/A | AU44: N/A | AV44: N/A | AW44: N/A | AX44: 45019 | AY44: 45019 | AZ44: 45063 | BA44: DEMOLIDO | BB44: FINALIZADO | BC44: =IF(AY44-ON44=0,"",AY44-O44) -> 119 | BD44: =IF(AND(AI44<>"SIM",AI44="UH"),"AA","INDENIZAÇÃO") -> AA | BE44: =IF(AND(AY44<>"AGUARDANDO",AY44<>"",N44="AUXÍLIO ALUGUEL ATÉ INDENIZAÇÃO"),"SIM","NÃO") -> NÃO | BF44: N/A | BG44: N/A | BH44: N/A | BI44: N/A | BJ44: N/A | BK44: N/A | BL44: N/A | BM44: FINALIZADO
...

Sheet Quantitativo Fora da Demanda
A1: REPROVADOS QUE NÃO DEVERÃO SER REASSENTADOS NO ESPANHA | E1: APROVADOS SEM CONDOMÍNIO QUE DEVERÃO SER REASSENTADOS NO CHÁCARA DO CONDE
A2: ÁREA | B2: QTD | E2: ÁREA | F2: QTD
A3: AUXÍLIO ALUGUEL | B3: 39 | E3: AUXÍLIO ALUGUEL | F3: 54
A4: CANTINHO DO CÉU (OBRAS) | B4: 15 | E4: CANTINHO DO CÉU (OBRAS) SETORES: 138 E 140 | F4: 13
A5: FUMAÇA | B5: 7 | E5: FUMAÇA | F5: 15
A6: NEBLINA | B6: 2 | E6: NEBLINA | F6: 9
A7: LEBLON | B7: 0 | E7: LEBLON | F7: 9
A8: PABREU / PRAINHA | B8: 15 | E8: PABREU / PRAINHA | F8: 21
A9: TOTAL | B9: =SUM(B3:B8) -> 78 | E9: TOTAL | F9: =SUM(F3:F8) -> 121

Sheet Listas (não utilizar)
A1: Área | B1: Condomínio | C1: Bloco | D1: Apartamento | E1: SITAH / CAIXA | F1: Status CAIXA | G1: Adequacao Imovel | H1: Renúncia | I1: Pendência | J1: Pendências / Reprovados caixa
A2: ALTO DA ALEGRIA | B2: AVILA | C2: 1 | D2: 101 | E2: AGENDADO | F2: APROVADO | G2: NÃO | H2: NÃO | I2: CRAS | J2: RENDA SUPERIOR
A3: ALTO DA ALEGRIA (OBRAS) | B3: BARCELONA | C3: 2 | D3: 102 | E3: AGUARDANDO OFICIO | F3: REPROVADO | G3: FÍSICA | H3: RENDA | I3: CRAS + DOCUMENTOS | J3: CADMUT
A4: ALTO DA ALEGRIA (RESERVA) | B4: BILBAO | C4: 3 | D4: 103 | E4: ATENDIMENTO CANCELADO | F4: PENDENCIA | G4: VISUAL | H4: CADIN | I4: DOCUMENTOS | J4: CADIN
A5: ANTERO GOMES | B5: CEUTA | C5: 4 | D5: 104 | E5: CADMUT | F5: SEM DOSSIE | G5: INTELECTUAL | H5: ESTADO CIVIL | I5: CADIN
A6: CANTINHO DO CEU / GAIVOTAS | B6: IBIZA | C6: 5 | D6: 201 | E6: CHACARA DO CONDE | G6: AUDITIVA | H6: SEPARACAO | I6: CRAS + CADIN
A7: CANTINHO DO CEU / OBRAS | B7: LEAO | C7: 6 | D7: 202 | E7: CONFLITO | G7: NANISMO | I7: R.LI.AV.
A8: CASTRO ALVES | B8: MADRID | C8: 7 | D8: 203 | E8: ENVIADO CAIXA | I8: IEME
A9: COCAIA | B9: MELILLA | C9: 8 | D9: 204 | E9: FALECEU
A10: ERUNDINA | B10: PAMPLONA | C10: 9 | D10: 301 | E10: FALTANTE DOSSIÊ
A11: FUMACA | B11: SALAMANCA | C11: 10 | D11: 302 | E11: HABISP ACERTO DE ÁREA
A12: GUAICURI (OBRAS) | B12: TERUEL | C12: 11 | D12: 303 | E12: HABISP AGUARDANDO CRÍTICA
A13: GUAICURI / CIDADE JULIA | B13: VALENCIA | C13: 12 | D13: 304 | E13: HABISP PEND DE ATUALIZ CADASTRAL
A14: JARDIM MIRNA | B14: VALVERDE | C14: 13 | D14: 401 | E14: INDENIZACAO
A15: JARDIM SELMA II | B15: VITORIA | C15: 14 | D15: 402 | E15: PENDENCIA
A16: JARDIM TUBO | C16: 15 | D16: 403 | E16: PERMUTA
A17: LEBLON | D17: 404 | E17: PESQUISA SMADS
A18: MARGINAL DOIS / FUNDAO | D18: 501 | E18: REANALISE
A19: MATA VIRGEM / JD ELDORADO | D19: 502 | E19: RECLUSO
A20: NEBLINA | D20: 503 | E20: RELATÓRIO SOCIAL
A21: NORONHA | D21: 504 | E21: RENDA SUPERIOR
A22: NOVA GRAJAU | E22: RESISTENTE
A23: NOVA MARILDA | E23: TROCA DE TITULARIDADE
A24: NOVA VARGINHA
A25: PABREU / PRAINHA
A26: PENDENCIA GABINETE
A27: PILAO / APURA
A28: PILAO / DOIS
A29: PILAO / PAULISTAS
A30: SANTA AMELIA
A31: VALE VERDE / MONTE VERDE
A32: VILA BREJINHO
A33: VILA NASCENTE
A34: ZR / COSTA BRANCA
A35: VILA RUBI

Sheet QUANT COND
A1: CONDOMINIOS | B1: QUANT
A2: AVILA | B2: =COUNTIF(#REF!,'QUANT COND'!A2) -> #REF!
A3: BARCELONA | B3: =COUNTIF(#REF!,'QUANT COND'!A3) -> #REF!
A4: BILBAO | B4: =COUNTIF(#REF!,'QUANT COND'!A4) -> #REF!
A5: CEUTA | B5: =COUNTIF(#REF!,'QUANT COND'!A5) -> #REF!
A6: IBIZA | B6: =COUNTIF(#REF!,'QUANT COND'!A6) -> #REF!
A7: LEAO | B7: =COUNTIF(#REF!,'QUANT COND'!A7) -> #REF!
A8: MADRID | B8: =COUNTIF(#REF!,'QUANT COND'!A8) -> #REF!
A9: MELILLA | B9: =COUNTIF(#REF!,'QUANT COND'!A9) -> #REF!
A10: PAMPLONA | B10: =COUNTIF(#REF!,'QUANT COND'!A10) -> #REF!
A11: SALAMANCA | B11: =COUNTIF(#REF!,'QUANT COND'!A11) -> #REF!
A12: TERUEL | B12: =COUNTIF(#REF!,'QUANT COND'!A12) -> #REF!
A13: VALENCIA | B13: =COUNTIF(#REF!,'QUANT COND'!A13) -> #REF!
... A15: VITORIA | B15: =COUNTIF(#REF!,'QUANT COND'!A15) -> #REF!

Sheet OFÍCIOS
A1: PLANILHA DE CONFRONTO OFÍCIOS DE INDICAÇÃO COM ENVIADOS CAIXA ECONÔMICA FEDERAL - CEF
A2: TITULAR | B2: CPF | C2: Cônjuge | D2: CPF | E2: OFÍCIO | F2: DATA | G2: STATUS CEF | H2: DATA ENVIO CAIXA | I2: DUPLICIDADE OFÍCIO | J2: DATA | K2: DATA ENVIO CAIXA | L2: OFÍCIO DE INDICAÇÃO | M2: DATA OFÍCIO INDICAÇÃO | O2: NR OFICIO | P2: QUANT | Q2: APROV | R2: REPROV | S2: PEND | T2: SEM STATUS (ANÁLISE) | Y2: CEF BD | Z2: CEF OFICIOS | AA2: CEF PLANILHA
A3: ABEL MEDEIROS FILHO | B3: 27140979871 | E3: 1128 | F3: 42972 | G3: APROVADO | H3: 42979 | O3: 810 | P3: =COUNTIF(OFÍCIOS!E:E,O3) -> 156 | Q3: =COUNTIFS(OFÍCIOS!$E:$E,$O3,OFÍCIOS!$G:$G,"APROVADO") -> 149 | R3: =COUNTIFS(OFÍCIOS!$E:$E,$O3,OFÍCIOS!$G:$G,"REPROVADO") -> 3 | S3: =COUNTIFS(OFÍCIOS!$E:$E,$O3,OFÍCIOS!$G:$G,"PENDENCIA") -> 2 | T3: =COUNTIFS(OFÍCIOS!$E:$E,$O3,OFÍCIOS!$G:$G,"") -> 2 | U3: =SUM(Q3:T3) -> 156 | X3: FEITOS | Y3: 1850 | Z3: 1827 | AA3: =SUM(AA4:AA7) -> 1615
A4: ABELINA FERREIRA DOS SANTOS | B4: 39200633846 | O4: 1417 | P4: =COUNTIF(OFÍCIOS!E:E,O4) -> 42 | Q4: =COUNTIFS(OFÍCIOS!$E:$E,$O4,OFÍCIOS!$G:$G,"APROVADO") -> 36 | R4: =COUNTIFS(OFÍCIOS!$E:$E,$O4,OFÍCIOS!$G:$G,"REPROVADO") -> 3 | S4: =COUNTIFS(OFÍCIOS!$E:$E,$O4,OFÍCIOS!$G:$G,"PENDENCIA") -> 3 | T4: =COUNTIFS(OFÍCIOS!$E:$E,$O4,OFÍCIOS!$G:$G,"") -> 0 | U4: =SUM(Q4:T4) -> 42 | X4: APROVADOS | Y4: 1517 | Z4: 1427 | AA4: 1559
A5: ABIGAIL DE OLIVEIRA PAULINO | B5: 75489104872 | E5: 1752 | F5: 43051 | G5: APROVADO | H5: 43089 | L5: 1759 | O5: 1359 | P5: =COUNTIF(OFÍCIOS!E:E,O5) -> 14 | Q5: =COUNTIFS(OFÍCIOS!$E:$E,$O5,OFÍCIOS!$G:$G,"APROVADO") -> 13 | R5: =COUNTIFS(OFÍCIOS!$E:$E,$O5,OFÍCIOS!$G:$G,"REPROVADO") -> 1 | S5: =COUNTIFS(OFÍCIOS!$E:$E,$O5,OFÍCIOS!$G:$G,"PENDENCIA") -> 0 | T5: =COUNTIFS(OFÍCIOS!$E:$E,$O5,OFÍCIOS!$G:$G,"") -> 0 | U5: =SUM(Q5:T5) -> 14 | X5: REPROVADOS | Y5: 73 | Z5: 79 | AA5: 28
A6: ABILIO OLIVEIRA SANTOS | B6: 43286003620 | O6: 1350 | P6: =COUNTIF(OFÍCIOS!E:E,O6) -> 79 | Q6: =COUNTIFS(OFÍCIOS!$E:$E,$O6,OFÍCIOS!$G:$G,"APROVADO") -> 75 | R6: =COUNTIFS(OFÍCIOS!$E:$E,$O6,OFÍCIOS!$G:$G,"REPROVADO") -> 3 | S6: =COUNTIFS(OFÍCIOS!$E:$E,$O6,OFÍCIOS!$G:$G,"PENDENCIA") -> 0 | T6: =COUNTIFS(OFÍCIOS!$E:$E,$O6,OFÍCIOS!$G:$G,"") -> 1 | U6: =SUM(Q6:T6) -> 79 | X6: PENDENCIAS | Y6: 36 | Z6: 32 | AA6: 11
A7: ABRAHAO SANTOS SILVA | O7: 1343 | P7: =COUNTIF(OFÍCIOS!E:E,O7) -> 6 | Q7: =COUNTIFS(OFÍCIOS!$E:$E,$O7,OFÍCIOS!$G:$G,"APROVADO") -> 5 | R7: =COUNTIFS(OFÍCIOS!$E:$E,$O7,OFÍCIOS!$G:$G,"REPROVADO") -> 0 | S7: =COUNTIFS(OFÍCIOS!$E:$E,$O7,OFÍCIOS!$G:$G,"PENDENCIA") -> 0 | T7: =COUNTIFS(OFÍCIOS!$E:$E,$O7,OFÍCIOS!$G:$G,"") -> 1 | U7: =SUM(Q7:T7) -> 6 | X7: SS / ANALISE | Y7: 224 | Z7: 275 | AA7: 17
A8: ADAIR DA SILVA BARROS | B8: 97443271620 | E8: 1106 | F8: 42965 | G8: APROVADO | H8: 42978 | O8: 1267 | P8: =COUNTIF(OFÍCIOS!E:E,O8) -> 34 | Q8: =COUNTIFS(OFÍCIOS!$E:$E,$O8,OFÍCIOS!$G:$G,"APROVADO") -> 28 | R8: =COUNTIFS(OFÍCIOS!$E:$E,$O8,OFÍCIOS!$G:$G,"REPROVADO") -> 5 | S8: =COUNTIFS(OFÍCIOS!$E:$E,$O8,OFÍCIOS!$G:$G,"PENDENCIA") -> 1 | T8: =COUNTIFS(OFÍCIOS!$E:$E,$O8,OFÍCIOS!$G:$G,"") -> 0 | U8: =SUM(Q8:T8) -> 34
A9: ADALBERTO CARVALHO DE OLIVEIRA | B9: 98058690597 | E9: 423 | F9: 43182 | G9: APROVADO | O9: 1262 | P9: =COUNTIF(OFÍCIOS!E:E,O9) -> 8 | Q9: =COUNTIFS(OFÍCIOS!$E:$E,$O9,OFÍCIOS!$G:$G,"APROVADO") -> 7 | R9: =COUNTIFS(OFÍCIOS!$E:$E,$O9,OFÍCIOS!$G:$G,"REPROVADO") -> 1 | S9: =COUNTIFS(OFÍCIOS!$E:$E,$O9,OFÍCIOS!$G:$G,"PENDENCIA") -> 0 | T9: =COUNTIFS(OFÍCIOS!$E:$E,$O9,OFÍCIOS!$G:$G,"") -> 0 | U9: =SUM(Q9:T9) -> 8
A10: ADALBERTO CAVALCANTE DOS SANTOS | B10: 38088438888 | O10: 1106 | P10: =COUNTIF(OFÍCIOS!E:E,O10) -> 78 | Q10: =COUNTIFS(OFÍCIOS!$E:$E,$O10,OFÍCIOS!$G:$G,"APROVADO") -> 73 | R10: =COUNTIFS(OFÍCIOS!$E:$E,$O10,OFÍCIOS!$G:$G,"REPROVADO") -> 5 | S10: =COUNTIFS(OFÍCIOS!$E:$E,$O10,OFÍCIOS!$G:$G,"PENDENCIA") -> 0 | T10: =COUNTIFS(OFÍCIOS!$E:$E,$O10,OFÍCIOS!$G:$G,"") -> 0 | U10: =SUM(Q10:T10) -> 78
A11: ADALMA MOREIRA DA ROCHA | B11: 26939799869 | E11: 573 | F11: 43224 | O11: 1128 | P11: =COUNTIF(OFÍCIOS!E:E,O11) -> 92 | Q11: =COUNTIFS(OFÍCIOS!$E:$E,$O11,OFÍCIOS!$G:$G,"APROVADO") -> 91 | R11: =COUNTIFS(OFÍCIOS!$E:$E,$O11,OFÍCIOS!$G:$G,"REPROVADO") -> 1 | S11: =COUNTIFS(OFÍCIOS!$E:$E,$O11,OFÍCIOS!$G:$G,"PENDENCIA") -> 0 | T11: =COUNTIFS(OFÍCIOS!$E:$E,$O11,OFÍCIOS!$G:$G,"") -> 0 | U11: =SUM(Q11:T11) -> 92
A12: ADAMILTON PEREIRA DA SILVA ( ALANA ) | B12: 34470559873 | E12: 292 | F12: 43168 | G12: APROVADO | H12: 43182 | L12: 318 | O12: 1214 | P12: =COUNTIF(OFÍCIOS!E:E,O12) -> 76 | Q12: =COUNTIFS(OFÍCIOS!$E:$E,$O12,OFÍCIOS!$G:$G,"APROVADO") -> 71 | R12: =COUNTIFS(OFÍCIOS!$E:$E,$O12,OFÍCIOS!$G:$G,"REPROVADO") -> 3 | S12: =COUNTIFS(OFÍCIOS!$E:$E,$O12,OFÍCIOS!$G:$G,"PENDENCIA") -> 0 | T12: =COUNTIFS(OFÍCIOS!$E:$E,$O12,OFÍCIOS!$G:$G,"") -> 2 | U12: =SUM(Q12:T12) -> 76
A13: ADAO MENDES AGOSTINHO | B13: 14369564808 | O13: 1241 | P13: =COUNTIF(OFÍCIOS!E:E,O13) -> 33 | Q13: =COUNTIFS(OFÍCIOS!$E:$E,$O13,OFÍCIOS!$G:$G,"APROVADO") -> 32 | R13: =COUNTIFS(OFÍCIOS!$E:$E,$O13,OFÍCIOS!$G:$G,"REPROVADO") -> 0 | S13: =COUNTIFS(OFÍCIOS!$E:$E,$O13,OFÍCIOS!$G:$G,"PENDENCIA") -> 1 | T13: =COUNTIFS(OFÍCIOS!$E:$E,$O13,OFÍCIOS!$G:$G,"") -> 0 | U13: =SUM(Q13:T13) -> 33
A14: ADEGMARIO DOS SANTOS | B14: 39544185844 | E14: 810 | F14: 42915 | G14: APROVADO | H14: 42921 | L14: 568-17 | O14: 1422 | P14: =COUNTIF(OFÍCIOS!E:E,O14) -> 7 | Q14: =COUNTIFS(OFÍCIOS!$E:$E,$O14,OFÍCIOS!$G:$G,"APROVADO") -> 7 | R14: =COUNTIFS(OFÍCIOS!$E:$E,$O14,OFÍCIOS!$G:$G,"REPROVADO") -> 0 | S14: =COUNTIFS(OFÍCIOS!$E:$E,$O14,OFÍCIOS!$G:$G,"PENDENCIA") -> 0 | T14: =COUNTIFS(OFÍCIOS!$E:$E,$O14,OFÍCIOS!$G:$G,"") -> 0 | U14: =SUM(Q14:T14) -> 7
A15: ADEILDA GABRIELA CAITANO SILVA | B15: 38772276860 | C15: LUCIANO MANOEL DA SILVA | D15: 3808243457 | O15: 1439 | P15: =COUNTIF(OFÍCIOS!E:E,O15) -> 16 | Q15: =COUNTIFS(OFÍCIOS!$E:$E,$O15,OFÍCIOS!$G:$G,"APROVADO") -> 14 | R15: =COUNTIFS(OFÍCIOS!$E:$E,$O15,OFÍCIOS!$G:$G,"REPROVADO") -> 1 | S15: =COUNTIFS(OFÍCIOS!$E:$E,$O15,OFÍCIOS!$G:$G,"PENDENCIA") -> 1 | T15: =COUNTIFS(OFÍCIOS!$E:$E,$O15,OFÍCIOS!$G:$G,"") -> 0 | U15: =SUM(Q15:T15) -> 16
A16: ADEILDA RODRIGUES DE OLIVEIRA | B16: 21538837846 | C16: PEDRO LUIZ SANTOS OLIVEIRA | D16: 94203180520 | E16: 810 | F16: 42915 | G16: APROVADO | H16: 42921 | L16: 568-17 | O16: 1451 | P16: =COUNTIF(OFÍCIOS!E:E,O16) -> 4 | Q16: =COUNTIFS(OFÍCIOS!$E:$E,$O16,OFÍCIOS!$G:$G,"APROVADO") -> 3 | R16: =COUNTIFS(OFÍCIOS!$E:$E,$O16,OFÍCIOS!$G:$G,"REPROVADO") -> 1 | S16: =COUNTIFS(OFÍCIOS!$E:$E,$O16,OFÍCIOS!$G:$G,"PENDENCIA") -> 0 | T16: =COUNTIFS(OFÍCIOS!$E:$E,$O16,OFÍCIOS!$G:$G,"") -> 0 | U16: =SUM(Q16:T16) -> 4
A17: ADEILDO ADELINO DE CARVALHO | B17: 57455392591 | O17: 1470 | P17: =COUNTIF(OFÍCIOS!E:E,O17) -> 4 | Q17: =COUNTIFS(OFÍCIOS!$E:$E,$O17,OFÍCIOS!$G:$G,"APROVADO") -> 4 | R17: =COUNTIFS(OFÍCIOS!$E:$E,$O17,OFÍCIOS!$G:$G,"REPROVADO") -> 0 | S17: =COUNTIFS(OFÍCIOS!$E:$E,$O17,OFÍCIOS!$G:$G,"PENDENCIA") -> 0 | T17: =COUNTIFS(OFÍCIOS!$E:$E,$O17,OFÍCIOS!$G:$G,"") -> 0 | U17: =SUM(Q17:T17) -> 4
A18: ADELCIDES DA CONCEICAO ALMEIDA | B18: 5304941594 | E18: 1106 | F18: 42965 | G18: APROVADO | H18: 42978 | O18: 1489 | P18: =COUNTIF(OFÍCIOS!E:E,O18) -> 35 | Q18: =COUNTIFS(OFÍCIOS!$E:$E,$O18,OFÍCIOS!$G:$G,"APROVADO") -> 34 | R18: =COUNTIFS(OFÍCIOS!$E:$E,$O18,OFÍCIOS!$G:$G,"REPROVADO") -> 0 | S18: =COUNTIFS(OFÍCIOS!$E:$E,$O18,OFÍCIOS!$G:$G,"PENDENCIA") -> 1 | T18: =COUNTIFS(OFÍCIOS!$E:$E,$O18,OFÍCIOS!$G:$G,"") -> 0 | U18: =SUM(Q18:T18) -> 35
A19: ADELIA MARIA DE OLIVEIRA | B19: 21600057896 | E19: 262 | F19: 43160 | G19: REPROVADO | H19: 43164 | L19: 255 | O19: 1555 | P19: =COUNTIF(OFÍCIOS!E:E,O19) -> 25 | Q19: =COUNTIFS(OFÍCIOS!$E:$E,$O19,OFÍCIOS!$G:$G,"APROVADO") -> 22 | R19: =COUNTIFS(OFÍCIOS!$E:$E,$O19,OFÍCIOS!$G:$G,"REPROVADO") -> 1 | S19: =COUNTIFS(OFÍCIOS!$E:$E,$O19,OFÍCIOS!$G:$G,"PENDENCIA") -> 2 | T19: =COUNTIFS(OFÍCIOS!$E:$E,$O19,OFÍCIOS!$G:$G,"") -> 0 | U19: =SUM(Q19:T19) -> 25
A20: ADEMARIO FERREIRA DOS SANTOS | B20: 18419589802 | O20: 1570 | P20: =COUNTIF(OFÍCIOS!E:E,O20) -> 24 | Q20: =COUNTIFS(OFÍCIOS!$E:$E,$O20,OFÍCIOS!$G:$G,"APROVADO") -> 23 | R20: =COUNTIFS(OFÍCIOS!$E:$E,$O20,OFÍCIOS!$G:$G,"REPROVADO") -> 1 | S20: =COUNTIFS(OFÍCIOS!$E:$E,$O20,OFÍCIOS!$G:$G,"PENDENCIA") -> 0 | T20: =COUNTIFS(OFÍCIOS!$E:$E,$O20,OFÍCIOS!$G:$G,"") -> 0 | U20: =SUM(Q20:T20) -> 24
A21: ADEMIR DA SILVA LIMA | B21: 15538537846 | E21: 573 | F21: 43224 | O21: 1752 | P21: =COUNTIF(OFÍCIOS!E:E,O21) -> 89 | Q21: =COUNTIFS(OFÍCIOS!$E:$E,$O21,OFÍCIOS!$G:$G,"APROVADO") -> 80 | R21: =COUNTIFS(OFÍCIOS!$E:$E,$O21,OFÍCIOS!$G:$G,"REPROVADO") -> 2 | S21: =COUNTIFS(OFÍCIOS!$E:$E,$O21,OFÍCIOS!$G:$G,"PENDENCIA") -> 5 | T21: =COUNTIFS(OFÍCIOS!$E:$E,$O21,OFÍCIOS!$G:$G,"") -> 2 | U21: =SUM(Q21:T21) -> 89
A22: ADENILDE SANTOS DA SILVA | B22: 899837506 | E22: 1824 | F22: 43091 | G22: APROVADO | H22: 43097 | L22: 1828 | O22: 1824 | P22: =COUNTIF(OFÍCIOS!E:E,O22) -> 81 | Q22: =COUNTIFS(OFÍCIOS!$E:$E,$O22,OFÍCIOS!$G:$G,"APROVADO") -> 67 | R22: =COUNTIFS(OFÍCIOS!$E:$E,$O22,OFÍCIOS!$G:$G,"REPROVADO") -> 7 | S22: =COUNTIFS(OFÍCIOS!$E:$E,$O22,OFÍCIOS!$G:$G,"PENDENCIA") -> 6 | T22: =COUNTIFS(OFÍCIOS!$E:$E,$O22,OFÍCIOS!$G:$G,"") -> 1 | U22: =SUM(Q22:T22) -> 81
A23: ADENILSON DA CONCEICAO | B23: 36197160803 | E23: 229 | F23: 43151 | G23: APROVADO | L23: 232 | O23: 1628 | P23: =COUNTIF(OFÍCIOS!E:E,O23) -> 6 | Q23: =COUNTIFS(OFÍCIOS!$E:$E,$O23,OFÍCIOS!$G:$G,"APROVADO") -> 5 | R23: =COUNTIFS(OFÍCIOS!$E:$E,$O23,OFÍCIOS!$G:$G,"REPROVADO") -> 1 | S23: =COUNTIFS(OFÍCIOS!$E:$E,$O23,OFÍCIOS!$G:$G,"PENDENCIA") -> 0 | T23: =COUNTIFS(OFÍCIOS!$E:$E,$O23,OFÍCIOS!$G:$G,"") -> 0 | U23: =SUM(Q23:T23) -> 6
A24: ADENIR MODESTO RIBEIRO | B24: 39248826814 | E24: 292 | F24: 43168 | G24: APROVADO | H24: 43182 | L24: 318 | O24: 608 | P24: =COUNTIF(OFÍCIOS!E:E,O24) -> 35 | Q24: =COUNTIFS(OFÍCIOS!$E:$E,$O24,OFÍCIOS!$G:$G,"APROVADO") -> 31 | R24: =COUNTIFS(OFÍCIOS!$E:$E,$O24,OFÍCIOS!$G:$G,"REPROVADO") -> 3 | S24: =COUNTIFS(OFÍCIOS!$E:$E,$O24,OFÍCIOS!$G:$G,"PENDENCIA") -> 1 | T24: =COUNTIFS(OFÍCIOS!$E:$E,$O24,OFÍCIOS!$G:$G,"") -> 0 | U24: =SUM(Q24:T24) -> 35
A25: ADILINA FARIAS DO NASCIMENTO | B25: 48925276534 | E25: 229 | F25: 43151 | L25: 232 | O25: 527 | P25: =COUNTIF(OFÍCIOS!E:E,O25) -> 29 | Q25: =COUNTIFS(OFÍCIOS!$E:$E,$O25,OFÍCIOS!$G:$G,"APROVADO") -> 0 | R25: =COUNTIFS(OFÍCIOS!$E:$E,$O25,OFÍCIOS!$G:$G,"REPROVADO") -> 0 | S25: =COUNTIFS(OFÍCIOS!$E:$E,$O25,OFÍCIOS!$G:$G,"PENDENCIA") -> 0 | T25: =COUNTIFS(OFÍCIOS!$E:$E,$O25,OFÍCIOS!$G:$G,"") -> 29 | U25: =SUM(Q25:T25) -> 29
A26: ADILSON SOARES DA COSTA | O26: 509 | P26: =COUNTIF(OFÍCIOS!E:E,O26) -> 14 | Q26: =COUNTIFS(OFÍCIOS!$E:$E,$O26,OFÍCIOS!$G:$G,"APROVADO") -> 0 | R26: =COUNTIFS(OFÍCIOS!$E:$E,$O26,OFÍCIOS!$G:$G,"REPROVADO") -> 0 | S26: =COUNTIFS(OFÍCIOS!$E:$E,$O26,OFÍCIOS!$G:$G,"PENDENCIA") -> 0 | T26: =COUNTIFS(OFÍCIOS!$E:$E,$O26,OFÍCIOS!$G:$G,"") -> 14 | U26: =SUM(Q26:T26) -> 14
A27: ADMEIA BARBOSA DE SOUZA | B27: 25894152810 | C27: REINALDO SANTOS REIS | D27: 8263008808 | E27: 292 | F27: 43168 | G27: APROVADO | H27: 43182 | L27: 318 | O27: 292 | P27: =COUNTIF(OFÍCIOS!E:E,O27) -> 233 | Q27: =COUNTIFS(OFÍCIOS!$E:$E,$O27,OFÍCIOS!$G:$G,"APROVADO") -> 212 | R27: =COUNTIFS(OFÍCIOS!$E:$E,$O27,OFÍCIOS!$G:$G,"REPROVADO") -> 9 | S27: =COUNTIFS(OFÍCIOS!$E:$E,$O27,OFÍCIOS!$G:$G,"PENDENCIA") -> 0 | T27: =COUNTIFS(OFÍCIOS!$E:$E,$O27,OFÍCIOS!$G:$G,"") -> 12 | U27: =SUM(Q27:T27) -> 233
A28: ADONES FERREIRA JORGE | B28: 43026389587 | C28: EUNICE FELICIANA BRITO JORGE | D28: 29124464813 | E28: 485 | F28: 43196 | H28: 43206 | L28: 483 | O28: 573 | P28: =COUNTIF(OFÍCIOS!E:E,O28) -> 43 | Q28: =COUNTIFS(OFÍCIOS!$E:$E,$O28,OFÍCIOS!$G:$G,"APROVADO") -> 0 | R28: =COUNTIFS(OFÍCIOS!$E:$E,$O28,OFÍCIOS!$G:$G,"REPROVADO") -> 0 | S28: =COUNTIFS(OFÍCIOS!$E:$E,$O28,OFÍCIOS!$G:$G,"PENDENCIA") -> 0 | T28: =COUNTIFS(OFÍCIOS!$E:$E,$O28,OFÍCIOS!$G:$G,"") -> 43 | U28: =SUM(Q28:T28) -> 43
A29: ADRIANA ALVES DA SILVA | B29: 26245112885 | E29: 262 | F29: 43160 | G29: REPROVADO | H29: 43164 | L29: 255 | O29: 563 | P29: =COUNTIF(OFÍCIOS!E:E,O29) -> 64 | Q29: =COUNTIFS(OFÍCIOS!$E:$E,$O29,OFÍCIOS!$G:$G,"APROVADO") -> 0 | R29: =COUNTIFS(OFÍCIOS!$E:$E,$O29,OFÍCIOS!$G:$G,"REPROVADO") -> 0 | S29: =COUNTIFS(OFÍCIOS!$E:$E,$O29,OFÍCIOS!$G:$G,"PENDENCIA") -> 0 | T29: =COUNTIFS(OFÍCIOS!$E:$E,$O29,OFÍCIOS!$G:$G,"") -> 64 | U29: =SUM(Q29:T29) -> 64
A30: ADRIANA ALVES FERREIRA | B30: 36531080809 | C30: MARCIO ROSA DE MIRA | D30: 22485483892 | E30: 1489 | F30: 43038 | G30: APROVADO | L30: 1647-17 | O30: 443 | P30: =COUNTIF(OFÍCIOS!E:E,O30) -> 66 | Q30: =COUNTIFS(OFÍCIOS!$E:$E,$O30,OFÍCIOS!$G:$G,"APROVADO") -> 0 | R30: =COUNTIFS(OFÍCIOS!$E:$E,$O30,OFÍCIOS!$G:$G,"REPROVADO") -> 0 | S30: =COUNTIFS(OFÍCIOS!$E:$E,$O30,OFÍCIOS!$G:$G,"PENDENCIA") -> 0 | T30: =COUNTIFS(OFÍCIOS!$E:$E,$O30,OFÍCIOS!$G:$G,"") -> 66 | U30: =SUM(Q30:T30) -> 66
A31: ADRIANA APARECIDA ROBERTO | B31: 28147186819 | C31: CARLOS ANTONIO BATISTA DOS SANTOS | D31: 24499714400 | O31: 423 | P31: =COUNTIF(OFÍCIOS!E:E,O31) -> 9 | Q31: =COUNTIFS(OFÍCIOS!$E:$E,$O31,OFÍCIOS!$G:$G,"APROVADO") -> 7 | R31: =COUNTIFS(OFÍCIOS!$E:$E,$O31,OFÍCIOS!$G:$G,"REPROVADO") -> 1 | S31: =COUNTIFS(OFÍCIOS!$E:$E,$O31,OFÍCIOS!$G:$G,"PENDENCIA") -> 0 | T31: =COUNTIFS(OFÍCIOS!$E:$E,$O31,OFÍCIOS!$G:$G,"") -> 1 | U31: =SUM(Q31:T31) -> 9
