Workbook
Name Adequacao_Imovel: 'Listas (não utilizar)'!$G$2:$G$7
Name ADEQUAR: 'Listas (não utilizar)'!$G$2:$G$7
Name Apartamento: 'Listas (não utilizar)'!$D$2:$D$21
Name APROVCEF: #REF!
Name Área: 'Listas (não utilizar)'!$A$2:$A$28
Name AREAS: #REF!
Name AVILDATA: #REF!
Name AVILDATA1: #REF!
Name BARCDATA: #REF!
Name BILBDATA: #REF!
Name Bloco: 'Listas (não utilizar)'!$C$2:$C$16
Name CEF: #REF!
Name CEUTDATA: #REF!
Name Condomínio: 'Listas (não utilizar)'!$B$2:$B$15
Name INDDEMAND: #REF!
Name INDEMAND: #REF!
Name it: #REF!
Name Pendência: 'Listas (não utilizar)'!$I$2:$I$7
Name PLANCCO: #REF!
Name Renúncia: 'Listas (não utilizar)'!$H$2:$H$6
Name RetornoSMADS: '[1]Listas (não utilizar)'!$E$2:$E$3
Name selogo: #REF!
Name selomv: #REF!
Name selos_go: #REF!
Name selosgo: #REF!
Name selosgo1: #REF!
Name SITAH_CAIXA: 'Listas (não utilizar)'!$E$2:$E$9
Name StatusCAIXA: 'Listas (não utilizar)'!$F$2:$F$5
Name TEPROC: #REF!
Name TEPROC1: #REF!

Sheet Listas (não utilizar)
A1: Área | B1: Condomínio | C1: Bloco | D1: Apartamento | E1: SITAH / CAIXA | F1: Status CAIXA | G1: Adequacao Imovel | H1: Renúncia | I1: Pendência | J1: Pendências / Reprovados caixa
A2: ALTO DA ALEGRIA | B2: AVILA | C2: 1 | D2: 101 | E2: AGENDADO | F2: APROVADO | G2: NÃO | H2: NÃO | I2: CRAS | J2: RENDA SUPERIOR
A3: ALTO DA ALEGRIA (OBRAS) | B3: BARCELONA | C3: 2 | D3: 102 | E3: AGUARDANDO OFICIO | F3: REPROVADO | G3: FÍSICA | H3: RENDA | I3: CRAS + DOCUMENTOS | J3: CADMUT
A4: ALTO DA ALEGRIA (RESERVA) | B4: BILBAO | C4: 3 | D4: 103 | E4: ATENDIMENTO CANCELADO | F4: PENDENCIA | G4: VISUAL | H4: CADIN | I4: DOCUMENTOS | J4: CADIN
A5: ANTERO GOMES | B5: CEUTA | C5: 4 | D5: 104 | E5: CADMUT | F5: SEM DOSSIE | G5: INTELECTUAL | H5: ESTADO CIVIL | I5: CADIN
A6: CANTINHO DO CEU / GAIVOTAS | B6: IBIZA | C6: 5 | D6: 201 | E6: CHACARA DO CONDE | G6: AUDITIVA | H6: SEPARACAO | I6: CRAS + CADIN
A7: CANTINHO DO CEU / OBRAS | B7: LEAO | C7: 6 | D7: 202 | E7: CONFLITO | G7: NANISMO | I7: R.LI.AV.
A8: CASTRO ALVES | B8: MADRID | C8: 7 | D8: 203 | E8: ENVIADO CAIXA | I8: IEME
A9: COCAIA | B9: MELILLA | C9: 8 | D9: 204 | E9: FALECEU
A10: ERUNDINA | B10: PAMPLONA | C10: 9 | D10: 301 | E10: FALTANTE DOSSIÊ
A11: FUMACA | B11: SALAMANCA | C11: 10 | D11: 302 | E11: HABISP ACERTO DE ÁREA
A12: GUAICURI (OBRAS) | B12: TERUEL | C12: 11 | D12: 303 | E12: HABISP AGUARDANDO CRÍTICA
A13: GUAICURI / CIDADE JULIA | B13: VALENCIA | C13: 12 | D13: 304 | E13: HABISP PEND DE ATUALIZ CADASTRAL
A14: JARDIM MIRNA | B14: VALVERDE | C14: 13 | D14: 401 | E14: INDENIZACAO
A15: JARDIM SELMA II | B15: VITORIA | C15: 14 | D15: 402 | E15: PENDENCIA
A16: JARDIM TUBO | C16: 15 | D16: 403 | E16: PERMUTA
A17: LEBLON | D17: 404 | E17: PESQUISA SMADS
A18: MARGINAL DOIS / FUNDAO | D18: 501 | E18: REANALISE
A19: MATA VIRGEM / JD ELDORADO | D19: 502 | E19: RECLUSO
A20: NEBLINA | D20: 503 | E20: RELATÓRIO SOCIAL
A21: NORONHA | D21: 504 | E21: RENDA SUPERIOR
A22: NOVA GRAJAU | E22: RESISTENTE
A23: NOVA MARILDA | E23: TROCA DE TITULARIDADE
A24: NOVA VARGINHA
A25: PABREU / PRAINHA
A26: PENDENCIA GABINETE
A27: PILAO / APURA
A28: PILAO / DOIS
A29: PILAO / PAULISTAS
A30: SANTA AMELIA
A31: VALE VERDE / MONTE VERDE
A32: VILA BREJINHO
A33: VILA NASCENTE
A34: ZR / COSTA BRANCA
A35: VILA RUBI

Sheet QUANT COND
A1: CONDOMINIOS | B1: QUANT
A2: AVILA | B2: =COUNTIF(#REF!,'QUANT COND'!A2) -> #REF!
A3: BARCELONA | B3: =COUNTIF(#REF!,'QUANT COND'!A3) -> #REF!
A4: BILBAO | B4: =COUNTIF(#REF!,'QUANT COND'!A4) -> #REF!
A5: CEUTA | B5: =COUNTIF(#REF!,'QUANT COND'!A5) -> #REF!
A6: IBIZA | B6: =COUNTIF(#REF!,'QUANT COND'!A6) -> #REF!
A7: LEAO | B7: =COUNTIF(#REF!,'QUANT COND'!A7) -> #REF!
A8: MADRID | B8: =COUNTIF(#REF!,'QUANT COND'!A8) -> #REF!
A9: MELILLA | B9: =COUNTIF(#REF!,'QUANT COND'!A9) -> #REF!
A10: PAMPLONA | B10: =COUNTIF(#REF!,'QUANT COND'!A10) -> #REF!
A11: SALAMANCA | B11: =COUNTIF(#REF!,'QUANT COND'!A11) -> #REF!
A12: TERUEL | B12: =COUNTIF(#REF!,'QUANT COND'!A12) -> #REF!
A13: VALENCIA | B13: =COUNTIF(#REF!,'QUANT COND'!A13) -> #REF!
... A15: VITORIA | B15: =COUNTIF(#REF!,'QUANT COND'!A15) -> #REF!

Sheet OFÍCIOS
A1: PLANILHA DE CONFRONTO OFÍCIOS DE INDICAÇÃO COM ENVIADOS CAIXA ECONÔMICA FEDERAL - CEF
A2: TITULAR | B2: CPF | C2: Cônjuge | D2: CPF | E2: OFÍCIO | F2: DATA | G2: STATUS CEF | H2: DATA ENVIO CAIXA | I2: DUPLICIDADE OFÍCIO | J2: DATA | K2: DATA ENVIO CAIXA | L2: OFÍCIO DE INDICAÇÃO | M2: DATA OFÍCIO INDICAÇÃO | O2: NR OFICIO | P2: QUANT | Q2: APROV | R2: REPROV | S2: PEND | T2: SEM STATUS (ANÁLISE) | Y2: CEF BD | Z2: CEF OFICIOS | AA2: CEF PLANILHA
A3: ABEL MEDEIROS FILHO | B3: 27140979871 | E3: 1128 | F3: 42972 | G3: APROVADO | H3: 42979 | O3: 810 | P3: =COUNTIF(OFÍCIOS!E:E,O3) -> 156 | Q3: =COUNTIFS(OFÍCIOS!$E:$E,$O3,OFÍCIOS!$G:$G,"APROVADO") -> 149 | R3: =COUNTIFS(OFÍCIOS!$E:$E,$O3,OFÍCIOS!$G:$G,"REPROVADO") -> 3 | S3: =COUNTIFS(OFÍCIOS!$E:$E,$O3,OFÍCIOS!$G:$G,"PENDENCIA") -> 2 | T3: =COUNTIFS(OFÍCIOS!$E:$E,$O3,OFÍCIOS!$G:$G,"") -> 2 | U3: =SUM(Q3:T3) -> 156 | X3: FEITOS | Y3: 1850 | Z3: 1827 | AA3: =SUM(AA4:AA7) -> 1615
A4: ABELINA FERREIRA DOS SANTOS | B4: 39200633846 | O4: 1417 | P4: =COUNTIF(OFÍCIOS!E:E,O4) -> 42 | Q4: =COUNTIFS(OFÍCIOS!$E:$E,$O4,OFÍCIOS!$G:$G,"APROVADO") -> 36 | R4: =COUNTIFS(OFÍCIOS!$E:$E,$O4,OFÍCIOS!$G:$G,"REPROVADO") -> 3 | S4: =COUNTIFS(OFÍCIOS!$E:$E,$O4,OFÍCIOS!$G:$G,"PENDENCIA") -> 3 | T4: =COUNTIFS(OFÍCIOS!$E:$E,$O4,OFÍCIOS!$G:$G,"") -> 0 | U4: =SUM(Q4:T4) -> 42 | X4: APROVADOS | Y4: 1517 | Z4: 1427 | AA4: 1559
A5: ABIGAIL DE OLIVEIRA PAULINO | B5: 75489104872 | E5: 1752 | F5: 43051 | G5: APROVADO | H5: 43089 | L5: 1759 | O5: 1359 | P5: =COUNTIF(OFÍCIOS!E:E,O5) -> 14 | Q5: =COUNTIFS(OFÍCIOS!$E:$E,$O5,OFÍCIOS!$G:$G,"APROVADO") -> 13 | R5: =COUNTIFS(OFÍCIOS!$E:$E,$O5,OFÍCIOS!$G:$G,"REPROVADO") -> 1 | S5: =COUNTIFS(OFÍCIOS!$E:$E,$O5,OFÍCIOS!$G:$G,"PENDENCIA") -> 0 | T5: =COUNTIFS(OFÍCIOS!$E:$E,$O5,OFÍCIOS!$G:$G,"") -> 0 | U5: =SUM(Q5:T5) -> 14 | X5: REPROVADOS | Y5: 73 | Z5: 79 | AA5: 28
A6: ABILIO OLIVEIRA SANTOS | B6: 43286003620 | O6: 1350 | P6: =COUNTIF(OFÍCIOS!E:E,O6) -> 79 | Q6: =COUNTIFS(OFÍCIOS!$E:$E,$O6,OFÍCIOS!$G:$G,"APROVADO") -> 75 | R6: =COUNTIFS(OFÍCIOS!$E:$E,$O6,OFÍCIOS!$G:$G,"REPROVADO") -> 3 | S6: =COUNTIFS(OFÍCIOS!$E:$E,$O6,OFÍCIOS!$G:$G,"PENDENCIA") -> 0 | T6: =COUNTIFS(OFÍCIOS!$E:$E,$O6,OFÍCIOS!$G:$G,"") -> 1 | U6: =SUM(Q6:T6) -> 79 | X6: PENDENCIAS | Y6: 36 | Z6: 32 | AA6: 11
A7: ABRAHAO SANTOS SILVA | O7: 1343 | P7: =COUNTIF(OFÍCIOS!E:E,O7) -> 6 | Q7: =COUNTIFS(OFÍCIOS!$E:$E,$O7,OFÍCIOS!$G:$G,"APROVADO") -> 5 | R7: =COUNTIFS(OFÍCIOS!$E:$E,$O7,OFÍCIOS!$G:$G,"REPROVADO") -> 0 | S7: =COUNTIFS(OFÍCIOS!$E:$E,$O7,OFÍCIOS!$G:$G,"PENDENCIA") -> 0 | T7: =COUNTIFS(OFÍCIOS!$E:$E,$O7,OFÍCIOS!$G:$G,"") -> 1 | U7: =SUM(Q7:T7) -> 6 | X7: SS / ANALISE | Y7: 224 | Z7: 275 | AA7: 17
A8: ADAIR DA SILVA BARROS | B8: 97443271620 | E8: 1106 | F8: 42965 | G8: APROVADO | H8: 42978 | O8: 1267 | P8: =COUNTIF(OFÍCIOS!E:E,O8) -> 34 | Q8: =COUNTIFS(OFÍCIOS!$E:$E,$O8,OFÍCIOS!$G:$G,"APROVADO") -> 28 | R8: =COUNTIFS(OFÍCIOS!$E:$E,$O8,OFÍCIOS!$G:$G,"REPROVADO") -> 5 | S8: =COUNTIFS(OFÍCIOS!$E:$E,$O8,OFÍCIOS!$G:$G,"PENDENCIA") -> 1 | T8: =COUNTIFS(OFÍCIOS!$E:$E,$O8,OFÍCIOS!$G:$G,"") -> 0 | U8: =SUM(Q8:T8) -> 34
A9: ADALBERTO CARVALHO DE OLIVEIRA | B9: 98058690597 | E9: 423 | F9: 43182 | G9: APROVADO | O9: 1262 | P9: =COUNTIF(OFÍCIOS!E:E,O9) -> 8 | Q9: =COUNTIFS(OFÍCIOS!$E:$E,$O9,OFÍCIOS!$G:$G,"APROVADO") -> 7 | R9: =COUNTIFS(OFÍCIOS!$E:$E,$O9,OFÍCIOS!$G:$G,"REPROVADO") -> 1 | S9: =COUNTIFS(OFÍCIOS!$E:$E,$O9,OFÍCIOS!$G:$G,"PENDENCIA") -> 0 | T9: =COUNTIFS(OFÍCIOS!$E:$E,$O9,OFÍCIOS!$G:$G,"") -> 0 | U9: =SUM(Q9:T9) -> 8
A10: ADALBERTO CAVALCANTE DOS SANTOS | B10: 38088438888 | O10: 1106 | P10: =COUNTIF(OFÍCIOS!E:E,O10) -> 78 | Q10: =COUNTIFS(OFÍCIOS!$E:$E,$O10,OFÍCIOS!$G:$G,"APROVADO") -> 73 | R10: =COUNTIFS(OFÍCIOS!$E:$E,$O10,OFÍCIOS!$G:$G,"REPROVADO") -> 5 | S10: =COUNTIFS(OFÍCIOS!$E:$E,$O10,OFÍCIOS!$G:$G,"PENDENCIA") -> 0 | T10: =COUNTIFS(OFÍCIOS!$E:$E,$O10,OFÍCIOS!$G:$G,"") -> 0 | U10: =SUM(Q10:T10) -> 78
A11: ADALMA MOREIRA DA ROCHA | B11: 26939799869 | E11: 573 | F11: 43224 | O11: 1128 | P11: =COUNTIF(OFÍCIOS!E:E,O11) -> 92 | Q11: =COUNTIFS(OFÍCIOS!$E:$E,$O11,OFÍCIOS!$G:$G,"APROVADO") -> 91 | R11: =COUNTIFS(OFÍCIOS!$E:$E,$O11,OFÍCIOS!$G:$G,"REPROVADO") -> 1 | S11: =COUNTIFS(OFÍCIOS!$E:$E,$O11,OFÍCIOS!$G:$G,"PENDENCIA") -> 0 | T11: =COUNTIFS(OFÍCIOS!$E:$E,$O11,OFÍCIOS!$G:$G,"") -> 0 | U11: =SUM(Q11:T11) -> 92
A12: ADAMILTON PEREIRA DA SILVA ( ALANA ) | B12: 34470559873 | E12: 292 | F12: 43168 | G12: APROVADO | H12: 43182 | L12: 318 | O12: 1214 | P12: =COUNTIF(OFÍCIOS!E:E,O12) -> 76 | Q12: =COUNTIFS(OFÍCIOS!$E:$E,$O12,OFÍCIOS!$G:$G,"APROVADO") -> 71 | R12: =COUNTIFS(OFÍCIOS!$E:$E,$O12,OFÍCIOS!$G:$G,"REPROVADO") -> 3 | S12: =COUNTIFS(OFÍCIOS!$E:$E,$O12,OFÍCIOS!$G:$G,"PENDENCIA") -> 0 | T12: =COUNTIFS(OFÍCIOS!$E:$E,$O12,OFÍCIOS!$G:$G,"") -> 2 | U12: =SUM(Q12:T12) -> 76
A13: ADAO MENDES AGOSTINHO | B13: 14369564808 | O13: 1241 | P13: =COUNTIF(OFÍCIOS!E:E,O13) -> 33 | Q13: =COUNTIFS(OFÍCIOS!$E:$E,$O13,OFÍCIOS!$G:$G,"APROVADO") -> 32 | R13: =COUNTIFS(OFÍCIOS!$E:$E,$O13,OFÍCIOS!$G:$G,"REPROVADO") -> 0 | S13: =COUNTIFS(OFÍCIOS!$E:$E,$O13,OFÍCIOS!$G:$G,"PENDENCIA") -> 1 | T13: =COUNTIFS(OFÍCIOS!$E:$E,$O13,OFÍCIOS!$G:$G,"") -> 0 | U13: =SUM(Q13:T13) -> 33
A14: ADEGMARIO DOS SANTOS | B14: 39544185844 | E14: 810 | F14: 42915 | G14: APROVADO | H14: 42921 | L14: 568-17 | O14: 1422 | P14: =COUNTIF(OFÍCIOS!E:E,O14) -> 7 | Q14: =COUNTIFS(OFÍCIOS!$E:$E,$O14,OFÍCIOS!$G:$G,"APROVADO") -> 7 | R14: =COUNTIFS(OFÍCIOS!$E:$E,$O14,OFÍCIOS!$G:$G,"REPROVADO") -> 0 | S14: =COUNTIFS(OFÍCIOS!$E:$E,$O14,OFÍCIOS!$G:$G,"PENDENCIA") -> 0 | T14: =COUNTIFS(OFÍCIOS!$E:$E,$O14,OFÍCIOS!$G:$G,"") -> 0 | U14: =SUM(Q14:T14) -> 7
A15: ADEILDA GABRIELA CAITANO SILVA | B15: 38772276860 | C15: LUCIANO MANOEL DA SILVA | D15: 3808243457 | O15: 1439 | P15: =COUNTIF(OFÍCIOS!E:E,O15) -> 16 | Q15: =COUNTIFS(OFÍCIOS!$E:$E,$O15,OFÍCIOS!$G:$G,"APROVADO") -> 14 | R15: =COUNTIFS(OFÍCIOS!$E:$E,$O15,OFÍCIOS!$G:$G,"REPROVADO") -> 1 | S15: =COUNTIFS(OFÍCIOS!$E:$E,$O15,OFÍCIOS!$G:$G,"PENDENCIA") -> 1 | T15: =COUNTIFS(OFÍCIOS!$E:$E,$O15,OFÍCIOS!$G:$G,"") -> 0 | U15: =SUM(Q15:T15) -> 16
A16: ADEILDA RODRIGUES DE OLIVEIRA | B16: 21538837846 | C16: PEDRO LUIZ SANTOS OLIVEIRA | D16: 94203180520 | E16: 810 | F16: 42915 | G16: APROVADO | H16: 42921 | L16: 568-17 | O16: 1451 | P16: =COUNTIF(OFÍCIOS!E:E,O16) -> 4 | Q16: =COUNTIFS(OFÍCIOS!$E:$E,$O16,OFÍCIOS!$G:$G,"APROVADO") -> 3 | R16: =COUNTIFS(OFÍCIOS!$E:$E,$O16,OFÍCIOS!$G:$G,"REPROVADO") -> 1 | S16: =COUNTIFS(OFÍCIOS!$E:$E,$O16,OFÍCIOS!$G:$G,"PENDENCIA") -> 0 | T16: =COUNTIFS(OFÍCIOS!$E:$E,$O16,OFÍCIOS!$G:$G,"") -> 0 | U16: =SUM(Q16:T16) -> 4
A17: ADEILDO ADELINO DE CARVALHO | B17: 57455392591 | O17: 1470 | P17: =COUNTIF(OFÍCIOS!E:E,O17) -> 4 | Q17: =COUNTIFS(OFÍCIOS!$E:$E,$O17,OFÍCIOS!$G:$G,"APROVADO") -> 4 | R17: =COUNTIFS(OFÍCIOS!$E:$E,$O17,OFÍCIOS!$G:$G,"REPROVADO") -> 0 | S17: =COUNTIFS(OFÍCIOS!$E:$E,$O17,OFÍCIOS!$G:$G,"PENDENCIA") -> 0 | T17: =COUNTIFS(OFÍCIOS!$E:$E,$O17,OFÍCIOS!$G:$G,"") -> 0 | U17: =SUM(Q17:T17) -> 4
A18: ADELCIDES DA CONCEICAO ALMEIDA | B18: 5304941594 | E18: 1106 | F18: 42965 | G18: APROVADO | H18: 42978 | O18: 1489 | P18: =COUNTIF(OFÍCIOS!E:E,O18) -> 35 | Q18: =COUNTIFS(OFÍCIOS!$E:$E,$O18,OFÍCIOS!$G:$G,"APROVADO") -> 34 | R18: =COUNTIFS(OFÍCIOS!$E:$E,$O18,OFÍCIOS!$G:$G,"REPROVADO") -> 0 | S18: =COUNTIFS(OFÍCIOS!$E:$E,$O18,OFÍCIOS!$G:$G,"PENDENCIA") -> 1 | T18: =COUNTIFS(OFÍCIOS!$E:$E,$O18,OFÍCIOS!$G:$G,"") -> 0 | U18: =SUM(Q18:T18) -> 35
A19: ADELIA MARIA DE OLIVEIRA | B19: 21600057896 | E19: 262 | F19: 43160 | G19: REPROVADO | H19: 43164 | L19: 255 | O19: 1555 | P19: =COUNTIF(OFÍCIOS!E:E,O19) -> 25 | Q19: =COUNTIFS(OFÍCIOS!$E:$E,$O19,OFÍCIOS!$G:$G,"APROVADO") -> 22 | R19: =COUNTIFS(OFÍCIOS!$E:$E,$O19,OFÍCIOS!$G:$G,"REPROVADO") -> 1 | S19: =COUNTIFS(OFÍCIOS!$E:$E,$O19,OFÍCIOS!$G:$G,"PENDENCIA") -> 2 | T19: =COUNTIFS(OFÍCIOS!$E:$E,$O19,OFÍCIOS!$G:$G,"") -> 0 | U19: =SUM(Q19:T19) -> 25
A20: ADEMARIO FERREIRA DOS SANTOS | B20: 18419589802 | O20: 1570 | P20: =COUNTIF(OFÍCIOS!E:E,O20) -> 24 | Q20: =COUNTIFS(OFÍCIOS!$E:$E,$O20,OFÍCIOS!$G:$G,"APROVADO") -> 23 | R20: =COUNTIFS(OFÍCIOS!$E:$E,$O20,OFÍCIOS!$G:$G,"REPROVADO") -> 1 | S20: =COUNTIFS(OFÍCIOS!$E:$E,$O20,OFÍCIOS!$G:$G,"PENDENCIA") -> 0 | T20: =COUNTIFS(OFÍCIOS!$E:$E,$O20,OFÍCIOS!$G:$G,"") -> 0 | U20: =SUM(Q20:T20) -> 24
A21: ADEMIR DA SILVA LIMA | B21: 15538537846 | E21: 573 | F21: 43224 | O21: 1752 | P21: =COUNTIF(OFÍCIOS!E:E,O21) -> 89 | Q21: =COUNTIFS(OFÍCIOS!$E:$E,$O21,OFÍCIOS!$G:$G,"APROVADO") -> 80 | R21: =COUNTIFS(OFÍCIOS!$E:$E,$O21,OFÍCIOS!$G:$G,"REPROVADO") -> 2 | S21: =COUNTIFS(OFÍCIOS!$E:$E,$O21,OFÍCIOS!$G:$G,"PENDENCIA") -> 5 | T21: =COUNTIFS(OFÍCIOS!$E:$E,$O21,OFÍCIOS!$G:$G,"") -> 2 | U21: =SUM(Q21:T21) -> 89
A22: ADENILDE SANTOS DA SILVA | B22: 899837506 | E22: 1824 | F22: 43091 | G22: APROVADO | H22: 43097 | L22: 1828 | O22: 1824 | P22: =COUNTIF(OFÍCIOS!E:E,O22) -> 81 | Q22: =COUNTIFS(OFÍCIOS!$E:$E,$O22,OFÍCIOS!$G:$G,"APROVADO") -> 67 | R22: =COUNTIFS(OFÍCIOS!$E:$E,$O22,OFÍCIOS!$G:$G,"REPROVADO") -> 7 | S22: =COUNTIFS(OFÍCIOS!$E:$E,$O22,OFÍCIOS!$G:$G,"PENDENCIA") -> 6 | T22: =COUNTIFS(OFÍCIOS!$E:$E,$O22,OFÍCIOS!$G:$G,"") -> 1 | U22: =SUM(Q22:T22) -> 81
A23: ADENILSON DA CONCEICAO | B23: 36197160803 | E23: 229 | F23: 43151 | G23: APROVADO | L23: 232 | O23: 1628 | P23: =COUNTIF(OFÍCIOS!E:E,O23) -> 6 | Q23: =COUNTIFS(OFÍCIOS!$E:$E,$O23,OFÍCIOS!$G:$G,"APROVADO") -> 5 | R23: =COUNTIFS(OFÍCIOS!$E:$E,$O23,OFÍCIOS!$G:$G,"REPROVADO") -> 1 | S23: =COUNTIFS(OFÍCIOS!$E:$E,$O23,OFÍCIOS!$G:$G,"PENDENCIA") -> 0 | T23: =COUNTIFS(OFÍCIOS!$E:$E,$O23,OFÍCIOS!$G:$G,"") -> 0 | U23: =SUM(Q23:T23) -> 6
A24: ADENIR MODESTO RIBEIRO | B24: 39248826814 | E24: 292 | F24: 43168 | G24: APROVADO | H24: 43182 | L24: 318 | O24: 608 | P24: =COUNTIF(OFÍCIOS!E:E,O24) -> 35 | Q24: =COUNTIFS(OFÍCIOS!$E:$E,$O24,OFÍCIOS!$G:$G,"APROVADO") -> 31 | R24: =COUNTIFS(OFÍCIOS!$E:$E,$O24,OFÍCIOS!$G:$G,"REPROVADO") -> 3 | S24: =COUNTIFS(OFÍCIOS!$E:$E,$O24,OFÍCIOS!$G:$G,"PENDENCIA") -> 1 | T24: =COUNTIFS(OFÍCIOS!$E:$E,$O24,OFÍCIOS!$G:$G,"") -> 0 | U24: =SUM(Q24:T24) -> 35
A25: ADILINA FARIAS DO NASCIMENTO | B25: 48925276534 | E25: 229 | F25: 43151 | L25: 232 | O25: 527 | P25: =COUNTIF(OFÍCIOS!E:E,O25) -> 29 | Q25: =COUNTIFS(OFÍCIOS!$E:$E,$O25,OFÍCIOS!$G:$G,"APROVADO") -> 0 | R25: =COUNTIFS(OFÍCIOS!$E:$E,$O25,OFÍCIOS!$G:$G,"REPROVADO") -> 0 | S25: =COUNTIFS(OFÍCIOS!$E:$E,$O25,OFÍCIOS!$G:$G,"PENDENCIA") -> 0 | T25: =COUNTIFS(OFÍCIOS!$E:$E,$O25,OFÍCIOS!$G:$G,"") -> 29 | U25: =SUM(Q25:T25) -> 29
A26: ADILSON SOARES DA COSTA | O26: 509 | P26: =COUNTIF(OFÍCIOS!E:E,O26) -> 14 | Q26: =COUNTIFS(OFÍCIOS!$E:$E,$O26,OFÍCIOS!$G:$G,"APROVADO") -> 0 | R26: =COUNTIFS(OFÍCIOS!$E:$E,$O26,OFÍCIOS!$G:$G,"REPROVADO") -> 0 | S26: =COUNTIFS(OFÍCIOS!$E:$E,$O26,OFÍCIOS!$G:$G,"PENDENCIA") -> 0 | T26: =COUNTIFS(OFÍCIOS!$E:$E,$O26,OFÍCIOS!$G:$G,"") -> 14 | U26: =SUM(Q26:T26) -> 14
A27: ADMEIA BARBOSA DE SOUZA | B27: 25894152810 | C27: REINALDO SANTOS REIS | D27: 8263008808 | E27: 292 | F27: 43168 | G27: APROVADO | H27: 43182 | L27: 318 | O27: 292 | P27: =COUNTIF(OFÍCIOS!E:E,O27) -> 233 | Q27: =COUNTIFS(OFÍCIOS!$E:$E,$O27,OFÍCIOS!$G:$G,"APROVADO") -> 212 | R27: =COUNTIFS(OFÍCIOS!$E:$E,$O27,OFÍCIOS!$G:$G,"REPROVADO") -> 9 | S27: =COUNTIFS(OFÍCIOS!$E:$E,$O27,OFÍCIOS!$G:$G,"PENDENCIA") -> 0 | T27: =COUNTIFS(OFÍCIOS!$E:$E,$O27,OFÍCIOS!$G:$G,"") -> 12 | U27: =SUM(Q27:T27) -> 233
A28: ADONES FERREIRA JORGE | B28: 43026389587 | C28: EUNICE FELICIANA BRITO JORGE | D28: 29124464813 | E28: 485 | F28: 43196 | H28: 43206 | L28: 483 | O28: 573 | P28: =COUNTIF(OFÍCIOS!E:E,O28) -> 43 | Q28: =COUNTIFS(OFÍCIOS!$E:$E,$O28,OFÍCIOS!$G:$G,"APROVADO") -> 0 | R28: =COUNTIFS(OFÍCIOS!$E:$E,$O28,OFÍCIOS!$G:$G,"REPROVADO") -> 0 | S28: =COUNTIFS(OFÍCIOS!$E:$E,$O28,OFÍCIOS!$G:$G,"PENDENCIA") -> 0 | T28: =COUNTIFS(OFÍCIOS!$E:$E,$O28,OFÍCIOS!$G:$G,"") -> 43 | U28: =SUM(Q28:T28) -> 43
A29: ADRIANA ALVES DA SILVA | B29: 26245112885 | E29: 262 | F29: 43160 | G29: REPROVADO | H29: 43164 | L29: 255 | O29: 563 | P29: =COUNTIF(OFÍCIOS!E:E,O29) -> 64 | Q29: =COUNTIFS(OFÍCIOS!$E:$E,$O29,OFÍCIOS!$G:$G,"APROVADO") -> 0 | R29: =COUNTIFS(OFÍCIOS!$E:$E,$O29,OFÍCIOS!$G:$G,"REPROVADO") -> 0 | S29: =COUNTIFS(OFÍCIOS!$E:$E,$O29,OFÍCIOS!$G:$G,"PENDENCIA") -> 0 | T29: =COUNTIFS(OFÍCIOS!$E:$E,$O29,OFÍCIOS!$G:$G,"") -> 64 | U29: =SUM(Q29:T29) -> 64
A30: ADRIANA ALVES FERREIRA | B30: 36531080809 | C30: MARCIO ROSA DE MIRA | D30: 22485483892 | E30: 1489 | F30: 43038 | G30: APROVADO | L30: 1647-17 | O30: 443 | P30: =COUNTIF(OFÍCIOS!E:E,O30) -> 66 | Q30: =COUNTIFS(OFÍCIOS!$E:$E,$O30,OFÍCIOS!$G:$G,"APROVADO") -> 0 | R30: =COUNTIFS(OFÍCIOS!$E:$E,$O30,OFÍCIOS!$G:$G,"REPROVADO") -> 0 | S30: =COUNTIFS(OFÍCIOS!$E:$E,$O30,OFÍCIOS!$G:$G,"PENDENCIA") -> 0 | T30: =COUNTIFS(OFÍCIOS!$E:$E,$O30,OFÍCIOS!$G:$G,"") -> 66 | U30: =SUM(Q30:T30) -> 66
A31: ADRIANA APARECIDA ROBERTO | B31: 28147186819 | C31: CARLOS ANTONIO BATISTA DOS SANTOS | D31: 24499714400 | O31: 423 | P31: =COUNTIF(OFÍCIOS!E:E,O31) -> 9 | Q31: =COUNTIFS(OFÍCIOS!$E:$E,$O31,OFÍCIOS!$G:$G,"APROVADO") -> 7 | R31: =COUNTIFS(OFÍCIOS!$E:$E,$O31,OFÍCIOS!$G:$G,"REPROVADO") -> 1 | S31: =COUNTIFS(OFÍCIOS!$E:$E,$O31,OFÍCIOS!$G:$G,"PENDENCIA") -> 0 | T31: =COUNTIFS(OFÍCIOS!$E:$E,$O31,OFÍCIOS!$G:$G,"") -> 1 | U31: =SUM(Q31:T31) -> 9
A32: ADRIANA ARAUJO DE LIMA | B32: 37559228860 | C32: ALEXANDRO ARAUJO DE LIMA | D32: 28072024892 | E32: 1555 | F32: 43049 | G32: APROVADO | O32: 229 | P32: =COUNTIF(OFÍCIOS!E:E,O32) -> 89 | Q32: =COUNTIFS(OFÍCIOS!$E:$E,$O32,OFÍCIOS!$G:$G,"APROVADO") -> 81 | R32: =COUNTIFS(OFÍCIOS!$E:$E,$O32,OFÍCIOS!$G:$G,"REPROVADO") -> 2 | S32: =COUNTIFS(OFÍCIOS!$E:$E,$O32,OFÍCIOS!$G:$G,"PENDENCIA") -> 5 | T32: =COUNTIFS(OFÍCIOS!$E:$E,$O32,OFÍCIOS!$G:$G,"") -> 1 | U32: =SUM(Q32:T32) -> 89
A33: ADRIANA CORDEIRO MACHADO | B33: 23635229822 | C33: ANDERSON DE MORAIS SANTOS | D33: 21668057875 | E33: 262 | F33: 43160 | G33: APROVADO | H33: 43164 | L33: 255 | O33: 262 | P33: =COUNTIF(OFÍCIOS!E:E,O33) -> 224 | Q33: =COUNTIFS(OFÍCIOS!$E:$E,$O33,OFÍCIOS!$G:$G,"APROVADO") -> 181 | R33: =COUNTIFS(OFÍCIOS!$E:$E,$O33,OFÍCIOS!$G:$G,"REPROVADO") -> 15 | S33: =COUNTIFS(OFÍCIOS!$E:$E,$O33,OFÍCIOS!$G:$G,"PENDENCIA") -> 0 | T33: =COUNTIFS(OFÍCIOS!$E:$E,$O33,OFÍCIOS!$G:$G,"") -> 28 | U33: =SUM(Q33:T33) -> 224
A34: ADRIANA DA SILVA | O34: 117 | P34: =COUNTIF(OFÍCIOS!E:E,O34) -> 91 | Q34: =COUNTIFS(OFÍCIOS!$E:$E,$O34,OFÍCIOS!$G:$G,"APROVADO") -> 77 | R34: =COUNTIFS(OFÍCIOS!$E:$E,$O34,OFÍCIOS!$G:$G,"REPROVADO") -> 7 | S34: =COUNTIFS(OFÍCIOS!$E:$E,$O34,OFÍCIOS!$G:$G,"PENDENCIA") -> 5 | T34: =COUNTIFS(OFÍCIOS!$E:$E,$O34,OFÍCIOS!$G:$G,"") -> 2 | U34: =SUM(Q34:T34) -> 91
A35: ADRIANA DA SILVA SANTOS | B35: 40902634844 | C35: GUILHERME DE OLIVEIRA SOUZA | D35: 23795007895 | E35: 117 | F35: 43117 | G35: APROVADO | H35: 43151 | L35: 118-18 | O35: 485 | P35: =COUNTIF(OFÍCIOS!E:E,O35) -> 23 | Q35: =COUNTIFS(OFÍCIOS!$E:$E,$O35,OFÍCIOS!$G:$G,"APROVADO") -> 0 | R35: =COUNTIFS(OFÍCIOS!$E:$E,$O35,OFÍCIOS!$G:$G,"REPROVADO") -> 3 | S35: =COUNTIFS(OFÍCIOS!$E:$E,$O35,OFÍCIOS!$G:$G,"PENDENCIA") -> 0 | T35: =COUNTIFS(OFÍCIOS!$E:$E,$O35,OFÍCIOS!$G:$G,"") -> 20 | U35: =SUM(Q35:T35) -> 23
A36: ADRIANA DE SA ROCHA | B36: 39615629898 | C36: MARCELO FERNANDES LIMA | D36: 43328275894 | E36: 423 | F36: 43182 | G36: APROVADO | O36: 85 | P36: =COUNTIF(OFÍCIOS!E:E,O36) -> 93 | Q36: =COUNTIFS(OFÍCIOS!$E:$E,$O36,OFÍCIOS!$G:$G,"APROVADO") -> 86 | R36: =COUNTIFS(OFÍCIOS!$E:$E,$O36,OFÍCIOS!$G:$G,"REPROVADO") -> 4 | S36: =COUNTIFS(OFÍCIOS!$E:$E,$O36,OFÍCIOS!$G:$G,"PENDENCIA") -> 3 | T36: =COUNTIFS(OFÍCIOS!$E:$E,$O36,OFÍCIOS!$G:$G,"") -> 0 | U36: =SUM(Q36:T36) -> 93
A37: ADRIANA DOS SANTOS | P37: =COUNTIF(OFÍCIOS!E:E,O37) -> 0 | Q37: =COUNTIFS(OFÍCIOS!$E:$E,$O37,OFÍCIOS!$G:$G,"APROVADO") -> 0 | R37: =COUNTIFS(OFÍCIOS!$E:$E,$O37,OFÍCIOS!$G:$G,"REPROVADO") -> 0 | S37: =COUNTIFS(OFÍCIOS!$E:$E,$O37,OFÍCIOS!$G:$G,"PENDENCIA") -> 0 | T37: =COUNTIFS(OFÍCIOS!$E:$E,$O37,OFÍCIOS!$G:$G,"") -> 0 | U37: =SUM(Q37:T37) -> 0
A38: ADRIANA FERREIRA DA SILVA | C38: LOURIVAL CANDIDO SILVA | P38: =COUNTIF(OFÍCIOS!E:E,O38) -> 0 | Q38: =COUNTIFS(OFÍCIOS!$E:$E,$O38,OFÍCIOS!$G:$G,"APROVADO") -> 0 | R38: =COUNTIFS(OFÍCIOS!$E:$E,$O38,OFÍCIOS!$G:$G,"REPROVADO") -> 0 | S38: =COUNTIFS(OFÍCIOS!$E:$E,$O38,OFÍCIOS!$G:$G,"PENDENCIA") -> 0 | T38: =COUNTIFS(OFÍCIOS!$E:$E,$O38,OFÍCIOS!$G:$G,"") -> 0 | U38: =SUM(Q38:T38) -> 0
A39: ADRIANA HELENA DE MORAIS | B39: 14268808809 | E39: 262 | F39: 43160 | G39: APROVADO | H39: 43164 | L39: 255 | P39: =COUNTIF(OFÍCIOS!E:E,O39) -> 0 | Q39: =COUNTIFS(OFÍCIOS!$E:$E,$O39,OFÍCIOS!$G:$G,"APROVADO") -> 0 | R39: =COUNTIFS(OFÍCIOS!$E:$E,$O39,OFÍCIOS!$G:$G,"REPROVADO") -> 0 | S39: =COUNTIFS(OFÍCIOS!$E:$E,$O39,OFÍCIOS!$G:$G,"PENDENCIA") -> 0 | T39: =COUNTIFS(OFÍCIOS!$E:$E,$O39,OFÍCIOS!$G:$G,"") -> 0 | U39: =SUM(Q39:T39) -> 0
A40: ADRIANA JESUS DA CUNHA | B40: 29628693867 | E40: 292 | F40: 43168 | G40: APROVADO | H40: 43182 | L40: 318 | P40: =COUNTIF(OFÍCIOS!E:E,O40) -> 0 | Q40: =COUNTIFS(OFÍCIOS!$E:$E,$O40,OFÍCIOS!$G:$G,"APROVADO") -> 0 | R40: =COUNTIFS(OFÍCIOS!$E:$E,$O40,OFÍCIOS!$G:$G,"REPROVADO") -> 0 | S40: =COUNTIFS(OFÍCIOS!$E:$E,$O40,OFÍCIOS!$G:$G,"PENDENCIA") -> 0 | T40: =COUNTIFS(OFÍCIOS!$E:$E,$O40,OFÍCIOS!$G:$G,"") -> 0 | U40: =SUM(Q40:T40) -> 0
...

Sheet PRIORIDADES
C1: -- | D1: -- | E1: -- | G1: OCUPADO | H1: RESIDENCIAL | I1: PROPRIETÁRIO NÃO RESIDENTE | M1: CADASTRADO | N1: INDENIZAÇÃO | X1: SAQUE PENDENTE | AE1: PROPRIETÁRIO NÃO RESIDENTE | AI1: SIM | AJ1: SIM | AK1: CADASTRADO | AL1: AGUARDANDO ASSINATURA COORDENAÇÃO CTS | AM1: FINALIZADO | AN1: SEM PENDÊNCIA
G2: VAZIO | H2: COMERCIAL | I2: PROPRIETÁRIO RESIDENTE | M2: NÃO CADASTRADO | N2: AUXÍLIO ALUGUEL UH | AE2: PROPRIETÁRIO RESIDENTE | AI2: NÃO | AJ2: NÃO | AK2: NÃO CADASTRADO | AL2: AGUARDANDO ASSINATURA SECRETÁRIO | AM2: PENDENTE | AN2: FALTA TERMO
G3: CONSTRUÇÃO | H3: MISTO | I3: INQULINO | N3: VERBA ATENDIMENTO HABITACIONAL | AI3: UH | AJ3: N.A | AL3: FINALIZADO | AM3: N/A | AN3: FALTA DOCS
G4: DEMOLIDO | I4: COABITAÇÃO | N4: NÃO TEM DIREITO ATENDIMENTO | AI4: ESTUDO DE CASO | AJ4: PENDENTE | AL4: AGUARDANDO CORREÇÃO | AN4: FALTA TERMO E DOCS
N5: AA ATÉ INDENIZAÇÃO | AL5: N/A | AN5: TERMO ASSINADO SECRETÁRIO
AN6: N/A
A8: INFORMAÇÕES INICIAIS | P8: INFORMAÇÕES AUXÍLIO ALUGUEL | AB8: INFORMAÇÕES INDENIZAÇÃO | BB8: PROCESSO ATENDIMENTO HABITACIONAL
A9: ORDEM | B9: ÁREA | C9: TRECHO | D9: FASE | E9: PRIORIDADE | F9: SELO | G9: SITUAÇÃO INICIAL IMÓVEL | H9: USO IMÓVEL | I9: SITUAÇÃO DO RESIDENTE | J9: TITULAR | K9: RG | L9: CPF | M9: CADASTRO HABITA SAMPA | N9: OPÇÃO DE ATENDIMENTO HABITACIONAL | O9: ENVIO DADOS | P9: SOLICITAÇÃO AUXÍLIO ALUGUEL ÁREA | Q9: No PROCESSO SEI (AUXÍLIO ALUGUEL) | R9: ANÁLISE DTS CADASTRO + CHECAGEM DUPLO | S9: INSTRUÇÃO PROCESSO SEI DTS | T9: ANÁLISE CTS ASSINATURA GABINETE | U9: DATA PUBLICAÇÃO DIÁRIO OFICIAL | V9: CONFECÇÃO TERMO | W9: ENVIO TERMO CARTÃO | X9: PREVISÃO PAGAMENTO | Y9: DATA SAQUE | Z9: DATA MUDANÇA | AA9: OBSERVAÇÕES AA | AB9: PROPRIETÁRIO | AC9: RG | AD9: CPF | AE9: SITUAÇÃO DO PROPRIETÁRIO | AF9: CADASTRO HABITASAMPA | AG9: VALOR AVALIAÇÃO | AH9: VALOR INDENIZAÇÃO | AI9: ACEITA VALOR INDENIZAÇÃO | AJ9: Nº SEI LAUDOS AVALIAÇÃO | AK9: Nº DOCUMENTO LAUDO | AL9: TERMO INDENIZAÇÃO | AM9: DOSSIÊ | AN9: PENDÊNCIA | AO9: OBSERVAÇÕES INDENIZAÇÃO | AP9: No PROCESSO SEI (INDENIZAÇÃO) | AQ9: INSTRUÇÃO PROCESSO SEI DTS | AR9: ASSINATURA DIRETOR DTS | AS9: ELABORAÇÃO DESPACHO CTS | AT9: ASSINATURA DESPACHO GABINETE | AU9: PUBLICAÇÃO DIÁRIO OFICIAL | AV9: ENCAMINHAMENTO DAF/DIF CTS | AW9: LIBERAÇÃO PAGAMENTO DAF/DIF | AX9: PREVISÃO PAGAMENTO | AY9: DATA PAGAMENTO | AZ9: DATA ENTREGA IMÓVEL | BA9: SITUAÇÃO ATUAL IMÓVEL | BB9: STATUS | BC9: DIAS TOTAIS | BD9: OPÇÃO ATENDIMENTO | BE9: NECESSITA BLOQUEIO AA | BF9: SOLICITAÇÃO BLOQUEIO AA DTS | BG9: SOLICITAÇÃO BLOQUEIO AA | BH9: DATA BLOQUEIO AA | BI9: DESPACHO EXCLUSÃO GABINETE | BJ9: ASSINATURA DESPACHO GABINETE | BK9: PUBLICAÇÃO DOC | BL9: ENCAMINHAMENTO SOLICITAÇÃO EXCLUSÃO DEPLAN | BM9: ENCERRAMENTO PROCESSO DTS
A10: 1 | B10: JD. AURORA | C10: -- | D10: -- | E10: -- | F10: 001/0008/A | J10: RAQUEL FERNANDEZ DE QUEIROZ | K10: 36.647.758-7 | L10: 297.435.165-49 | BC10: =IF(AY10-KD10=0,"",AY10-O10) | BD10: =IF(AND(AI10<>"SIM",AI10="UH"),"AA","INDENIZAÇÃO") -> INDENIZAÇÃO | BE10: =IF(AND(AY10<>"AGUARDANDO",AY10<>"",N10="AUXÍLIO ALUGUEL ATÉ INDENIZAÇÃO"),"SIM","NÃO") -> NÃO
A11: 2 | B11: JD. AURORA | C11: -- | D11: -- | E11: -- | F11: 001/0008/B | J11: ERIKA CRISTINA FELICIANO MARQUES | K11: 47.637.886-2 | L11: 424.408.848-20 | BC11: =IF(AY11-KD11=0,"",AY11-O11) | BD11: =IF(AND(AI11<>"SIM",AI11="UH"),"AA","INDENIZAÇÃO") -> INDENIZAÇÃO | BE11: =IF(AND(AY11<>"AGUARDANDO",AY11<>"",N11="AUXÍLIO ALUGUEL ATÉ INDENIZAÇÃO"),"SIM","NÃO") -> NÃO
A12: 3 | B12: JD. AURORA | C12: -- | D12: -- | E12: -- | F12: 001/0008/C | J12: RAPHAEL QUEIROZ SIMPLICIO | K12: 47.214.327-X | L12: 395.907.698-37 | BC12: =IF(AY12-KD12=0,"",AY12-O12) | BD12: =IF(AND(AI12<>"SIM",AI12="UH"),"AA","INDENIZAÇÃO") -> INDENIZAÇÃO | BE12: =IF(AND(AY12<>"AGUARDANDO",AY12<>"",N12="AUXÍLIO ALUGUEL ATÉ INDENIZAÇÃO"),"SIM","NÃO") -> NÃO
A13: 4 | B13: JD. AURORA | C13: -- | D13: -- | E13: -- | F13: 001/0027/B | J13: GLEICE CRISTINA DE SOUZA | K13: 47.483.525-X | L13: 413.011.438-71 | BC13: =IF(AY13-KD13=0,"",AY13-O13) | BD13: =IF(AND(AI13<>"SIM",AI13="UH"),"AA","INDENIZAÇÃO") -> INDENIZAÇÃO | BE13: =IF(AND(AY13<>"AGUARDANDO",AY13<>"",N13="AUXÍLIO ALUGUEL ATÉ INDENIZAÇÃO"),"SIM","NÃO") -> NÃO
A14: 5 | B14: JD. AURORA | C14: -- | D14: -- | E14: -- | F14: 001/0029/B | J14: LUCIANA MARIA SANTOS DA SILVA | K14: 38.510.210-0 | L14: 346.889.848-71 | BC14: =IF(AY14-KD14=0,"",AY14-O14) | BD14: =IF(AND(AI14<>"SIM",AI14="UH"),"AA","INDENIZAÇÃO") -> INDENIZAÇÃO | BE14: =IF(AND(AY14<>"AGUARDANDO",AY14<>"",N14="AUXÍLIO ALUGUEL ATÉ INDENIZAÇÃO"),"SIM","NÃO") -> NÃO
A15: 6 | B15: JD. AURORA | C15: -- | D15: -- | E15: -- | F15: 001/0029/B | J15: ANTONIA VALQUIANA MOREIRA DE SOUSA | K15: 42.572.902-3 | L15: 389.352.538-63 | BC15: =IF(AY15-KD15=0,"",AY15-O15) | BD15: =IF(AND(AI15<>"SIM",AI15="UH"),"AA","INDENIZAÇÃO") -> INDENIZAÇÃO | BE15: =IF(AND(AY15<>"AGUARDANDO",AY15<>"",N15="AUXÍLIO ALUGUEL ATÉ INDENIZAÇÃO"),"SIM","NÃO") -> NÃO
A16: 7 | B16: JD. AURORA | C16: -- | D16: -- | E16: -- | F16: 002/0001/A | J16: ANALIA DA CONCEIÇÃO PRIMO MEDEIROS | K16: 37.358.607-3 | L16: 318.882.178-63 | BC16: =IF(AY16-KD16=0,"",AY16-O16) | BD16: =IF(AND(AI16<>"SIM",AI16="UH"),"AA","INDENIZAÇÃO") -> INDENIZAÇÃO | BE16: =IF(AND(AY16<>"AGUARDANDO",AY16<>"",N16="AUXÍLIO ALUGUEL ATÉ INDENIZAÇÃO"),"SIM","NÃO") -> NÃO
A17: 8 | B17: JD. AURORA | C17: -- | D17: -- | E17: -- | F17: 002/0001/B | J17: MANUEL JOSÉ SOARES | K17: 66.888.065-X | L17: 428.988.623-04 | BC17: =IF(AY17-KD17=0,"",AY17-O17) | BD17: =IF(AND(AI17<>"SIM",AI17="UH"),"AA","INDENIZAÇÃO") -> INDENIZAÇÃO | BE17: =IF(AND(AY17<>"AGUARDANDO",AY17<>"",N17="AUXÍLIO ALUGUEL ATÉ INDENIZAÇÃO"),"SIM","NÃO") -> NÃO
A18: 9 | B18: JD. AURORA | C18: -- | D18: -- | E18: -- | F18: 002/0001/B | J18: EDISON SAMPAIO FIGUEIREDO | K18: 22.904.827-4 | L18: 142.907.508-26 | BC18: =IF(AY18-KD18=0,"",AY18-O18) | BD18: =IF(AND(AI18<>"SIM",AI18="UH"),"AA","INDENIZAÇÃO") -> INDENIZAÇÃO | BE18: =IF(AND(AY18<>"AGUARDANDO",AY18<>"",N18="AUXÍLIO ALUGUEL ATÉ INDENIZAÇÃO"),"SIM","NÃO") -> NÃO
A19: 10 | B19: JD. AURORA | C19: -- | D19: -- | E19: -- | F19: 002/0001/C | J19: KAUANE SANTOS NASCIMENTO | K19: 55.762.596-8 | L19: 406.935.838-27 | BC19: =IF(AY19-KD19=0,"",AY19-O19) | BD19: =IF(AND(AI19<>"SIM",AI19="UH"),"AA","INDENIZAÇÃO") -> INDENIZAÇÃO | BE19: =IF(AND(AY19<>"AGUARDANDO",AY19<>"",N19="AUXÍLIO ALUGUEL ATÉ INDENIZAÇÃO"),"SIM","NÃO") -> NÃO
A20: 11 | B20: JD. AURORA | C20: -- | D20: -- | E20: -- | F20: 002/0001/C | J20: LUIZA GOMES TRINDADE | K20: 23.416.922-9 | L20: 134.160.398-90 | BC20: =IF(AY20-KD20=0,"",AY20-O20) | BD20: =IF(AND(AI20<>"SIM",AI20="UH"),"AA","INDENIZAÇÃO") -> INDENIZAÇÃO | BE20: =IF(AND(AY20<>"AGUARDANDO",AY20<>"",N20="AUXÍLIO ALUGUEL ATÉ INDENIZAÇÃO"),"SIM","NÃO") -> NÃO
A21: 12 | B21: JD. AURORA | C21: -- | D21: -- | E21: -- | F21: 002/0001/D | J21: SEVERINO UMBELINO DA SILVA | K21: 54.413.141-1 | L21: 093.420.864-62 | BC21: =IF(AY21-KD21=0,"",AY21-O21) | BD21: =IF(AND(AI21<>"SIM",AI21="UH"),"AA","INDENIZAÇÃO") -> INDENIZAÇÃO | BE21: =IF(AND(AY21<>"AGUARDANDO",AY21<>"",N21="AUXÍLIO ALUGUEL ATÉ INDENIZAÇÃO"),"SIM","NÃO") -> NÃO
... A24: 15 | B24: JD. AURORA | C24: -- | D24: -- | E24: -- | F24: 002/0003/D | J24: TATIANE ROCHA DO NASCIMENTO | K24: 44.716.705-4 | L24: 372.899.928-81 | BC24: =IF(AY24-KD24=0,"",AY24-O24) | BD24: =IF(AND(AI24<>"SIM",AI24="UH"),"AA","INDENIZAÇÃO") -> INDENIZAÇÃO | BE24: =IF(AND(AY24<>"AGUARDANDO",AY24<>"",N24="AUXÍLIO ALUGUEL ATÉ INDENIZAÇÃO"),"SIM","NÃO") -> NÃO
A25: 16 | B25: JD. AURORA | C25: -- | D25: -- | E25: -- | F25: 003/0001/A | J25: IVANILDES FAGUNDES DE OLIVEIRA | L25: 004.106.358-98 | BC25: =IF(AY25-KD25=0,"",AY25-O25) | BD25: =IF(AND(AI25<>"SIM",AI25="UH"),"AA","INDENIZAÇÃO") -> INDENIZAÇÃO | BE25: =IF(AND(AY25<>"AGUARDANDO",AY25<>"",N25="AUXÍLIO ALUGUEL ATÉ INDENIZAÇÃO"),"SIM","NÃO") -> NÃO
A26: 17 | B26: JD. AURORA | C26: -- | D26: -- | E26: -- | F26: 003/0001/A | J26: ROGERIO GARCIA DE OLIVEIRA | K26: 26.333.056-4 | L26: 262.288.348-00 | BC26: =IF(AY26-KD26=0,"",AY26-O26) | BD26: =IF(AND(AI26<>"SIM",AI26="UH"),"AA","INDENIZAÇÃO") -> INDENIZAÇÃO | BE26: =IF(AND(AY26<>"AGUARDANDO",AY26<>"",N26="AUXÍLIO ALUGUEL ATÉ INDENIZAÇÃO"),"SIM","NÃO") -> NÃO
A27: 18 | B27: JD. AURORA | C27: -- | D27: -- | E27: -- | F27: 004/0007/A | G27: OCUPADO | H27: RESIDENCIAL | I27: PROPRIETÁRIO RESIDENTE | J27: CLEONICE ALVES DE SOUSA | K27: 53.603.228-2 | L27: 576.533.055-04 | M27: CADASTRADO | N27: INDENIZAÇÃO | O27: 46210 | P27: N.A | Q27: N.A | R27: N.A | S27: N.A | T27: N.A | U27: N.A | V27: N.A | W27: N.A | X27: N.A | Y27: N.A | Z27: N.A | AA27: N.A | AB27: CLEONICE ALVES DE SOUSA | AC27: 53.603.228-2 | AD27: 576.533.055-04 | AE27: PROPRIETÁRIO RESIDENTE | AF27: CADASTRADO | AG27: 64352.57 | AH27: 64352.57 | AI27: SIM | AJ27: 6014.2026/0002719-0 | AK27: 155550560 | AL27: AGUARDANDO ASSINATURA SECRETÁRIO | AM27: FINALIZADO | AN27: TERMO ASSINADO SECRETÁRIO | BC27: =IF(AY27-KD27=0,"",AY27-O27) | BD27: =IF(AND(AI27<>"SIM",AI27="UH"),"AA","INDENIZAÇÃO") -> INDENIZAÇÃO | BE27: =IF(AND(AY27<>"AGUARDANDO",AY27<>"",N27="AUXÍLIO ALUGUEL ATÉ INDENIZAÇÃO"),"SIM","NÃO") -> NÃO
A28: 19 | B28: JD. AURORA | C28: -- | D28: -- | E28: -- | F28: 004/0007/A | J28: YURI ALVES DE SOUSA | K28: 36.348.682-3 | L28: 402.077.608-37 | BC28: =IF(AY28-KD28=0,"",AY28-O28) | BD28: =IF(AND(AI28<>"SIM",AI28="UH"),"AA","INDENIZAÇÃO") -> INDENIZAÇÃO | BE28: =IF(AND(AY28<>"AGUARDANDO",AY28<>"",N28="AUXÍLIO ALUGUEL ATÉ INDENIZAÇÃO"),"SIM","NÃO") -> NÃO
A29: 20 | B29: JD. AURORA | C29: -- | D29: -- | E29: -- | BC29: =IF(AY29-KD29=0,"",AY29-O29) | BD29: =IF(AND(AI29<>"SIM",AI29="UH"),"AA","INDENIZAÇÃO") -> INDENIZAÇÃO | BE29: =IF(AND(AY29<>"AGUARDANDO",AY29<>"",N29="AUXÍLIO ALUGUEL ATÉ INDENIZAÇÃO"),"SIM","NÃO") -> NÃO
A30: 21 | B30: JD. AURORA | C30: -- | D30: -- | E30: -- | BC30: =IF(AY30-KD30=0,"",AY30-O30) | BD30: =IF(AND(AI30<>"SIM",AI30="UH"),"AA","INDENIZAÇÃO") -> INDENIZAÇÃO | BE30: =IF(AND(AY30<>"AGUARDANDO",AY30<>"",N30="AUXÍLIO ALUGUEL ATÉ INDENIZAÇÃO"),"SIM","NÃO") -> NÃO
A31: 22 | B31: JD. AURORA | C31: -- | D31: -- | E31: -- | BC31: =IF(AY31-KD31=0,"",AY31-O31) | BD31: =IF(AND(AI31<>"SIM",AI31="UH"),"AA","INDENIZAÇÃO") -> INDENIZAÇÃO | BE31: =IF(AND(AY31<>"AGUARDANDO",AY31<>"",N31="AUXÍLIO ALUGUEL ATÉ INDENIZAÇÃO"),"SIM","NÃO") -> NÃO
A32: 23 | B32: JD. AURORA | C32: -- | D32: -- | E32: -- | BC32: =IF(AY32-KD32=0,"",AY32-O32) | BD32: =IF(AND(AI32<>"SIM",AI32="UH"),"AA","INDENIZAÇÃO") -> INDENIZAÇÃO | BE32: =IF(AND(AY32<>"AGUARDANDO",AY32<>"",N32="AUXÍLIO ALUGUEL ATÉ INDENIZAÇÃO"),"SIM","NÃO") -> NÃO
A33: 24 | B33: JD. AURORA | C33: -- | D33: -- | E33: -- | BC33: =IF(AY33-KD33=0,"",AY33-O33) | BD33: =IF(AND(AI33<>"SIM",AI33="UH"),"AA","INDENIZAÇÃO") -> INDENIZAÇÃO | BE33: =IF(AND(AY33<>"AGUARDANDO",AY33<>"",N33="AUXÍLIO ALUGUEL ATÉ INDENIZAÇÃO"),"SIM","NÃO") -> NÃO
A34: 25 | B34: JD. AURORA | C34: -- | D34: -- | E34: -- | BC34: =IF(AY34-KD34=0,"",AY34-O34) | BD34: =IF(AND(AI34<>"SIM",AI34="UH"),"AA","INDENIZAÇÃO") -> INDENIZAÇÃO | BE34: =IF(AND(AY34<>"AGUARDANDO",AY34<>"",N34="AUXÍLIO ALUGUEL ATÉ INDENIZAÇÃO"),"SIM","NÃO") -> NÃO
A35: 26 | B35: JD. AURORA | C35: -- | D35: -- | E35: -- | BC35: =IF(AY35-KD35=0,"",AY35-O35) | BD35: =IF(AND(AI35<>"SIM",AI35="UH"),"AA","INDENIZAÇÃO") -> INDENIZAÇÃO | BE35: =IF(AND(AY35<>"AGUARDANDO",AY35<>"",N35="AUXÍLIO ALUGUEL ATÉ INDENIZAÇÃO"),"SIM","NÃO") -> NÃO
A36: 27 | B36: JD. AURORA | C36: -- | D36: -- | E36: -- | BC36: =IF(AY36-KD36=0,"",AY36-O36) | BD36: =IF(AND(AI36<>"SIM",AI36="UH"),"AA","INDENIZAÇÃO") -> INDENIZAÇÃO | BE36: =IF(AND(AY36<>"AGUARDANDO",AY36<>"",N36="AUXÍLIO ALUGUEL ATÉ INDENIZAÇÃO"),"SIM","NÃO") -> NÃO
A37: 28 | B37: JD. AURORA | C37: -- | D37: -- | E37: -- | BC37: =IF(AY37-KD37=0,"",AY37-O37) | BD37: =IF(AND(AI37<>"SIM",AI37="UH"),"AA","INDENIZAÇÃO") -> INDENIZAÇÃO | BE37: =IF(AND(AY37<>"AGUARDANDO",AY37<>"",N37="AUXÍLIO ALUGUEL ATÉ INDENIZAÇÃO"),"SIM","NÃO") -> NÃO
A38: 29 | B38: JD. AURORA | C38: -- | D38: -- | E38: -- | BC38: =IF(AY38-KD38=0,"",AY38-O38) | BD38: =IF(AND(AI38<>"SIM",AI38="UH"),"AA","INDENIZAÇÃO") -> INDENIZAÇÃO | BE38: =IF(AND(AY38<>"AGUARDANDO",AY38<>"",N38="AUXÍLIO ALUGUEL ATÉ INDENIZAÇÃO"),"SIM","NÃO") -> NÃO

Sheet EMAIL
E1: PUBLICAÇÃO DOC
E2: PREVISÃO PAGAMENTO
E3: CONFIRMAÇÃO PAGAMENTO
A5: ÁREA | B5: TRECHO | C5: SELO | D5: TITULAR | E5: CONFIRMAÇÃO PAGAMENTO
A6: JD. PANTANAL | B6: VILA DA PAZ | C6: 002/0018/D | D6: ERICLES DE SOUSA SILVA | E6: 46189
A7: JD. PANTANAL | B7: NOVO HORIZONTE | C7: 002/0001/A | D7: LUANA KELLY DA SILVA SOUSA | E7: 46192
A8: JD. PANTANAL | B8: SÃO MARTINHO VÁRZEA | C8: 002/0017/A | D8: LUCILENE LUZIA DE OLIVEIRA FIGUEIREDO | E8: 46195
A9: JD. PANTANAL | B9: VILA DA PAZ | C9: 002/0020/A | D9: MARIA DAS DORES BASTOS DA SILVA | E9: 46195
A23: JD. PANTANAL | B23: SÃO MARTINHO VÁRZEA | C23: 008/0011/A | D23: REGINALDO BARRENSE DE LIMA | E23: 46139
A24: JD. PANTANAL | B24: SÃO MARTINHO VÁRZEA | C24: 008/0042/A | D24: JUCIENE DOS SANTOS SILVA | E24: 46139
A25: JD. PANTANAL | B25: SÃO MARTINHO VÁRZEA | C25: 011/0009/A | D25: EDISON DE JESUS | E25: 46139
A26: JD. PANTANAL | B26: SÃO MARTINHO VÁRZEA | C26: 012/0008/B | D26: ELIAS RIBEIRO GUIMARÃES | E26: 46139
A27: JD. PANTANAL | B27: SÃO MARTINHO VÁRZEA | C27: 013/0002/A | D27: EDSON FRANCISCO DA SILVA SA | E27: 46139
A28: JD. PANTANAL | B28: SÃO MARTINHO VÁRZEA | C28: 002/0014/A | D28: MARINALVA DOS SANTOS | E28: 46140
A29: JD. PANTANAL | B29: SÃO MARTINHO VÁRZEA | C29: 002/0018/A | D29: JÉSSIKA DE ANDRADE SOUZA | E29: 46140
A30: JD. PANTANAL | B30: SÃO MARTINHO VÁRZEA | C30: 006/0010/B | D30: CAMILA DE LIRA FERNANDES | E30: 46140
... A34: JD. PANTANAL | B34: VILA DA PAZ | C34: 002/0014/B | D34: MARIANE CAMILA DE FREITAS VALES | E34: 46146
A46: PARAISÓPOLIS/ANTONICO | C46: 029/0036/M | D46: LUCIANA PEREIRA DE SOUZA | E46: 44961
A47: PARAISÓPOLIS/ANTONICO | C47: 029/0036/N | D47: FERNANDO ARAUJO DA SILVA | E47: 44923
A48: PARAISÓPOLIS/ANTONICO | C48: 029/0036/O | D48: MARIA ANTONIA CARVALHO SAMPAIO SANTOS | E48: 45013
A49: PARAISÓPOLIS/ANTONICO | C49: 029/0042/A | D49: CARLOS DA SILVA BARBOSA | E49: 45148
A50: PARAISÓPOLIS/ANTONICO | C50: 029/0042/B | D50: DIRCEU DA SILVA BARBOSA
A51: PARAISÓPOLIS/ANTONICO | C51: 029/0054/E | D51: JADI DE JESUS SILVA
A52: PARAISÓPOLIS/ANTONICO | C52: 029/0066/C | D52: DAMIÃO DOS SANTOS MEDEIROS
A53: PARAISÓPOLIS/ANTONICO | C53: 029/0085/D | D53: JOSÉ GERALDO CARLOS DOS SANTOS
A54: PARAISÓPOLIS/ANTONICO | C54: 031/0006/C | D54: SILVANEIDE DE LIMA SOUZA
A55: PARAISÓPOLIS/ANTONICO | C55: 031/0009/A | D55: GABRIELA DAS DORES NASCIMENTO DE JESUS
A56: PARAISÓPOLIS/ANTONICO | C56: 031/0009/B | D56: SAMANTHA DAS DORES OLIVEIRA
A57: PARAISÓPOLIS/ANTONICO | C57: 031/0010/A | D57: JAÍLSON ALVES TELES | E57: 45056
A58: PARAISÓPOLIS/ANTONICO | C58: 031/0017/F | D58: CAMILA BERNARDO DA CRUZ SILVA | E58: 45013
A59: PARAISÓPOLIS/ANTONICO | C59: 031/0017/G | D59: NATÁLIA DE ALMEIDA DE BARROS | E59: 45097
A60: PARAISÓPOLIS/ANTONICO | C60: 031/0018/A | D60: ALEXANDRE DOS SANTOS RIBEIRO | E60: 44816
A61: PARAISÓPOLIS/ANTONICO | C61: 031/0023/B | D61: DANIELA GOMES DE CARVALHO
A62: PARAISÓPOLIS/ANTONICO | C62: 031/0023/C | D62: QUEZIANE ALVES DO NASCIMENTO | E62: N/A
A63: PARAISÓPOLIS/ANTONICO | C63: 031/0026/E | D63: VIVIANE DA SILVA ALMEIDA
A64: PARAISÓPOLIS/ANTONICO | C64: 031/0032/C | D64: ANTONIA CAMILA CASSIMIRO BARBOSA
A65: PARAISÓPOLIS/ANTONICO | C65: 031/0034/E | D65: DAMARYS BRITO DA SILVA | E65: 44877
A66: PARAISÓPOLIS/ANTONICO | C66: 031/0034/H | D66: GISELY MAIANA DE OLIVEIRA SANTOS | E66: 44876
A67: PARAISÓPOLIS/ANTONICO | C67: 031/0034/I | D67: LINA MARIA DA CONCEIÇÃO DE SOUSA | E67: 44910
A68: PARAISÓPOLIS/ANTONICO | C68: 031/0034/K | D68: VÂNIA DE OLIVEIRA | E68: 45148
...

Sheet DEPLAN
F4: ÁREA | G4: SELO | H4: PROPRIETÁRIO | I4: CPF | J4: No PROCESSO SEI (INDENIZAÇÃO)
F5: JD. PANTANAL | G5: 001/0009/A | H5: WILLIAM MACIEL BISPO | I5: 362.311.548-74 | J5: 6014.2026/0001049-1
F6: JD. PANTANAL | G6: 003/0002/A | H6: SIMONE PEREIRA BRITO DA SILVA | I6: 330.971.178-14 | J6: 6014.2026/0000590-0
F7: JD. PANTANAL | G7: 003/0004/A | H7: JENIFER ALINE SANTANA DE ARAUJO | I7: 412.301.608-17 | J7: 6014.2026/0001059-9
F8: JD. PANTANAL | G8: 001/0008/A | H8: ROSELI APARECIDA CARDOSO DOS SANTOS | I8: 297.937.398-27 | J8: 6014.2026/0001565-5
F9: JD. PANTANAL | G9: 001/0010/A | H9: ANTONIO MARCOS DOS SANTOS | I9: 222.428.258-36 | J9: 6014.2026/0001182-0
F10: JD. PANTANAL | G10: 002/0002/A | H10: CLEMENS MARTINS DA CRUZ | I10: 142.323.228/33 | J10: 6014.2026/0002211-2
F11: JD. PANTANAL | G11: 002/0004/B | H11: THAMYRIS ERNESTO DOS SANTOS | I11: 366.046.798-70 | J11: 6014.2026/0001765-8
F12: JD. PANTANAL | G12: 002/0009/A | H12: EDNEIDE DA COSTA FIGUEROA | I12: 743.510.954-15 | J12: 6014.2026/0001185-4
F13: JD. PANTANAL | G13: 002/0010/A | H13: LEONARDO RODRIGUES MÁXIMO LEÃO | I13: 555.672.058-48 | J13: 6014.2026/0001951-0
F14: JD. PANTANAL | G14: 002/0014/A | H14: MARINALVA DOS SANTOS | I14: 045.174.525-65 | J14: 6014.2026/0000954-0
F15: JD. PANTANAL | G15: 002/0018/A | H15: JÉSSIKA DE ANDRADE SOUZA | I15: 073.054.673-08 | J15: 6014.2026/0000925-6
... F34: JD. PANTANAL | G34: 002/0026/A | H34: JANAINA FERREIRA ROMÃO | I34: 308.584.918-18 | J34: 6014.2026/0001939-1
