Workbook
Name Adequacao_Imovel: 'Listas (não utilizar)'!$G$2:$G$7
Name ADEQUAR: 'Listas (não utilizar)'!$G$2:$G$7
Name Apartamento: 'Listas (não utilizar)'!$D$2:$D$21
Name APROVCEF: #REF!
Name Área: 'Listas (não utilizar)'!$A$2:$A$28
Name AREAS: #REF!
Name AVILDATA: #REF!
Name AVILDATA1: #REF!
Name BARCDATA: #REF!
Name BILBDATA: #REF!
Name Bloco: 'Listas (não utilizar)'!$C$2:$C$16
Name CEF: #REF!
Name CEUTDATA: #REF!
Name Condomínio: 'Listas (não utilizar)'!$B$2:$B$15
Name INDDEMAND: #REF!
Name INDEMAND: #REF!
Name it: #REF!
Name Pendência: 'Listas (não utilizar)'!$I$2:$I$7
Name PLANCCO: #REF!
Name Renúncia: 'Listas (não utilizar)'!$H$2:$H$6
Name RetornoSMADS: '[1]Listas (não utilizar)'!$E$2:$E$3
Name selogo: #REF!
Name selomv: #REF!
Name selos_go: #REF!
Name selosgo: #REF!
Name selosgo1: #REF!
Name SITAH_CAIXA: 'Listas (não utilizar)'!$E$2:$E$9
Name StatusCAIXA: 'Listas (não utilizar)'!$F$2:$F$5
Name TEPROC: #REF!
Name TEPROC1: #REF!

Sheet PRIORIDADES
C3: 2 | D3: PRIORITÁRIO | G3: OCUPADO | H3: RESIDENCIAL | I3: PROPRIETÁRIO NÃO RESIDENTE | M3: CADASTRADO | N3: INDENIZAÇÃO | P3: SIM | R3: SIM | X3: SAQUE PENDENTE | AE3: PROPRIETÁRIO NÃO RESIDENTE | AH3: SIM | AI3: SIM | AJ3: CADASTRADO | AL3: COMPLETA | AM3: SEM PENDÊNCIAS
C4: 4 | G4: VAZIO | H4: COMERCIAL | I4: PROPRIETÁRIO RESIDENTE | M4: NÃO CADASTRADO | N4: AUXÍLIO ALUGUEL UH | P4: NÃO | R4: NÃO | AE4: PROPRIETÁRIO RESIDENTE | AH4: NÃO | AI4: NÃO | AJ4: NÃO CADASTRADO | AL4: PENDENTE | AM4: FALTA TERMO
G5: OCUPADO/RISCO | H5: MISTO | I5: INQULINO | N5: RECUSA AUXÍLIO ALUGUEL UH | AH5: UH | AI5: N/A | AM5: FALTA DOCS
G6: CONSTRUÇÃO | N6: NÃO TEM DIREITO ATENDIMENTO | AH6: ESTUDO DE CASO | AI6: PENDENTE | AM6: FALTA TERMO E DOCS
G7: DEMOLIDO
G8: DESCARACTERIZADO
G9: DESABADO
A12: INFORMAÇÕES INICIAIS | P12: INFORMAÇÕES AUXÍLIO ALUGUEL | AB12: INFORMAÇÕES INDENIZAÇÃO | BA12: PROCESSO ATENDIMENTO HABITACIONAL
A13: ORDEM | B13: ÁREA | C13: FASE | D13: TRECHO | E13: PRIORIDADE | F13: SELO | G13: SITUAÇÃO INICIAL IMÓVEL | H13: USO IMÓVEL | I13: SITUAÇÃO DO RESIDENTE | J13: TITULAR | K13: RG | L13: CPF | M13: CADASTRO HABITA SAMPA | N13: OPÇÃO DE ATENDIMENTO HABITACIONAL | O13: ENVIO DADOS | P13: SOLICITAÇÃO AUXÍLIO ALUGUEL ÁREA | Q13: No PROCESSO SEI (AUXÍLIO ALUGUEL) | R13: ANÁLISE DTS CADASTRO + CHECAGEM DUPLO | S13: INSTRUÇÃO PROCESSO SEI DTS | T13: ANÁLISE CTS ASSINATURA GABINETE | U13: DATA PUBLICAÇÃO DIÁRIO OFICIAL | V13: CONFECÇÃO TERMO | W13: ENVIO TERMO CARTÃO | X13: PREVISÃO PAGAMENTO | Y13: DATA SAQUE | Z13: DATA MUDANÇA | AA13: OBSERVAÇÕES AA | AB13: PROPRIETÁRIO | AC13: RG | AD13: CPF | AE13: SITUAÇÃO DO PROPRIETÁRIO | AF13: VALOR INDENIZAÇÃO | AG13: VALOR COM BONIFICAÇÃO | AH13: ACEITA VALOR INDENIZAÇÃO | AI13: LAUDO VALOR INDENIZAÇÃO | AJ13: CADASTRO HABITASAMPA | AK13: TERMO INDENIZAÇÃO | AL13: DOSSIÊ | AM13: PENDÊNCIA | AN13: OBSERVAÇÕES INDENIZAÇÃO | AO13: No PROCESSO SEI (INDENIZAÇÃO) | AP13: INSTRUÇÃO PROCESSO SEI DTS | AQ13: ASSINATURA DIRETOR DTS | AR13: ELABORAÇÃO DESPACHO CTS | AS13: ASSINATURA DESPACHO GABINETE | AT13: PUBLICAÇÃO DIÁRIO OFICIAL | AU13: ENCAMINHAMENTO DAF/DIF CTS | AV13: LIBERAÇÃO PAGAMENTO DAF/DIF | AW13: PREVISÃO PAGAMENTO | AX13: DATA PAGAMENTO | AY13: DATA ENTREGA IMÓVEL | AZ13: SITUAÇÃO ATUAL IMÓVEL | BA13: STATUS | BB13: DIAS TOTAIS | BC13: OPÇÃO ATENDIMENTO | BD13: NECESSITA BLOQUEIO AA | BE13: SOLICITAÇÃO BLOQUEIO AA DTS | BF13: SOLICITAÇÃO BLOQUEIO AA | BG13: DATA BLOQUEIO AA | BH13: DESPACHO EXCLUSÃO GABINETE | BI13: ASSINATURA DESPACHO GABINETE | BJ13: PUBLICAÇÃO DOC | BK13: ENCAMINHAMENTO SOLICITAÇÃO EXCLUSÃO DEPLAN | BL13: ENCERRAMENTO PROCESSO DTS
A14: 1 | B14: CEI EDITH MASON | C14: -- | D14: -- | E14: -- | F14: 001/0001/A | G14: OCUPADO | H14: RESIDENCIAL | I14: PROPRIETÁRIO RESIDENTE | J14: EDINEIDE DA SILVA PORTELA DE SANTANA | K14: 28.136.525-8 | L14: 258.226.108-46 | M14: CADASTRADO | N14: INDENIZAÇÃO | O14: 45246 | P14: N/A | Q14: N/A | R14: N/A | S14: N/A | T14: N/A | U14: N/A | V14: N/A | W14: N/A | X14: N/A | Y14: N/A | Z14: N/A | AB14: EDINEIDE DA SILVA PORTELA DE SANTANA | AC14: 28.136.525-8 | AD14: 258.226.108-46 | AE14: PROPRIETÁRIO RESIDENTE | AF14: 173876.77 | AG14: 173876.77 | AH14: SIM | AI14: FINALIZADO | AJ14: CADASTRADO | AK14: FINALIZADO | AL14: FINALIZADO | AM14: SEM PENDÊNCIA | AO14: 6014.2023/0004047-6 | AP14: FINALIZADO | AQ14: FINALIZADO | AR14: FINALIZADO | AS14: FINALIZADO | AT14: 45267 | AU14: FINALIZADO | AV14: FINALIZADO | AW14: 45278 | AX14: 45278 | AY14: 45280 | AZ14: DEMOLIDO | BA14: FINALIZADO | BB14: =IF(AX14-KC14=0,"",AX14-O14) -> 32 | BC14: =IF(AND(AH14<>"SIM",AH14="UH"),"AA","INDENIZAÇÃO") -> INDENIZAÇÃO | BD14: =IF(AND(AX14<>"AGUARDANDO",AX14<>"",N14="AUXÍLIO ALUGUEL ATÉ INDENIZAÇÃO"),"SIM","NÃO") -> NÃO | BE14: N/A | BF14: N/A | BG14: N/A | BH14: FINALIZADO | BI14: FINALIZADO | BJ14: 45510 | BK14: FINALIZADO | BL14: FINALIZADO

Sheet RESUMO ANTONICO
B4: CONTROLE INDENIZAÇÃO FASE 2
B5: PROCESSOS FINALIZADOS | F5: 1244478.6
B6: PROCESSOS EM ANDAMENTO | F6: 1416872.4
B7: TOTAL | F7: =SUM(F5:F6) -> 2661350.9
B9: CONTROLE INDENIZAÇÃO FASE 4
B10: PROCESSOS FINALIZADOS | F10: 0
B11: PROCESSOS EM ANDAMENTO | F11: 3434696.5
B12: TOTAL | F12: =SUM(F10:F11) -> 3434696.5
B14: TOTAL ANTONICO | F14: =SUM(F7,F12) -> 6096047.4
B16: CONTROLE INDENIZAÇÃO COLOMBO
B17: PROCESSOS FINALIZADOS | F17: 4695554.2
B18: PROCESSOS EM ANDAMENTO | F18: 1324563
B19: TOTAL | F19: =SUM(F17:F18) -> 6020117.2
B22: TOTAL | F22: =SUM(F14,F19) -> 12116165

Sheet Planilha1
G3: 024/0030/B | I3: 029/0024/C
A4: ÁREA | B4: FASE | C4: SELO | D4: TITULAR | E4: PREVISÃO PAGAMENTO | G4: 024/0041/A | I4: 029/0023/E
A5: PARAISÓPOLIS/ANTONICO | B5: 2 | C5: 024/0029/B | D5: MARIA CHAVES DE CARVALHO | E5: 45244 | G5: 024/0041/B | I5: 029/0071/B
A6: PARAISÓPOLIS/ANTONICO | B6: 2 | C6: 024/0106/A | D6: VANDERLEIA LOIOLA GOMES | E6: 45244 | G6: 024/0051/A | I6: 024/0057/A
A7: PARAISÓPOLIS/ANTONICO | B7: 3 | C7: 025/0002/C | D7: RODRIGO LIMA PEREIRA | E7: 45244 | G7: 024/0052/A | I7: 031/0033/Q
A8: PARAISÓPOLIS/ANTONICO | B8: 3 | C8: 025/0002/D | D8: CARLOS MATHEUS FILHO | E8: 45244 | G8: 024/0055/B | I8: 029/0066/A
A9: PARAISÓPOLIS/ANTONICO | B9: 3 | C9: 025/0002/E | D9: ADRIANA CONCEIÇÃO CAMILO | E9: 45244 | G9: 024/0057/A | I9: 024/0105/B
A10: PARAISÓPOLIS/ANTONICO | B10: 3 | C10: 025/0003/H | D10: EDIVALDO RAMOS MASCARENHAS | E10: 45244 | G10: 024/0070/E | I10: 031/0022/E
A11: PARAISÓPOLIS/ANTONICO | B11: 3 | C11: 025/0008/A | D11: HELENA FERREIRA DE OLIVEIRA | E11: 45244 | G11: 024/0077/B | I11: 031/0031/B
A12: PARAISÓPOLIS/ANTONICO | B12: 3 | C12: 025/0010/D | D12: MANOEL LUIZ PAIXÃO DA SILVA | E12: 45244 | G12: 024/0079/C | I12: 031/0020/C
A13: PARAISÓPOLIS/ANTONICO | B13: 3 | C13: 025/0012/F | D13: MIRIAM DA CONCEIÇÃO SANTOS | E13: 45244 | G13: 024/0088/B | I13: 029/0069/D
A14: PARAISÓPOLIS/ANTONICO | B14: 4 | C14: 031/0034/J | D14: ELIAS GABRIEL SANTANA DE BRITO | E14: 45244 | G14: 024/0099/A | I14: 031/0033/K
A15: PARAISÓPOLIS/ANTONICO | B15: 4 | C15: 031/0040/C | D15: FABIANA APARECIDA FRANCISCO | E15: 45243 | G15: 024/0102/D | I15: 029/0016/B
A16: PARAISÓPOLIS/ANTONICO | B16: 4 | C16: 031/0076/B | D16: LUCIENE FERREIRA DA SILVA | E16: 45243 | G16: 024/0105/A | I16: 029/0066/E
... A18: PARAISÓPOLIS/ANTONICO | B18: 4 | C18: 031/0076/D | D18: VIVALDO JOSÉ DE SANTANA FILHO | E18: 45243 | G18: 029/0007/A | I18: 029/0022/B
G19: 029/0007/B | I19: 031/0039/C
G20: 029/0016/B | I20: 029/0081/A
G21: 029/0022/B | I21: 024/0052/A
A22: PARAISÓPOLIS/ANTONICO | B22: 3 | C22: 027/0018/I | D22: WEBERT BOAVENTURA DA SILVA | E22: 45247 | G22: 029/0023/E | I22: 029/0035/B
A23: PARAISÓPOLIS/ANTONICO | B23: 3 | C23: 027/0019/C | D23: GUILHERME DE OLIVEIRA LIMA | E23: 45247 | G23: 029/0024/C | I23: 029/0027/A
A24: PARAISÓPOLIS/ANTONICO | B24: 4 | C24: 029/0035/C | D24: GLAUCIA APARECIDA FIDELIX DA SILVA | E24: 45247 | G24: 029/0027/A | I24: 029/0064/A
A25: PARAISÓPOLIS/ANTONICO | B25: 4 | C25: 031/0020/C | D25: NATALINA MATIAS ALMEIDA DE SOUZA | E25: 45247 | G25: 029/0035/B | I25: 029/0069/B
A26: PARAISÓPOLIS/ANTONICO | B26: 4 | C26: 031/0033/Q | D26: LEANDRO PEREIRA DE OLIVEIRA | E26: 45247 | G26: 029/0036/F | I26: 031/0028/D
A27: PARAISÓPOLIS/ANTONICO | B27: 4 | C27: 031/0034/I | D27: APARECIDA RIBEIRO DA CRUZ | E27: 45247 | G27: 029/0039/B | I27: 029/0067/A
G28: 029/0045/A | I28: 029/0007/A
G29: 029/0061/A | I29: 029/0070/C
G30: 029/0064/A | I30: 029/0007/B
G31: 029/0064/F | I31: 029/0070/B
G32: 029/0066/A | I32: 029/0045/A
G33: 029/0066/B | I33: 024/0102/D
G34: 029/0066/E | I34: 024/0041/A
G35: 029/0067/A | I35: 031/0035/A
A36: PARAISÓPOLIS/ANTONICO | B36: 3 | C36: 025/0021/D | D36: SANDRO MARIANO DE ALMEIDA | E36: 45224 | G36: 029/0067/F | I36: 031/0067/B
A37: PARAISÓPOLIS/ANTONICO | B37: 3 | C37: 025/0023/D | D37: SIMONE FAUSTINO DOS SANTOS | E37: 45224 | G37: 029/0069/B | I37: 024/0077/B
A38: PARAISÓPOLIS/ANTONICO | B38: 3 | C38: 025/0024/B | D38: CARLOS LUIS SOUZA DA CUNHA | E38: 45224 | G38: 029/0069/C | I38: 033/0016/C
A39: PARAISÓPOLIS/ANTONICO | B39: 3 | C39: 025/0025/I | D39: JOSEFA LUCIA DOS SANTOS SOUZA | E39: 45224 | G39: 029/0069/D | I39: 029/0069/C
A40: PARAISÓPOLIS/ANTONICO | B40: 3 | C40: 025/0025/L | D40: EDVALDO PINHEIRO DA SILVA | E40: 45224 | G40: 029/0070/B | I40: 029/0061/A
A41: PARAISÓPOLIS/ANTONICO | B41: 3 | C41: 025/0026/H | D41: VANDERSON DE SOUZA MENEZES | E41: 45224 | G41: 029/0070/C | I41: 029/0066/B
A42: PARAISÓPOLIS/ANTONICO | B42: 3 | C42: 025/0028/G | D42: LUCAS SANTOS NERY REIS | E42: 45224 | G42: 029/0071/B | I42: 029/0071/D
A43: PARAISÓPOLIS/ANTONICO | B43: 3 | C43: 025/0031/B | D43: PEDRO IZIDORIO BISPO | E43: 45224 | G43: 029/0071/D | I43: 031/0058/A
...

Sheet Quantitativo Fora da Demanda
A1: REPROVADOS QUE NÃO DEVERÃO SER REASSENTADOS NO ESPANHA | E1: APROVADOS SEM CONDOMÍNIO QUE DEVERÃO SER REASSENTADOS NO CHÁCARA DO CONDE
A2: ÁREA | B2: QTD | E2: ÁREA | F2: QTD
A3: AUXÍLIO ALUGUEL | B3: 39 | E3: AUXÍLIO ALUGUEL | F3: 54
A4: CANTINHO DO CÉU (OBRAS) | B4: 15 | E4: CANTINHO DO CÉU (OBRAS) SETORES: 138 E 140 | F4: 13
A5: FUMAÇA | B5: 7 | E5: FUMAÇA | F5: 15
A6: NEBLINA | B6: 2 | E6: NEBLINA | F6: 9
A7: LEBLON | B7: 0 | E7: LEBLON | F7: 9
A8: PABREU / PRAINHA | B8: 15 | E8: PABREU / PRAINHA | F8: 21
A9: TOTAL | B9: =SUM(B3:B8) -> 78 | E9: TOTAL | F9: =SUM(F3:F8) -> 121

Sheet Listas (não utilizar)
A1: Área | B1: Condomínio | C1: Bloco | D1: Apartamento | E1: SITAH / CAIXA | F1: Status CAIXA | G1: Adequacao Imovel | H1: Renúncia | I1: Pendência | J1: Pendências / Reprovados caixa
A2: ALTO DA ALEGRIA | B2: AVILA | C2: 1 | D2: 101 | E2: AGENDADO | F2: APROVADO | G2: NÃO | H2: NÃO | I2: CRAS | J2: RENDA SUPERIOR
A3: ALTO DA ALEGRIA (OBRAS) | B3: BARCELONA | C3: 2 | D3: 102 | E3: AGUARDANDO OFICIO | F3: REPROVADO | G3: FÍSICA | H3: RENDA | I3: CRAS + DOCUMENTOS | J3: CADMUT
A4: ALTO DA ALEGRIA (RESERVA) | B4: BILBAO | C4: 3 | D4: 103 | E4: ATENDIMENTO CANCELADO | F4: PENDENCIA | G4: VISUAL | H4: CADIN | I4: DOCUMENTOS | J4: CADIN
A5: ANTERO GOMES | B5: CEUTA | C5: 4 | D5: 104 | E5: CADMUT | F5: SEM DOSSIE | G5: INTELECTUAL | H5: ESTADO CIVIL | I5: CADIN
A6: CANTINHO DO CEU / GAIVOTAS | B6: IBIZA | C6: 5 | D6: 201 | E6: CHACARA DO CONDE | G6: AUDITIVA | H6: SEPARACAO | I6: CRAS + CADIN
A7: CANTINHO DO CEU / OBRAS | B7: LEAO | C7: 6 | D7: 202 | E7: CONFLITO | G7: NANISMO | I7: R.LI.AV.
A8: CASTRO ALVES | B8: MADRID | C8: 7 | D8: 203 | E8: ENVIADO CAIXA | I8: IEME
A9: COCAIA | B9: MELILLA | C9: 8 | D9: 204 | E9: FALECEU
A10: ERUNDINA | B10: PAMPLONA | C10: 9 | D10: 301 | E10: FALTANTE DOSSIÊ
A11: FUMACA | B11: SALAMANCA | C11: 10 | D11: 302 | E11: HABISP ACERTO DE ÁREA
A12: GUAICURI (OBRAS) | B12: TERUEL | C12: 11 | D12: 303 | E12: HABISP AGUARDANDO CRÍTICA
A13: GUAICURI / CIDADE JULIA | B13: VALENCIA | C13: 12 | D13: 304 | E13: HABISP PEND DE ATUALIZ CADASTRAL
A14: JARDIM MIRNA | B14: VALVERDE | C14: 13 | D14: 401 | E14: INDENIZACAO
A15: JARDIM SELMA II | B15: VITORIA | C15: 14 | D15: 402 | E15: PENDENCIA
A16: JARDIM TUBO | C16: 15 | D16: 403 | E16: PERMUTA
A17: LEBLON | D17: 404 | E17: PESQUISA SMADS
A18: MARGINAL DOIS / FUNDAO | D18: 501 | E18: REANALISE
A19: MATA VIRGEM / JD ELDORADO | D19: 502 | E19: RECLUSO
A20: NEBLINA | D20: 503 | E20: RELATÓRIO SOCIAL
A21: NORONHA | D21: 504 | E21: RENDA SUPERIOR
A22: NOVA GRAJAU | E22: RESISTENTE
A23: NOVA MARILDA | E23: TROCA DE TITULARIDADE
A24: NOVA VARGINHA
A25: PABREU / PRAINHA
A26: PENDENCIA GABINETE
A27: PILAO / APURA
A28: PILAO / DOIS
A29: PILAO / PAULISTAS
A30: SANTA AMELIA
A31: VALE VERDE / MONTE VERDE
A32: VILA BREJINHO
A33: VILA NASCENTE
A34: ZR / COSTA BRANCA
A35: VILA RUBI

Sheet QUANT COND
A1: CONDOMINIOS | B1: QUANT
A2: AVILA | B2: =COUNTIF(#REF!,'QUANT COND'!A2) -> #REF!
A3: BARCELONA | B3: =COUNTIF(#REF!,'QUANT COND'!A3) -> #REF!
A4: BILBAO | B4: =COUNTIF(#REF!,'QUANT COND'!A4) -> #REF!
A5: CEUTA | B5: =COUNTIF(#REF!,'QUANT COND'!A5) -> #REF!
A6: IBIZA | B6: =COUNTIF(#REF!,'QUANT COND'!A6) -> #REF!
A7: LEAO | B7: =COUNTIF(#REF!,'QUANT COND'!A7) -> #REF!
A8: MADRID | B8: =COUNTIF(#REF!,'QUANT COND'!A8) -> #REF!
A9: MELILLA | B9: =COUNTIF(#REF!,'QUANT COND'!A9) -> #REF!
A10: PAMPLONA | B10: =COUNTIF(#REF!,'QUANT COND'!A10) -> #REF!
A11: SALAMANCA | B11: =COUNTIF(#REF!,'QUANT COND'!A11) -> #REF!
A12: TERUEL | B12: =COUNTIF(#REF!,'QUANT COND'!A12) -> #REF!
A13: VALENCIA | B13: =COUNTIF(#REF!,'QUANT COND'!A13) -> #REF!
... A15: VITORIA | B15: =COUNTIF(#REF!,'QUANT COND'!A15) -> #REF!

Sheet OFÍCIOS
A1: PLANILHA DE CONFRONTO OFÍCIOS DE INDICAÇÃO COM ENVIADOS CAIXA ECONÔMICA FEDERAL - CEF
A2: TITULAR | B2: CPF | C2: Cônjuge | D2: CPF | E2: OFÍCIO | F2: DATA | G2: STATUS CEF | H2: DATA ENVIO CAIXA | I2: DUPLICIDADE OFÍCIO | J2: DATA | K2: DATA ENVIO CAIXA | L2: OFÍCIO DE INDICAÇÃO | M2: DATA OFÍCIO INDICAÇÃO | O2: NR OFICIO | P2: QUANT | Q2: APROV | R2: REPROV | S2: PEND | T2: SEM STATUS (ANÁLISE) | Y2: CEF BD | Z2: CEF OFICIOS | AA2: CEF PLANILHA
A3: ABEL MEDEIROS FILHO | B3: 27140979871 | E3: 1128 | F3: 42972 | G3: APROVADO | H3: 42979 | O3: 810 | P3: =COUNTIF(OFÍCIOS!E:E,O3) -> 156 | Q3: =COUNTIFS(OFÍCIOS!$E:$E,$O3,OFÍCIOS!$G:$G,"APROVADO") -> 149 | R3: =COUNTIFS(OFÍCIOS!$E:$E,$O3,OFÍCIOS!$G:$G,"REPROVADO") -> 3 | S3: =COUNTIFS(OFÍCIOS!$E:$E,$O3,OFÍCIOS!$G:$G,"PENDENCIA") -> 2 | T3: =COUNTIFS(OFÍCIOS!$E:$E,$O3,OFÍCIOS!$G:$G,"") -> 2 | U3: =SUM(Q3:T3) -> 156 | X3: FEITOS | Y3: 1850 | Z3: 1827 | AA3: =SUM(AA4:AA7) -> 1615
A4: ABELINA FERREIRA DOS SANTOS | B4: 39200633846 | O4: 1417 | P4: =COUNTIF(OFÍCIOS!E:E,O4) -> 42 | Q4: =COUNTIFS(OFÍCIOS!$E:$E,$O4,OFÍCIOS!$G:$G,"APROVADO") -> 36 | R4: =COUNTIFS(OFÍCIOS!$E:$E,$O4,OFÍCIOS!$G:$G,"REPROVADO") -> 3 | S4: =COUNTIFS(OFÍCIOS!$E:$E,$O4,OFÍCIOS!$G:$G,"PENDENCIA") -> 3 | T4: =COUNTIFS(OFÍCIOS!$E:$E,$O4,OFÍCIOS!$G:$G,"") -> 0 | U4: =SUM(Q4:T4) -> 42 | X4: APROVADOS | Y4: 1517 | Z4: 1427 | AA4: 1559
A5: ABIGAIL DE OLIVEIRA PAULINO | B5: 75489104872 | E5: 1752 | F5: 43051 | G5: APROVADO | H5: 43089 | L5: 1759 | O5: 1359 | P5: =COUNTIF(OFÍCIOS!E:E,O5) -> 14 | Q5: =COUNTIFS(OFÍCIOS!$E:$E,$O5,OFÍCIOS!$G:$G,"APROVADO") -> 13 | R5: =COUNTIFS(OFÍCIOS!$E:$E,$O5,OFÍCIOS!$G:$G,"REPROVADO") -> 1 | S5: =COUNTIFS(OFÍCIOS!$E:$E,$O5,OFÍCIOS!$G:$G,"PENDENCIA") -> 0 | T5: =COUNTIFS(OFÍCIOS!$E:$E,$O5,OFÍCIOS!$G:$G,"") -> 0 | U5: =SUM(Q5:T5) -> 14 | X5: REPROVADOS | Y5: 73 | Z5: 79 | AA5: 28
A6: ABILIO OLIVEIRA SANTOS | B6: 43286003620 | O6: 1350 | P6: =COUNTIF(OFÍCIOS!E:E,O6) -> 79 | Q6: =COUNTIFS(OFÍCIOS!$E:$E,$O6,OFÍCIOS!$G:$G,"APROVADO") -> 75 | R6: =COUNTIFS(OFÍCIOS!$E:$E,$O6,OFÍCIOS!$G:$G,"REPROVADO") -> 3 | S6: =COUNTIFS(OFÍCIOS!$E:$E,$O6,OFÍCIOS!$G:$G,"PENDENCIA") -> 0 | T6: =COUNTIFS(OFÍCIOS!$E:$E,$O6,OFÍCIOS!$G:$G,"") -> 1 | U6: =SUM(Q6:T6) -> 79 | X6: PENDENCIAS | Y6: 36 | Z6: 32 | AA6: 11
A7: ABRAHAO SANTOS SILVA | O7: 1343 | P7: =COUNTIF(OFÍCIOS!E:E,O7) -> 6 | Q7: =COUNTIFS(OFÍCIOS!$E:$E,$O7,OFÍCIOS!$G:$G,"APROVADO") -> 5 | R7: =COUNTIFS(OFÍCIOS!$E:$E,$O7,OFÍCIOS!$G:$G,"REPROVADO") -> 0 | S7: =COUNTIFS(OFÍCIOS!$E:$E,$O7,OFÍCIOS!$G:$G,"PENDENCIA") -> 0 | T7: =COUNTIFS(OFÍCIOS!$E:$E,$O7,OFÍCIOS!$G:$G,"") -> 1 | U7: =SUM(Q7:T7) -> 6 | X7: SS / ANALISE | Y7: 224 | Z7: 275 | AA7: 17
A8: ADAIR DA SILVA BARROS | B8: 97443271620 | E8: 1106 | F8: 42965 | G8: APROVADO | H8: 42978 | O8: 1267 | P8: =COUNTIF(OFÍCIOS!E:E,O8) -> 34 | Q8: =COUNTIFS(OFÍCIOS!$E:$E,$O8,OFÍCIOS!$G:$G,"APROVADO") -> 28 | R8: =COUNTIFS(OFÍCIOS!$E:$E,$O8,OFÍCIOS!$G:$G,"REPROVADO") -> 5 | S8: =COUNTIFS(OFÍCIOS!$E:$E,$O8,OFÍCIOS!$G:$G,"PENDENCIA") -> 1 | T8: =COUNTIFS(OFÍCIOS!$E:$E,$O8,OFÍCIOS!$G:$G,"") -> 0 | U8: =SUM(Q8:T8) -> 34
A9: ADALBERTO CARVALHO DE OLIVEIRA | B9: 98058690597 | E9: 423 | F9: 43182 | G9: APROVADO | O9: 1262 | P9: =COUNTIF(OFÍCIOS!E:E,O9) -> 8 | Q9: =COUNTIFS(OFÍCIOS!$E:$E,$O9,OFÍCIOS!$G:$G,"APROVADO") -> 7 | R9: =COUNTIFS(OFÍCIOS!$E:$E,$O9,OFÍCIOS!$G:$G,"REPROVADO") -> 1 | S9: =COUNTIFS(OFÍCIOS!$E:$E,$O9,OFÍCIOS!$G:$G,"PENDENCIA") -> 0 | T9: =COUNTIFS(OFÍCIOS!$E:$E,$O9,OFÍCIOS!$G:$G,"") -> 0 | U9: =SUM(Q9:T9) -> 8
A10: ADALBERTO CAVALCANTE DOS SANTOS | B10: 38088438888 | O10: 1106 | P10: =COUNTIF(OFÍCIOS!E:E,O10) -> 78 | Q10: =COUNTIFS(OFÍCIOS!$E:$E,$O10,OFÍCIOS!$G:$G,"APROVADO") -> 73 | R10: =COUNTIFS(OFÍCIOS!$E:$E,$O10,OFÍCIOS!$G:$G,"REPROVADO") -> 5 | S10: =COUNTIFS(OFÍCIOS!$E:$E,$O10,OFÍCIOS!$G:$G,"PENDENCIA") -> 0 | T10: =COUNTIFS(OFÍCIOS!$E:$E,$O10,OFÍCIOS!$G:$G,"") -> 0 | U10: =SUM(Q10:T10) -> 78
A11: ADALMA MOREIRA DA ROCHA | B11: 26939799869 | E11: 573 | F11: 43224 | O11: 1128 | P11: =COUNTIF(OFÍCIOS!E:E,O11) -> 92 | Q11: =COUNTIFS(OFÍCIOS!$E:$E,$O11,OFÍCIOS!$G:$G,"APROVADO") -> 91 | R11: =COUNTIFS(OFÍCIOS!$E:$E,$O11,OFÍCIOS!$G:$G,"REPROVADO") -> 1 | S11: =COUNTIFS(OFÍCIOS!$E:$E,$O11,OFÍCIOS!$G:$G,"PENDENCIA") -> 0 | T11: =COUNTIFS(OFÍCIOS!$E:$E,$O11,OFÍCIOS!$G:$G,"") -> 0 | U11: =SUM(Q11:T11) -> 92
A12: ADAMILTON PEREIRA DA SILVA ( ALANA ) | B12: 34470559873 | E12: 292 | F12: 43168 | G12: APROVADO | H12: 43182 | L12: 318 | O12: 1214 | P12: =COUNTIF(OFÍCIOS!E:E,O12) -> 76 | Q12: =COUNTIFS(OFÍCIOS!$E:$E,$O12,OFÍCIOS!$G:$G,"APROVADO") -> 71 | R12: =COUNTIFS(OFÍCIOS!$E:$E,$O12,OFÍCIOS!$G:$G,"REPROVADO") -> 3 | S12: =COUNTIFS(OFÍCIOS!$E:$E,$O12,OFÍCIOS!$G:$G,"PENDENCIA") -> 0 | T12: =COUNTIFS(OFÍCIOS!$E:$E,$O12,OFÍCIOS!$G:$G,"") -> 2 | U12: =SUM(Q12:T12) -> 76
A13: ADAO MENDES AGOSTINHO | B13: 14369564808 | O13: 1241 | P13: =COUNTIF(OFÍCIOS!E:E,O13) -> 33 | Q13: =COUNTIFS(OFÍCIOS!$E:$E,$O13,OFÍCIOS!$G:$G,"APROVADO") -> 32 | R13: =COUNTIFS(OFÍCIOS!$E:$E,$O13,OFÍCIOS!$G:$G,"REPROVADO") -> 0 | S13: =COUNTIFS(OFÍCIOS!$E:$E,$O13,OFÍCIOS!$G:$G,"PENDENCIA") -> 1 | T13: =COUNTIFS(OFÍCIOS!$E:$E,$O13,OFÍCIOS!$G:$G,"") -> 0 | U13: =SUM(Q13:T13) -> 33
A14: ADEGMARIO DOS SANTOS | B14: 39544185844 | E14: 810 | F14: 42915 | G14: APROVADO | H14: 42921 | L14: 568-17 | O14: 1422 | P14: =COUNTIF(OFÍCIOS!E:E,O14) -> 7 | Q14: =COUNTIFS(OFÍCIOS!$E:$E,$O14,OFÍCIOS!$G:$G,"APROVADO") -> 7 | R14: =COUNTIFS(OFÍCIOS!$E:$E,$O14,OFÍCIOS!$G:$G,"REPROVADO") -> 0 | S14: =COUNTIFS(OFÍCIOS!$E:$E,$O14,OFÍCIOS!$G:$G,"PENDENCIA") -> 0 | T14: =COUNTIFS(OFÍCIOS!$E:$E,$O14,OFÍCIOS!$G:$G,"") -> 0 | U14: =SUM(Q14:T14) -> 7
A15: ADEILDA GABRIELA CAITANO SILVA | B15: 38772276860 | C15: LUCIANO MANOEL DA SILVA | D15: 3808243457 | O15: 1439 | P15: =COUNTIF(OFÍCIOS!E:E,O15) -> 16 | Q15: =COUNTIFS(OFÍCIOS!$E:$E,$O15,OFÍCIOS!$G:$G,"APROVADO") -> 14 | R15: =COUNTIFS(OFÍCIOS!$E:$E,$O15,OFÍCIOS!$G:$G,"REPROVADO") -> 1 | S15: =COUNTIFS(OFÍCIOS!$E:$E,$O15,OFÍCIOS!$G:$G,"PENDENCIA") -> 1 | T15: =COUNTIFS(OFÍCIOS!$E:$E,$O15,OFÍCIOS!$G:$G,"") -> 0 | U15: =SUM(Q15:T15) -> 16
A16: ADEILDA RODRIGUES DE OLIVEIRA | B16: 21538837846 | C16: PEDRO LUIZ SANTOS OLIVEIRA | D16: 94203180520 | E16: 810 | F16: 42915 | G16: APROVADO | H16: 42921 | L16: 568-17 | O16: 1451 | P16: =COUNTIF(OFÍCIOS!E:E,O16) -> 4 | Q16: =COUNTIFS(OFÍCIOS!$E:$E,$O16,OFÍCIOS!$G:$G,"APROVADO") -> 3 | R16: =COUNTIFS(OFÍCIOS!$E:$E,$O16,OFÍCIOS!$G:$G,"REPROVADO") -> 1 | S16: =COUNTIFS(OFÍCIOS!$E:$E,$O16,OFÍCIOS!$G:$G,"PENDENCIA") -> 0 | T16: =COUNTIFS(OFÍCIOS!$E:$E,$O16,OFÍCIOS!$G:$G,"") -> 0 | U16: =SUM(Q16:T16) -> 4
A17: ADEILDO ADELINO DE CARVALHO | B17: 57455392591 | O17: 1470 | P17: =COUNTIF(OFÍCIOS!E:E,O17) -> 4 | Q17: =COUNTIFS(OFÍCIOS!$E:$E,$O17,OFÍCIOS!$G:$G,"APROVADO") -> 4 | R17: =COUNTIFS(OFÍCIOS!$E:$E,$O17,OFÍCIOS!$G:$G,"REPROVADO") -> 0 | S17: =COUNTIFS(OFÍCIOS!$E:$E,$O17,OFÍCIOS!$G:$G,"PENDENCIA") -> 0 | T17: =COUNTIFS(OFÍCIOS!$E:$E,$O17,OFÍCIOS!$G:$G,"") -> 0 | U17: =SUM(Q17:T17) -> 4
A18: ADELCIDES DA CONCEICAO ALMEIDA | B18: 5304941594 | E18: 1106 | F18: 42965 | G18: APROVADO | H18: 42978 | O18: 1489 | P18: =COUNTIF(OFÍCIOS!E:E,O18) -> 35 | Q18: =COUNTIFS(OFÍCIOS!$E:$E,$O18,OFÍCIOS!$G:$G,"APROVADO") -> 34 | R18: =COUNTIFS(OFÍCIOS!$E:$E,$O18,OFÍCIOS!$G:$G,"REPROVADO") -> 0 | S18: =COUNTIFS(OFÍCIOS!$E:$E,$O18,OFÍCIOS!$G:$G,"PENDENCIA") -> 1 | T18: =COUNTIFS(OFÍCIOS!$E:$E,$O18,OFÍCIOS!$G:$G,"") -> 0 | U18: =SUM(Q18:T18) -> 35
A19: ADELIA MARIA DE OLIVEIRA | B19: 21600057896 | E19: 262 | F19: 43160 | G19: REPROVADO | H19: 43164 | L19: 255 | O19: 1555 | P19: =COUNTIF(OFÍCIOS!E:E,O19) -> 25 | Q19: =COUNTIFS(OFÍCIOS!$E:$E,$O19,OFÍCIOS!$G:$G,"APROVADO") -> 22 | R19: =COUNTIFS(OFÍCIOS!$E:$E,$O19,OFÍCIOS!$G:$G,"REPROVADO") -> 1 | S19: =COUNTIFS(OFÍCIOS!$E:$E,$O19,OFÍCIOS!$G:$G,"PENDENCIA") -> 2 | T19: =COUNTIFS(OFÍCIOS!$E:$E,$O19,OFÍCIOS!$G:$G,"") -> 0 | U19: =SUM(Q19:T19) -> 25
A20: ADEMARIO FERREIRA DOS SANTOS | B20: 18419589802 | O20: 1570 | P20: =COUNTIF(OFÍCIOS!E:E,O20) -> 24 | Q20: =COUNTIFS(OFÍCIOS!$E:$E,$O20,OFÍCIOS!$G:$G,"APROVADO") -> 23 | R20: =COUNTIFS(OFÍCIOS!$E:$E,$O20,OFÍCIOS!$G:$G,"REPROVADO") -> 1 | S20: =COUNTIFS(OFÍCIOS!$E:$E,$O20,OFÍCIOS!$G:$G,"PENDENCIA") -> 0 | T20: =COUNTIFS(OFÍCIOS!$E:$E,$O20,OFÍCIOS!$G:$G,"") -> 0 | U20: =SUM(Q20:T20) -> 24
A21: ADEMIR DA SILVA LIMA | B21: 15538537846 | E21: 573 | F21: 43224 | O21: 1752 | P21: =COUNTIF(OFÍCIOS!E:E,O21) -> 89 | Q21: =COUNTIFS(OFÍCIOS!$E:$E,$O21,OFÍCIOS!$G:$G,"APROVADO") -> 80 | R21: =COUNTIFS(OFÍCIOS!$E:$E,$O21,OFÍCIOS!$G:$G,"REPROVADO") -> 2 | S21: =COUNTIFS(OFÍCIOS!$E:$E,$O21,OFÍCIOS!$G:$G,"PENDENCIA") -> 5 | T21: =COUNTIFS(OFÍCIOS!$E:$E,$O21,OFÍCIOS!$G:$G,"") -> 2 | U21: =SUM(Q21:T21) -> 89
A22: ADENILDE SANTOS DA SILVA | B22: 899837506 | E22: 1824 | F22: 43091 | G22: APROVADO | H22: 43097 | L22: 1828 | O22: 1824 | P22: =COUNTIF(OFÍCIOS!E:E,O22) -> 81 | Q22: =COUNTIFS(OFÍCIOS!$E:$E,$O22,OFÍCIOS!$G:$G,"APROVADO") -> 67 | R22: =COUNTIFS(OFÍCIOS!$E:$E,$O22,OFÍCIOS!$G:$G,"REPROVADO") -> 7 | S22: =COUNTIFS(OFÍCIOS!$E:$E,$O22,OFÍCIOS!$G:$G,"PENDENCIA") -> 6 | T22: =COUNTIFS(OFÍCIOS!$E:$E,$O22,OFÍCIOS!$G:$G,"") -> 1 | U22: =SUM(Q22:T22) -> 81
A23: ADENILSON DA CONCEICAO | B23: 36197160803 | E23: 229 | F23: 43151 | G23: APROVADO | L23: 232 | O23: 1628 | P23: =COUNTIF(OFÍCIOS!E:E,O23) -> 6 | Q23: =COUNTIFS(OFÍCIOS!$E:$E,$O23,OFÍCIOS!$G:$G,"APROVADO") -> 5 | R23: =COUNTIFS(OFÍCIOS!$E:$E,$O23,OFÍCIOS!$G:$G,"REPROVADO") -> 1 | S23: =COUNTIFS(OFÍCIOS!$E:$E,$O23,OFÍCIOS!$G:$G,"PENDENCIA") -> 0 | T23: =COUNTIFS(OFÍCIOS!$E:$E,$O23,OFÍCIOS!$G:$G,"") -> 0 | U23: =SUM(Q23:T23) -> 6
A24: ADENIR MODESTO RIBEIRO | B24: 39248826814 | E24: 292 | F24: 43168 | G24: APROVADO | H24: 43182 | L24: 318 | O24: 608 | P24: =COUNTIF(OFÍCIOS!E:E,O24) -> 35 | Q24: =COUNTIFS(OFÍCIOS!$E:$E,$O24,OFÍCIOS!$G:$G,"APROVADO") -> 31 | R24: =COUNTIFS(OFÍCIOS!$E:$E,$O24,OFÍCIOS!$G:$G,"REPROVADO") -> 3 | S24: =COUNTIFS(OFÍCIOS!$E:$E,$O24,OFÍCIOS!$G:$G,"PENDENCIA") -> 1 | T24: =COUNTIFS(OFÍCIOS!$E:$E,$O24,OFÍCIOS!$G:$G,"") -> 0 | U24: =SUM(Q24:T24) -> 35
A25: ADILINA FARIAS DO NASCIMENTO | B25: 48925276534 | E25: 229 | F25: 43151 | L25: 232 | O25: 527 | P25: =COUNTIF(OFÍCIOS!E:E,O25) -> 29 | Q25: =COUNTIFS(OFÍCIOS!$E:$E,$O25,OFÍCIOS!$G:$G,"APROVADO") -> 0 | R25: =COUNTIFS(OFÍCIOS!$E:$E,$O25,OFÍCIOS!$G:$G,"REPROVADO") -> 0 | S25: =COUNTIFS(OFÍCIOS!$E:$E,$O25,OFÍCIOS!$G:$G,"PENDENCIA") -> 0 | T25: =COUNTIFS(OFÍCIOS!$E:$E,$O25,OFÍCIOS!$G:$G,"") -> 29 | U25: =SUM(Q25:T25) -> 29
A26: ADILSON SOARES DA COSTA | O26: 509 | P26: =COUNTIF(OFÍCIOS!E:E,O26) -> 14 | Q26: =COUNTIFS(OFÍCIOS!$E:$E,$O26,OFÍCIOS!$G:$G,"APROVADO") -> 0 | R26: =COUNTIFS(OFÍCIOS!$E:$E,$O26,OFÍCIOS!$G:$G,"REPROVADO") -> 0 | S26: =COUNTIFS(OFÍCIOS!$E:$E,$O26,OFÍCIOS!$G:$G,"PENDENCIA") -> 0 | T26: =COUNTIFS(OFÍCIOS!$E:$E,$O26,OFÍCIOS!$G:$G,"") -> 14 | U26: =SUM(Q26:T26) -> 14
A27: ADMEIA BARBOSA DE SOUZA | B27: 25894152810 | C27: REINALDO SANTOS REIS | D27: 8263008808 | E27: 292 | F27: 43168 | G27: APROVADO | H27: 43182 | L27: 318 | O27: 292 | P27: =COUNTIF(OFÍCIOS!E:E,O27) -> 233 | Q27: =COUNTIFS(OFÍCIOS!$E:$E,$O27,OFÍCIOS!$G:$G,"APROVADO") -> 212 | R27: =COUNTIFS(OFÍCIOS!$E:$E,$O27,OFÍCIOS!$G:$G,"REPROVADO") -> 9 | S27: =COUNTIFS(OFÍCIOS!$E:$E,$O27,OFÍCIOS!$G:$G,"PENDENCIA") -> 0 | T27: =COUNTIFS(OFÍCIOS!$E:$E,$O27,OFÍCIOS!$G:$G,"") -> 12 | U27: =SUM(Q27:T27) -> 233
A28: ADONES FERREIRA JORGE | B28: 43026389587 | C28: EUNICE FELICIANA BRITO JORGE | D28: 29124464813 | E28: 485 | F28: 43196 | H28: 43206 | L28: 483 | O28: 573 | P28: =COUNTIF(OFÍCIOS!E:E,O28) -> 43 | Q28: =COUNTIFS(OFÍCIOS!$E:$E,$O28,OFÍCIOS!$G:$G,"APROVADO") -> 0 | R28: =COUNTIFS(OFÍCIOS!$E:$E,$O28,OFÍCIOS!$G:$G,"REPROVADO") -> 0 | S28: =COUNTIFS(OFÍCIOS!$E:$E,$O28,OFÍCIOS!$G:$G,"PENDENCIA") -> 0 | T28: =COUNTIFS(OFÍCIOS!$E:$E,$O28,OFÍCIOS!$G:$G,"") -> 43 | U28: =SUM(Q28:T28) -> 43
A29: ADRIANA ALVES DA SILVA | B29: 26245112885 | E29: 262 | F29: 43160 | G29: REPROVADO | H29: 43164 | L29: 255 | O29: 563 | P29: =COUNTIF(OFÍCIOS!E:E,O29) -> 64 | Q29: =COUNTIFS(OFÍCIOS!$E:$E,$O29,OFÍCIOS!$G:$G,"APROVADO") -> 0 | R29: =COUNTIFS(OFÍCIOS!$E:$E,$O29,OFÍCIOS!$G:$G,"REPROVADO") -> 0 | S29: =COUNTIFS(OFÍCIOS!$E:$E,$O29,OFÍCIOS!$G:$G,"PENDENCIA") -> 0 | T29: =COUNTIFS(OFÍCIOS!$E:$E,$O29,OFÍCIOS!$G:$G,"") -> 64 | U29: =SUM(Q29:T29) -> 64
A30: ADRIANA ALVES FERREIRA | B30: 36531080809 | C30: MARCIO ROSA DE MIRA | D30: 22485483892 | E30: 1489 | F30: 43038 | G30: APROVADO | L30: 1647-17 | O30: 443 | P30: =COUNTIF(OFÍCIOS!E:E,O30) -> 66 | Q30: =COUNTIFS(OFÍCIOS!$E:$E,$O30,OFÍCIOS!$G:$G,"APROVADO") -> 0 | R30: =COUNTIFS(OFÍCIOS!$E:$E,$O30,OFÍCIOS!$G:$G,"REPROVADO") -> 0 | S30: =COUNTIFS(OFÍCIOS!$E:$E,$O30,OFÍCIOS!$G:$G,"PENDENCIA") -> 0 | T30: =COUNTIFS(OFÍCIOS!$E:$E,$O30,OFÍCIOS!$G:$G,"") -> 66 | U30: =SUM(Q30:T30) -> 66
A31: ADRIANA APARECIDA ROBERTO | B31: 28147186819 | C31: CARLOS ANTONIO BATISTA DOS SANTOS | D31: 24499714400 | O31: 423 | P31: =COUNTIF(OFÍCIOS!E:E,O31) -> 9 | Q31: =COUNTIFS(OFÍCIOS!$E:$E,$O31,OFÍCIOS!$G:$G,"APROVADO") -> 7 | R31: =COUNTIFS(OFÍCIOS!$E:$E,$O31,OFÍCIOS!$G:$G,"REPROVADO") -> 1 | S31: =COUNTIFS(OFÍCIOS!$E:$E,$O31,OFÍCIOS!$G:$G,"PENDENCIA") -> 0 | T31: =COUNTIFS(OFÍCIOS!$E:$E,$O31,OFÍCIOS!$G:$G,"") -> 1 | U31: =SUM(Q31:T31) -> 9
A32: ADRIANA ARAUJO DE LIMA | B32: 37559228860 | C32: ALEXANDRO ARAUJO DE LIMA | D32: 28072024892 | E32: 1555 | F32: 43049 | G32: APROVADO | O32: 229 | P32: =COUNTIF(OFÍCIOS!E:E,O32) -> 89 | Q32: =COUNTIFS(OFÍCIOS!$E:$E,$O32,OFÍCIOS!$G:$G,"APROVADO") -> 81 | R32: =COUNTIFS(OFÍCIOS!$E:$E,$O32,OFÍCIOS!$G:$G,"REPROVADO") -> 2 | S32: =COUNTIFS(OFÍCIOS!$E:$E,$O32,OFÍCIOS!$G:$G,"PENDENCIA") -> 5 | T32: =COUNTIFS(OFÍCIOS!$E:$E,$O32,OFÍCIOS!$G:$G,"") -> 1 | U32: =SUM(Q32:T32) -> 89
A33: ADRIANA CORDEIRO MACHADO | B33: 23635229822 | C33: ANDERSON DE MORAIS SANTOS | D33: 21668057875 | E33: 262 | F33: 43160 | G33: APROVADO | H33: 43164 | L33: 255 | O33: 262 | P33: =COUNTIF(OFÍCIOS!E:E,O33) -> 224 | Q33: =COUNTIFS(OFÍCIOS!$E:$E,$O33,OFÍCIOS!$G:$G,"APROVADO") -> 181 | R33: =COUNTIFS(OFÍCIOS!$E:$E,$O33,OFÍCIOS!$G:$G,"REPROVADO") -> 15 | S33: =COUNTIFS(OFÍCIOS!$E:$E,$O33,OFÍCIOS!$G:$G,"PENDENCIA") -> 0 | T33: =COUNTIFS(OFÍCIOS!$E:$E,$O33,OFÍCIOS!$G:$G,"") -> 28 | U33: =SUM(Q33:T33) -> 224
A34: ADRIANA DA SILVA | O34: 117 | P34: =COUNTIF(OFÍCIOS!E:E,O34) -> 91 | Q34: =COUNTIFS(OFÍCIOS!$E:$E,$O34,OFÍCIOS!$G:$G,"APROVADO") -> 77 | R34: =COUNTIFS(OFÍCIOS!$E:$E,$O34,OFÍCIOS!$G:$G,"REPROVADO") -> 7 | S34: =COUNTIFS(OFÍCIOS!$E:$E,$O34,OFÍCIOS!$G:$G,"PENDENCIA") -> 5 | T34: =COUNTIFS(OFÍCIOS!$E:$E,$O34,OFÍCIOS!$G:$G,"") -> 2 | U34: =SUM(Q34:T34) -> 91
A35: ADRIANA DA SILVA SANTOS | B35: 40902634844 | C35: GUILHERME DE OLIVEIRA SOUZA | D35: 23795007895 | E35: 117 | F35: 43117 | G35: APROVADO | H35: 43151 | L35: 118-18 | O35: 485 | P35: =COUNTIF(OFÍCIOS!E:E,O35) -> 23 | Q35: =COUNTIFS(OFÍCIOS!$E:$E,$O35,OFÍCIOS!$G:$G,"APROVADO") -> 0 | R35: =COUNTIFS(OFÍCIOS!$E:$E,$O35,OFÍCIOS!$G:$G,"REPROVADO") -> 3 | S35: =COUNTIFS(OFÍCIOS!$E:$E,$O35,OFÍCIOS!$G:$G,"PENDENCIA") -> 0 | T35: =COUNTIFS(OFÍCIOS!$E:$E,$O35,OFÍCIOS!$G:$G,"") -> 20 | U35: =SUM(Q35:T35) -> 23
A36: ADRIANA DE SA ROCHA | B36: 39615629898 | C36: MARCELO FERNANDES LIMA | D36: 43328275894 | E36: 423 | F36: 43182 | G36: APROVADO | O36: 85 | P36: =COUNTIF(OFÍCIOS!E:E,O36) -> 93 | Q36: =COUNTIFS(OFÍCIOS!$E:$E,$O36,OFÍCIOS!$G:$G,"APROVADO") -> 86 | R36: =COUNTIFS(OFÍCIOS!$E:$E,$O36,OFÍCIOS!$G:$G,"REPROVADO") -> 4 | S36: =COUNTIFS(OFÍCIOS!$E:$E,$O36,OFÍCIOS!$G:$G,"PENDENCIA") -> 3 | T36: =COUNTIFS(OFÍCIOS!$E:$E,$O36,OFÍCIOS!$G:$G,"") -> 0 | U36: =SUM(Q36:T36) -> 93
A37: ADRIANA DOS SANTOS | P37: =COUNTIF(OFÍCIOS!E:E,O37) -> 0 | Q37: =COUNTIFS(OFÍCIOS!$E:$E,$O37,OFÍCIOS!$G:$G,"APROVADO") -> 0 | R37: =COUNTIFS(OFÍCIOS!$E:$E,$O37,OFÍCIOS!$G:$G,"REPROVADO") -> 0 | S37: =COUNTIFS(OFÍCIOS!$E:$E,$O37,OFÍCIOS!$G:$G,"PENDENCIA") -> 0 | T37: =COUNTIFS(OFÍCIOS!$E:$E,$O37,OFÍCIOS!$G:$G,"") -> 0 | U37: =SUM(Q37:T37) -> 0
A38: ADRIANA FERREIRA DA SILVA | C38: LOURIVAL CANDIDO SILVA | P38: =COUNTIF(OFÍCIOS!E:E,O38) -> 0 | Q38: =COUNTIFS(OFÍCIOS!$E:$E,$O38,OFÍCIOS!$G:$G,"APROVADO") -> 0 | R38: =COUNTIFS(OFÍCIOS!$E:$E,$O38,OFÍCIOS!$G:$G,"REPROVADO") -> 0 | S38: =COUNTIFS(OFÍCIOS!$E:$E,$O38,OFÍCIOS!$G:$G,"PENDENCIA") -> 0 | T38: =COUNTIFS(OFÍCIOS!$E:$E,$O38,OFÍCIOS!$G:$G,"") -> 0 | U38: =SUM(Q38:T38) -> 0
A39: ADRIANA HELENA DE MORAIS | B39: 14268808809 | E39: 262 | F39: 43160 | G39: APROVADO | H39: 43164 | L39: 255 | P39: =COUNTIF(OFÍCIOS!E:E,O39) -> 0 | Q39: =COUNTIFS(OFÍCIOS!$E:$E,$O39,OFÍCIOS!$G:$G,"APROVADO") -> 0 | R39: =COUNTIFS(OFÍCIOS!$E:$E,$O39,OFÍCIOS!$G:$G,"REPROVADO") -> 0 | S39: =COUNTIFS(OFÍCIOS!$E:$E,$O39,OFÍCIOS!$G:$G,"PENDENCIA") -> 0 | T39: =COUNTIFS(OFÍCIOS!$E:$E,$O39,OFÍCIOS!$G:$G,"") -> 0 | U39: =SUM(Q39:T39) -> 0
A40: ADRIANA JESUS DA CUNHA | B40: 29628693867 | E40: 292 | F40: 43168 | G40: APROVADO | H40: 43182 | L40: 318 | P40: =COUNTIF(OFÍCIOS!E:E,O40) -> 0 | Q40: =COUNTIFS(OFÍCIOS!$E:$E,$O40,OFÍCIOS!$G:$G,"APROVADO") -> 0 | R40: =COUNTIFS(OFÍCIOS!$E:$E,$O40,OFÍCIOS!$G:$G,"REPROVADO") -> 0 | S40: =COUNTIFS(OFÍCIOS!$E:$E,$O40,OFÍCIOS!$G:$G,"PENDENCIA") -> 0 | T40: =COUNTIFS(OFÍCIOS!$E:$E,$O40,OFÍCIOS!$G:$G,"") -> 0 | U40: =SUM(Q40:T40) -> 0
...

Sheet Planilha2
M2: 6014.2022/0003314-1 | R2: SELO | S2: PROPRIETÁRIO | T2: CPF
B3: PARAISÓPOLIS/ANTONICO | C3: 4 | D3: 029/0023/B | E3: FRANCISCO WILLIAN GOMES DO NASCIMENTO | F3: 58.276.710-6 | G3: 519.576.918-40 | M3: 6014.2022/0003318-4 | R3: 025/0005/D | S3: DAIANA DE MOURA BATISTA | T3: 465.961.548-07
B4: PARAISÓPOLIS/ANTONICO | C4: 4 | D4: 029/0036/G | E4: JANAINA SANTOS DE MELO | F4: 52.949.011-0 | G4: 417.618.098-65 | M4: 6014.2022/0003489-0 | R4: 025/0005/F | S4: ALESSANDRA CLEMENTE DA SILVA | T4: 383.679.488-82
B5: PARAISÓPOLIS/ANTONICO | C5: 4 | D5: 029/0036/H | E5: DJAILSON FREITAS DE LIMA | F5: 57.410.954-7 | G5: 105.534.934-00 | M5: 6014.2022/0003413-0 | R5: 025/0006/E | S5: LUANA CANDIDA DA SILVA | T5: 422.356.908/23
B6: PARAISÓPOLIS/ANTONICO | C6: 4 | D6: 029/0043/B | E6: MARIVANEIDE MOREIRA SILVA | F6: 50.175.775-2 | G6: 371.473.818-58 | M6: 6014.2022/0003286-2 | R6: 025/0007/B | S6: MARIANA PEREIRA DUARTE | T6: 484.098.078-07
B7: PARAISÓPOLIS/ANTONICO | C7: 4 | D7: 029/0049/A | E7: FLAVIA SANTOS SOUZA | F7: 49.345.172-9 | G7: 435.377.298-80 | M7: 6014.2022/0003320-6 | R7: 025/0010/C | S7: CLOVIS RODRIGUES DA SILVA | T7: 060.045.884-90
B8: PARAISÓPOLIS/ANTONICO | C8: 4 | D8: 029/0055/A | E8: GLEICON CARLOS CESAR GOMES | F8: 49.183.499-8 | G8: 344.351.508-83 | M8: 6014.2022/0002870-9 | R8: 025/0012/B | S8: JAQUELINE DE JESUS SANTOS | T8: 057.048.705-62
B9: PARAISÓPOLIS/ANTONICO | C9: 4 | D9: 029/0056/A | E9: MARIA GERLANE DE SOUZA BOÍBA | F9: 57.816.422-X | G9: 494.665.018-01 | M9: 6014.2022/0003634-5 | R9: 025/0013/D | S9: MARLENE PORTO DA SILVA | T9: 324.983.298-70
B10: PARAISÓPOLIS/ANTONICO | C10: 4 | D10: 029/0056/B | E10: MAICO JONHATAS ALVARES PINTO | F10: 53.032.399-0 | G10: 428.355.978-40 | M10: 6014.2022/0003262-5 | R10: 025/0022/A | S10: VERA LUCIA SILVA | T10: 191.039.398-39
B11: PARAISÓPOLIS/ANTONICO | C11: 4 | D11: 029/0085/F | E11: ORLANDO CONCEIÇÃO SANTIAGO | F11: 41.041.836-5 | G11: 353.178.248-77 | M11: 6014.2022/0003332-0 | R11: 027/0004/B | S11: GILMARIO RODRIGUES FERREIRA | T11: 313.783.998-03
M12: 6014.2022/0003263-3 | R12: 027/0005/A | S12: JOSÉ LAILTON DOS SANTOS | T12: 406.718.788-24
D13: 024/0041/D | E13: MARICÉLIA OLIMPIO DE OLIVEIRA | M13: 6014.2022/0003352-4 | R13: 027/0005/C | S13: CARLITO IZIDORIO BISPO | T13: 022.817.018-40
D14: 024/0069/A | E14: LOURISMAR LIMA BRAGA | M14: 6014.2022/0003161-0 | R14: 027/0005/D | S14: MATEUS LEITE DE MELO | T14: 102.388.884-01
M15: 6014.2022/0002739-7 | R15: 027/0005/F | S15: CRISTIAN DE JESUS DIAS | T15: 101.526.245-70
M16: 6014.2022/0003157-2 | R16: 027/0005/G | S16: VINICIUS LINS MELO | T16: 509.886.698-70
M17: 6014.2022/0003160-2 | R17: 027/0005/H | S17: CRICIELTON MARQUES DA SILVA PEREIRA | T17: 482.097.038-03
M18: 6014.2022/0003353-2 | R18: 027/0005/I | S18: LUCAS ALVES DE ANDRADE FERREIRA | T18: 469.732.328-92
E19: 6014.2022/0002993-4 | M19: 6014.2022/0002844-0 | R19: 027/0005/J | S19: LUIS HENRIQUE DE CARVALHO BARBOSA | T19: 506.599.238-07
E20: 6014.2022/0003157-2 | M20: 6014.2022/0002952-7 | R20: 027/0006/A | S20: NILANDE DA SILVA SOUZA | T20: 333.539.708-86
E21: 6014.2022/0002667-6 | M21: 6014.2022/0003496-2 | R21: 027/0016/A | S21: DANILO DA SILVA MIRANDA | T21: 432.676.048-69
M22: 6014.2022/0002687-0 | R22: 027/0016/B | S22: EDNADYJA ANDRELLI VITAL | T22: 371.476.568-90
M23: 6014.2022/0002677-3 | R23: 027/0016/C | S23: SEVERINO MIRANDA DE SOUSA | T23: 170.908.718-86
M24: 6014.2022/0003638-8 | R24: 027/0016/D | S24: VALMIRA SILVA ARAUJO | T24: 014.002.428-00
M25: 6014.2022/0002747-8 | R25: 027/0018/C | S25: LUCILÉIA DE ARAUJO LIMA | T25: 282.762.598-98
M26: 6014.2022/0003196-3 | R26: 027/0018/D | S26: REGINALDO NASCIMENTO DA SILVA | T26: 157.653.378-64
M27: 6014.2022/0002665-0 | R27: 027/0018/F | S27: ALBERT DE ARAUJO KELLER | T27: 435.878.808-40
M28: 6014.2022/0003497-0 | R28: 027/0018/H | S28: CRISTIANE DE ARAÚJO KELLER | T28: 403.961.018-01
M29: 6014.2022/0002834-2 | R29: 027/0019/A | S29: DANIELA MARIA DE JESUS | T29: 330.092.718-83
M30: 6014.2022/0003298-6
M31: 6014.2022/0002673-0
M32: 6014.2022/0002683-8
M33: 6014.2022/0003261-7
M34: 6014.2022/0002679-0
M35: 6014.2022/0002894-6
M36: 6014.2022/0002901-2
M37: 6014.2022/0002681-1
M38: 6014.2022/0003047-9
M39: 6014.2022/0003641-8
M40: 6014.2022/0003347-8
M41: 6014.2022/0003350-8
...

Sheet Planilha3
B3: ÁREA | C3: FASE | D3: SELO | E3: PROPRIETÁRIO | F3: CPF | G3: STATUS | H3: VALOR INDENIZAÇÃO
B4: PARAISÓPOLIS/ANTONICO | C4: 2 | D4: 024/0005/B | E4: MARIA JOSE HONORIO SILVA | F4: 397.255.294-72 | G4: RECUSA INDENIZAÇÃO | H4: 66528.26
B5: PARAISÓPOLIS/ANTONICO | C5: 2 | D5: 024/0005/C | E5: DOUGLAS FELIX DA SILVA | F5: 350.792.428-50 | G5: RECUSA INDENIZAÇÃO | H5: 60000
B6: PARAISÓPOLIS/ANTONICO | C6: 2 | D6: 024/0005/D | E6: DOUGLAS FELIX DA SILVA | F6: 350.792.428-50 | G6: RECUSA INDENIZAÇÃO | H6: 60000
B7: PARAISÓPOLIS/ANTONICO | C7: 2 | D7: 024/0045/A | E7: JOVINA DE JESUS SANTANA | F7: 252.848.568-99 | G7: RECUSA INDENIZAÇÃO | H7: 71112.51
B8: PARAISÓPOLIS/ANTONICO | C8: 2 | D8: 024/0046/A | E8: JOÃO BRASILINO DE SOUSA | F8: 014.102.728-26 | G8: RECUSA INDENIZAÇÃO | H8: 100370.59
B9: PARAISÓPOLIS/ANTONICO | C9: 2 | D9: 024/0047/F | E9: ROSA HELENA DE SOUZA | F9: 291.466.998-48 | G9: RECUSA INDENIZAÇÃO | H9: 60000
B10: PARAISÓPOLIS/ANTONICO | C10: 2 | D10: 024/0053/A | E10: SELMA SOARES SANTOS DE OLIVEIRA | F10: 324.973.128-50 | G10: RECUSA INDENIZAÇÃO | H10: 60000
B11: PARAISÓPOLIS/ANTONICO | C11: 2 | D11: 024/0077/A | E11: PROPRIETÁRIO NÃO IDENTIFICADO | F11: -- | G11: RECUSA INDENIZAÇÃO | H11: 60000
B12: PARAISÓPOLIS/ANTONICO | C12: 2 | D12: 024/0077/B | E12: LUCIANA FRANCILINO DE LIMA | F12: 296.566.438-60 | G12: RECUSA INDENIZAÇÃO | H12: 87351.82
B13: PARAISÓPOLIS/ANTONICO | C13: 2 | D13: 024/0079/D | E13: EUDES GONÇALVES CAVALCANTE | F13: 064.025.638-46 | G13: RECUSA INDENIZAÇÃO | H13: 56418.89
B14: PARAISÓPOLIS/ANTONICO | C14: 2 | D14: 024/0079/G | E14: EUDES GONÇALVES CAVALCANTI | F14: 064.025.638-46 | G14: RECUSA INDENIZAÇÃO | H14: 60000
B15: PARAISÓPOLIS/ANTONICO | C15: 4 | D15: 029/0016/C | E15: ADINALDO GOMES DA SILVA | F15: 975.984.883-04 | G15: RECUSA INDENIZAÇÃO | H15: 60000
... B17: PARAISÓPOLIS/ANTONICO | C17: 4 | D17: 029/0086/D | E17: EDUARDO FERNANDES | F17: -- | G17: RECUSA INDENIZAÇÃO | H17: 60000
B23: PARAISÓPOLIS/ANTONICO | C23: 2 | D23: 024/0079/D | E23: EUDES GONÇALVES CAVALCANTE | F23: 064.025.638-46 | G23: ESTUDO DE CASO
B24: PARAISÓPOLIS/ANTONICO | C24: 2 | D24: 024/0079/E | E24: DANIELE COSTA | F24: 374.435.458-00 | G24: ESTUDO DE CASO
B25: PARAISÓPOLIS/ANTONICO | C25: 2 | D25: 024/0079/F | G25: ESTUDO DE CASO
B26: PARAISÓPOLIS/ANTONICO | C26: 2 | D26: 024/0079/G | E26: EUDES GONÇALVES CAVALCANTI | F26: 064.025.638-46 | G26: ESTUDO DE CASO
B27: PARAISÓPOLIS/ANTONICO | C27: 2 | D27: 024/0079/J | E27: ELIO NEVES DE SOUZA | F27: 350.318.858-40 | G27: RECUSA
B28: PARAISÓPOLIS/ANTONICO | C28: 2 | D28: 024/0082/A | E28: IVÃ CERQUEIRA LENARES | F28: 006.868.775-35 | G28: PENDENTE
B29: PARAISÓPOLIS/ANTONICO | C29: 2 | D29: 024/0082/D | E29: JOÃO VITOR DE SANTANA | F29: 534.193.048-70 | G29: ESTUDO DE CASO
B30: PARAISÓPOLIS/ANTONICO | C30: 2 | D30: 024/0088/K | E30: MARIA APARECIDA FLECKENSTEIN VIEIRA | F30: 304.821.048-21 | G30: ESTUDO DE CASO
B31: PARAISÓPOLIS/ANTONICO | C31: 2 | D31: 024/0088/M | E31: PROPRIETÁRIO NÃO IDENTIFICADO | F31: N/A | G31: PROPRIETÁRIO NÃO IDENTIFICADO
B32: PARAISÓPOLIS/ANTONICO | C32: 2 | D32: 027/0002/E | G32: PROPRIETÁRIO NÃO IDENTIFICADO
B33: PARAISÓPOLIS/ANTONICO | C33: 2 | D33: 027/0012/C | G33: PROPRIETÁRIO NÃO IDENTIFICADO

Sheet Planilha4
C6: ORDEM | D6: SELO | E6: DATA PAGAMENTO | F6: DATA ENTREGA IMÓVEL | G6: SITUAÇÃO ATUAL IMÓVEL
C7: 1 | D7: 024/0049/B | E7: 45068 | F7: AGUARDANDO | G7: LIBERADO DEMOLIÇÃO
C8: 2 | D8: 029/0036/O | E8: 45068 | F8: AGUARDANDO | G8: LIBERADO DEMOLIÇÃO
C9: 3 | D9: 031/0028/D | E9: 45068 | F9: 44894 | G9: DESCARACTERIZADO
C10: 4 | D10: 031/0034/H | E10: 45068 | F10: AGUARDANDO | G10: LIBERADO DEMOLIÇÃO
C11: 5 | D11: 024/0093/B | E11: 45065 | F11: AGUARDANDO | G11: LIBERADO DEMOLIÇÃO
C12: 6 | D12: 029/0036/P | E12: 45065 | F12: AGUARDANDO | G12: LIBERADO DEMOLIÇÃO
C13: 7 | D13: 029/0042/A | E13: 45065 | F13: AGUARDANDO | G13: LIBERADO DEMOLIÇÃO
C14: 8 | D14: 029/0081/A | E14: 45065 | F14: 44526 | G14: DEMOLIDO
C15: 9 | D15: 029/0083/A | E15: 45065 | F15: 44642 | G15: DEMOLIDO
C16: 10 | D16: 031/0020/B | E16: 45065 | F16: 44694 | G16: DESCARACTERIZADO
C17: 11 | D17: 031/0023/B | E17: 45065 | F17: AGUARDANDO | G17: LIBERADO DEMOLIÇÃO
C18: 12 | D18: 031/0024/A | E18: 45065 | F18: 44659 | G18: DESCARACTERIZADO
C19: 13 | D19: 024/0079/A | E19: 45064 | F19: AGUARDANDO | G19: LIBERADO DEMOLIÇÃO
C20: 14 | D20: 024/0082/H | E20: 45064 | F20: AGUARDANDO | G20: LIBERADO DEMOLIÇÃO
C21: 15 | D21: 029/0022/A | E21: 45064 | F21: AGUARDANDO | G21: LIBERADO DEMOLIÇÃO
C22: 16 | D22: 029/0022/D | E22: 45064 | F22: AGUARDANDO | G22: LIBERADO DEMOLIÇÃO
C23: 17 | D23: 029/0035/A | E23: 45064 | F23: 44859 | G23: DEMOLIDO
C24: 18 | D24: 029/0036/L | E24: 45064 | F24: AGUARDANDO | G24: LIBERADO DEMOLIÇÃO
C25: 19 | D25: 029/0036/N | E25: 45064 | F25: AGUARDANDO | G25: LIBERADO DEMOLIÇÃO
C26: 20 | D26: 031/0035/A | E26: 45064 | F26: 44643 | G26: DESCARACTERIZADO
C27: 21 | D27: 031/0035/F | E27: 45064 | F27: 44638 | G27: DESCARACTERIZADO
C28: 22 | D28: 031/0058/E | E28: 45064 | F28: AGUARDANDO | G28: LIBERADO DEMOLIÇÃO
C29: 23 | D29: 031/0058/H | E29: 45064 | F29: AGUARDANDO | G29: LIBERADO DEMOLIÇÃO
C30: 24 | D30: 031/0078/G | E30: 45064 | F30: AGUARDANDO | G30: LIBERADO DEMOLIÇÃO
C31: 25 | D31: 024/0004/B | E31: 45063 | F31: AGUARDANDO | G31: LIBERADO DEMOLIÇÃO
C32: 26 | D32: 024/0050/B | E32: 45063 | F32: AGUARDANDO | G32: LIBERADO DEMOLIÇÃO
C33: 27 | D33: 024/0074/A | E33: 45063 | F33: AGUARDANDO | G33: LIBERADO DEMOLIÇÃO
C34: 28 | D34: 024/0074/D | E34: 45063 | F34: AGUARDANDO | G34: LIBERADO DEMOLIÇÃO
C35: 29 | D35: 024/0078/B | E35: 45063 | F35: AGUARDANDO | G35: LIBERADO DEMOLIÇÃO
C36: 30 | D36: 024/0082/C | E36: 45063 | F36: AGUARDANDO | G36: LIBERADO DEMOLIÇÃO
C37: 31 | D37: 024/0093/A | E37: 45063 | F37: AGUARDANDO | G37: LIBERADO DEMOLIÇÃO
C38: 32 | D38: 031/0022/B | E38: 45063 | F38: 44655 | G38: DESCARACTERIZADO
C39: 33 | D39: 031/0028/L | E39: 45063 | F39: 44659 | G39: DESCARACTERIZADO
C40: 34 | D40: 031/0030/B | E40: 45063 | F40: AGUARDANDO | G40: LIBERADO DEMOLIÇÃO
C41: 35 | D41: 031/0030/C | E41: 45063 | F41: 44642 | G41: DESCARACTERIZADO
C42: 36 | D42: 031/0033/E | E42: 45063 | F42: 44638 | G42: DESCARACTERIZADO
C43: 37 | D43: 031/0034/A | E43: 45063 | F43: AGUARDANDO | G43: LIBERADO DEMOLIÇÃO
C44: 38 | D44: 031/0034/B | E44: 45063 | F44: AGUARDANDO | G44: LIBERADO DEMOLIÇÃO
C45: 39 | D45: 031/0034/E | E45: 45063 | F45: AGUARDANDO | G45: LIBERADO DEMOLIÇÃO
...

Sheet Planilha5
D3: ÁREA | E3: No PROCESSO SEI (INDENIZAÇÃO) | F3: VALOR COM BONIFICAÇÃO | H3: ÁREA | I3: FASE | J3: SELO | K3: PENDÊNCIA
D4: PARAISÓPOLIS/ANTONICO | E4: 6014.2023/0002356-3 | F4: 60000 | H4: PARAISÓPOLIS/ANTONICO | I4: 2 | J4: 024/0029/A | K4: FALTA VALOR PLANILHA
D5: PARAISÓPOLIS/ANTONICO | E5: 6014.2023/0001968-0 | F5: 53382.82 | H5: PARAISÓPOLIS/ANTONICO | I5: 2 | J5: 024/0029/B | K5: FALTA VALOR PLANILHA
D6: PARAISÓPOLIS/ANTONICO | E6: 6014.2023/0001973-6 | F6: 55091.16 | H6: PARAISÓPOLIS/ANTONICO | I6: 2 | J6: 024/0092/A | K6: FALTA VALOR PLANILHA
D7: PARAISÓPOLIS/ANTONICO | E7: 6014.2023/0001445-9 | F7: 71112.51 | H7: PARAISÓPOLIS/ANTONICO | I7: 2 | J7: 024/0098/A | K7: FALTA VALOR PLANILHA
D8: PARAISÓPOLIS/ANTONICO | E8: 6014.2023/0002108-0 | F8: 60000 | H8: PARAISÓPOLIS/ANTONICO | I8: 2 | J8: 024/0106/A | K8: FALTA VALOR PLANILHA
D9: PARAISÓPOLIS/ANTONICO | E9: 6014.2023/0001334-7 | F9: 60000 | H9: PARAISÓPOLIS/ANTONICO | I9: 2 | J9: 024/0106/B | K9: FALTA VALOR PLANILHA
D10: PARAISÓPOLIS/ANTONICO | E10: 6014.2023/0001523-4 | F10: 60000 | H10: PARAISÓPOLIS/ANTONICO | I10: 3 | J10: 025/0005/A | K10: FALTA VALOR PLANILHA
D11: PARAISÓPOLIS/ANTONICO | E11: 6014.2023/0001799-7 | F11: 60000 | H11: PARAISÓPOLIS/ANTONICO | I11: 3 | J11: 025/0012/D | K11: FALTA VALOR PLANILHA
D12: PARAISÓPOLIS/ANTONICO | E12: 6014.2023/0000796-7 | F12: 48801.81 | H12: PARAISÓPOLIS/ANTONICO | I12: 3 | J12: 025/0012/E | K12: FALTA LAUDO, VALOR PLANILHA E RRT
D13: PARAISÓPOLIS/ANTONICO | E13: 6014.2023/0003032-2 | F13: 60000 | H13: PARAISÓPOLIS/ANTONICO | I13: 3 | J13: 025/0012/F | K13: FALTA LAUDO, VALOR PLANILHA E RRT
D14: PARAISÓPOLIS/ANTONICO | E14: 6014.2023/0001144-1 | F14: 48087.05 | H14: PARAISÓPOLIS/ANTONICO | I14: 3 | J14: 025/0016/D | K14: FALTA VALOR PLANILHA
D15: PARAISÓPOLIS/ANTONICO | E15: 6014.2023/0002532-9 | F15: 56900.74 | H15: PARAISÓPOLIS/ANTONICO | I15: 3 | J15: 025/0016/E | K15: FALTA LAUDO, VALOR PLANILHA E RRT
... D25: PARAISÓPOLIS/ANTONICO | E25: 6014.2023/0002420-9 | F25: 40219.46 | H25: PARAISÓPOLIS/ANTONICO | I25: 4 | J25: 031/0039/D | K25: FALTA RATIFICAÇÃO
D26: PARAISÓPOLIS/ANTONICO | E26: 6014.2023/0002345-8 | F26: 34607.3
D27: PARAISÓPOLIS/ANTONICO | E27: 6014.2023/0002337-7 | F27: 36263.09
D28: PARAISÓPOLIS/ANTONICO | E28: 6014.2023/0002328-8 | F28: 35849.73
D29: PARAISÓPOLIS/ANTONICO | E29: 6014.2023/0002535-3 | F29: 33958.27
D30: PARAISÓPOLIS/ANTONICO | E30: 6014.2023/0002536-1 | F30: 35807.66
D31: PARAISÓPOLIS/ANTONICO | E31: 6014.2023/0002571-0 | F31: 34233.85
D32: PARAISÓPOLIS/ANTONICO | E32: 6014.2023/0002595-7 | F32: 43197.84
D33: PARAISÓPOLIS/ANTONICO | E33: 6014.2023/0002596-5 | F33: 40476.01
D34: PARAISÓPOLIS/ANTONICO | E34: 6014.2023/0002597-3 | F34: 40038.41
D35: PARAISÓPOLIS/ANTONICO | E35: 6014.2023/0002600-7 | F35: 38035.89
D36: PARAISÓPOLIS/ANTONICO | E36: 6014.2023/0002605-8 | F36: 35969.52
D37: PARAISÓPOLIS/ANTONICO | E37: 6014.2023/0002608-2 | F37: 42410.14
... D96: PARAISÓPOLIS/ANTONICO | E96: 6014.2023/0003154-0 | F96: 57433.2
E98: VALOR TOTAL | F98: =SUM(F4:F97) -> 4865724.7
